Workbook
Name _05_04_2009: #REF!
Name _05_04_2009: #REF!
Name _05_04_2009: #REF!
Name _05_04_2009: #REF!
Name _05_04_2009: #REF!
Name AA: #REF!
Name AA: #REF!
Name AA: #REF!
Name AA: #REF!
Name AA: #REF!
Name aaa: #REF!
Name aaa: #REF!
Name aaa: #REF!
Name aaa: #REF!
Name aaa: #REF!
Name aaaaa: #REF!
Name aaaaa: #REF!
Name aaaaa: #REF!
Name aaaaa: #REF!
Name aaaaa: #REF!
Name aaaaaaaaaa: #REF!
Name aaaaaaaaaa: #REF!
Name aaaaaaaaaa: #REF!
Name aaaaaaaaaa: #REF!
Name aaaaaaaaaa: #REF!
Name AAAAAAAAAAAAA: #REF!
Name AAAAAAAAAAAAA: #REF!
Name AAAAAAAAAAAAA: #REF!
Name AAAAAAAAAAAAA: #REF!
Name AAAAAAAAAAAAA: #REF!
Name AAAAAAAAAAAAAAAAAA: #REF!
Name AAAAAAAAAAAAAAAAAA: #REF!
Name AAAAAAAAAAAAAAAAAA: #REF!
Name AAAAAAAAAAAAAAAAAA: #REF!
Name AAAAAAAAAAAAAAAAAA: #REF!
Name AAAAAAAAAAAAAAAAAAAAA: #REF!
Name AAAAAAAAAAAAAAAAAAAAA: #REF!
Name AAAAAAAAAAAAAAAAAAAAA: #REF!
Name AAAAAAAAAAAAAAAAAAAAA: #REF!
Name AAAAAAAAAAAAAAAAAAAAA: #REF!
Name AAAAAAAAAAAAAAAAAAAAAAAAAAA: #REF!
Name AAAAAAAAAAAAAAAAAAAAAAAAAAA: #REF!
Name AAAAAAAAAAAAAAAAAAAAAAAAAAA: #REF!
Name AAAAAAAAAAAAAAAAAAAAAAAAAAA: #REF!
Name AAAAAAAAAAAAAAAAAAAAAAAAAAA: #REF!
Name AAAAAAAAAAAAAAAAAAAAAAAAAAAA: #REF!
Name AAAAAAAAAAAAAAAAAAAAAAAAAAAA: #REF!
Name AAAAAAAAAAAAAAAAAAAAAAAAAAAA: #REF!
Name AAAAAAAAAAAAAAAAAAAAAAAAAAAA: #REF!
Name AAAAAAAAAAAAAAAAAAAAAAAAAAAA: #REF!
Name AAAAAAAAAAAAAAAAAAAAAAAAAAAAAA: #REF!
Name AAAAAAAAAAAAAAAAAAAAAAAAAAAAAA: #REF!
Name AAAAAAAAAAAAAAAAAAAAAAAAAAAAAA: #REF!
Name AAAAAAAAAAAAAAAAAAAAAAAAAAAAAA: #REF!
Name AAAAAAAAAAAAAAAAAAAAAAAAAAAAAA: #REF!
Name AAAAAAAAAAAAAAAAAAAAAAAAAAAAAAA: #REF!
Name AAAAAAAAAAAAAAAAAAAAAAAAAAAAAAA: #REF!
Name AAAAAAAAAAAAAAAAAAAAAAAAAAAAAAA: #REF!
Name AAAAAAAAAAAAAAAAAAAAAAAAAAAAAAA: #REF!
Name AAAAAAAAAAAAAAAAAAAAAAAAAAAAAAA: #REF!

Sheet MASTERLIST ASSET
A1: APPROVED LIST MASTERLIST ASSET FOR HOSPITAL SHAH ALAM 2022
A3: No. | B3: Service | C3: Period Name | D3: Hospital | E3: Department | F3: User Area | G3: Description UMDNS | H3: Asset Description | I3: Equipment Group | J3: Equipment Group | K3: Asset Type Code | L3: Qty | M3: Asset No. | N3: Purchase Cost (RM) | O3: Total Purchase Cost (RM) | P3: Status | Q3: Date Start Service | R3: Warranty Expiry Date | S3: Date Stop Service
A4: 1 | B4: BEMS | C4: P0 | D4: Hospital Shah Alam, Selangor | E4: Jabatan Kecemasan & Trauma | F4: Jabatan Kecemasan & Trauma | G4: Compressors, Medical-Air | H4: COMPRESSOR AIR (DENTAL) | I4: Therapeutic | J4: Basic | K4: 10-972 | L4: 1 | M4: KKM/JKN/HSA/10-05-01/H/15/4893 | N4: 13000 | O4: =N4*L4 -> 13000 | Q4: 46023
A5: 2 | B5: BEMS | C5: P0 | D5: Hospital Shah Alam, Selangor | E5: Jabatan Kecemasan & Trauma | F5: Jabatan Kecemasan & Trauma | G5: Compressors, Medical-Air | H5: SUCTION UNIT (DENTAL) | I5: Therapeutic | J5: Basic | K5: 10-972 | L5: 1 | M5: KKM/JKN/HSA/10-05-01/H/15/466 | N5: 14000 | O5: =N5*L5 -> 14000 | Q5: 46023
A6: 3 | B6: BEMS | C6: P0 | D6: Hospital Shah Alam, Selangor | E6: Jabatan Bedah Mulut & Pergigian Pediatrik | F6: Klinik Bedah Mulut & Klinik Pergigian Pediatrik | G6: Compressors, Medical-Air | H6: CENTRAL COMPRESSOR (DENTAL) | I6: Therapeutic | J6: Basic | K6: 10-972 | L6: 1 | M6: KKM/JKN/HSA/10-05-01/H/15/4891 | N6: 78000 | O6: =N6*L6 -> 78000 | Q6: 46023
A7: 4 | B7: BEMS | C7: P0 | D7: Hospital Shah Alam, Selangor | E7: Jabatan Bedah Mulut & Pergigian Pediatrik | F7: Klinik Bedah Mulut & Klinik Pergigian Pediatrik | G7: Compressors, Medical-Air | H7: CENTRAL SUCTION (DENTAL) | I7: Therapeutic | J7: Basic | K7: 10-972 | L7: 1 | M7: KKM/JKN/HSA/10-05-01/H/15/4886 | N7: 65000 | O7: =N7*L7 -> 65000 | Q7: 46023
A8: 5 | B8: BEMS | C8: P0 | D8: Hospital Shah Alam, Selangor | E8: Jabatan Kecemasan & Trauma | F8: Jabatan Kecemasan & Trauma | G8: Chairs, Examination/Treatment, Dentistry | H8: DENTAL CHAIR, OFFICER | I8: Therapeutic | J8: Intermediate | K8: 10-792 | L8: 1 | M8: KKM/JKN/HSA/10-05-01/H/15/4892 | N8: 89700 | O8: =N8*L8 -> 89700 | Q8: 46023
A9: 6 | B9: BEMS | C9: P0 | D9: Hospital Shah Alam, Selangor | E9: Jabatan Bedah Mulut & Pergigian Pediatrik | F9: Klinik Bedah Mulut & Klinik Pergigian Pediatrik | G9: Chairs, Examination/Treatment, Dentistry | H9: DENTAL CHAIR, OFFICER | I9: Therapeutic | J9: Intermediate | K9: 10-792 | L9: 1 | M9: KKM/JKN/HSA/10-05-01/H/15/1118 | N9: 69000 | O9: =N9*L9 -> 69000 | Q9: 46023
A10: 7 | B10: BEMS | C10: P0 | D10: Hospital Shah Alam, Selangor | E10: Jabatan Bedah Mulut & Pergigian Pediatrik | F10: Klinik Bedah Mulut & Klinik Pergigian Pediatrik | G10: Chairs, Examination/Treatment, Dentistry | H10: DENTAL CHAIR, OFFICER | I10: Therapeutic | J10: Intermediate | K10: 10-792 | L10: 1 | M10: KKM/JKN/HSA/10-05-01/H/15/1119 | N10: 69000 | O10: =N10*L10 -> 69000 | Q10: 46023
A11: 8 | B11: BEMS | C11: P0 | D11: Hospital Shah Alam, Selangor | E11: Jabatan Bedah Mulut & Pergigian Pediatrik | F11: Klinik Bedah Mulut & Klinik Pergigian Pediatrik | G11: Chairs, Examination/Treatment, Dentistry | H11: DENTAL CHAIR, OFFICER | I11: Therapeutic | J11: Intermediate | K11: 10-792 | L11: 1 | M11: KKM/JKN/HSA/10-05-01/H/15/1120 | N11: 69000 | O11: =N11*L11 -> 69000 | Q11: 46023
A12: 9 | B12: BEMS | C12: P0 | D12: Hospital Shah Alam, Selangor | E12: Jabatan Bedah Mulut & Pergigian Pediatrik | F12: Klinik Bedah Mulut & Klinik Pergigian Pediatrik | G12: Chairs, Examination/Treatment, Dentistry | H12: DENTAL CHAIR, OFFICER | I12: Therapeutic | J12: Intermediate | K12: 10-792 | L12: 1 | M12: KKM/JKN/HSA/10-05-01/H/15/1121 | N12: 69000 | O12: =N12*L12 -> 69000 | Q12: 46023
A13: 10 | B13: BEMS | C13: P0 | D13: Hospital Shah Alam, Selangor | E13: Jabatan Bedah Mulut & Pergigian Pediatrik | F13: Klinik Bedah Mulut & Klinik Pergigian Pediatrik | G13: Chairs, Examination/Treatment, Dentistry | H13: DENTAL CHAIR, OFFICER | I13: Therapeutic | J13: Intermediate | K13: 10-792 | L13: 1 | M13: KKM/JKN/HSA/10-05-01/H/15/1122 | N13: 69000 | O13: =N13*L13 -> 69000 | Q13: 46023
A14: 11 | B14: BEMS | C14: P0 | D14: Hospital Shah Alam, Selangor | E14: Jabatan Bedah Mulut & Pergigian Pediatrik | F14: Klinik Bedah Mulut & Klinik Pergigian Pediatrik | G14: Chairs, Examination/Treatment, Dentistry | H14: DENTAL CHAIR, OFFICER | I14: Therapeutic | J14: Intermediate | K14: 10-792 | L14: 1 | M14: KKM/JKN/HSA/10-05-01/H/15/1123 | N14: 69000 | O14: =N14*L14 -> 69000 | Q14: 46023
A15: 12 | B15: BEMS | C15: P0 | D15: Hospital Shah Alam, Selangor | E15: Jabatan Bedah Mulut & Pergigian Pediatrik | F15: Klinik Bedah Mulut & Klinik Pergigian Pediatrik | G15: Chairs, Examination/Treatment, Dentistry | H15: DENTAL CHAIR, OFFICER | I15: Therapeutic | J15: Intermediate | K15: 10-792 | L15: 1 | M15: KKM/JKN/HSA/10-05-01/H/15/1124 | N15: 69000 | O15: =N15*L15 -> 69000 | Q15: 46023
... A67: 64 | B67: BEMS | C67: P0 | D67: Hospital Shah Alam, Selangor | E67: Jabatan Bedah Mulut & Pergigian Pediatrik | F67: Klinik Bedah Mulut & Klinik Pergigian Pediatrik | G67: Handpieces, Dental | H67: DENTAL HANDPIECE | I67: Therapeutic | J67: Intermediate | K67: 11-161 | L67: 1 | M67: KKM/JKN/HSA/10-05-01/H/18/144 | N67: 10000 | O67: =N67*L67 -> 10000 | Q67: 46023
A68: 65 | B68: BEMS | C68: P0 | D68: Hospital Shah Alam, Selangor | E68: Jabatan Otorinolaringologi (ORL) | G68: Light Sources, Fiberoptic, Flexible Endoscopic | H68: LIGHT SOURCE FIBEROPTIC COMPACT | I68: Diagnostic | J68: Basic | K68: 12-343 | L68: 1 | M68: KKM/JKN/HSA/10-01-01/R/15/7575 | N68: 1320 | O68: =N68*L68 -> 1320 | Q68: 46023
A69: 66 | B69: BEMS | C69: P0 | D69: Hospital Shah Alam, Selangor | E69: Jabatan Pembedahan Am | F69: Unit Rawatan Perubatan Harian | G69: Light Sources, Fiberoptic, Flexible Endoscopic | H69: LIGHT SOURCE XENON 300 WATTS | I69: Diagnostic | J69: Basic | K69: 12-343 | L69: 1 | M69: KKM/JKN/HSA/10-01-01/H/15/1327 | N69: 24700 | O69: =N69*L69 -> 24700 | Q69: 46023
A70: 67 | B70: BEMS | C70: P0 | D70: Hospital Shah Alam, Selangor | E70: Jabatan Pembedahan Am | F70: Unit Rawatan Perubatan Harian | G70: Light Sources, Fiberoptic, Flexible Endoscopic | H70: LIGHT SOURCE XENON 300 WATTS | I70: Diagnostic | J70: Basic | K70: 12-343 | L70: 1 | M70: KKM/JKN/HSA/10-01-01/H/15/1328 | N70: 24700 | O70: =N70*L70 -> 24700 | Q70: 46023
A71: 68 | B71: BEMS | C71: P0 | D71: Hospital Shah Alam, Selangor | E71: Jabatan Pembedahan Am | F71: Unit Rawatan Perubatan Harian | G71: Light Sources, Fiberoptic, Flexible Endoscopic | H71: LIGHT SOURCE XENON 300 WATTS | I71: Diagnostic | J71: Basic | K71: 12-343 | L71: 1 | M71: KKM/JKN/HSA/10-01-01/H/15/1329 | N71: 24700 | O71: =N71*L71 -> 24700 | Q71: 46023
A72: 69 | B72: BEMS | C72: P0 | D72: Hospital Shah Alam, Selangor | E72: Jabatan Pembedahan Am | F72: Unit Rawatan Perubatan Harian | G72: Lavange Unit, Surgical | H72: ENDOSCOPIC FLUSHING PUMP | I72: Therapeutic | J72: Intermediate | K72: 12-306 | L72: 1 | M72: KKM/JKN/HSA/10-01-01/H/15/4083 | N72: 2430 | O72: =N72*L72 -> 2430 | Q72: 46023
A73: 70 | B73: BEMS | C73: P0 | D73: Hospital Shah Alam, Selangor | E73: Jabatan Pembedahan Am | F73: Unit Rawatan Perubatan Harian | G73: Lavange Unit, Surgical | H73: ENDOSCOPIC FLUSHING PUMP | I73: Therapeutic | J73: Intermediate | K73: 12.306 | L73: 1 | M73: KKM/JKN/HSA/10-01-01/H/15/4084 | N73: 2430 | O73: =N73*L73 -> 2430 | Q73: 46023
A74: 71 | B74: BEMS | C74: P0 | D74: Hospital Shah Alam, Selangor | E74: Jabatan Pembedahan Am | F74: Unit Rawatan Perubatan Harian | G74: Lavange Unit, Surgical | H74: ENDOSCOPIC FLUSHING PUMP | I74: Therapeutic | J74: Intermediate | K74: 12-306 | L74: 1 | M74: KKM/JKN/HSA/10-01-01/H/15/4085 | N74: 2430 | O74: =N74*L74 -> 2430 | Q74: 46023
A75: 72 | B75: BEMS | C75: P0 | D75: Hospital Shah Alam, Selangor | E75: Jabatan Anestesiologi & Rawatan Kritikal | F75: Dewan Bedah Utama (GOT) | G75: Light Sources, Fiberoptic, Flexible Endoscopic | H75: LIGHT SOURCE XENON 300 WATTS | I75: Diagnostic | J75: Basic | K75: 12-343 | L75: 1 | M75: KKM/JKN/HSA/10-01-01/H/15/1330 | N75: 24700 | O75: =N75*L75 -> 24700 | Q75: 46023
A76: 73 | B76: BEMS | C76: P0 | D76: Hospital Shah Alam, Selangor | E76: Jabatan Anestesiologi & Rawatan Kritikal | F76: Dewan Bedah Utama (GOT) | G76: Light Sources, Fiberoptic, Flexible Endoscopic | H76: LIGHT SOURCE XENON 300 WATTS | I76: Diagnostic | J76: Basic | K76: 12-343 | L76: 1 | M76: KKM/JKN/HSA/10-01-01/H/15/1331 | N76: 24700 | O76: =N76*L76 -> 24700 | Q76: 46023
A77: 74 | B77: BEMS | C77: P0 | D77: Hospital Shah Alam, Selangor | E77: Jabatan Anestesiologi & Rawatan Kritikal | F77: Dewan Bedah Utama (GOT) | G77: Light Sources, Fiberoptic, Flexible Endoscopic | H77: LIGHT SOURCE XENON 300 WATTS | I77: Diagnostic | J77: Basic | K77: 12-343 | L77: 1 | M77: KKM/JKN/HSA/10-01-01/H/15/1332 | N77: 24700 | O77: =N77*L77 -> 24700 | Q77: 46023
A78: 75 | B78: BEMS | C78: P0 | D78: Hospital Shah Alam, Selangor | E78: Jabatan Anestesiologi & Rawatan Kritikal | F78: Dewan Bedah Utama (GOT) | G78: Light Sources, Fiberoptic | H78: LIGHT GUIDE 3.5MM | I78: Diagnostic | J78: Basic | K78: 12-345 | L78: 1 | M78: KKM/JKN/HSA/10-05-01/R/15/6818 | N78: 1930 | O78: =N78*L78 -> 1930 | Q78: 46023
A79: 76 | B79: BEMS | C79: P0 | D79: Hospital Shah Alam, Selangor | E79: Jabatan Anestesiologi & Rawatan Kritikal | F79: Dewan Bedah Utama (GOT) | G79: Light Sources, Fiberoptic | H79: LIGHT GUIDE 3.5MM | I79: Diagnostic | J79: Basic | K79: 12-345 | L79: 1 | M79: KKM/JKN/HSA/10-05-01/R/15/6819 | N79: 1930 | O79: =N79*L79 -> 1930 | Q79: 46023
A80: 77 | B80: BEMS | C80: P0 | D80: Hospital Shah Alam, Selangor | E80: Jabatan Anestesiologi & Rawatan Kritikal | F80: Dewan Bedah Utama (GOT) | G80: Light Sources, Fiberoptic | H80: LIGHT GUIDE 3.5MM | I80: Diagnostic | J80: Basic | K80: 12-345 | L80: 1 | M80: KKM/JKN/HSA/10-05-01/R/15/6821 | N80: 1930 | O80: =N80*L80 -> 1930 | Q80: 46023
A81: 78 | B81: BEMS | C81: P0 | D81: Hospital Shah Alam, Selangor | E81: Jabatan Pembedahan Am | F81: Unit Rawatan Perubatan Harian | G81: Printers, Video | H81: VIDEO PRINTER | I81: Diagnostic | J81: Basic | K81: 17-508 | L81: 1 | M81: KKM/JKN/HSA/10-05-01/H/15/4086 | N81: 4870 | O81: =N81*L81 -> 4870 | Q81: 46023
A82: 79 | B82: BEMS | C82: P0 | D82: Hospital Shah Alam, Selangor | E82: Jabatan Pembedahan Am | F82: Unit Rawatan Perubatan Harian | G82: Printers, Video | H82: VIDEO PRINTER | I82: Diagnostic | J82: Basic | K82: 17-508 | L82: 1 | M82: KKM/JKN/HSA/10-05-01/H/15/4087 | N82: 4870 | O82: =N82*L82 -> 4870 | Q82: 46023
A83: 80 | B83: BEMS | C83: P0 | D83: Hospital Shah Alam, Selangor | E83: Jabatan Pembedahan Am | F83: Unit Rawatan Perubatan Harian | G83: Printers, Video | H83: VIDEO PRINTER | I83: Diagnostic | J83: Basic | K83: 17-508 | L83: 1 | M83: KKM/JKN/HSA/10-05-01/H/15/4088 | N83: 4870 | O83: =N83*L83 -> 4870 | Q83: 46023
A84: 81 | B84: BEMS | C84: P0 | D84: Hospital Shah Alam, Selangor | E84: Jabatan Kecemasan & Trauma | F84: Jabatan Kecemasan & Trauma | G84: Cast Cutters, Electric | H84: SAW PLASTER ELECTRIC C/W VACUUM | I84: Therapeutic | J84: Basic | K84: 16-340 | L84: 1 | M84: KKM/JKN/HSA/10-05-01/H/15/2826 | N84: 8500 | O84: =N84*L84 -> 8500 | Q84: 46023
A85: 82 | B85: BEMS | C85: P0 | D85: Hospital Shah Alam, Selangor | E85: Jabatan Ortopedik | F85: Wad Ortopedik | G85: Cast Cutters, Electric | H85: SAW PLASTER ELECTRIC C/W VACUUM | I85: Therapeutic | J85: Basic | K85: 16-340 | L85: 1 | M85: KKM/JKN/HSA/10-05-01/H/15/4157 | N85: 11050 | O85: =N85*L85 -> 11050 | Q85: 46023
... A229: 226 | B229: BEMS | C229: P0 | D229: Hospital Shah Alam, Selangor | E229: Jabatan Pembedahan Am | F229: Wad Pembedahan Lelaki 9A | G229: Monitors, Physiologic, Vital Signs | H229: BLOOD PRESSURE MONITOR NON INVASIVE | I229: Diagnostic | J229: Intermediate | K229: 25-209 | L229: 1 | M229: KKM/JKN/HSA/10-05-01/R/15/7154 | N229: 1855 | O229: =N229*L229 -> 1855 | Q229: 46023
A230: 227 | B230: BEMS | C230: P0 | D230: Hospital Shah Alam, Selangor | E230: Jabatan Perubatan Am | G230: Monitors, Physiologic, Vital Signs | H230: BLOOD PRESSURE MONITOR NON INVASIVE | I230: Diagnostic | J230: Intermediate | K230: 25-209 | L230: 1 | M230: KKM/JKN/HSA/10-05-01/R/15/7155 | N230: 1855 | O230: =N230*L230 -> 1855 | Q230: 46023
A231: 228 | B231: BEMS | C231: P0 | D231: Hospital Shah Alam, Selangor | E231: Jabatan Otorinolaringologi (ORL) | F231: Klinik Otorinolaringologi (ORL) | G231: Monitors, Physiologic, Vital Signs | H231: SPHYGMOMANOMETER DIGITAL BATTERY OP | I231: Diagnostic | J231: Intermediate | K231: 25-209 | L231: 1 | M231: KKM/JKN/HSA/10-05-01/R/15/7143 | N231: 1855 | O231: =N231*L231 -> 1855 | Q231: 46023
A232: 229 | B232: BEMS | C232: P0 | D232: Hospital Shah Alam, Selangor | E232: Jabatan Pediatrik | F232: Klinik Pediatrik | G232: Monitors, Physiologic, Vital Signs | H232: SPHYGMOMANOMETER DIGITAL BATTERY OP | I232: Diagnostic | J232: Intermediate | K232: 25-209 | L232: 1 | M232: KKM/JKN/HSA/10-05-01/R/15/15296 | N232: 1855 | O232: =N232*L232 -> 1855 | Q232: 46023
A233: 230 | B233: BEMS | C233: P0 | D233: Hospital Shah Alam, Selangor | E233: Jabatan Oftalmologi | F233: Klinik Oftalmologi | G233: Monitors, Physiologic, Vital Signs | H233: SPHYGMOMANOMETER DIGITAL BATTERY OP | I233: Diagnostic | J233: Intermediate | K233: 25-209 | L233: 1 | M233: KKM/JKN/HSA/10-05-01/R/15/15914 | N233: 1855 | O233: =N233*L233 -> 1855 | Q233: 46023
A234: 231 | B234: BEMS | C234: P0 | D234: Hospital Shah Alam, Selangor | E234: Jabatan Oftalmologi | F234: Klinik Oftalmologi | G234: Monitors, Physiologic, Vital Signs | H234: SPHYGMOMANOMETER DIGITAL BATTERY OP | I234: Diagnostic | J234: Intermediate | K234: 25-209 | L234: 1 | M234: KKM/JKN/HSA/10-05-01/R/15/15915 | N234: 1855 | O234: =N234*L234 -> 1855 | Q234: 46023
A235: 232 | B235: BEMS | C235: P0 | D235: Hospital Shah Alam, Selangor | E235: Jabatan Obstetrik & Ginekologi | F235: Klinik Obstetrik & Ginekologi | G235: Monitors, Physiologic, Vital Signs | H235: SPHYGMOMANOMETER DIGITAL BATTERY OP | I235: Diagnostic | J235: Intermediate | K235: 25-209 | L235: 1 | M235: KKM/JKN/HSA/10-05-01/R/15/16386 | N235: 1855 | O235: =N235*L235 -> 1855 | Q235: 46023
...

Sheet UPTIME
E2: >5 | F2: 5-10 | G2: >10
A3: Equipments | B3: Group | C3: Operating Hours | D3: Operating Hours/WK (Days) | E3: Uptime Equipment | F3: Uptime Equipment | G3: Uptime Equipment
E4: < 5YRS | F4: 5-10 YRS | G4: >10 YRS
A5: Therapeutics
A6: Alternating Pressure Mattress | B6: P | C6: 12 | D6: 6 | E6: 0.96 | F6: 0.92 | G6: 0.85
A7: Aneasthesia Units and Vaporizers | B7: C | C7: 24 | D7: 7 | E7: 0.99 | F7: 0.95 | G7: 0.88
A8: Aneasthesia Ventilators | B8: C | C8: 24 | D8: 7 | E8: 0.99 | F8: 0.95 | G8: 0.88
A9: Aspirators | B9: C | C9: 24 | D9: 7 | E9: 0.99 | F9: 0.95 | G9: 0.88
A10: Defibrillators | B10: C | C10: 24 | D10: 7 | E10: 0.99 | F10: 0.95 | G10: 0.88
A11: Dental Equipment | B11: P | C11: 24 | D11: 7 | E11: 0.96 | F11: 0.92 | G11: 0.85
A12: Diathermy Units | B12: C | C12: 24 | D12: 7 | E12: 0.99 | F12: 0.95 | G12: 0.88
A13: Electrosurgical Units | B13: C | C13: 24 | D13: 7 | E13: 0.99 | F13: 0.95 | G13: 0.88
A14: Heamodialysis Units | B14: C | C14: 24 | D14: 7 | E14: 0.99 | F14: 0.95 | G14: 0.88
A15: Humidifiers | B15: C | C15: 24 | D15: 7 | E15: 0.99 | F15: 0.95 | G15: 0.88
A16: Hypo/hyperthermia Units | B16: C | C16: 24 | D16: 7 | E16: 0.99 | F16: 0.95 | G16: 0.88
A17: Incubators | B17: C | C17: 24 | D17: 7 | E17: 0.99 | F17: 0.95 | G17: 0.88
... A59: Vector Cardiographs | B59: P | C59: 12 | D59: 6 | E59: 0.96 | F59: 0.92 | G59: 0.85
A60: Analysers
A61: · Amino Acid | B61: P | C61: 12 | D61: 6 | E61: 0.96 | F61: 0.92 | G61: 0.85
A62: · Bilirubinometers | B62: P | C62: 12 | D62: 6 | E62: 0.96 | F62: 0.92 | G62: 0.85
A63: · Blood Gas | B63: P | C63: 12 | D63: 6 | E63: 0.96 | F63: 0.92 | G63: 0.85
A64: · Calcium | B64: P | C64: 12 | D64: 6 | E64: 0.96 | F64: 0.92 | G64: 0.85
A65: · Clinical Chemistry | B65: P | C65: 12 | D65: 6 | E65: 0.96 | F65: 0.92 | G65: 0.85
A66: · Coagulation | B66: P | C66: 12 | D66: 6 | E66: 0.96 | F66: 0.92 | G66: 0.85
A67: · Counter, Gamma | B67: P | C67: 12 | D67: 6 | E67: 0.96 | F67: 0.92 | G67: 0.85
A68: · Electrolyte | B68: P | C68: 12 | D68: 6 | E68: 0.96 | F68: 0.92 | G68: 0.85
A69: · Immunoassay | B69: P | C69: 12 | D69: 6 | E69: 0.96 | F69: 0.92 | G69: 0.85
A70: · Glucose | B70: P | C70: 12 | D70: 6 | E70: 0.96 | F70: 0.92 | G70: 0.85
A71: · Hematology | B71: P | C71: 12 | D71: 6 | E71: 0.96 | F71: 0.92 | G71: 0.85
A72: · Platelet Aggregation | B72: P | C72: 12 | D72: 6 | E72: 0.96 | F72: 0.92 | G72: 0.85
... A84: Spectrophotometers | B84: P | C84: 12 | D84: 6 | E84: 0.96 | F84: 0.92 | G84: 0.85

Sheet Public Holiday
A1: Date | B1: Day | C1: Holiday
A2: 46023 | B2: Thu | C2: New Year's Day
A3: 46054 | B3: Sun | C3: Thaipusam
A4: 46070 | B4: Tue | C4: Chinese New Year
A5: 46071 | B5: Wed | C5: Chinese New Year Holiday
A6: 46088 | B6: Sat | C6: Nuzul Al-Quran
A7: 46102 | B7: Sat | C7: Hari Raya Aidilfitri
A8: 46103 | B8: Sun | C8: Hari Raya Aidilfitri Holiday
A9: 46143 | B9: Fri | C9: Labour Day
A10: 46169 | B10: Wed | C10: Hari Raya Haji
A11: 46173 | B11: Sun | C11: Wesak Day
A12: 46174 | B12: Mon | C12: Agong's Birthday
A13: 46190 | B13: Wed | C13: Awal Muharram
... A46: 45651 | B46: Wed | C46: Christmas Day

Sheet KDI
A1: Indicator No. | B1: Indicator | E1: Frequency of Deduction | F1: Biomedical Equipment Purchase Cost (RM) | H1: Deduction Range Value (RM) | J1: Maximum Demerit Point per Work Order
F2: From | G2: To
A3: B.1 | B3: The Company shall respond to the request within the specified time frame | E3: Per event | F3: 0.00 5,000.00 10,000.00 15,000.00 20,000.00 25,000.00 30,000.00 35,000.00 40,000.00 > 45,000.00 | G3: 4,999.99 9,999.99 14,999.99 19,999.99 24,999.99 29,999.99 34,999.99 39,999.99 44,999.99 | H3: 10.00 20.00 30.00 40.00 50.00 60.00 70.00 80.00 90.00 100.00 | J3: 1
A4: B.2 | B4: The Company shall carry out repairs to restore faulty medical equipment to a specified condition when it fails to function as per manufacturer’s specification within seven (7) working days. | E4: Per day | F4: 0.00 5,000.00 10,000.00 15,000.00 20,000.00 25,000.00 30,000.00 35,000.00 40,000.00 > 45,000.00 | G4: 4,999.99 9,999.99 14,999.99 19,999.99 24,999.99 29,999.99 34,999.99 39,999.99 44,999.99 | H4: 10.00 20.00 30.00 40.00 50.00 60.00 70.00 80.00 90.00 100.00 | J4: Number of working days for the month
A5: B.3 | B5: The Company shall carry out scheduled maintenance as per schedule in accordance to the procedure as specified in Agreement. Scheduled maintenance shall include complete safety and performance tests. | E5: Per event | F5: 0.00 5,000.00 10,000.00 15,000.00 20,000.00 25,000.00 30,000.00 35,000.00 40,000.00 45,000.00 | G5: 4,999.99 9,999.99 14,999.99 19,999.99 24,999.99 29,999.99 34,999.99 39,999.99 44,999.99 49,999.99 | H5: 10.00 20.00 30.00 40.00 50.00 60.00 70.00 80.00 90.00 100.00 | J5: 1
F6: For every RM 5,000 increment of equipment cost, an increase of RM10 will be applied subsequently
A7: B.4 | B7: The Company shall ensure biomedical equipment meets the uptime target as set in the Agreement. | E7: Per event | H7: 1st level of Uptime Target (TRKPI) | I7: 2nd level of Uptime Target (80%) | J7: 2
F8: 0.00 5,000.00 10,000.00 15,000.00 20,000.00 25,000.00 30,000.00 35,000.00 40,000.00 45,000.00 | G8: 4,999.99 9,999.99 14,999.99 19,999.99 24,999.99 29,999.99 34,999.99 39,999.99 44,999.99 49,999.99 | H8: 10.00 20.00 30.00 40.00 50.00 60.00 70.00 80.00 90.00 100.00 | I8: 20.00 40.00 60.00 80.00 100.00 120.00 140.00 160.00 180.00 200.00
F9: For every RM 5,000 increment of equipment cost, an increase of RM10 will be applied subsequently for 1st Uptime Target and an increase of RM20 for 2nd Uptime Target will be applied subsequently
A10: B.5 | B10: The Company shall attend and witness T&C and manage biomedical equipment within the warranty period. | E10: Per event | F10: 0.00 5,000.00 10,000.00 15,000.00 20,000.00 25,000.00 30,000.00 35,000.00 40,000.00 45,000.00 | G10: 4,999.99 9,999.99 14,999.99 19,999.99 24,999.99 29,999.99 34,999.99 39,999.99 44,999.99 49,999.99 | H10: 10.00 20.00 30.00 40.00 50.00 60.00 70.00 80.00 90.00 100.00 | J10: 1
F11: For every RM 5,000 increment of equipment cost, an increase of RM10 will be applied subsequently

Sheet KDI 2
A1: Indicator No. | B1: Indicator | E1: Frequency of Deduction | F1: Biomedical Equipment Purchase Cost (RM) | H1: Deduction Range Value (RM) | J1: Maximum Demerit Point per Work Order
F2: From | G2: To
A3: B.1 | B3: The Company shall respond to the request within the specified time frame | E3: Per event | F3: 0.00 5,000.00 10,000.00 15,000.00 20,000.00 25,000.00 30,000.00 35,000.00 40,000.00 > 45,000.00 | G3: 4,999.99 9,999.99 14,999.99 19,999.99 24,999.99 29,999.99 34,999.99 39,999.99 44,999.99 | H3: 10.00 20.00 30.00 40.00 50.00 60.00 70.00 80.00 90.00 100.00 | J3: 1
A4: B.2 | B4: The Company shall carry out repairs to restore faulty medical equipment to a specified condition when it fails to function as per manufacturer’s specification within seven (7) working days. | E4: Per day | F4: 0.00 5,000.00 10,000.00 15,000.00 20,000.00 25,000.00 30,000.00 35,000.00 40,000.00 > 45,000.00 | G4: 4,999.99 9,999.99 14,999.99 19,999.99 24,999.99 29,999.99 34,999.99 39,999.99 44,999.99 | H4: 10.00 20.00 30.00 40.00 50.00 60.00 70.00 80.00 90.00 100.00 | J4: Number of working days for the month
A5: B.3 | B5: The Company shall carry out scheduled maintenance as per schedule in accordance to the procedure as specified in Agreement. Scheduled maintenance shall include complete safety and performance tests. | E5: Per event | F5: 0.00 5,000.00 10,000.00 15,000.00 20,000.00 25,000.00 30,000.00 35,000.00 40,000.00 45,000.00 | G5: 4,999.99 9,999.99 14,999.99 19,999.99 24,999.99 29,999.99 34,999.99 39,999.99 44,999.99 49,999.99 | H5: 10.00 20.00 30.00 40.00 50.00 60.00 70.00 80.00 90.00 100.00 | J5: 1
F6: For every RM 5,000 increment of equipment cost, an increase of RM10 will be applied subsequently
A7: B.4 | B7: The Company shall ensure biomedical equipment meets the uptime target as set in the Agreement. | E7: Per event | H7: 1st level of Uptime Target (TRKPI) | I7: 2nd level of Uptime Target (80%) | J7: 2
F8: 0.00 5,000.00 10,000.00 15,000.00 20,000.00 25,000.00 30,000.00 35,000.00 40,000.00 45,000.00 | G8: 4,999.99 9,999.99 14,999.99 19,999.99 24,999.99 29,999.99 34,999.99 39,999.99 44,999.99 49,999.99 | H8: 10.00 20.00 30.00 40.00 50.00 60.00 70.00 80.00 90.00 100.00 | I8: 20.00 40.00 60.00 80.00 100.00 120.00 140.00 160.00 180.00 200.00
F9: For every RM 5,000 increment of equipment cost, an increase of RM10 will be applied subsequently for 1st Uptime Target and an increase of RM20 for 2nd Uptime Target will be applied subsequently
A10: B.5 | B10: The Company shall attend and witness T&C and manage biomedical equipment within the warranty period. | E10: Per event | F10: 0.00 5,000.00 10,000.00 15,000.00 20,000.00 25,000.00 30,000.00 35,000.00 40,000.00 45,000.00 | G10: 4,999.99 9,999.99 14,999.99 19,999.99 24,999.99 29,999.99 34,999.99 39,999.99 44,999.99 49,999.99 | H10: 10.00 20.00 30.00 40.00 50.00 60.00 70.00 80.00 90.00 100.00 | J10: 1
F11: For every RM 5,000 increment of equipment cost, an increase of RM10 will be applied subsequently

Sheet BEMSdar
A1: MINISTRY OF HEALTH
A2: Deduction Mapping Report Biomedical Engineering Maintenance Services (BEMS)
D5: HOSPITAL NAME : | E5: HOSPITAL SHAH ALAM | I5: State: | J5: SELANGOR
D7: MONTH/YEAR : | E7: 46082 | I7: Company: | J7: Ambang Wira Sdn Bhd
D9: Monthly Service Fee (RM): | E9: 361632.64
D11: Monthly Service Fee for BEMS (RM) @ 97.5%: | E11: =E9*0.975 -> 352591.82
D13: Monthly Service Fee for FMS (RM) @ 2.5%: | E13: =E9-E11 -> 9040.816
A17: No | B17: Key Deduction Indicators | I17: Frequency | L17: Deduction Value (RM) | N17: Deduction % | O17: Performance Level (%)
A19: B.1 | B19: All service requests shall be responded by the Company’s trained technical personal within the timeframe as stipulated in the Agreement. | I19: Per event | L19: ='B1-RESPONSE & B2-REPAIR'!N230 -> 0 | N19: =L19/$E$11% -> 0 | O19: =100-N19 -> 100
A20: B.2 | B20: All unscheduled maintenance works including relevant maintenance calibration, safety tests and functional checks shall be completed within seven (7) working days. | I20: Per day | L20: ='B1-RESPONSE & B2-REPAIR'!T230 -> 8670 | N20: =L20/$E$11% -> 2.4589339 | O20: =100-N20 -> 97.541066
A21: B.3 | B21: Scheduled maintenance shall be carried out as per schedule and according to the procedure as specified in the Agreement. Scheduled maintenance shall include complete safety and performance tests. | I21: Per event | L21: ='B3-SCHEDULED'!M503 -> 0 | N21: =L21/$E$11% -> 0 | O21: =100-N21 -> 100
A22: B.4 | B22: All biomedical equipment shall be functioning and maintained to ensure uptime target as specified in the TRKPI are met. | I22: Per event | L22: ='B4-UPTIME'!Z94 -> 830 | N22: =L22/$E$11% -> 0.23539967 | O22: =100-N22 -> 99.7646
A23: B.5 | B23: T&C and Warranty Management of newly introduced biomedical shall be managed and performed according to the Agreement and related acts, standards and regulations. | I23: Per event | L23: =SUM('B5-T&C'!O23) -> 0 | N23: =L23/$E$11% -> 0 | O23: =100-N23 -> 100
A24: Total | L24: =SUM(L19:M23) -> 9500 | N24: =L24/$E$9% -> 2.6269753 | O24: =100-N24 -> 97.373025
C27: Prepared by: | I27: Verified by:
C31: NOR JALILAH BINTI JUMAHAT | I31: MOHD SALLEH B. MAT SAHAT
C32: Head of BEMS | I32: Facility Manager
C33: Ambang Wira Sdn Bhd- Hospital Shah Alam | I33: Ambang Wira Sdn Bhd- Hospital Shah Alam
C34: Date: | I34: Date:

Sheet B1-RESPONSE & B2-REPAIR
B1: MINISTRY OF HEALTH
B2: Deduction Mapping Report Biomedical Engineering Maintenance Services (BEMS)
B3: INDICATOR B.1 RESPONSE TIME & B.2 REPAIR TIME
B5: HOSPITAL NAME : | C5: HOSPITAL SHAH ALAM | L5: FIRST DATE OF THE MONTH : | N5: =BEMSdar!E7 -> 46082
B7: STATE : | C7: SELANGOR | L7: LAST DATE OF THE MONTH : | N7: 46112
B9: COMPANY : | C9: AMBANG WIRA SDN BHD | L9: BEMS MONTHLY FEE (RM) @ 97.5% : | N9: =BEMSdar!E11 -> 352591.82
B11: MONTH/YEAR : | C11: =BEMSdar!E7 -> 46082 | L11: FMS MONTHLY FEE (RM) @ 2.5% : | N11: =BEMSdar!E13 -> 9040.816
A13: Notes:
A14: 1) Deduction Ringgit Equivalent is based on Appendix 11 of the Agreement, Section B3 Key Deduction Indicators for BEMS
A15: 2) Deduction Value for Indicator B.1 is Deduction Ringgit Equivalent (per event)
A16: 3) Total Repair Time includes weekend & public holiday
A17: 4) Demerit Point for Indicator B.2 is calculated based on completion date against request date, less by 7 working days
A18: 5) Deduction Value for Indicator B.2 is Demerit Point multiply by Deduction Ringgit Equivalent
A20: No | B20: Asset No | C20: Asset Description | D20: Asset Purchase Price (RM) | E20: Work Order No. | F20: User Location | G20: Work Order/ Complaint Details | H20: Response Category (Emergency/ Normal) | I20: Total Response Time (minutes) | J20: Work Request Date | K20: Work Completion Date | L20: Deduction Ringgit Equivalent (RM) | M20: Indicator B.1 | P20: Indicator B.2
M21: Validate Status (Y/N) | N21: Deduction Value (RM) | O21: Remarks/ Exemption | P21: Validate Status (Y/N) | Q21: Total Repair Time (day) | R21: Last date of 7 working days (dd/mm/yy) | S21: Demerit Point | T21: Deduction Value (RM) | U21: Remarks/ Exemption
A22: Current Month (Work Order Closed)
A23: 1 | B23: KKM/JKN/HSA/10-05-01/H/15/1121 | C23: DENTAL CHAIR, OFFICER | D23: 69000 | E23: HSASWIBE26011783 | F23: Klinik Bedah Mulut & Klinik Pergigian Pediatrik | G23: DENTAL CHAIR TIDAK BERFUNGSI DENGAN BAIK DI BILIK 4 KLINIK DENTAL (H/15/1121) | H23: NORMAL | I23: 0 days, 0 hrs, 16 mins | J23: 46083.458 | K23: 46083 | L23: =IF(D23>44999.99,100,ROUNDUP((D23/4999.99)*10,-1)) -> 100 | M23: N | N23: =IF(M23="Y",L23,0) -> 0 | P23: N | Q23: =K23-J23+1 -> 0.54236111 | R23: =WORKDAY(J23,7,'Public Holiday'!$A$2:$A$46) -> 46092 | S23: 0 | T23: =L23*S23 -> 0 | U23: BD
A24: 2 | B24: KKM/JKN/HSA/10-05-01/H/15/3629 | C24: VENTILATOR FOR NEONATES & INFANTS | D24: 53000 | E24: HSASWIBE26011786 | F24: Unit Rawatan Rapi Neonatal (NICU) | G24: OKSIGEN SENSOR VENTILATOR TIDAK BERFUNGSI DI WAD NICU (H/15/3621) | H24: NORMAL | I24: 0 days, 0 hrs, 07 mins | J24: 46083.503 | K24: 46083 | L24: =IF(D24>44999.99,100,ROUNDUP((D24/4999.99)*10,-1)) -> 100 | M24: N | N24: =IF(M24="Y",L24,0) -> 0 | P24: N | Q24: =K24-J24+1 -> 0.49652778 | R24: =WORKDAY(J24,7,'Public Holiday'!$A$2:$A$46) -> 46092 | S24: 0 | T24: =L24*S24 -> 0 | U24: BD
A25: 3 | B25: KKM/JKN/HSA/10-05-01/H/18/127 | C25: ECG (EKG) MACHINE | D25: 12000 | E25: HSASWIBE26011787 | F25: Jabatan Kecemasan & Trauma (ED) | G25: MESIN ECG TIDAK BERFUNGSI DENGAN BAIK DI BILIK NO.6 GREENZONE ED (H/18/127) | H25: NORMAL | I25: 0 days, 0 hrs, 17 mins | J25: 46083.523 | K25: 46083 | L25: =IF(D25>44999.99,100,ROUNDUP((D25/4999.99)*10,-1)) -> 30 | M25: N | N25: =IF(M25="Y",L25,0) -> 0 | P25: N | Q25: =K25-J25+1 -> 0.47708333 | R25: =WORKDAY(J25,7,'Public Holiday'!$A$2:$A$46) -> 46092 | S25: 0 | T25: =L25*S25 -> 0 | U25: BD
A26: 4 | B26: KKM/JKN/HSA/10-05-01/R/15/7037 | C26: SCALES BABY DIGITAL/ELECTRONIC W/MEASURE | D26: 1500 | E26: HSASWIBE26011866 | F26: WAD 8A (Wad Obstetrik & Ginekologi 8A) | G26: INFANT/ BABY SCALER (R/15/7037): PENIMBANG BABY TIDAK BOLEH ON DI BILIK BABY WAD 8A | H26: NORMAL | I26: 0 days, 0 hrs, 19 mins | J26: 46084.299 | K26: 46095 | L26: =IF(D26>44999.99,100,ROUNDUP((D26/4999.99)*10,-1)) -> 10 | M26: N | N26: =IF(M26="Y",L26,0) -> 0 | P26: N | Q26: =K26-J26+1 -> 11.700694 | R26: =WORKDAY(J26,7,'Public Holiday'!$A$2:$A$46) -> 46093 | S26: 0 | T26: =L26*S26 -> 0 | U26: BD
A27: 5 | B27: KKM/JKN/HSA/10-05-01/H/22/146 | C27: DEFIBRILLATOR | D27: 27500 | E27: HSASWIBE26011868 | F27: Wad Perubatan Lelaki 10A | G27: DEFIBRILLATOR (H/22/146): MESIN DEFIB TIDAK BERFUNGSI DENGAN BAIK- GRAF BACAAN ECG TIDAK JELAS DI WAD 10A | H27: NORMAL | I27: 0 days, 0 hrs, 24 mins | J27: 46084.338 | K27: 46084 | L27: =IF(D27>44999.99,100,ROUNDUP((D27/4999.99)*10,-1)) -> 60 | M27: N | N27: =IF(M27="Y",L27,0) -> 0 | P27: N | Q27: =K27-J27+1 -> 0.6625 | R27: =WORKDAY(J27,7,'Public Holiday'!$A$2:$A$46) -> 46093 | S27: 0 | T27: =L27*S27 -> 0 | U27: BD
A28: 6 | B28: KKM/JKN/HSA/10-05-10/H/21/204 | C28: ECG MACHINE | D28: 4200 | E28: HSASWIBE26011980 | F28: Unit Rawatan Rapi (ICU) | G28: ECG MACHINE (H/21/204)-MONITOR DISPLAY TIDAK KELUAR WAVE DI ICU | H28: NORMAL | I28: 0 days, 0 hrs, 40 mins | J28: 46084.679 | K28: 46084 | L28: =IF(D28>44999.99,100,ROUNDUP((D28/4999.99)*10,-1)) -> 10 | M28: N | N28: =IF(M28="Y",L28,0) -> 0 | P28: N | Q28: =K28-J28+1 -> 0.32083333 | R28: =WORKDAY(J28,7,'Public Holiday'!$A$2:$A$46) -> 46093 | S28: 0 | T28: =L28*S28 -> 0 | U28: BD
A29: 7 | B29: KKM/JKN/HSA/10-05-01/H/15/1616 | C29: VENTILATOR HIGH FREQUENCY NEONATE | D29: 64000 | E29: HSASWIBE26011998 | F29: Unit Rawatan Rapi Neonatal (NICU) | G29: INFANT VENTILATOR (H/15/1616): OKSIGEN SENSOR ROSAK DI NICU | H29: NORMAL | I29: 0 days, 0 hrs, 07 mins | J29: 46085.37 | K29: 46085 | L29: =IF(D29>44999.99,100,ROUNDUP((D29/4999.99)*10,-1)) -> 100 | M29: N | N29: =IF(M29="Y",L29,0) -> 0 | P29: N | Q29: =K29-J29+1 -> 0.62986111 | R29: =WORKDAY(J29,7,'Public Holiday'!$A$2:$A$46) -> 46094 | S29: 0 | T29: =L29*S29 -> 0 | U29: BD
A30: 8 | B30: KKM/JKN/HSA/10-05-01/H/23/42 | C30: X-RAY CARM | D30: 332177.94 | E30: HSASWIBE26012023 | F30: Dewan Bedah Utama (GOT) | G30: XRAY CARM (H/23/42): MOBILE C ARM HANDSWITCH HOLDER ROSAK DI GOT | H30: NORMAL | I30: 0 days, 0 hrs, 17 mins | J30: 46085.495 | K30: 46085 | L30: =IF(D30>44999.99,100,ROUNDUP((D30/4999.99)*10,-1)) -> 100 | M30: N | N30: =IF(M30="Y",L30,0) -> 0 | P30: N | Q30: =K30-J30+1 -> 0.50486111 | R30: =WORKDAY(J30,7,'Public Holiday'!$A$2:$A$46) -> 46094 | S30: 0 | T30: =L30*S30 -> 0 | U30: BD
A31: 9 | B31: KKM/JKN/HSA/10-05-01/H/15/2087 | C31: MONITOR 4 CH, ECG/RR/NIBP/SP02/TEMP | D31: 9000 | E31: HSASWIBE26012027 | F31: Jabatan Kecemasan & Trauma (ED) | G31: SPO2 PROB PUTUS DI KATIL 2 RESUS ED | H31: NORMAL | I31: 0 days, 0 hrs, 40 mins | J31: 46085.618 | K31: 46085 | L31: =IF(D31>44999.99,100,ROUNDUP((D31/4999.99)*10,-1)) -> 20 | M31: N | N31: =IF(M31="Y",L31,0) -> 0 | P31: N | Q31: =K31-J31+1 -> 0.38194444 | R31: =WORKDAY(J31,7,'Public Holiday'!$A$2:$A$46) -> 46094 | S31: 0 | T31: =L31*S31 -> 0 | U31: BD
A32: 10 | B32: KKM/JKN/HSA/10-05-01/H/20/179 | C32: SPOT VITAL SIGN (NIBP) | D32: 6500 | E32: HSASWIBE26012033 | F32: Wad 13 (VIP) | G32: Asset Name: Patient Monitor No asset : H/20/179 Description: Spo2 probe tidak dapat bacaan Location: Wad 13 | H32: NORMAL | I32: 0 days, 0 hrs, 33 mins | J32: 46085.713 | K32: 46085 | L32: =IF(D32>44999.99,100,ROUNDUP((D32/4999.99)*10,-1)) -> 20 | M32: N | N32: =IF(M32="Y",L32,0) -> 0 | P32: N | Q32: =K32-J32+1 -> 0.28680556 | R32: =WORKDAY(J32,7,'Public Holiday'!$A$2:$A$46) -> 46094 | S32: 0 | T32: =L32*S32 -> 0 | U32: BD
A33: 11 | B33: KKM/JKN/HSA/10-05-01/H/15/4261 | C33: LASER DIODE(RED) PHOTOCOAGULATOR | D33: 125347 | E33: HSASWIBE26012070 | F33: Klinik Oftalmologi (OPHTHAL CLINIC) | G33: LASER DIODE (RED) PHOTOCOAGULATION (H/15/4261): CERMIN MESIN LASER TERCABUT DI KLINIK MATA | H33: NORMAL | I33: 0 days, 0 hrs, 12 mins | J33: 46086.672 | K33: 46086 | L33: =IF(D33>44999.99,100,ROUNDUP((D33/4999.99)*10,-1)) -> 100 | M33: N | N33: =IF(M33="Y",L33,0) -> 0 | P33: N | Q33: =K33-J33+1 -> 0.32777778 | R33: =WORKDAY(J33,7,'Public Holiday'!$A$2:$A$46) -> 46097 | S33: 0 | T33: =L33*S33 -> 0 | U33: BD
A34: 12 | B34: KKM/JKN/HSA/10-05-01/H/23/8 | C34: ULTRASOUND SCANNER | D34: 97500 | E34: HSASWIBE26012073 | F34: PAC | G34: MESIN ULTRASOUND TIDAK BERFUNGSI DENGAN BAIK DI PAC 3 (H/23/8) | H34: NORMAL | I34: 0 days, 0 hrs, 34 mins | J34: 46086.851 | K34: 46086 | L34: =IF(D34>44999.99,100,ROUNDUP((D34/4999.99)*10,-1)) -> 100 | M34: N | N34: =IF(M34="Y",L34,0) -> 0 | P34: N | Q34: =K34-J34+1 -> 0.14861111 | R34: =WORKDAY(J34,7,'Public Holiday'!$A$2:$A$46) -> 46097 | S34: 0 | T34: =L34*S34 -> 0 | U34: BD
... A129: 107 | B129: KKM/JKNS/HSA/10-05-01/H/24/15 | C129: OTOACOUSTIC EMISSION (OAE) SCREENING SYSTEM | D129: 19900 | E129: HSASWIBE26015620 | F129: Klinik Otorinolaringologi (ORL) | G129: Asset no: H/24/15 Serial no: GI1010317 Asset description: DPOAE Screening Problem: replace OAE cable Lokasi: Klinik orl | H129: NORMAL | I129: 0 days, 0 hrs, 09 mins | J129: 46112 | K129: 46112 | L129: =IF(D129>44999.99,100,ROUNDUP((D129/4999.99)*10,-1)) -> 40 | M129: N | N129: =IF(M129="Y",L129,0) -> 0 | P129: N | Q129: =K129-J129+1 -> 1 | R129: =WORKDAY(J129,7,'Public Holiday'!$A$2:$A$46) -> 46121 | S129: 0 | T129: =L129*S129 -> 0 | U129: BREAKDOWN RIW
A130: Current Month (Work Order Open)
A131: 1 | B131: KKM/JKN/HSA/10-05-01/H/15/1586 | C131: INFANT WARMER (RADIANT) | D131: 24000 | E131: HSASWIBE26011777 | F131: Dewan Bedah Bersalin (MOT) | G131: BABY WARMER ERROR DI BILIK MOT 1 MOT (H/15/1586) | H131: NORMAL | I131: 0 days, 0 hrs, 06 mins | J131: 46083.329 | K131: 46112 | L131: =IF(D131>44999.99,100,ROUNDUP((D131/4999.99)*10,-1)) -> 50 | M131: N | N131: =IF(M131="Y",L131,0) -> 0 | P131: N | Q131: =K131-J131+1 -> 29.670833 | R131: =WORKDAY(J131,7,'Public Holiday'!$A$2:$A$46) -> 46092 | S131: 0 | T131: =L131*S131 -> 0 | U131: BD PO 71818 DRAGER
A132: 2 | B132: KKM/JKN/HSA/10-05-01/H/22/126 | C132: ULTRASOUND SCANNER | D132: 49000 | E132: HSASWIBE26011974 | F132: Dewan Bersalin (LDU) | G132: ULTRASOUND SCANNER (H/22/126)- MESIN SCAN LOOSE DI PAC 4 | H132: NORMAL | I132: 0 days, 0 hrs, 01 mins | J132: 46084.541 | K132: 46112 | L132: =IF(D132>44999.99,100,ROUNDUP((D132/4999.99)*10,-1)) -> 100 | M132: N | N132: =IF(M132="Y",L132,0) -> 0 | P132: N | Q132: =K132-J132+1 -> 28.459028 | R132: =WORKDAY(J132,7,'Public Holiday'!$A$2:$A$46) -> 46093 | S132: 0 | T132: =L132*S132 -> 0 | U132: BD, TA RIW
A133: 3 | B133: KKM/JKN/HSA/10-05-01/H/22/144 | C133: PATIENT MONITORING EQUIPMENT | D133: 8700 | E133: HSASWIBE26012132 | F133: JABATAN PEMBEDAHAN AM | G133: Asset Name: Patient Monitor No asset : H/22/144 Description: Spo2 tidak dapat bacaan Location: Wad 13 | H133: NORMAL | I133: 0 days, 0 hrs, 13 mins | J133: 46089.946 | K133: 46112 | L133: =IF(D133>44999.99,100,ROUNDUP((D133/4999.99)*10,-1)) -> 20 | M133: N | N133: =IF(M133="Y",L133,0) -> 0 | P133: N | Q133: =K133-J133+1 -> 23.054167 | R133: =WORKDAY(J133,7,'Public Holiday'!$A$2:$A$46) -> 46098 | S133: 0 | T133: =L133*S133 -> 0 | U133: BD, PO AWSB-72006 QP MANUFACTURING
A134: 4 | B134: KKM/JKN/HSA/10-05-01/H/15/470 | C134: INFANT INCUBATOR | D134: 24000 | E134: HSASWIBE26012148 | F134: Unit Rawatan Rapi Neonatal (NICU) | G134: INFANT INCUBATOR TIDAK BERFUNGSI DENGAN BAIK (H/15/470) NICU | H134: NORMAL | I134: 0 days, 0 hrs, 29 mins | J134: 46090.438 | K134: 46112 | L134: =IF(D134>44999.99,100,ROUNDUP((D134/4999.99)*10,-1)) -> 50 | M134: N | N134: =IF(M134="Y",L134,0) -> 0 | P134: N | Q134: =K134-J134+1 -> 22.561806 | R134: =WORKDAY(J134,7,'Public Holiday'!$A$2:$A$46) -> 46099 | S134: 0 | T134: =L134*S134 -> 0 | U134: BD, QUOTATION QUO-AFMAL-26068-001 RECEIVE 30/3/26
A135: 5 | B135: KKM/JKN/HSA/10-05-01/H/15/475 | C135: INFANT INCUBATOR | D135: 24000 | E135: HSASWIBE26012149 | F135: Unit Rawatan Rapi Neonatal (NICU) | G135: INFANT INCUBATOR LOCK PINTU PATAH (H/15/475) DI NICU | H135: NORMAL | I135: 0 days, 0 hrs, 30 mins | J135: 46090.44 | K135: 46112 | L135: =IF(D135>44999.99,100,ROUNDUP((D135/4999.99)*10,-1)) -> 50 | M135: N | N135: =IF(M135="Y",L135,0) -> 0 | P135: N | Q135: =K135-J135+1 -> 22.559722 | R135: =WORKDAY(J135,7,'Public Holiday'!$A$2:$A$46) -> 46099 | S135: 1 | T135: =L135*S135 -> 50 | U135: BD , PO AWSB-72503 DRAGER
A136: 6 | B136: KKM/JKN/HSA/10-05-01/H/15/2449 | C136: PATIENT WARMER (BLANKET) | D136: 6560 | E136: HSASWIBE26012333 | F136: Dewan Bedah Utama (GOT) | G136: PATIENT WARMER TIDAK PANAS DI MOT (H/15/2449) | H136: NORMAL | I136: 0 days, 0 hrs, 36 mins | J136: 46091.35 | K136: 46112 | L136: =IF(D136>44999.99,100,ROUNDUP((D136/4999.99)*10,-1)) -> 20 | M136: N | N136: =IF(M136="Y",L136,0) -> 0 | P136: N | Q136: =K136-J136+1 -> 21.65 | R136: =WORKDAY(J136,7,'Public Holiday'!$A$2:$A$46) -> 46100 | S136: 0 | T136: =L136*S136 -> 0 | U136: BD, PO 72051 IDS MEDICAL
A137: 7 | B137: KKM/JKN/HSA/10-05-01/H/17/4 | C137: ULTRASOUND SCANNER | D137: 198800 | E137: HSASWIBE26012350 | F137: Jabatan Kecemasan & Trauma (ED) | G137: MESIN UTLRASOUND SCANNER TIDAK BERFUNGSI DENGAN BAIK (GAMBAR TIDAK JELAS) DI REDZONE ED | H137: NORMAL | I137: 0 days, 0 hrs, 40 mins | J137: 46091.388 | K137: 46112 | L137: =IF(D137>44999.99,100,ROUNDUP((D137/4999.99)*10,-1)) -> 100 | M137: N | N137: =IF(M137="Y",L137,0) -> 0 | P137: N | Q137: =K137-J137+1 -> 21.611806 | R137: =WORKDAY(J137,7,'Public Holiday'!$A$2:$A$46) -> 46100 | S137: 0 | T137: =L137*S137 -> 0 | U137: BD, PROBE FAULTY. WAITING INVOICE INFINITY MEDICAL
A138: 8 | B138: KKM/JKN/HSA/10-05-01/H/15/309 | C138: VENTILATOR | D138: 31000 | E138: HSASWIBE26012381 | F138: Jabatan Kecemasan & Trauma (ED) | G138: Asset Name: Transport Ventilator No asset : H/15/309 Description: Unit tidak berfungsi dengan baik Location: ED | H138: NORMAL | I138: 0 days, 0 hrs, 29 mins | J138: 46091.417 | K138: 46112 | L138: =IF(D138>44999.99,100,ROUNDUP((D138/4999.99)*10,-1)) -> 70 | M138: N | N138: =IF(M138="Y",L138,0) -> 0 | P138: N | Q138: =K138-J138+1 -> 21.582639 | R138: =WORKDAY(J138,7,'Public Holiday'!$A$2:$A$46) -> 46100 | S138: 7 | T138: =L138*S138 -> 490 | U138: BD, PRAWSB73640 DRAGER
A139: 9 | B139: KKM/JKN/HSA/10-05-01/H/14/2 | C139: ULTRASOUND SCANNER | D139: 160000 | E139: HSASWIBE26012752 | F139: Dewan Bedah Utama (GOT) | G139: MESIN ULTRASOUND GAMBAR TIDAK KELUAR DI ICU | H139: NORMAL | I139: 0 days, 0 hrs, 30 mins | J139: 46094.349 | K139: 46112 | L139: =IF(D139>44999.99,100,ROUNDUP((D139/4999.99)*10,-1)) -> 100 | M139: N | N139: =IF(M139="Y",L139,0) -> 0 | P139: N | Q139: =K139-J139+1 -> 18.650694 | R139: =WORKDAY(J139,7,'Public Holiday'!$A$2:$A$46) -> 46105 | S139: 4 | T139: =L139*S139 -> 400 | U139: BD, WAIITNG MYLAB ALPHA INVOICE
A140: 10 | B140: KKM/JKN/HSA/10-05-01/H/16/193 | C140: DEFIBRILLATOR | D140: 65000 | E140: HSASWIBE26012814 | F140: JABATAN KECEMASAN DAN TRAUMA | G140: MESIN ZOLL-SPO2 PROBE TIDAK DETECT DI BILIK CDC ED | H140: NORMAL | I140: 0 days, 0 hrs, 30 mins | J140: 46097.38 | K140: 46112 | L140: =IF(D140>44999.99,100,ROUNDUP((D140/4999.99)*10,-1)) -> 100 | M140: N | N140: =IF(M140="Y",L140,0) -> 0 | P140: N | Q140: =K140-J140+1 -> 15.620139 | R140: =WORKDAY(J140,7,'Public Holiday'!$A$2:$A$46) -> 46106 | S140: 0 | T140: =L140*S140 -> 0 | U140: BD, PRF-439 RAPHA MEDICAL, UNIT SEND FOR REPAIR
...

Sheet B3-SCHEDULED
A3: MINISTRY OF HEALTH
A4: Deduction Mapping Report Biomedical Engineering Maintenance Services (BEMS)
B5: INDICATOR B.3 SCHEDULED MAINTENANCE
B7: HOSPITAL NAME : | C7: HOSPITAL SHAH ALAM | H7: MONTH/YEAR : | J7: =BEMSdar!E7 -> 46082
B9: STATE : | C9: SELANGOR | H9: BEMS MONTHLY FEE (RM)@ 97.5% : | J9: =BEMSdar!E11 -> 352591.82
B11: COMPANY : | C11: AMBANG WIRA SDN BHD | H11: FMS MONTHLY FEE (RM) @ 2.5% : | J11: =BEMSdar!E13 -> 9040.816
A13: Notes:
A14: 1) Deduction Ringgit Equivalent is based on Appendix 11 of the Agreement, Section B3 Key Deduction Indicators for BEMS
A15: 2) Deduction Value for Indicator B.3 is Deduction Ringgit Equivalent (per event)
A16: 3) Rescheduled Date is the final rescheduled date if there are multiple rescheduling
A17: 4) Display only asset affected by deduction
A19: No | B19: Asset No | C19: Asset Description | D19: Asset Purchase Price (RM) | E19: Work Order No. | F19: User Location | G19: Scheduled Start Date | H19: Scheduled End Date | I19: Rescheduled Date | J19: Maintenance Date | K19: Validate Status (Y/N) | L19: Deduction Ringgit Equivalent (RM) | M19: Indicator B.3
M20: Deduction Value (RM) | N20: Remarks/ Exemption
A21: Current Month (Work order closed)
A22: 1 | B22: KKM/JKN/HSA/10-05-01/R/15/16747 | C22: DIGITAL BLOOD PRESSURE | D22: 1855 | E22: HSASWOBE26012177 | F22: Klinik Pediatrik (PAEDIATRIC CLINIC) | G22: 46083 | H22: 46084 | J22: 46084 | K22: N | L22: =ROUNDUP((D22/4999.99)*10,-1) -> 10 | M22: =IF(K22="N",0,L22) -> 0 | N22: PPM DONE
A23: 5 | B23: KKM/JKN/HSA/10-05-01/R/15/16154 | C23: NEBULIZER | D23: 1950 | E23: HSASWOBE26012181 | F23: Klinik Pediatrik (PAEDIATRIC CLINIC) | G23: 46084 | H23: 46085 | J23: 46084 | K23: N | L23: =ROUNDUP((D23/4999.99)*10,-1) -> 10 | M23: =IF(K23="N",0,L23) -> 0 | N23: PPM DONE
A24: 6 | B24: KKM/JKN/HSA/10-05-01/H/15/574 | C24: ECG (EKG) MACHINE | D24: 10000 | E24: HSASWOBE26012182 | F24: WAD 12 (Paediatric Ward) | G24: 46084 | H24: 46085 | J24: 46085 | K24: N | L24: =ROUNDUP((D24/4999.99)*10,-1) -> 30 | M24: =IF(K24="N",0,L24) -> 0 | N24: PPM DONE
A25: 7 | B25: KKM/JKN/HSA/10-05-01/H/15/5358 | C25: LASER PRINTER | D25: 3499 | E25: HSASWOBE26012183 | F25: Unit Rawatan Koronari (CCU) | G25: 46084 | H25: 46085 | J25: 46084 | K25: N | L25: =ROUNDUP((D25/4999.99)*10,-1) -> 10 | M25: =IF(K25="N",0,L25) -> 0 | N25: PPM DONE
A26: 8 | B26: FA004 | C26: LASER PRINTER | D26: 3499 | E26: HSASWOBE26012184 | F26: Unit Rawatan Koronari (CCU) | G26: 46084 | H26: 46085 | J26: 46084 | K26: N | L26: =ROUNDUP((D26/4999.99)*10,-1) -> 10 | M26: =IF(K26="N",0,L26) -> 0 | N26: PPM DONE
A27: 10 | B27: KKM/JKN/HSA/10-05-01/H/15/2153 | C27: SUCTION APPARATUS | D27: 3386.5 | E27: HSASWOBE26012186 | F27: Klinik Pediatrik (PAEDIATRIC CLINIC) | G27: 46084 | H27: 46085 | J27: 46084 | K27: N | L27: =ROUNDUP((D27/4999.99)*10,-1) -> 10 | M27: =IF(K27="N",0,L27) -> 0 | N27: PPM DONE
A28: 11 | B28: KKM/JKN/HSA/10-05-01/R/15/16151 | C28: NEBULIZER | D28: 1950 | E28: HSASWOBE26012187 | F28: Klinik Pediatrik (PAEDIATRIC CLINIC) | G28: 46084 | H28: 46085 | J28: 46084 | K28: N | L28: =ROUNDUP((D28/4999.99)*10,-1) -> 10 | M28: =IF(K28="N",0,L28) -> 0 | N28: PPM DONE
A29: 12 | B29: KKM/JKN/HSA/10-05-01/R/15/16152 | C29: NEBULIZER | D29: 1950 | E29: HSASWOBE26012188 | F29: Klinik Pediatrik (PAEDIATRIC CLINIC) | G29: 46084 | H29: 46085 | J29: 46084 | K29: N | L29: =ROUNDUP((D29/4999.99)*10,-1) -> 10 | M29: =IF(K29="N",0,L29) -> 0 | N29: PPM DONE
A30: 13 | B30: KKM/JKN/HSA/10-05-01/R/15/16153 | C30: NEBULIZER | D30: 1950 | E30: HSASWOBE26012189 | F30: Klinik Pediatrik (PAEDIATRIC CLINIC) | G30: 46084 | H30: 46085 | J30: 46084 | K30: N | L30: =ROUNDUP((D30/4999.99)*10,-1) -> 10 | M30: =IF(K30="N",0,L30) -> 0 | N30: PPM DONE
A31: 14 | B31: KKM/JKN/HSA/10-05-01/H/15/1232 | C31: INFUSION PUMP | D31: 7245 | E31: HSASWOBE26012190 | F31: WAD 10B (Wad Perubatan Perempuan 10B) | G31: 46084 | H31: 46085 | J31: 46084 | K31: N | L31: =ROUNDUP((D31/4999.99)*10,-1) -> 20 | M31: =IF(K31="N",0,L31) -> 0 | N31: PPM DONE
A32: 15 | B32: KKM/JKN/HSA/10-05-01/H/15/1234 | C32: INFUSION PUMP | D32: 7245 | E32: HSASWOBE26012191 | F32: WAD 10B (Wad Perubatan Perempuan 10B) | G32: 46084 | H32: 46085 | J32: 46084 | K32: N | L32: =ROUNDUP((D32/4999.99)*10,-1) -> 20 | M32: =IF(K32="N",0,L32) -> 0 | N32: PPM DONE
A33: 16 | B33: KKM/JKN/HSA/10-05-01/H/15/1235 | C33: INFUSION PUMP | D33: 7245 | E33: HSASWOBE26012192 | F33: WAD 10B (Wad Perubatan Perempuan 10B) | G33: 46084 | H33: 46085 | J33: 46084 | K33: N | L33: =ROUNDUP((D33/4999.99)*10,-1) -> 20 | M33: =IF(K33="N",0,L33) -> 0 | N33: PPM DONE
... A70: 77 | B70: KKM/JKN/HSA/10-05-01/H/21/267 | C70: RESPIRATION HUMIDIFIER | D70: 21000 | E70: HSASWOBE26012254 | F70: Unit Rawatan Rapi (ICU) | G70: 46090 | H70: 46091 | J70: 46090 | K70: N | L70: =ROUNDUP((D70/4999.99)*10,-1) -> 50 | M70: =IF(K70="N",0,L70) -> 0 | N70: PPM DONE
A71: 78 | B71: KKM/JKN/HSA/10-05-01/H/21/233 | C71: VOLUMETRIC PUMP | D71: 2400 | E71: HSASWOBE26012255 | F71: Unit Rawatan Koronari (CCU) | G71: 46090 | H71: 46091 | J71: 46090 | K71: N | L71: =ROUNDUP((D71/4999.99)*10,-1) -> 10 | M71: =IF(K71="N",0,L71) -> 0 | N71: PPM DONE | O71: H/21/144
A72: 79 | B72: KKM/JKN/HSA/10-05-01/H/21/234 | C72: VOLUMETRIC PUMP | D72: 2400 | E72: HSASWOBE26012256 | F72: Unit Rawatan Koronari (CCU) | G72: 46090 | H72: 46091 | J72: 46090 | K72: N | L72: =ROUNDUP((D72/4999.99)*10,-1) -> 10 | M72: =IF(K72="N",0,L72) -> 0 | N72: PPM DONE
A73: 80 | B73: KKM/JKN/HSA/10-05-01/H/21/235 | C73: VOLUMETRIC PUMP | D73: 2400 | E73: HSASWOBE26012257 | F73: Unit Rawatan Koronari (CCU) | G73: 46090 | H73: 46091 | J73: 46090 | K73: N | L73: =ROUNDUP((D73/4999.99)*10,-1) -> 10 | M73: =IF(K73="N",0,L73) -> 0 | N73: PPM DONE | O73: H/21/147
A74: 81 | B74: KKM/JKN/HSA/10-05-01/H/21/236 | C74: VOLUMETRIC PUMP | D74: 2400 | E74: HSASWOBE26012258 | F74: Unit Rawatan Koronari (CCU) | G74: 46090 | H74: 46091 | J74: 46090 | K74: N | L74: =ROUNDUP((D74/4999.99)*10,-1) -> 10 | M74: =IF(K74="N",0,L74) -> 0 | N74: PPM DONE
A75: 83 | B75: KKM/JKN/HSA/10-05-01/R/15/14870 | C75: BLOOD PRESSURE MONITOR (SPHYGMOMANOMETER) | D75: 452.81 | E75: HSASWOBE26012263 | F75: Dewan Bersalin (LDU) | G75: 46091 | H75: 46092 | J75: 46091 | K75: N | L75: =ROUNDUP((D75/4999.99)*10,-1) -> 10 | M75: =IF(K75="N",0,L75) -> 0 | N75: PPM DONE
A76: 92 | B76: KKM/JKN/HSA/10-05-01/H/15/4007 | C76: PLASMA THAWER | D76: 14279 | E76: HSASWOBE26012272 | F76: PATHOLOGY | G76: 46092 | H76: 46093 | J76: 46093 | K76: N | L76: =ROUNDUP((D76/4999.99)*10,-1) -> 30 | M76: =IF(K76="N",0,L76) -> 0 | N76: PPM DONE
A77: 93 | B77: KKM/JKN/HSA/10-05-01/H/15/637 | C77: SYRINGE INFUSION PUMP | D77: 4300 | E77: HSASWOBE26012273 | F77: Unit Rawatan Koronari (CCU) | G77: 46092 | H77: 46093 | J77: 46092 | K77: N | L77: =ROUNDUP((D77/4999.99)*10,-1) -> 10 | M77: =IF(K77="N",0,L77) -> 0 | N77: PPM DONE
A78: 94 | B78: KKM/JKN/HSA/10-05-01/H/15/638 | C78: SYRINGE INFUSION PUMP | D78: 4300 | E78: HSASWOBE26012274 | F78: Unit Rawatan Koronari (CCU) | G78: 46092 | H78: 46093 | J78: 46092 | K78: N | L78: =ROUNDUP((D78/4999.99)*10,-1) -> 10 | M78: =IF(K78="N",0,L78) -> 0 | N78: PPM DONE
A79: 95 | B79: KKM/JKN/HSA/10-05-01/H/15/639 | C79: SYRINGE INFUSION PUMP | D79: 4300 | E79: HSASWOBE26012275 | F79: Unit Rawatan Koronari (CCU) | G79: 46092 | H79: 46093 | J79: 46092 | K79: N | L79: =ROUNDUP((D79/4999.99)*10,-1) -> 10 | M79: =IF(K79="N",0,L79) -> 0 | N79: PPM DONE
A80: 96 | B80: KKM/JKN/HSA/10-05-01/H/15/640 | C80: SYRINGE INFUSION PUMP | D80: 4300 | E80: HSASWOBE26012276 | F80: Unit Rawatan Koronari (CCU) | G80: 46092 | H80: 46093 | J80: 46092 | K80: N | L80: =ROUNDUP((D80/4999.99)*10,-1) -> 10 | M80: =IF(K80="N",0,L80) -> 0 | N80: PPM DONE
A81: 97 | B81: KKM/JKN/HSA/10-05-01/H/15/641 | C81: SYRINGE INFUSION PUMP | D81: 4300 | E81: HSASWOBE26012277 | F81: Unit Rawatan Koronari (CCU) | G81: 46092 | H81: 46093 | J81: 46092 | K81: N | L81: =ROUNDUP((D81/4999.99)*10,-1) -> 10 | M81: =IF(K81="N",0,L81) -> 0 | N81: PPM DONE
A82: 105 | B82: KKM/JKN/HSA/10-05-01/R/15/16750 | C82: ELECTRICAL NERVE STIMULATOR | D82: 949 | E82: HSASWOBE26012285 | F82: Jabatan Perubatan Rehabilitasi | G82: 46092 | H82: 46093 | J82: 46093 | K82: N | L82: =ROUNDUP((D82/4999.99)*10,-1) -> 10 | M82: =IF(K82="N",0,L82) -> 0 | N82: PPM DONE
A83: 106 | B83: KKM/JKN/HSA/10-05-01/R/15/16157 | C83: NEBULIZER | D83: 1950 | E83: HSASWOBE26012286 | F83: Wad 13 (VIP) | G83: 46092 | H83: 46093 | J83: 46092 | K83: N | L83: =ROUNDUP((D83/4999.99)*10,-1) -> 10 | M83: =IF(K83="N",0,L83) -> 0 | N83: PPM DONE
...

Sheet B4-UPTIME
A1: MINISTRY OF HEALTH
A2: Deduction Mapping Report Biomedical Engineering Maintenance Services (BEMS)
A3: INDICATOR B.4 UPTIME GUARANTEE
C5: HOSPITAL SHAH ALAM | P5: MONTH/YEAR : | Q5: =BEMSdar!E7 -> 46082
C7: SELANGOR | M7: BEMS MONTHLY FEE (RM)@ 97.5% : | Q7: =BEMSdar!E11 -> 352591.82
C9: AMBANG WIRA SDN BHD | M9: FMS MONTHLY FEE (RM) @ 2.5% : | Q9: =BEMSdar!E13 -> 9040.816
B11: Notes:
B12: 1) Deduction Ringgit Equivalent is based on Appendix 11 of the Agreement, Section B3 Key Deduction Indicators for BEMS
B13: 2) Deduction Value for 1st cut off is Deduction Ringgit Equivalent (per event)
B14: 3) Deduction Value for 2nd cut off is Deduction Ringgit Equivalent (per event) multiply by 2
B15: 4) Display only asset affected by deduction
A17: No. | B17: Asset No | C17: Type Description | D17: Asset Purchase cost | E17: Asset Age | F17: TRKPI % | G17: Uptime % | S17: Deduction Ringgit Equivalent (RM) | T17: Previous Deduction (Month) | V17: Deduction for the month (Y/N) | X17: Deduction Value (RM) | Z17: Total Deduction (RM) | AA17: Remarks
G18: Jan | H18: Feb | I18: Mar | J18: Apr | K18: May | L18: Jun | M18: Jul | N18: Aug | O18: Sep | P18: Oct | Q18: Nov | R18: Dec | T18: 1st | U18: 2nd | V18: 1st | W18: 2nd | X18: 1st | Y18: 2nd
A19: 1 | B19: KKM/JKN/HSA/10-05-01/H/15/2458 | C19: AUDIOMETER | D19: ='B1-RESPONSE & B2-REPAIR'!D213 -> 43690 | E19: 11 | F19: 0.88 | G19: 0.92876712 | H19: 0.85205479 | I19: 0.76712329 | S19: =ROUNDUP((D19/4999.99)*10,-1) -> 90 | T19: Y | W19: Y | X19: =IF(V19="Y",S19,0) -> 0 | Y19: =IF(W19="Y",S19*2,0) -> 180 | Z19: =X19+Y19 -> 180 | AA19: BELUM CLOSE
A20: 2 | B20: KKM/JKN/HSA/10-05-01/H/15/2538 | C20: MAMMOGRAPHY WITH BIOPSY, DIGITAL | D20: ='B1-RESPONSE & B2-REPAIR'!D214 -> 990000 | E20: 11 | F20: 0.85 | G20: 0.9369863 | I20: 0.77534247 | S20: =ROUNDUP((D20/4999.99)*10,-1) -> 1990 | T20: N | W20: N | X20: =IF(V20="Y",S20,0) -> 0 | Y20: =IF(W20="Y",S20*2,0) -> 0 | Z20: =X20+Y20 -> 0 | AA20: BELUM CLOSE, RIW
A21: 3 | B21: KKM/JKN/HSA/10-05-01/H/20/129 | C21: INFUSION PUMP | D21: ='B1-RESPONSE & B2-REPAIR'!D164 -> 3150 | E21: 6 | F21: 0.95 | G21: 0.9369863 | H21: 0.86027397 | I21: 0.77534247 | S21: =ROUNDUP((D21/4999.99)*10,-1) -> 10 | T21: Y | W21: Y | X21: =IF(V21="Y",S21,0) -> 0 | Y21: =IF(W21="Y",S21*2,0) -> 20 | Z21: =X21+Y21 -> 20 | AA21: BELUM CLOSE
A22: 4 | B22: KKM/JKN/HSA/10-05-01/H/20/268 | C22: Ventilators, Intensive Care, Neonatal/Pediatric | D22: ='B1-RESPONSE & B2-REPAIR'!D215 -> 50000 | E22: 6 | F22: 0.95 | G22: 0.93972603 | H22: 0.8630137 | I22: 0.77808219 | S22: =ROUNDUP((D22/4999.99)*10,-1) -> 110 | T22: Y | W22: Y | X22: =IF(V22="Y",S22,0) -> 0 | Y22: =IF(W22="Y",S22*2,0) -> 220 | Z22: =X22+Y22 -> 220 | AA22: BELUM CLOSE
A23: 5 | B23: KKM/JKN/HSA/10-05-01/H/21/291 | C23: Phototherapy Units, Visible Light, Hyperbilirubinemia | D23: ='B1-RESPONSE & B2-REPAIR'!D181 -> 7100 | E23: 5 | F23: 0.99 | G23: 0.94520548 | H23: 0.86849315 | I23: 0.86575342 | S23: =ROUNDUP((D23/4999.99)*10,-1) -> 20 | T23: Y | W23: N | X23: =IF(V23="Y",S23,0) -> 0 | Y23: =IF(W23="Y",S23*2,0) -> 0 | Z23: =X23+Y23 -> 0 | AA23: CLOSE
A24: 6 | B24: KKM/JKN/HSA/10-05-01/H/22/84 | C24: PHOTOTHERAPY MACHINE | D24: ='B1-RESPONSE & B2-REPAIR'!D216 -> 7100 | E24: 4 | F24: 0.99 | G24: 0.94520548 | H24: 0.86849315 | I24: 0.78356164 | S24: =ROUNDUP((D24/4999.99)*10,-1) -> 20 | T24: Y | W24: Y | X24: =IF(V24="Y",S24,0) -> 0 | Y24: =IF(W24="Y",S24*2,0) -> 40 | Z24: =X24+Y24 -> 40 | AA24: BELUM CLOSE
A25: 7 | B25: KKM/JKN/HSA/10-05-01/H/15/1609 | C25: INFANT VENTILATOR | D25: 53000 | E25: 11 | F25: 0.88 | G25: 0.94520548 | S25: =ROUNDUP((D25/4999.99)*10,-1) -> 110 | T25: N | V25: N | X25: =IF(V25="Y",S25,0) -> 0 | Y25: =IF(W25="Y",S25*2,0) -> 0 | Z25: =X25+Y25 -> 0 | AA25: CLOSE
A26: 8 | B26: KKM/JKN/HSA/10-05-01/H/15/4018 | C26: HEMOGLOBIN SYSTEM FOR HBA1C | D26: ='B1-RESPONSE & B2-REPAIR'!D182 -> 67000 | E26: 11 | F26: 0.85 | G26: 0.95068493 | H26: 0.8739726 | I26: 0.8 | S26: =ROUNDUP((D26/4999.99)*10,-1) -> 140 | T26: Y | W26: N | X26: =IF(V26="Y",S26,0) -> 0 | Y26: =IF(W26="Y",S26*2,0) -> 0 | Z26: =X26+Y26 -> 0 | AA26: CLOSE 27/3/26
A27: 9 | B27: KKM/JKN/HSA/10-05-01/H/21/339 | C27: VENTILATOR (NEONATAL) | D27: ='B1-RESPONSE & B2-REPAIR'!D183 -> 137000 | E27: 5 | F27: 0.99 | G27: 0.95342466 | H27: 0.87671233 | I27: 0.83287671 | S27: =ROUNDUP((D27/4999.99)*10,-1) -> 280 | T27: Y | W27: N | X27: =IF(V27="Y",S27,0) -> 0 | Y27: =IF(W27="Y",S27*2,0) -> 0 | Z27: =X27+Y27 -> 0 | AA27: CLOSE
A28: 10 | B28: KKM/JKN/HSA/10-05-01/H/15/581 | C28: PATIENT MONITORING EQUIP.(AUTOMATIC MULTIPARAMETER) | D28: ='B1-RESPONSE & B2-REPAIR'!D184 -> 4300 | E28: 11 | F28: 0.88 | G28: 0.95616438 | H28: 0.89041096 | S28: =ROUNDUP((D28/4999.99)*10,-1) -> 10 | T28: Y | W28: N | X28: =IF(V28="Y",S28,0) -> 0 | Y28: =IF(W28="Y",S28*2,0) -> 0 | Z28: =X28+Y28 -> 0 | AA28: CLOSE
A29: 11 | B29: KKM/JKN/HSA/10-05-01/H/15/479 | C29: INFANT INCUBATOR | D29: 24000 | E29: 11 | F29: 0.88 | H29: 0.95616438 | I29: 0.90136986 | S29: =ROUNDUP((D29/4999.99)*10,-1) -> 50 | T29: N | V29: N | X29: =IF(V29="Y",S29,0) -> 0 | Y29: =IF(W29="Y",S29*2,0) -> 0 | Z29: =X29+Y29 -> 0 | AA29: BELUM CLOSE
A30: 12 | B30: KKM/JKN/HSA/10-05-01/H/17/4 | C30: ULTRASOUND SCANNER/MINDRAY M9 | D30: 198800 | E30: 9 | F30: 0.92 | H30: 0.95890411 | I30: 0.94078957 | S30: =ROUNDUP((D30/4999.99)*10,-1) -> 400 | T30: N | V30: N | X30: =IF(V30="Y",S30,0) -> 0 | Y30: =IF(W30="Y",S30*2,0) -> 0 | Z30: =X30+Y30 -> 0 | AA30: BELUM CLOSE
A31: 13 | B31: KKM/JKN/HSA/10-05-01/H/15/790 | C31: SYRINGE INFUSION PUMP | D31: ='B1-RESPONSE & B2-REPAIR'!D184 -> 4300 | E31: 11 | F31: 0.88 | G31: 0.96164384 | H31: 0.88493151 | I31: 0.83835616 | S31: =ROUNDUP((D31/4999.99)*10,-1) -> 10 | T31: N | V31: Y | X31: =IF(V31="Y",S31,0) -> 10 | Y31: =IF(W31="Y",S31*2,0) -> 0 | Z31: =X31+Y31 -> 10 | AA31: CLOSE 17/3/26
A32: 14 | B32: HSAS10016 | C32: DRILL, SURGICAL, SMALL BONE, PNEUMATIC | D32: ='B1-RESPONSE & B2-REPAIR'!D186 -> 80900 | E32: 10 | F32: 0.95 | G32: 0.96438356 | H32: 0.88767123 | I32: 0.84383562 | S32: =ROUNDUP((D32/4999.99)*10,-1) -> 170 | T32: N | V32: Y | X32: =IF(V32="Y",S32,0) -> 170 | Y32: =IF(W32="Y",S32*2,0) -> 0 | Z32: =X32+Y32 -> 170 | AA32: BELUM CLOSE
A33: 15 | B33: KKM/JKN/HSA/10-05-01/H/15/312 | C33: VENTILATOR | D33: ='B1-RESPONSE & B2-REPAIR'!D217 -> 50000 | E33: 11 | F33: 0.88 | G33: 0.96438356 | H33: 0.88767123 | I33: 0.80273973 | S33: =ROUNDUP((D33/4999.99)*10,-1) -> 110 | T33: N | V33: Y | X33: =IF(V33="Y",S33,0) -> 110 | Y33: =IF(W33="Y",S33*2,0) -> 0 | Z33: =X33+Y33 -> 110 | AA33: BELUM CLOSE
A34: 16 | B34: KKM/JKN/HSA/10-05-01/H/15/985 | C34: ELECTROSURGICAL UNIT | D34: ='B1-RESPONSE & B2-REPAIR'!D218 -> 20328 | E34: 11 | F34: 0.88 | G34: 0.96438356 | H34: 0.88767123 | I34: 0.80273973 | S34: =ROUNDUP((D34/4999.99)*10,-1) -> 50 | T34: N | V34: Y | X34: =IF(V34="Y",S34,0) -> 50 | Y34: =IF(W34="Y",S34*2,0) -> 0 | Z34: =X34+Y34 -> 50 | AA34: BELUM CLOSE
A35: 17 | B35: KKM/JKN/HSA/10-05-01/H/15/2250 | C35: Infusion Pumps, Syringe | D35: ='B1-RESPONSE & B2-REPAIR'!D185 -> 2700 | E35: 11 | F35: 0.88 | G35: 0.96438356 | H35: 0.88767123 | I35: 0.80547945 | S35: =ROUNDUP((D35/4999.99)*10,-1) -> 10 | T35: N | V35: Y | X35: =IF(V35="Y",S35,0) -> 10 | Y35: =IF(W35="Y",S35*2,0) -> 0 | Z35: =X35+Y35 -> 10 | AA35: CLOSE 30/3/26
A36: 18 | B36: KKM/JKN/HSA/10-05-01/H/19/17 | C36: PULSE OXIMETER AND SIMULATOR | D36: ='B1-RESPONSE & B2-REPAIR'!D219 -> 5450 | E36: 7 | F36: 0.95 | G36: 0.96712329 | H36: 0.89041096 | I36: 0.80547945 | S36: =ROUNDUP((D36/4999.99)*10,-1) -> 20 | T36: N | V36: Y | X36: =IF(V36="Y",S36,0) -> 20 | Y36: =IF(W36="Y",S36*2,0) -> 0 | Z36: =X36+Y36 -> 20 | AA36: BELUM CLOSE
A37: 19 | B37: KKM/JKN/HSA/10-05-01/H/15/1236 | C37: INFUSION PUMP | D37: 7245 | E37: 11 | F37: 0.88 | G37: 0.96712329 | S37: =ROUNDUP((D37/4999.99)*10,-1) -> 20 | T37: N | X37: =IF(V37="Y",S37,0) -> 0 | Y37: =IF(W37="Y",S37*2,0) -> 0 | Z37: =X37+Y37 -> 0 | AA37: CLOSE
A38: 20 | B38: KKM/JKN/HSA/10-05-01/H/15/1235 | C38: INFUSION PUMP | D38: 7245 | E38: 11 | F38: 0.88 | G38: 0.96712329 | S38: =ROUNDUP((D38/4999.99)*10,-1) -> 20 | T38: N | X38: =IF(V38="Y",S38,0) -> 0 | Y38: =IF(W38="Y",S38*2,0) -> 0 | Z38: =X38+Y38 -> 0 | AA38: CLOSE
A39: 21 | B39: KKM/JKN/HSA/10-05-01/H/16/85 | C39: PULSE OXIMETER AND SIMULATOR | D39: ='B1-RESPONSE & B2-REPAIR'!D220 -> 7400 | E39: 10 | F39: 0.88 | G39: 0.96986301 | H39: 0.89315068 | I39: 0.80821918 | S39: =ROUNDUP((D39/4999.99)*10,-1) -> 20 | T39: N | V39: N | X39: =IF(V39="Y",S39,0) -> 0 | Y39: =IF(W39="Y",S39*2,0) -> 0 | Z39: =X39+Y39 -> 0 | AA39: BELUM CLOSE
A40: 22 | B40: KKM/JKN/HSA/10-05-01/H/15/3630 | C40: INFANT VENTILATOR | D40: 53000 | E40: 11 | F40: 0.88 | G40: 0.96986301 | S40: =ROUNDUP((D40/4999.99)*10,-1) -> 110 | V40: N | X40: =IF(V40="Y",S40,0) -> 0 | Y40: =IF(W40="Y",S40*2,0) -> 0 | Z40: =X40+Y40 -> 0 | AA40: CLOSE
