Workbook
Name _05_04_2009: #REF!
Name _05_04_2009: #REF!
Name _05_04_2009: #REF!
Name _05_04_2009: #REF!
Name _05_04_2009: #REF!
Name a: '[1]Term Outstanding Payment'!#REF!
Name a: '[1]Term Outstanding Payment'!#REF!
Name a: '[1]Term Outstanding Payment'!#REF!
Name a: '[1]Term Outstanding Payment'!#REF!
Name a: '[1]Term Outstanding Payment'!#REF!
Name AA: #REF!
Name AA: #REF!
Name AA: #REF!
Name AA: #REF!
Name AA: #REF!
Name aaa: #REF!
Name aaa: #REF!
Name aaa: #REF!
Name aaa: #REF!
Name aaa: #REF!
Name aaaaa: #REF!
Name aaaaa: #REF!
Name aaaaa: #REF!
Name aaaaa: #REF!
Name aaaaa: #REF!
Name aaaaaaaaaa: #REF!
Name aaaaaaaaaa: #REF!
Name aaaaaaaaaa: #REF!
Name aaaaaaaaaa: #REF!
Name AAAAAAAAAAAAA: #REF!
Name AAAAAAAAAAAAA: #REF!
Name AAAAAAAAAAAAA: #REF!
Name AAAAAAAAAAAAA: #REF!
Name AAAAAAAAAAAAAAAAAA: #REF!
Name AAAAAAAAAAAAAAAAAA: #REF!
Name AAAAAAAAAAAAAAAAAA: #REF!
Name AAAAAAAAAAAAAAAAAA: #REF!
Name AAAAAAAAAAAAAAAAAAAAA: #REF!
Name AAAAAAAAAAAAAAAAAAAAA: #REF!
Name AAAAAAAAAAAAAAAAAAAAA: #REF!
Name AAAAAAAAAAAAAAAAAAAAA: #REF!
Name AAAAAAAAAAAAAAAAAAAAAAAAAAA: #REF!
Name AAAAAAAAAAAAAAAAAAAAAAAAAAA: #REF!
Name AAAAAAAAAAAAAAAAAAAAAAAAAAA: #REF!
Name AAAAAAAAAAAAAAAAAAAAAAAAAAA: #REF!
Name AAAAAAAAAAAAAAAAAAAAAAAAAAAA: #REF!
Name AAAAAAAAAAAAAAAAAAAAAAAAAAAA: #REF!
Name AAAAAAAAAAAAAAAAAAAAAAAAAAAA: #REF!
Name AAAAAAAAAAAAAAAAAAAAAAAAAAAA: #REF!
Name AAAAAAAAAAAAAAAAAAAAAAAAAAAAAA: #REF!
Name AAAAAAAAAAAAAAAAAAAAAAAAAAAAAA: #REF!
Name AAAAAAAAAAAAAAAAAAAAAAAAAAAAAA: #REF!
Name AAAAAAAAAAAAAAAAAAAAAAAAAAAAAA: #REF!
Name AAAAAAAAAAAAAAAAAAAAAAAAAAAAAAA: #REF!
Name AAAAAAAAAAAAAAAAAAAAAAAAAAAAAAA: #REF!
Name AAAAAAAAAAAAAAAAAAAAAAAAAAAAAAA: #REF!
Name AAAAAAAAAAAAAAAAAAAAAAAAAAAAAAA: #REF!
Name AAAAAAAAAAAAAAAAAAAAAAAAAAAAAAAAA: #REF!
Name AAAAAAAAAAAAAAAAAAAAAAAAAAAAAAAAA: #REF!
Name AAAAAAAAAAAAAAAAAAAAAAAAAAAAAAAAA: #REF!

Sheet BEMSdar
A1: MINISTRY OF HEALTH
A2: Deduction Mapping Report Biomedical Engineering Maintenance Services (BEMS)
D5: HOSPITAL NAME : | E5: Institut Kanser Negara | I5: STATE: | J5: W.P. Putrajaya
D7: MONTH/YEAR : | E7: 46143 | I7: COMPANY: | J7: Ambang Wira Sdn Bhd
A9: MONTHLY SERVICE FEE (RM) : | E9: 1363910.9
A11: BEMS MONTHLY FEE (RM) @ 97.5% : | E11: =97.5%*E9 -> 1329813.2
A13: FMS MONTHLY FEE (RM) @ 2.5% : | E13: =2.5%*E9 -> 34097.773
A17: No | B17: Key Deduction Indicators | I17: Frequency | L17: Deduction Value (RM) | N17: Deduction % | O17: Performance Level (%)
A19: B.1 | B19: All service requests shall be responded by the Company’s trained technical personal within the timeframe as stipulated in the Agreement. | I19: Per event | L19: 0 | N19: 0 | O19: =100-N19 -> 100
A20: B.2 | B20: All unscheduled maintenance works including relevant maintenance calibration, safety tests and functional checks shall be completed within seven (7) working days. | I20: Per day | L20: ='B1&B2 UNSCHEDULED'!U106 -> 13280 | N20: =L20/$E$11% -> 0.99863653 | O20: =100-N20 -> 99.001363
A21: B.3 | B21: Scheduled maintenance shall be carried out as per schedule and according to the procedure as specified in the Agreement. Scheduled maintenance shall include complete safety and performance tests. | I21: Per event | L21: ='B3-SCHEDULED'!L216 -> 0 | N21: =L21/$E$11% -> 0 | O21: =100-N21 -> 100
A22: B.4 | B22: All biomedical equipment shall be functioning and maintained to ensure uptime target as specified in the TRKPI are met. | I22: Per event | L22: 0 | N22: =L22/$E$11% -> 0 | O22: =100-N22 -> 100
A23: B.5 | B23: T&C and Warranty Management of newly introduced biomedical shall be managed and performed according to the Agreement and related acts, standards and regulations. | I23: Per event | L23: ='B5-T&C'!O24 -> 0 | N23: =L23/$E$11% -> 0 | O23: =100-N23 -> 100
A24: Total | L24: =SUM(L19:M23) -> 13280 | N24: =SUM(N19:N23) -> 0.99863653 | O24: =100-N24 -> 99.001363
C27: Prepared by: | I27: Verified by:
C31: Siti Norsaliana Binti Abu Khalid | I31: Mohd Shahrulnizam bin Tarmizi
C32: Head of BEMS | I32: Facility Manager
C33: Ambang Wira Sdn Bhd- Institut Kanser Negara | I33: Ambang Wira Sdn Bhd- Institut Kanser Negara
C34: Date: | I34: Date:

Sheet B1&B2 UNSCHEDULED
A2: MINISTRY OF HEALTH
A3: Deduction Mapping Report Biomedical Engineering Maintenance Services (BEMS)
A4: INDICATOR B.1 RESPONSE TIME & B.2 REPAIR TIME
A6: HOSPITAL NAME: | C6: INSTITUT KANSER NEGARA | I6: FIRST DATE OF THE MONTH : | M6: 46143 | Q6: (For Calculation)
A8: STATE: | C8: WILAYAH PERSEKUTUAN PUTRAJAYA | I8: LAST DATE OF THE MONTH : | M8: 46173 | Q8: (For Calculation)
A10: COMPANY: | C10: AMBANG WIRA SDN BHD | I10: BEMS MONTHLY FEE (RM) @ 97.5% : | M10: =BEMSdar!E11 -> 1329813.2
A12: MONTH/YEAR: | C12: 46143 | I12: FMS MONTHLY FEE (RM) @ 2.5% : | M12: =BEMSdar!E13 -> 34097.773
A14: Notes:
A15: 1) Deduction Ringgit Equivalent is based on Appendix 11 of the Agreement, Section B3 Key Deduction Indicators for BEMS
A16: 2) Deduction Value for Indicator B.1 is Deduction Ringgit Equivalent (per event)
A17: 3) Total Repair Time includes weekend & public holiday
A18: 4) Demerit Point for Indicator B.2 is calculated based on completion date against request date, less by 7 working days
A19: 5) Deduction Value for Indicator B.2 is Demerit Point multiply by Deduction Ringgit Equivalent
A21: No | B21: Asset No | C21: Asset Description | D21: Asset Purchase Price (RM) | E21: Work Order No. | F21: User Location | G21: Work Order/ Complaint Details | H21: Response Category (Emergency/ Normal) | I21: Total Response Time (minutes) | J21: Work Request Date | K21: Response Time (Minutes) | L21: Work Completion Date | M21: Deduction Ringgit Equivalent (RM) | N21: Indicator B.1 | Q21: Indicator B.2
N22: Validate Status (Y/N) | O22: Deduction Value (RM) | P22: Remarks/ Exemption | Q22: Validate Status (Y/N) | R22: Total Repair Time (day) | S22: Last date of 7 working days (dd/mm/yy) | T22: Demerit Point | U22: Deduction Value (RM) | V22: Remarks/ Exemption
A23: Current Month (Work Order Completed)
A24: 1 | B24: IKN400755 | C24: =VLOOKUP(B24,[13]AssetDetails_UEM!$A$3:$AH$1849,6,FALSE) -> Analyzers, Laboratory, Hematology, Coagulation, Automated | D24: =VLOOKUP(B24,[13]AssetDetails_UEM!$A$3:$AK$1849,22,FALSE) -> 105860 | E24: IKNWIBE26008258 | F24: 04LA132 | G24: MESIN ACL ELITE PRO ALARM SAMPLE LEVEL LOW - PATOLOGI ARAS 4 | H24: Normal | I24: 0 days, 0 hrs, 20 mins | J24: 02-May-2026 09:40:00 | K24: 02-May-2026 10:00:00 | L24: 08-May-2026 11:00:00 | M24: =IF(D24>44999.99,100,ROUNDUP((D24/4999.99)*10,-1)) -> 100 | N24: N | O24: ='[14]B1& B2 UNSCHEDULED'!$O$24 -> 0 | Q24: N | R24: 6 | S24: =WORKDAY(J24,6,AKHIR) -> 46153 | T24: 0 | U24: =IF(Q24="N",0,M24*T24) -> 0 | V24: M-RUN CALIBRATION , QC, ALLIGNMENT THE PROBE, TEST FUNCTIONING OK
A25: 2 | B25: IKN400342 | C25: =VLOOKUP(B25,[13]AssetDetails_UEM!$A$3:$AH$1849,6,FALSE) -> Mattress Systems, Alternating-Pressure | D25: =VLOOKUP(B25,[13]AssetDetails_UEM!$A$3:$AK$1849,22,FALSE) -> 28630 | E25: IKNWIBE26008371 | F25: 07WF121 | G25: RIPPLE MATTRESS CONNECTOR TUBING ROSAK - WAD 7B | H25: Normal | I25: 0 days, 0 hrs, 5 mins | J25: 04-May-2026 20:40:00 | K25: 04-May-2026 20:45:00 | L25: 05-May-2026 19:30:00 | M25: =IF(D25>44999.99,100,ROUNDUP((D25/4999.99)*10,-1)) -> 60 | N25: N | O25: ='[14]B1& B2 UNSCHEDULED'!$O$24 -> 0 | Q25: N | R25: =IF(L25="",AKHIR-J25,L25-J25+1) -> 1.9513889 | S25: =WORKDAY(J25,6,AKHIR) -> 46154 | T25: 0 | U25: =IF(Q25="N",0,M25*T25) -> 0 | V25: L, QE:12-RE -SEAT CONNECTOR HOSE , MONITORING FOR 1 DAY TESTED OKAY
A26: 3 | B26: IKN400965 | C26: =VLOOKUP(B26,[13]AssetDetails_UEM!$A$3:$AH$1849,6,FALSE) -> Linear Accelerators | D26: =VLOOKUP(B26,[13]AssetDetails_UEM!$A$3:$AK$1849,22,FALSE) -> 19351760 | E26: IKNWIBE26008469 | F26: 01RT177 | G26: MACHINE TOMOTHERAPHY MLC PROBLEM- RT | H26: Normal | I26: 0 days, 0 hrs, 3 mins | J26: 05-May-2026 16:37:00 | K26: 05-May-2026 16:40:00 | L26: 05-May-2026 21:00:00 | M26: =IF(D26>44999.99,100,ROUNDUP((D26/4999.99)*10,-1)) -> 100 | N26: N | O26: ='[14]B1& B2 UNSCHEDULED'!$O$24 -> 0 | Q26: N | R26: =IF(L26="",AKHIR-J26,L26-J26+1) -> 1.1826389 | S26: =WORKDAY(J26,6,AKHIR) -> 46155 | T26: 0 | U26: =IF(Q26="N",0,M26*T26) -> 0 | V26: L, QE:12-REPLACED WITH NEW UPS BATTERIES AND TESTED PDU TURNED ON UNIT LEFT
A27: 4 | B27: IKN400231 | C27: =VLOOKUP(B27,[13]AssetDetails_UEM!$A$3:$AH$1849,6,FALSE) -> Infusion Pumps, General-Purpose | D27: =VLOOKUP(B27,[13]AssetDetails_UEM!$A$3:$AK$1849,22,FALSE) -> 10825 | E27: IKNWIBE26008530 | F27: 09WJ126 | G27: MACHINE INFUSION PUMP BUTTON WARNA HIJAU PATAH- WAD 9A | H27: Normal | I27: 0 days, 0 hrs, 12 mins | J27: 06-May-2026 10:48:00 | K27: 46148.458 | L27: 46149.396 | M27: =IF(D27>44999.99,100,ROUNDUP((D27/4999.99)*10,-1)) -> 30 | N27: N | O27: ='[14]B1& B2 UNSCHEDULED'!$O$24 -> 0 | Q27: N | R27: =IF(L27="",AKHIR-J27,L27-J27+1) -> 1.9458333 | S27: =WORKDAY(J27,6,AKHIR) -> 46156 | T27: 0 | U27: =IF(Q27="N",0,M27*T27) -> 0 | V27: NO PHYSICAL DAMAGE ON UNIT, USER MISSUNDERTAND THE LOCK ON IV LINE AS A PART OF THE MACHINE. UNIT OK
A28: 5 | B28: IKN400366 | C28: =VLOOKUP(B28,[13]AssetDetails_UEM!$A$3:$AH$1849,6,FALSE) -> Infusion Pumps, General-Purpose | D28: =VLOOKUP(B28,[13]AssetDetails_UEM!$A$3:$AK$1849,22,FALSE) -> 10825 | E28: IKNWIBE26008551 | F28: 07WE113 | G28: WAYAR CHARGER INFUSION PUMP TERCABUT- WAD 7A | H28: Normal | I28: 0 days, 0 hrs, 9 mins | J28: 06-May-2026 17:24:00 | K28: 46148.733 | L28: 14-May-2026 11:30:00 | M28: =IF(D28>44999.99,100,ROUNDUP((D28/4999.99)*10,-1)) -> 30 | N28: N | O28: ='[14]B1& B2 UNSCHEDULED'!$O$24 -> 0 | Q28: N | R28: 7 | S28: =WORKDAY(J28,6,AKHIR) -> 46156 | T28: 0 | U28: =IF(Q28="N",0,M28*T28) -> 0 | V28: L, QE:12-REPLACE NEW CHARGER , TESTED AND ABLE TO CHANGE THE MACHINE
A29: 6 | B29: IKN400288 | C29: =VLOOKUP(B29,[13]AssetDetails_UEM!$A$3:$AH$1849,6,FALSE) -> Infusion Pumps, General-Purpose | D29: =VLOOKUP(B29,[13]AssetDetails_UEM!$A$3:$AK$1849,22,FALSE) -> 10825 | E29: IKNWIBE26008552 | F29: 08WH121 | G29: MACHINE INFUSION PUMP ROSAK (ERROR 2035)- WAD 8B | H29: Normal | I29: 0 days, 0 hrs, 41 mins | J29: 06-May-2026 17:49:00 | K29: 06-May-2026 18:30:00 | L29: 08-May-2026 18:45:00 | M29: =IF(D29>44999.99,100,ROUNDUP((D29/4999.99)*10,-1)) -> 30 | N29: N | O29: ='[14]B1& B2 UNSCHEDULED'!$O$24 -> 0 | Q29: N | R29: =IF(L29="",AKHIR-J29,L29-J29+1) -> 3.0388889 | S29: =WORKDAY(J29,6,AKHIR) -> 46156 | T29: 0 | U29: =IF(Q29="N",0,M29*T29) -> 0 | V29: L, QE:10-REPAIR MACHINE CLEAN THE MOTOR DRIVER,ROTATE CLOCKWISE, CLEAN USING CONTACT CLEANER , MAKE SURE MOTOR FUNCTIONING WELL, TEST MACHINE PASSER, MOTOR DRIVER FUNCTIONING WELL, DOOR CLOSE WELL , UNIT READY FOR USE
A30: 7 | B30: IKN400956 | C30: =VLOOKUP(B30,[13]AssetDetails_UEM!$A$3:$AH$1849,6,FALSE) -> Linear Accelerators | D30: =VLOOKUP(B30,[13]AssetDetails_UEM!$A$3:$AK$1849,22,FALSE) -> 21961900 | E30: IKNWIBE26008603 | F30: 01RT172 | G30: SPEAKER MACHINE NOVALIS ROSAK- RT | H30: Normal | I30: 0 days, 0 hrs, 21 mins | J30: 07-May-2026 08:09:00 | K30: 07-May-2026 08:30:00 | L30: 07-May-2026 18:00:00 | M30: =IF(D30>44999.99,100,ROUNDUP((D30/4999.99)*10,-1)) -> 100 | N30: N | O30: ='[14]B1& B2 UNSCHEDULED'!$O$24 -> 0 | Q30: N | R30: =IF(L30="",AKHIR-J30,L30-J30+1) -> 1.4104167 | S30: =WORKDAY(J30,6,AKHIR) -> 46157 | T30: 0 | U30: =IF(Q30="N",0,M30*T30) -> 0 | V30: L, QE:1- REPLACED WHOLE SYSTEM SPEAKER AND TESTED OKAY . UNIT LEFT WITH GOOD WORKING CONDITION
A31: 8 | B31: IKN400199 | C31: =VLOOKUP(B31,[13]AssetDetails_UEM!$A$3:$AH$1849,6,FALSE) -> Mattress Systems, Alternating-Pressure | D31: =VLOOKUP(B31,[13]AssetDetails_UEM!$A$3:$AK$1849,22,FALSE) -> 28630 | E31: IKNWIBE26008698 | F31: 09WJ130 | G31: RIPPLE MATTRESS TIDAK KEMBANG- WAD 9A (ASSET NUM: NB355553) | H31: Normal | I31: 0 days, 0 hrs, 29 mins | J31: 08-May-2026 13:31:00 | K31: 08-May-2026 14:00:00 | L31: 08-May-2026 17:00:00 | M31: =IF(D31>44999.99,100,ROUNDUP((D31/4999.99)*10,-1)) -> 60 | N31: N | O31: ='[14]B1& B2 UNSCHEDULED'!$O$24 -> 0 | Q31: N | R31: =IF(L31="",AKHIR-J31,L31-J31+1) -> 1.1451389 | S31: =WORKDAY(J31,6,AKHIR) -> 46160 | T31: 0 | U31: =IF(Q31="N",0,M31*T31) -> 0 | V31: L, QE:12-TIGHTEN TUBING , MAKE SURE NO LEAKING , TEST MATTRESS PASSED, UNIT READY FOR USE
A32: 9 | B32: IKN400198 | C32: =VLOOKUP(B32,[13]AssetDetails_UEM!$A$3:$AH$1849,6,FALSE) -> Mattress Systems, Alternating-Pressure | D32: =VLOOKUP(B32,[13]AssetDetails_UEM!$A$3:$AK$1849,22,FALSE) -> 28630 | E32: IKNWIBE26008699 | F32: 09WJ126 | G32: RIPPLE MATTRESS TIDAK KEMBANG- WAD 9A | H32: Normal | I32: 0 days, 0 hrs, 26 mins | J32: 08-May-2026 14:49:00 | K32: 08-May-2026 15:15:00 | L32: 08-May-2026 16:15:00 | M32: =IF(D32>44999.99,100,ROUNDUP((D32/4999.99)*10,-1)) -> 60 | N32: N | O32: ='[14]B1& B2 UNSCHEDULED'!$O$24 -> 0 | Q32: N | R32: =IF(L32="",AKHIR-J32,L32-J32+1) -> 1.0597222 | S32: =WORKDAY(J32,6,AKHIR) -> 46160 | T32: 0 | U32: =IF(Q32="N",0,M32*T32) -> 0 | V32: L, QE:12-TIGHTEN TUBING , MAKE SURE NO LEAKING , TEST MATTRESS PASSED, UNIT FULLY INFLATE AND READY FOR USE
A33: 10 | B33: IKN402180 | C33: =VLOOKUP(B33,[13]AssetDetails_UEM!$A$3:$AH$1849,6,FALSE) -> Scanning Systems, Computed Tomography/ Positron Emission Tomography | D33: =VLOOKUP(B33,[13]AssetDetails_UEM!$A$3:$AK$1849,22,FALSE) -> 3413750 | E33: IKNWIBE26008704 | F33: 03NM158 | G33: ENHANCED QC FAILED- KLINIK NUKLEAR | H33: Normal | I33: 0 days, 0 hrs, 10 mins | J33: 08-May-2026 11:00:00 | K33: 08-May-2026 11:10:00 | L33: 08-May-2026 17:00:00 | M33: =IF(D33>44999.99,100,ROUNDUP((D33/4999.99)*10,-1)) -> 100 | N33: N | O33: ='[14]B1& B2 UNSCHEDULED'!$O$24 -> 0 | Q33: N | R33: =IF(L33="",AKHIR-J33,L33-J33+1) -> 1.25 | S33: =WORKDAY(J33,6,AKHIR) -> 46160 | T33: 0 | U33: =IF(Q33="N",0,M33*T33) -> 0 | V33: L, QE:12- VENDOR TROUBLESHOOT RUN DETECTOR CALIBRATION AND CREATED NEW MAP FOR CO57 FLOOD FOURCE , UNIT FUNCTIONING OKAY
A34: 11 | B34: IKN400267 | C34: =VLOOKUP(B34,[13]AssetDetails_UEM!$A$3:$AH$1849,6,FALSE) -> Sphygmomanometers, Electronic, Automatic | D34: =VLOOKUP(B34,[13]AssetDetails_UEM!$A$3:$AK$1849,22,FALSE) -> 4510 | E34: IKNWIBE26008805 | F34: 08WG143 | G34: BP CUFF LEAKING- WAD 8A | H34: Normal | I34: 0 days, 0 hrs, 19 mins | J34: 11-May-2026 09:11:00 | K34: 11-May-2026 09:30:00 | L34: 11-May-2026 10:00:00 | M34: =IF(D34>44999.99,100,ROUNDUP((D34/4999.99)*10,-1)) -> 10 | N34: N | O34: ='[14]B1& B2 UNSCHEDULED'!$O$24 -> 0 | Q34: N | R34: =IF(L34="",AKHIR-J34,L34-J34+1) -> 1.0340278 | S34: =WORKDAY(J34,6,AKHIR) -> 46161 | T34: 0 | U34: =IF(Q34="N",0,M34*T34) -> 0 | V34: L, QE:12-TEST UNIT, CUFF INFLATE WELL, UNIT READY FOR USE
A35: 12 | B35: IKN400300 | C35: =VLOOKUP(B35,[13]AssetDetails_UEM!$A$3:$AH$1849,6,FALSE) -> Mattress Systems, Alternating-Pressure | D35: =VLOOKUP(B35,[13]AssetDetails_UEM!$A$3:$AK$1849,22,FALSE) -> 28630 | E35: IKNWIBE26008806 | F35: 08WH121 | G35: RIPPLE MATTRESS ROSAK- WAD 8B | H35: Normal | I35: 0 days, 0 hrs, 21 mins | J35: 11-May-2026 09:39:00 | K35: 11-May-2026 10:00:00 | L35: 11-May-2026 12:00:00 | M35: =IF(D35>44999.99,100,ROUNDUP((D35/4999.99)*10,-1)) -> 60 | N35: N | O35: ='[14]B1& B2 UNSCHEDULED'!$O$24 -> 0 | Q35: N | R35: =IF(L35="",AKHIR-J35,L35-J35+1) -> 1.0979167 | S35: =WORKDAY(J35,6,AKHIR) -> 46161 | T35: 0 | U35: =IF(Q35="N",0,M35*T35) -> 0 | V35: L, QE:12-TIGHTEN TUBING ,UNIT INFLATE OKAY, TEST PASSED, UNIT READY FOR USE, NO LEAKING AT ALL
A36: 13 | B36: IKN402009 | C36: =VLOOKUP(B36,[13]AssetDetails_UEM!$A$3:$AH$1849,6,FALSE) -> Concentrators, Oxygen | D36: =VLOOKUP(B36,[13]AssetDetails_UEM!$A$3:$AK$1849,22,FALSE) -> 3400 | E36: IKNWIBE26009008 | F36: 04PC109 | G36: CM- REQ FOR PERFORMANCE CHECK | H36: Corrective Maintenance (CM) | I36: 0 days, 0 hrs, 10 mins | J36: 11-May-2026 16:00:00 | K36: 11-May-2026 16:10:00 | L36: 11-May-2026 17:10:00 | M36: =IF(D36>44999.99,100,ROUNDUP((D36/4999.99)*10,-1)) -> 10 | N36: N | O36: ='[14]B1& B2 UNSCHEDULED'!$O$24 -> 0 | Q36: N | R36: =IF(L36="",AKHIR-J36,L36-J36+1) -> 1.0486111 | S36: =WORKDAY(J36,6,AKHIR) -> 46161 | T36: 0 | U36: =IF(Q36="N",0,M36*T36) -> 0 | V36: AN- DONE PERFORMANCE CHECKING AS PER CHECKLIST ATTACHED
A37: 14 | B37: IKN402187 | C37: =VLOOKUP(B37,[13]AssetDetails_UEM!$A$3:$AH$1849,6,FALSE) -> Ultrasound | D37: 164800 | E37: IKNWIBE26009013 | F37: 03ID162 | G37: CM- MONITOR FAULTY | H37: Corrective Maintenance (CM) | I37: 0 days, 0 hrs, 5 mins | J37: 11-May-2026 14:00:00 | K37: 11-May-2026 14:05:00 | L37: 11-May-2026 16:00:00 | M37: =IF(D37>44999.99,100,ROUNDUP((D37/4999.99)*10,-1)) -> 100 | N37: N | O37: ='[14]B1& B2 UNSCHEDULED'!$O$24 -> 0 | Q37: N | R37: =IF(L37="",AKHIR-J37,L37-J37+1) -> 1.0833333 | S37: =WORKDAY(J37,6,AKHIR) -> 46161 | T37: 0 | U37: =IF(Q37="N",0,M37*T37) -> 0 | V37: L, QE:12-REPLACE NEW MONITOR WARRANTY TESTSED OKAY
A38: 15 | B38: IKN401237 | C38: =VLOOKUP(B38,[13]AssetDetails_UEM!$A$3:$AH$1849,6,FALSE) -> Electrocardiographs, Multichannel, Interpretative | D38: =VLOOKUP(B38,[13]AssetDetails_UEM!$A$3:$AK$1849,22,FALSE) -> 5590.2 | E38: IKNWIBE26009079 | F38: 03NM108 | G38: MACHINE ECG ERROR- KLINIK NUKLEAR | H38: Normal | I38: 0 days, 0 hrs, 16 mins | J38: 12-May-2026 10:59:00 | K38: 12-May-2026 11:15:00 | L38: 12-May-2026 13:00:00 | M38: =IF(D38>44999.99,100,ROUNDUP((D38/4999.99)*10,-1)) -> 20 | N38: N | O38: ='[14]B1& B2 UNSCHEDULED'!$O$24 -> 0 | Q38: N | R38: =IF(L38="",AKHIR-J38,L38-J38+1) -> 1.0840278 | S38: =WORKDAY(J38,6,AKHIR) -> 46162 | T38: 0 | U38: =IF(Q38="N",0,M38*T38) -> 0 | V38: L, QE:12- ADVICE USER TO USE ALL LIMB CLISTO PATIENT FIXED AND ENSURE ALL LIMB CLIP IN GOOD CONDITION , TESTED USING ANALYSER AND TO PERSON OKAY. IU
A39: 16 | B39: IKN402179 | C39: =VLOOKUP(B39,[13]AssetDetails_UEM!$A$3:$AH$1849,6,FALSE) -> Scanning Systems, Computed Tomography/ Positron Emission Tomography | D39: =VLOOKUP(B39,[13]AssetDetails_UEM!$A$3:$AK$1849,22,FALSE) -> 3410390 | E39: IKNWIBE26009088 | F39: 03NM161 | G39: CM- PREDICTIVE MAINTENANCE XELERIS | H39: Corrective Maintenance (CM) | I39: 0 days, 0 hrs, 15 mins | J39: 12-May-2026 10:00:00 | K39: 12-May-2026 10:15:00 | L39: 12-May-2026 13:15:00 | M39: =IF(D39>44999.99,100,ROUNDUP((D39/4999.99)*10,-1)) -> 100 | N39: N | O39: ='[14]B1& B2 UNSCHEDULED'!$O$24 -> 0 | Q39: N | R39: =IF(L39="",AKHIR-J39,L39-J39+1) -> 1.1354167 | S39: =WORKDAY(J39,6,AKHIR) -> 46162 | T39: 0 | U39: =IF(Q39="N",0,M39*T39) -> 0 | V39: L, QE:12-XELAERIS MAINTAINANCE COMPLETE BY VENDOR TESTED OKAY
A40: 17 | B40: IKN402180 | C40: =VLOOKUP(B40,[13]AssetDetails_UEM!$A$3:$AH$1849,6,FALSE) -> Scanning Systems, Computed Tomography/ Positron Emission Tomography | D40: =VLOOKUP(B40,[13]AssetDetails_UEM!$A$3:$AK$1849,22,FALSE) -> 3413750 | E40: IKNWIBE26009089 | F40: 03NM158 | G40: CM- PREDICTIVE MAINTENANCE XELERIS | H40: Corrective Maintenance (CM) | I40: 0 days, 0 hrs, 15 mins | J40: 12-May-2026 10:00:00 | K40: 12-May-2026 10:15:00 | L40: 12-May-2026 16:00:00 | M40: =IF(D40>44999.99,100,ROUNDUP((D40/4999.99)*10,-1)) -> 100 | N40: N | O40: ='[14]B1& B2 UNSCHEDULED'!$O$24 -> 0 | Q40: N | R40: =IF(L40="",AKHIR-J40,L40-J40+1) -> 1.25 | S40: =WORKDAY(J40,6,AKHIR) -> 46162 | T40: 0 | U40: =IF(Q40="N",0,M40*T40) -> 0 | V40: L, QE:12-XELERIS MAINTAINANACE COMPLETE BY VENDOR TEST OKAY
A41: 18 | B41: IKN400007 | C41: =VLOOKUP(B41,[13]AssetDetails_UEM!$A$3:$AH$1849,6,FALSE) -> Physiologic Monitoring Systems, Acute Care | D41: =VLOOKUP(B41,[13]AssetDetails_UEM!$A$3:$AK$1849,22,FALSE) -> 87400 | E41: IKNWIBE26009091 | F41: 01AE118 | G41: MACHINE SPO2 ROSAK- ACCU | H41: Normal | I41: 0 days, 0 hrs, 05 mins | J41: 12-May-2026 13:00:00 | K41: 46154.545 | L41: 46154.562 | M41: =IF(D41>44999.99,100,ROUNDUP((D41/4999.99)*10,-1)) -> 100 | N41: N | O41: ='[14]B1& B2 UNSCHEDULED'!$O$24 -> 0 | Q41: N | R41: =IF(L41="",AKHIR-J41,L41-J41+1) -> 1.0208333 | S41: =WORKDAY(J41,6,AKHIR) -> 46162 | T41: 0 | U41: =IF(Q41="N",0,M41*T41) -> 0 | V41: SPO2 SENSOR CABLE TEAR OFF, REPLACED WITH NEW SPO2 SENSOR AND TESTED PASS.UNIT RETURN WITH FULL FUNCTIONING.
A42: 19 | B42: IKN400446 | C42: =VLOOKUP(B42,[13]AssetDetails_UEM!$A$3:$AH$1849,6,FALSE) -> Infusion Pumps, General-Purpose | D42: =VLOOKUP(B42,[13]AssetDetails_UEM!$A$3:$AK$1849,22,FALSE) -> 10825 | E42: IKNWIBE26009165 | F42: 06WC113 | G42: INFUSION PUMP TIDAK BOLEH CLOSE- WAD 6A | H42: Normal | I42: 0 days, 0 hrs, 39 mins | J42: 13-May-2026 11:21:00 | K42: 13-May-2026 12:00:00 | L42: 13-May-2026 15:00:00 | M42: =IF(D42>44999.99,100,ROUNDUP((D42/4999.99)*10,-1)) -> 30 | N42: N | O42: ='[14]B1& B2 UNSCHEDULED'!$O$24 -> 0 | Q42: N | R42: =IF(L42="",AKHIR-J42,L42-J42+1) -> 1.1520833 | S42: =WORKDAY(J42,6,AKHIR) -> 46163 | T42: 0 | U42: =IF(Q42="N",0,M42*T42) -> 0 | V42: L, QE:12-UNIT CONNECT TO POWER SUPPLY , RESET MACHINE , TEST CLOSER DOOR MACHINE PASSED , UNIT READY FOR USE
A43: 20 | B43: IKN402180 | C43: =VLOOKUP(B43,[13]AssetDetails_UEM!$A$3:$AH$1849,6,FALSE) -> Scanning Systems, Computed Tomography/ Positron Emission Tomography | D43: =VLOOKUP(B43,[13]AssetDetails_UEM!$A$3:$AK$1849,22,FALSE) -> 3413750 | E43: IKNWIBE26009181 | F43: 03NM158 | G43: XELERIS CANNOT BOOT UP- KLINIK PERUBATAN NUKLEAR | H43: Normal | I43: 0 days, 0 hrs, 15 mins | J43: 13-May-2026 14:00:00 | K43: 13-May-2026 14:15:00 | L43: 13-May-2026 15:30:00 | M43: =IF(D43>44999.99,100,ROUNDUP((D43/4999.99)*10,-1)) -> 100 | N43: N | O43: ='[14]B1& B2 UNSCHEDULED'!$O$24 -> 0 | Q43: N | R43: =IF(L43="",AKHIR-J43,L43-J43+1) -> 1.0625 | S43: =WORKDAY(J43,6,AKHIR) -> 46163 | T43: 0 | U43: =IF(Q43="N",0,M43*T43) -> 0 | V43: L, QE:16-VENDOR TROUBLESHOOT PERFORMED LFC AND CONFIGURE TESTED OKAY
A44: 21 | B44: IKN400044 | C44: =VLOOKUP(B44,[13]AssetDetails_UEM!$A$3:$AH$1849,6,FALSE) -> Physiologic Monitoring Systems, Acute Care | D44: =VLOOKUP(B44,[13]AssetDetails_UEM!$A$3:$AK$1849,22,FALSE) -> 119690 | E44: IKNWIBE26009182 | F44: 05IC113 | G44: BP CUFF LEAKING - ICU | H44: Normal | I44: 0 days, 0 hrs, 8 mins | J44: 13-May-2026 15:52:00 | K44: 13-May-2026 16:00:00 | L44: 13-May-2026 16:15:00 | M44: =IF(D44>44999.99,100,ROUNDUP((D44/4999.99)*10,-1)) -> 100 | N44: N | O44: ='[14]B1& B2 UNSCHEDULED'!$O$24 -> 0 | Q44: N | R44: =IF(L44="",AKHIR-J44,L44-J44+1) -> 1.0159722 | S44: =WORKDAY(J44,6,AKHIR) -> 46163 | T44: 0 | U44: =IF(Q44="N",0,M44*T44) -> 0 | V44: L, QE:12-REPLACE NEW CUFF ,AND PULSE OXIMETER PROBE UNIT FUNCTIONING IN GOOD CONDITION
A45: 22 | B45: IKN400348 | C45: =VLOOKUP(B45,[13]AssetDetails_UEM!$A$3:$AH$1849,6,FALSE) -> Physiologic Monitoring Systems, Acute Care | D45: =VLOOKUP(B45,[13]AssetDetails_UEM!$A$3:$AK$1849,22,FALSE) -> 44510 | E45: IKNWIBE26009187 | F45: 07WF121 | G45: CM- REPLACE POWER CORD | H45: Corrective Maintenance (CM) | I45: 0 days, 0 hrs, 10 mins | J45: 13-May-2026 17:00:00 | K45: 13-May-2026 17:10:00 | L45: 13-May-2026 17:40:00 | M45: =IF(D45>44999.99,100,ROUNDUP((D45/4999.99)*10,-1)) -> 90 | N45: N | O45: ='[14]B1& B2 UNSCHEDULED'!$O$24 -> 0 | Q45: N | R45: =IF(L45="",AKHIR-J45,L45-J45+1) -> 1.0277778 | S45: =WORKDAY(J45,6,AKHIR) -> 46163 | T45: 0 | U45: =IF(Q45="N",0,M45*T45) -> 0 | V45: L, QE:16-REPLACE NEW POWER CARD , TESTED AND FUNCTIONING
A46: 23 | B46: IKN401246 | C46: =VLOOKUP(B46,[13]AssetDetails_UEM!$A$3:$AH$1849,6,FALSE) -> Computers, Radiotherapy Planning System | D46: =VLOOKUP(B46,[13]AssetDetails_UEM!$A$3:$AK$1849,22,FALSE) -> 2403940 | E46: IKNWIBE26009257 | F46: 01RT156 | G46: CM- MONACO MONTHLY CHECKING | H46: Normal | I46: 0 days, 0 hrs, 10 mins | J46: 14-May-2026 13:00:00 | K46: 46156.549 | L46: 14-May-2026 14:01:00 | M46: =IF(D46>44999.99,100,ROUNDUP((D46/4999.99)*10,-1)) -> 100 | N46: N | O46: ='[14]B1& B2 UNSCHEDULED'!$O$24 -> 0 | Q46: N | R46: =IF(L46="",AKHIR-J46,L46-J46+1) -> 1.0423611 | S46: =WORKDAY(J46,6,AKHIR) -> 46164 | T46: 0 | U46: =IF(Q46="N",0,M46*T46) -> 0 | V46: L, QE:12- MONTHLY CHECKING DONE AS PER CHECKLIST ATTACHED
A47: 24 | B47: IKN400774 | C47: =VLOOKUP(B47,[13]AssetDetails_UEM!$A$3:$AH$1849,6,FALSE) -> Scanning Systems, Computed Tomography | D47: =VLOOKUP(B47,[13]AssetDetails_UEM!$A$3:$AK$1849,22,FALSE) -> 4605710 | E47: IKNWIBE26009258 | F47: 03ID156 | G47: CM- MYRIAN MONTHLY CHECKING | H47: Corrective Maintenance (CM) | I47: 0 days, 0 hrs, 4 mins | J47: 14-May-2026 12:00:00 | K47: 14-May-2026 12:04:00 | L47: 14-May-2026 14:03:00 | M47: =IF(D47>44999.99,100,ROUNDUP((D47/4999.99)*10,-1)) -> 100 | N47: N | O47: ='[14]B1& B2 UNSCHEDULED'!$O$24 -> 0 | Q47: N | R47: =IF(L47="",AKHIR-J47,L47-J47+1) -> 1.0854167 | S47: =WORKDAY(J47,6,AKHIR) -> 46164 | T47: 0 | U47: =IF(Q47="N",0,M47*T47) -> 0 | V47: L, QE:12-MAYRIAN MONTHLY CHECKING COMPLETE BY VENDOR
...

Sheet B3-SCHEDULED
A3: MINISTRY OF HEALTH
A4: Deduction Mapping Report Biomedical Engineering Maintenance Services (BEMS)
A5: INDICATOR B.3 SCHEDULED MAINTENANCE
A7: HOSPITAL NAME : | C7: INSTITUT KANSER NEGARA | H7: MONTH/YEAR : | J7: 46143
B9: STATE : | C9: WILAYAH PERSEKUTUAN PUTRAJAYA | G9: BEMS MONTHLY FEE (RM) @ 97.5% : | J9: =BEMSdar!E11 -> 1329813.2
B11: COMPANY : | C11: AMBANG WIRA SDN BHD | G11: FMS MONTHLY FEE (RM) @ 2.5% : | J11: =BEMSdar!E13 -> 34097.773
A13: Notes:
A14: 1) Deduction Ringgit Equivalent is based on Appendix 11 of the Agreement, Section B3 Key Deduction Indicators for BEMS
A15: 2) Deduction Value for Indicator B.3 is Deduction Ringgit Equivalent (per event)
A16: 3) Rescheduled Date is the final rescheduled date if there are multiple rescheduling
A17: 4) Display only asset affected by deduction
A19: No | B19: Asset No | C19: Asset Description | D19: Asset Purchase Price (RM) | E19: Work Order No. | F19: User Location | G19: Scheduled Start Date | H19: Maintenance Date | I19: Rescheduled Date | J19: Validate Status (Y/N) | K19: Deduction Ringgit Equivalent (RM) | L19: Indicator B.3
L20: Deduction Value (RM) | M20: Remarks/ Exemption
A21: Current Month (Closed)
A22: 1 | B22: IKN400699 | C22: Analgesia Units, Inhalation | D22: =VLOOKUP(B22,[13]AssetDetails_UEM!$A$3:$X$1848,22,FALSE) -> 96230 | E22: IKNWOBE26007422 | F22: 04PY130 | G22: 02-May-2026 00:00:00 | H22: 02-May-2026 10:00:00 | I22: NA | J22: N | K22: =ROUNDUP((D22/4999.99)*10,-1) -> 200 | L22: =IF(J22="N",0,K22) -> 0 | M22: L, QE:16 -UNIT PROPOSSED BER
A23: 2 | B23: IKN400034 | C23: Infusion/ Monitoring Line Organizer System | D23: =VLOOKUP(B23,[13]AssetDetails_UEM!$A$3:$X$1848,22,FALSE) -> 84200 | E23: IKNWOBE26007423 | F23: 05IC113 | G23: 04-May-2026 00:00:00 | H23: 04-May-2026 08:00:00 | I23: NA | J23: N | K23: =ROUNDUP((D23/4999.99)*10,-1) -> 170 | L23: =IF(J23="N",0,K23) -> 0 | M23: L, QE:16- MAINTENANCE DONE AS PER HEPPM CHECKLIST ATTACHED,UNIT FUNCTIONING IN GOOD CONDITION
A24: 3 | B24: IKN400099 | C24: Infusion Pumps, Syringe | D24: =VLOOKUP(B24,[13]AssetDetails_UEM!$A$3:$X$1848,22,FALSE) -> 10225 | E24: IKNWOBE26007424 | F24: 05IC113 | G24: 04-May-2026 00:00:00 | H24: 04-May-2026 09:00:00 | I24: NA | J24: N | K24: =ROUNDUP((D24/4999.99)*10,-1) -> 30 | L24: =IF(J24="N",0,K24) -> 0 | M24: L, QE:16- MAINTENANCE DONE AS PER HEPPM CHECKLIST ATTACHED,UNIT FUNCTIONING IN GOOD CONDITION
A25: 4 | B25: IKN400100 | C25: Infusion Pumps, Syringe | D25: =VLOOKUP(B25,[13]AssetDetails_UEM!$A$3:$X$1848,22,FALSE) -> 10225 | E25: IKNWOBE26007425 | F25: 05IC113 | G25: 04-May-2026 00:00:00 | H25: 04-May-2026 10:00:00 | I25: NA | J25: N | K25: =ROUNDUP((D25/4999.99)*10,-1) -> 30 | L25: =IF(J25="N",0,K25) -> 0 | M25: L, QE:16 -MAINTENANCE DONE AS PER HEPPM CHECKLIST ATTACHED, UNIT FUNCTIONING IN GOOD CONDITION
A26: 5 | B26: IKN400101 | C26: Infusion Pumps, Syringe | D26: =VLOOKUP(B26,[13]AssetDetails_UEM!$A$3:$X$1848,22,FALSE) -> 10225 | E26: IKNWOBE26007426 | F26: 05IC113 | G26: 04-May-2026 00:00:00 | H26: 04-May-2026 11:00:00 | I26: NA | J26: N | K26: =ROUNDUP((D26/4999.99)*10,-1) -> 30 | L26: =IF(J26="N",0,K26) -> 0 | M26: L, QE:16- MAINTENANCE DONE AS PER HEPPM CHECKLIST ATTACHED,UNIT FUNCTIONING IN GOOD CONDITION
A27: 6 | B27: IKN400102 | C27: Infusion Pumps, Syringe | D27: =VLOOKUP(B27,[13]AssetDetails_UEM!$A$3:$X$1848,22,FALSE) -> 10225 | E27: IKNWOBE26007427 | F27: 05IC113 | G27: 04-May-2026 00:00:00 | H27: 04-May-2026 12:00:00 | I27: NA | J27: N | K27: =ROUNDUP((D27/4999.99)*10,-1) -> 30 | L27: =IF(J27="N",0,K27) -> 0 | M27: L, QE:16- MAINTENANCE DONE AS PER HEPPM CHECKLIST ATTACHED,UNIT FUNCTIONING IN GOOD CONDITION
A28: 7 | B28: IKN400103 | C28: Infusion Pumps, Syringe | D28: =VLOOKUP(B28,[13]AssetDetails_UEM!$A$3:$X$1848,22,FALSE) -> 10225 | E28: IKNWOBE26007428 | F28: 05IC113 | G28: 04-May-2026 00:00:00 | H28: 04-May-2026 16:00:00 | I28: NA | J28: N | K28: =ROUNDUP((D28/4999.99)*10,-1) -> 30 | L28: =IF(J28="N",0,K28) -> 0 | M28: L, QE:16- MAINTENANCE DONE AS PER HEPPM CHECKLIST ATTACHED,UNIT FUNCTIONING IN GOOD CONDITION
A29: 8 | B29: IKN400104 | C29: Infusion Pumps, Syringe | D29: =VLOOKUP(B29,[13]AssetDetails_UEM!$A$3:$X$1848,22,FALSE) -> 10225 | E29: IKNWOBE26007429 | F29: 05IC113 | G29: 04-May-2026 00:00:00 | H29: 04-May-2026 15:00:00 | I29: NA | J29: N | K29: =ROUNDUP((D29/4999.99)*10,-1) -> 30 | L29: =IF(J29="N",0,K29) -> 0 | M29: L, QE:16- MAINTENANCE DONE AS PER HEPPM CHECKLIST ATTACHED,UNIT FUNCTIONING IN GOOD CONDITION
A30: 9 | B30: IKN400139 | C30: Infusion Pumps, General-Purpose | D30: =VLOOKUP(B30,[13]AssetDetails_UEM!$A$3:$X$1848,22,FALSE) -> 10825 | E30: IKNWOBE26007430 | F30: 05IC113 | G30: 04-May-2026 00:00:00 | H30: 04-May-2026 16:00:00 | I30: NA | J30: N | K30: =ROUNDUP((D30/4999.99)*10,-1) -> 30 | L30: =IF(J30="N",0,K30) -> 0 | M30: L, QE:16- MAINTENANCE DONE AS PER HEPPM CHECKLIST ATTACHED,UNIT FUNCTIONING IN GOOD CONDITION
A31: 10 | B31: IKN400140 | C31: Infusion Pumps, General-Purpose | D31: =VLOOKUP(B31,[13]AssetDetails_UEM!$A$3:$X$1848,22,FALSE) -> 10825 | E31: IKNWOBE26007431 | F31: 05IC113 | G31: 04-May-2026 00:00:00 | H31: 04-May-2026 17:30:00 | I31: NA | J31: N | K31: =ROUNDUP((D31/4999.99)*10,-1) -> 30 | L31: =IF(J31="N",0,K31) -> 0 | M31: L, QE:16- MAINTENANCE DONE AS PER HEPPM CHECKLIST ATTACHED,UNIT FUNCTIONING IN GOOD CONDITION
A32: 11 | B32: IKN400667 | C32: Stimulators, Electrical, Peripheral Nerve, Acupuncture | D32: =VLOOKUP(B32,[13]AssetDetails_UEM!$A$3:$X$1848,22,FALSE) -> 10725 | E32: IKNWOBE26007432 | F32: 04TC108 | G32: 04-May-2026 00:00:00 | H32: 04-May-2026 15:50:00 | I32: NA | J32: N | K32: =ROUNDUP((D32/4999.99)*10,-1) -> 30 | L32: =IF(J32="N",0,K32) -> 0 | M32: L, QE:16- PPM DONE AS PER HEPPM CHECKLIST
A33: 12 | B33: IKN400670 | C33: Stimulators, Electrical, Peripheral Nerve, Acupuncture | D33: =VLOOKUP(B33,[13]AssetDetails_UEM!$A$3:$X$1848,22,FALSE) -> 10725 | E33: IKNWOBE26007433 | F33: 04TC129 | G33: 04-May-2026 00:00:00 | H33: 04-May-2026 15:50:00 | I33: NA | J33: N | K33: =ROUNDUP((D33/4999.99)*10,-1) -> 30 | L33: =IF(J33="N",0,K33) -> 0 | M33: L, QE:16- PPM DONE AS PER HEPPM CHECKLIST
... A40: 19 | B40: IKN400806 | C40: Cystoscopes, Flexible | D40: =VLOOKUP(B40,[13]AssetDetails_UEM!$A$3:$X$1848,22,FALSE) -> 37408 | E40: IKNWOBE26007440 | F40: 01RT233 | G40: 04-May-2026 00:00:00 | H40: 04-May-2026 20:00:00 | I40: NA | J40: N | K40: =ROUNDUP((D40/4999.99)*10,-1) -> 80 | L40: =IF(J40="N",0,K40) -> 0 | M40: L, QE:16- MAINTENANCE DONE AS PER HEPPM CHECKLIST ATTACHED,UNIT FUNCTIONING IN GOOD CONDITION
A41: 20 | B41: IKN400961 | C41: Physiologic Monitoring Systems, Acute Care | D41: =VLOOKUP(B41,[13]AssetDetails_UEM!$A$3:$X$1848,22,FALSE) -> 87400 | E41: IKNWOBE26007441 | F41: 01RT212 | G41: 04-May-2026 00:00:00 | H41: 46146.417 | I41: NA | J41: N | K41: =ROUNDUP((D41/4999.99)*10,-1) -> 180 | L41: =IF(J41="N",0,K41) -> 0 | M41: AN-QE:16, PPM DONE AS PER HEPPM CHECKLIST
A42: 21 | B42: IKN400226 | C42: Infusion Pumps, General-Purpose | D42: =VLOOKUP(B42,[13]AssetDetails_UEM!$A$3:$X$1848,22,FALSE) -> 10825 | E42: IKNWOBE26007443 | F42: 09WJ126 | G42: 06-May-2026 00:00:00 | H42: 06-May-2026 08:00:00 | I42: NA | J42: N | K42: =ROUNDUP((D42/4999.99)*10,-1) -> 30 | L42: =IF(J42="N",0,K42) -> 0 | M42: L, QE:16- PPM DONE AS PERCHECKLIST
A43: 22 | B43: IKN400227 | C43: Infusion Pumps, General-Purpose | D43: =VLOOKUP(B43,[13]AssetDetails_UEM!$A$3:$X$1848,22,FALSE) -> 10825 | E43: IKNWOBE26007444 | F43: 09WJ126 | G43: 06-May-2026 00:00:00 | H43: 06-May-2026 10:00:00 | I43: NA | J43: N | K43: =ROUNDUP((D43/4999.99)*10,-1) -> 30 | L43: =IF(J43="N",0,K43) -> 0 | M43: L, QE:16- PPM DONE AS PERCHECKLIST
A44: 23 | B44: IKN400228 | C44: Infusion Pumps, General-Purpose | D44: =VLOOKUP(B44,[13]AssetDetails_UEM!$A$3:$X$1848,22,FALSE) -> 10825 | E44: IKNWOBE26007445 | F44: 09WJ126 | G44: 06-May-2026 00:00:00 | H44: 06-May-2026 11:00:00 | I44: NA | J44: N | K44: =ROUNDUP((D44/4999.99)*10,-1) -> 30 | L44: =IF(J44="N",0,K44) -> 0 | M44: L, QE:16- PPM DONE AS PERCHECKLIST AT 09WJ222 9B
A45: 24 | B45: IKN400229 | C45: Infusion Pumps, General-Purpose | D45: =VLOOKUP(B45,[13]AssetDetails_UEM!$A$3:$X$1848,22,FALSE) -> 10825 | E45: IKNWOBE26007446 | F45: 09WJ126 | G45: 06-May-2026 00:00:00 | H45: 06-May-2026 12:00:00 | I45: NA | J45: N | K45: =ROUNDUP((D45/4999.99)*10,-1) -> 30 | L45: =IF(J45="N",0,K45) -> 0 | M45: L, QE:16- PPM DONE AS PERCHECKLIST,
A46: 25 | B46: IKN400304 | C46: Incubators, Laboratory, Thermocycling | D46: =VLOOKUP(B46,[13]AssetDetails_UEM!$A$3:$X$1848,22,FALSE) -> 16240 | E46: IKNWOBE26007447 | F46: 03NM112 | G46: 07-May-2026 00:00:00 | H46: 07-May-2026 11:00:00 | I46: NA | J46: N | K46: =ROUNDUP((D46/4999.99)*10,-1) -> 40 | L46: =IF(J46="N",0,K46) -> 0 | M46: AN- QE:16, PPM DONE AS PER HEPPM CHECKLIST
A47: 26 | B47: IKN400714 | C47: Incubators, Test Tube, Portable | D47: =VLOOKUP(B47,[13]AssetDetails_UEM!$A$3:$X$1848,22,FALSE) -> 14435 | E47: IKNWOBE26007448 | F47: 04LA132 | G47: 07-May-2026 00:00:00 | H47: 07-May-2026 09:00:00 | I47: NA | J47: N | K47: =ROUNDUP((D47/4999.99)*10,-1) -> 30 | L47: =IF(J47="N",0,K47) -> 0 | M47: AN-QE:16, PPM DONE AS PER HEPPM CHECKLIST
A48: 27 | B48: IKN400717 | C48: Incubators, Test Tube, Portable | D48: =VLOOKUP(B48,[13]AssetDetails_UEM!$A$3:$X$1848,22,FALSE) -> 14435 | E48: IKNWOBE26007449 | F48: 04LA140 | G48: 07-May-2026 00:00:00 | H48: 07-May-2026 10:00:00 | I48: NA | J48: N | K48: =ROUNDUP((D48/4999.99)*10,-1) -> 30 | L48: =IF(J48="N",0,K48) -> 0 | M48: AN- QE:16. PPM DONE AS PER HEPPM CHECKLIST
A49: 28 | B49: IKN402145 | C49: Scanning Systems, Ultrasonic, General-Purpose | D49: =VLOOKUP(B49,[13]AssetDetails_UEM!$A$3:$X$1848,22,FALSE) -> 68500 | E49: IKNWOBE26007450 | F49: 06WC107 | G49: 07-May-2026 00:00:00 | H49: 07-May-2026 15:30:00 | I49: NA | J49: N | K49: =ROUNDUP((D49/4999.99)*10,-1) -> 140 | L49: =IF(J49="N",0,K49) -> 0 | M49: L, QE:16- PPM DONE AS PERCHECKLIST
A50: 29 | B50: IKN402174 | C50: Testers | D50: =VLOOKUP(B50,[13]AssetDetails_UEM!$A$3:$X$1848,22,FALSE) -> 8295.6 | E50: IKNWOBE26007452 | F50: 03ID169 | G50: 08-May-2026 00:00:00 | H50: 08-May-2026 08:30:00 | I50: NA | J50: N | K50: =ROUNDUP((D50/4999.99)*10,-1) -> 20 | L50: =IF(J50="N",0,K50) -> 0 | M50: L, QE:16- UNIT FUNCTIONING OKAY , PPM COMPLETE
A51: 30 | B51: IKN400967 | C51: Linear Accelerators | D51: =VLOOKUP(B51,[13]AssetDetails_UEM!$A$3:$X$1848,22,FALSE) -> 12049370 | E51: IKNWOBE26007453 | F51: 01RT165 | G51: 08-May-2026 00:00:00 | H51: 46150.75 | I51: NA | J51: N | K51: =ROUNDUP((D51/4999.99)*10,-1) -> 24100 | L51: =IF(J51="N",0,K51) -> 0 | M51: AN- QE:16. PPM DONE AS PER HEPPM CHECKLIST
A52: 31 | B52: IKN400737 | C52: Incubators, Laboratory, Thermocycling | D52: =VLOOKUP(B52,[13]AssetDetails_UEM!$A$3:$X$1848,22,FALSE) -> 16240 | E52: IKNWOBE26007454 | F52: 04LA126 | G52: 08-May-2026 00:00:00 | H52: 08-May-2026 10:00:00 | I52: NA | J52: N | K52: =ROUNDUP((D52/4999.99)*10,-1) -> 40 | L52: =IF(J52="N",0,K52) -> 0 | M52: AN- QE:16. PPM DONE AS PER HEPPM CHECKLIST
A53: 32 | B53: IKN400753 | C53: Mixers, Clinical Laboratory | D53: =VLOOKUP(B53,[13]AssetDetails_UEM!$A$3:$X$1848,22,FALSE) -> 1200 | E53: IKNWOBE26007455 | F53: 04LA126 | G53: 08-May-2026 00:00:00 | H53: 08-May-2026 09:30:00 | I53: NA | J53: N | K53: =ROUNDUP((D53/4999.99)*10,-1) -> 10 | L53: =IF(J53="N",0,K53) -> 0 | M53: AN- QE:16. PPM DONE AS PER HEPPM CHECKLIST
...

Sheet B4-UPTIME
A1: MINISTRY OF HEALTH
A2: Deduction Mapping Report Biomedical Engineering Maintenance Services (BEMS)
A3: INDICATOR B.4 UPTIME GUARANTEE
B5: HOSPITAL NAME : | C5: INSTITUT KANSER NEGARA | N5: MONTH/YEAR : | U5: 46143
B7: STATE : | C7: WILAYAH PERSEKUTUAN PUTRAJAYA | N7: BEMS MONTHLY FEE (RM)@ 97.5% : | U7: =BEMSdar!E11 -> 1329813.2
B9: COMPANY : | C9: AMBANG WIRA SDN BHD | N9: FMS MONTHLY FEE (RM) @ 2.5% : | U9: =BEMSdar!E13 -> 34097.773
A11: Notes:
A12: 1) Deduction Ringgit Equivalent is based on Appendix 11 of the Agreement, Section B3 Key Deduction Indicators for BEMS
A13: 2) Deduction Value for 1st cut off is Deduction Ringgit Equivalent (per event)
A14: 3) Deduction Value for 2nd cut off is Deduction Ringgit Equivalent (per event) multiply by 2
A15: 4) Display only asset affected by deduction
A17: No. | B17: Asset No | C17: Type Code | D17: Type Description | E17: Asset Purchase cost (RM) | F17: Asset Age | G17: TRKPI % | H17: Uptime % | T17: Deduction Ringgit Equivalent (RM) | U17: Previous Deduction (Month) | W17: Deduction for the month (Y/N) | Y17: Deduction Value (RM) | AA17: Total Deduction (RM) | AB17: Remarks
H18: Jan | I18: Feb | J18: Mar | K18: Apr | L18: May | M18: Jun | N18: Jul | O18: Aug | P18: Sep | Q18: Oct | R18: Nov | S18: Dec | U18: 1st | V18: 2nd | W18: 1st | X18: 2nd | Y18: 1st | Z18: 2nd
A19: 1 | B19: IKN400440 | C19: 16-173 | D19: Sphygmomanometers, Electronic, Automatic | E19: 4510 | F19: 13 | G19: 88 | H19: 99.82733 | I19: 99.78 | J19: - | K19: - | L19: - | T19: =ROUNDUP((E19/4999.99)*10,-1) -> 10 | U19: N | V19: N | W19: N | X19: N | Y19: =IF(W19="Y",T19,0) -> 0 | Z19: =IF(X19="Y",T19*2,0) -> 0 | AA19: =Y19+Z19 -> 0
A20: 2 | B20: IKN400645 | C20: 13-215 | D20: Infusion Pumps, General-Purpose | E20: 10825 | F20: 13 | G20: 88 | H20: 99.961971 | I20: 99.93 | J20: - | K20: - | L20: - | T20: =ROUNDUP((E20/4999.99)*10,-1) -> 30 | U20: N | V20: N | W20: N | X20: N | Y20: =IF(W20="Y",T20,0) -> 0 | Z20: =IF(X20="Y",T20*2,0) -> 0 | AA20: =Y20+Z20 -> 0
A21: 3 | B21: IKN401714 | C21: 13-215 | D21: Infusion Pumps, General-Purpose | E21: 5800 | F21: 8 | G21: 95 | H21: 99.962034 | I21: 99.93 | J21: - | K21: - | L21: - | T21: =ROUNDUP((E21/4999.99)*10,-1) -> 20 | U21: Y | V21: Y | W21: N | X21: N | Y21: =IF(W21="Y",T21,0) -> 0 | Z21: =IF(X21="Y",T21*2,0) -> 0 | AA21: =Y21+Z21 -> 0
A22: 4 | B22: IKN400446 | C22: 13-215 | D22: Infusion Pumps, General-Purpose | E22: 10825 | F22: 13 | G22: 88 | H22: 99.65 | I22: 99.68 | J22: 98.553172 | K22: - | L22: - | T22: =ROUNDUP((E22/4999.99)*10,-1) -> 30 | U22: N | V22: N | W22: N | X22: N | Y22: =IF(W22="Y",T22,0) -> 0 | Z22: =IF(X22="Y",T22*2,0) -> 0 | AA22: =Y22+Z22 -> 0
A23: 5 | B23: IKN400366 | C23: 13-215 | D23: Infusion Pumps, General-Purpose | E23: 10825 | F23: 13 | G23: 88 | H23: 99.65 | I23: 99.68 | J23: 99.330998 | K23: 99.04 | L23: - | T23: =ROUNDUP((E23/4999.99)*10,-1) -> 30 | U23: N | V23: N | W23: N | X23: N | Y23: =IF(W23="Y",T23,0) -> 0 | Z23: =IF(X23="Y",T23*2,0) -> 0 | AA23: =Y23+Z23 -> 0
A24: 6 | B24: IKN402165 | C24: 13-215 | D24: Infusion Pumps, General-Purpose | E24: 10825 | F24: 13 | G24: 88 | H24: 99.65 | I24: 99.45 | J24: - | K24: - | L24: - | T24: =ROUNDUP((E24/4999.99)*10,-1) -> 30 | U24: N | V24: N | W24: N | X24: N | Y24: =IF(W24="Y",T24,0) -> 0 | Z24: =IF(X24="Y",T24*2,0) -> 0 | AA24: =Y24+Z24 -> 0
A25: 7 | B25: IKN400565 | C25: 12-649 | D25: Physiologic Monitoring Systems, Stress Exercise | E25: 138350 | F25: 13 | G25: 88 | H25: 99.65 | I25: 99.56 | J25: - | K25: - | L25: 99.617707 | T25: =ROUNDUP((E25/4999.99)*10,-1) -> 280 | U25: N | V25: N | W25: N | X25: N | Y25: =IF(W25="Y",T25,0) -> 0 | Z25: =IF(X25="Y",T25*2,0) -> 0 | AA25: =Y25+Z25 -> 0
A26: 8 | B26: IKN400439 | C26: 16-173 | D26: Sphygmomanometers, Electronic, Automatic | E26: 4510 | F26: 13 | G26: 88 | H26: 99.65 | I26: 99.53 | J26: - | K26: - | L26: - | T26: =ROUNDUP((E26/4999.99)*10,-1) -> 10 | U26: N | V26: N | W26: N | X26: N | Y26: =IF(W26="Y",T26,0) -> 0 | Z26: =IF(X26="Y",T26*2,0) -> 0 | AA26: =Y26+Z26 -> 0
A27: 9 | B27: IKN401076 | C27: 12-306 | D27: Lavage Units, Surgical | E27: 5000 | F27: 13 | G27: 85 | H27: 99.65 | I27: 99.35 | J27: - | K27: - | L27: - | T27: =ROUNDUP((E27/4999.99)*10,-1) -> 20 | U27: N | V27: N | W27: N | X27: N | Y27: =IF(W27="Y",T27,0) -> 0 | Z27: =IF(X27="Y",T27*2,0) -> 0 | AA27: =Y27+Z27 -> 0
A28: 10 | B28: IKN402147 | C28: 15-605 | D28: Testers (Ion Chamber Set) | E28: 142000 | F28: 4 | G28: 96 | H28: 99.65 | I28: 99.39 | J28: - | K28: - | L28: - | T28: =ROUNDUP((E28/4999.99)*10,-1) -> 290 | U28: N | V28: N | W28: N | X28: N | Y28: =IF(W28="Y",T28,0) -> 0 | Z28: =IF(X28="Y",T28*2,0) -> 0 | AA28: =Y28+Z28 -> 0
A29: 11 | B29: IKN401071 | C29: 18-034 | D29: Video Image Processors, Endoscopic | E29: 80000 | F29: 13 | G29: 88 | H29: 99.65 | I29: 99.35 | J29: - | K29: - | L29: 99.990964 | T29: =ROUNDUP((E29/4999.99)*10,-1) -> 170 | U29: Y | V29: Y | W29: N | X29: N | Y29: =IF(W29="Y",T29,0) -> 0 | Z29: =IF(X29="Y",T29*2,0) -> 0 | AA29: =Y29+Z29 -> 0
A30: 12 | B30: IKN402081 | C30: 13-215 | D30: Infusion Pumps, General-Purpose | E30: 3500 | F30: 5 | G30: 95 | H30: 99.65 | I30: 99.68 | J30: 99.330998 | K30: 98.99 | L30: - | T30: =ROUNDUP((E30/4999.99)*10,-1) -> 10 | U30: N | V30: N | W30: N | X30: N | Y30: =IF(W30="Y",T30,0) -> 0 | Z30: =IF(X30="Y",T30*2,0) -> 0 | AA30: =Y30+Z30 -> 0
A31: 13 | B31: IKN401353 | C31: 11-758 | D31: Radiographic/Fluoroscopic Units, Mobile | E31: 399000 | F31: 10 | G31: 88 | H31: 99.65 | I31: - | J31: - | K31: 99.970764 | L31: 99.83783 | T31: =ROUNDUP((E31/4999.99)*10,-1) -> 800 | U31: N | V31: N | W31: N | X31: N | Y31: =IF(W31="Y",T31,0) -> 0 | Z31: =IF(X31="Y",T31*2,0) -> 0 | AA31: =Y31+Z31 -> 0
A32: 14 | B32: IKN400422 | C32: 13-215 | D32: Infusion Pumps, General-Purpose | E32: 10825 | F32: 13 | G32: 88 | H32: 99.65 | I32: 99.68 | J32: 99.330998 | K32: 98.87 | L32: - | T32: =ROUNDUP((E32/4999.99)*10,-1) -> 30 | U32: Y | V32: N | W32: N | X32: N | Y32: =IF(W32="Y",T32,0) -> 0 | Z32: =IF(X32="Y",T32*2,0) -> 0 | AA32: =Y32+Z32 -> 0 | AB32: RW
A33: 15 | B33: IKN400482 | C33: 13-215 | D33: Infusion Pumps, General-Purpose | E33: 10825 | F33: 13 | G33: 88 | H33: 99.65 | I33: 99.61 | J33: - | K33: - | L33: - | T33: =ROUNDUP((E33/4999.99)*10,-1) -> 30 | U33: N | V33: N | W33: N | X33: N | Y33: =IF(W33="Y",T33,0) -> 0 | Z33: =IF(X33="Y",T33*2,0) -> 0 | AA33: =Y33+Z33 -> 0
A34: 16 | B34: IKN400782 | C34: 17-679 | D34: Laser Imagers | E34: 83100 | F34: 13 | G34: 85 | H34: 99.65 | I34: 99.51 | J34: - | K34: - | L34: - | T34: =ROUNDUP((E34/4999.99)*10,-1) -> 170 | U34: N | V34: N | W34: N | X34: N | Y34: =IF(W34="Y",T34,0) -> 0 | Z34: =IF(X34="Y",T34*2,0) -> 0 | AA34: =Y34+Z34 -> 0
A35: 17 | B35: IKN400653 | C35: 16-173 | D35: Sphygmomanometers, Electronic, Automatic | E35: 4510 | F35: 12 | G35: 88 | H35: - | I35: 99.8 | J35: 99.385529 | K35: 99.37 | L35: - | T35: =ROUNDUP((E35/4999.99)*10,-1) -> 10 | U35: N | V35: N | W35: N | X35: N | Y35: =IF(W35="Y",T35,0) -> 0 | Z35: =IF(X35="Y",T35*2,0) -> 0 | AA35: =Y35+Z35 -> 0
A36: 18 | B36: IKN400171 | C36: 17-429 | D36: Ventilators, Intensive Care | E36: 151560 | F36: 12 | G36: 88 | H36: - | I36: 99.78 | J36: 99.425417 | K36: 99.08 | L36: 98.970548 | T36: =ROUNDUP((E36/4999.99)*10,-1) -> 310 | U36: N | V36: N | W36: N | X36: N | Y36: =IF(W36="Y",T36,0) -> 0 | Z36: =IF(X36="Y",T36*2,0) -> 0 | AA36: =Y36+Z36 -> 0
A37: 19 | B37: IKN400168 | C37: 17-429 | D37: Ventilators, Intensive Care | E37: 151560 | F37: 12 | G37: 88 | H37: - | I37: 99.9 | J37: 99.550176 | K37: 99.21 | L37: 99.090819 | T37: =ROUNDUP((E37/4999.99)*10,-1) -> 310 | U37: Y | V37: Y | W37: N | X37: N | Y37: =IF(W37="Y",T37,0) -> 0 | Z37: =IF(X37="Y",T37*2,0) -> 0 | AA37: =Y37+Z37 -> 0
A38: 20 | B38: IKN402184 | C38: 12-647 | D38: Physiologic Monitoring Systems, Acute Care | E38: 100000 | F38: 2 | G38: 99 | H38: - | I38: - | J38: 99.677138 | K38: 99.5 | L38: - | T38: =ROUNDUP((E38/4999.99)*10,-1) -> 210 | U38: N | V38: N | W38: N | X38: N | Y38: =IF(W38="Y",T38,0) -> 0 | Z38: =IF(X38="Y",T38*2,0) -> 0 | AA38: =Y38+Z38 -> 0
A39: 21 | B39: IKN400787 | C39: 13-272 | D39: Radiographic Units, Mobile | E39: 1149550 | F39: 13 | G39: 88 | H39: - | I39: - | J39: 99.824328 | K39: 99.48 | L39: 99.330051 | T39: =ROUNDUP((E39/4999.99)*10,-1) -> 2300 | U39: N | V39: N | W39: N | X39: N | Y39: =IF(W39="Y",T39,0) -> 0 | Z39: =IF(X39="Y",T39*2,0) -> 0 | AA39: =Y39+Z39 -> 0
A40: 22 | B40: IKN400937 | C40: 16-173 | D40: Sphygmomanometers, Electronic, Automatic | E40: 336 | F40: 13 | G40: 88 | H40: - | I40: - | J40: 99.916396 | K40: 99.58 | L40: 99.226016 | T40: =ROUNDUP((E40/4999.99)*10,-1) -> 10 | U40: Y | V40: N | W40: N | X40: N | Y40: =IF(W40="Y",T40,0) -> 0 | Z40: =IF(X40="Y",T40*2,0) -> 0 | AA40: =Y40+Z40 -> 0
A41: 23 | B41: IKN401007 | C41: 15-999 | D41: Washers, Flexible Endoscope | E41: 126300 | F41: 13 | G41: 85 | H41: - | I41: - | J41: 99.925846 | K41: 99.59 | L41: 99.235336 | T41: =ROUNDUP((E41/4999.99)*10,-1) -> 260 | U41: N | V41: N | W41: N | X41: N | Y41: =IF(W41="Y",T41,0) -> 0 | Z41: =IF(X41="Y",T41*2,0) -> 0 | AA41: =Y41+Z41 -> 0
A42: 24 | B42: IKN400293 | C42: 17-148 | D42: Oximeters, Pulse | E42: 5410 | F42: 13 | G42: 88 | H42: - | I42: - | J42: 99.935425 | K42: 99.93 | L42: - | T42: =ROUNDUP((E42/4999.99)*10,-1) -> 20 | U42: Y | V42: N | W42: N | X42: N
A43: 25 | B43: IKN400029 | C43: 12-647 | D43: Physiologic Monitoring Systems, Acute Care | E43: 105850 | F43: 13 | G43: 88 | H43: - | I43: - | J43: 99.946764 | K43: 99.95 | L43: - | T43: =ROUNDUP((E43/4999.99)*10,-1) -> 220 | U43: N | V43: N | W43: N | X43: N | Y43: =IF(W43="Y",T43,0) -> 0 | Z43: =IF(X43="Y",T43*2,0) -> 0 | AA43: =Y43+Z43 -> 0
A44: 26 | B44: IKN400722 | C44: 15-104 | D44: Analyzers, Laboratory, Hematology, Platelet Aggregation | E44: 42100 | F44: 13 | G44: 85 | H44: - | I44: - | J44: 99.981897 | K44: 99.91 | L44: - | T44: =ROUNDUP((E44/4999.99)*10,-1) -> 90 | U44: N | V44: N | W44: N | X44: N | Y44: =IF(W44="Y",T44,0) -> 0 | Z44: =IF(X44="Y",T44*2,0) -> 0 | AA44: =Y44+Z44 -> 0
A45: 27 | B45: IKN400200 | C45: 18-147 | D45: Mattress Systems, Alternating-Pressure | E45: 28630 | F45: 13 | G45: 85 | H45: - | I45: - | J45: - | K45: 99.664774 | L45: 99.314497 | T45: =ROUNDUP((E45/4999.99)*10,-1) -> 60 | U45: N | V45: N | W45: N | X45: N | Y45: =IF(W45="Y",T45,0) -> 0 | Z45: =IF(X45="Y",T45*2,0) -> 0 | AA45: =Y45+Z45 -> 0
...

Sheet B5-T&C
A1: MINISTRY OF HEALTH
A2: Deduction Mapping Report Biomedical Engineering Maintenance Services (BEMS)
A3: INDICATOR B.5 TESTING & COMMISSIONING AND WARRANTY MANAGEMENT
B5: HOSPITAL NAME : | C5: INSTITUT KANSER NEGARA | I5: MONTH/YEAR : | K5: 46143
B7: STATE : | C7: WILAYAH PERSEKUTUAN PUTRAJAYA | I7: BEMS MONTHLY FEE (RM) @ 97.5% : | K7: =BEMSdar!E11 -> 1329813.2
B9: COMPANY : | C9: AMBANG WIRA SDN BHD | I9: FMS MONTHLY FEE (RM) @ 2.5% : | K9: =BEMSdar!E13 -> 34097.773
A11: Notes:
A12: 1) Deduction Ringgit Equivalent is based on Appendix 11 of the Agreement, Section B3 Key Deduction Indicators for BEMS
A13: 2) Deduction Value is Deduction Ringgit Equivalent (per event)
A14: 3) Display only asset affected by deduction
A15: 4) *May not be applicable for unregistered asset
A16: 5) **Only applicable for under warranty management deduction
A18: No | B18: Work Order/ NCR | C18: Work Order/ NCR Date | D18: Work Order/ NCR Reference No. | E18: Work Order/ NCR Description | F18: User Location | G18: T&C Date | H18: Completion Date | I18: Asset Number* | J18: Asset Description | K18: Warranty Expiry Date** | L18: Asset Purchase Price (RM) | M18: Deduction Ringgit Equivalent (RM) | N18: Validate Status (Y/N) | O18: Deduction Value (RM) | P18: Remarks
A19: Work Order Close
A20: 1 | B20: Testing and Commissioning (T&C) | C20: 46156 | D20: IKNWIBE26009270 | E20: TNC- DEEP VEIN TROMBOSIS PUMP | F20: 05IC131 | G20: 14-May-2026 11:10:00 | H20: 14-May-2026 12:10:00 | I20: IKN402272 | J20: DEEP VEIN TROMBOSIS PUMP | K20: 1 YEAR | L20: 8000 | M20: - | N20: N | O20: - | P20: SUPPLIER INSAN DAMAI SDN BHD
A21: 2 | B21: Testing and Commissioning (T&C) | C21: 46156 | D21: IKNWIBE26009271 | E21: TNC- DEEP VEIN TROMBOSIS PUMP | F21: 05IC131 | G21: 14-May-2026 11:10:00 | H21: 14-May-2026 12:10:00 | I21: IKN402273 | J21: DEEP VEIN TROMBOSIS PUMP | K21: 1 YEAR | L21: 8000 | M21: - | N21: N | O21: - | P21: SUPPLIER INSAN DAMAI SDN BHD
A22: 3 | B22: Testing and Commissioning (T&C) | C22: 46156 | D22: IKNWIBE26009272 | E22: TNC- DEEP VEIN TROMBOSIS PUMP | F22: 05IC131 | G22: 14-May-2026 11:10:00 | H22: 14-May-2026 12:10:00 | I22: IKN402274 | J22: DEEP VEIN TROMBOSIS PUMP | K22: 1 YEAR | L22: 8000 | M22: - | N22: N | O22: - | P22: SUPPLIER INSAN DAMAI SDN BHD
A23: 4 | B23: Testing and Commissioning (T&C) | C23: 46156 | D23: IKNWIBE26009273 | E23: TNC- DEEP VEIN TROMBOSIS PUMP | F23: 05IC131 | G23: 14-May-2026 11:10:00 | H23: 14-May-2026 12:10:00 | I23: IKN402275 | J23: DEEP VEIN TROMBOSIS PUMP | K23: 1 YEAR | L23: 8000 | M23: - | N23: N | O23: - | P23: SUPPLIER INSAN DAMAI SDN BHD
A24: TOTAL DEDUCTION FOR IND. B.5: | O24: =SUM(O20:O20) -> 0 | P24: -

Sheet Public Holiday
A1: ­
A2: Tarikh | B2: Hari | C2: Cuti | D2: Negeri Berkenaan
A4: 46023 | B4: Khamis | C4: Tahun Baru | D4: Putrajaya
A6: 46070 | B6: Selasa | C6: Tahun Baru Cina | D6: Putrajaya
A8: 46071 | B8: Rabu | C8: Tahun Baru Cina Hari Kedua | D8: Putrajaya
A10: 46055 | B10: Isnin | C10: Hari Wilayah Persekutuan | D10: Putrajaya
A12: 46055 | B12: Isnin | C12: Hari Thaipusam | D12: Putrajaya
A14: 46088 | B14: Sabtu | C14: Hari Nuzul Al-Quran | D14: Putrajaya
A16: 46101 | B16: Sabtu | C16: Hari Raya Aidilfitri | D16: Putrajaya
A18: 46102 | B18: Sabtu | C18: Hari Raya Aidilfitri | D18: Putrajaya
A20: 46103 | B20: Ahad | C20: Hari Raya Aidilfitri Hari Kedua | D20: Putrajaya
A22: 46104 | B22: Ahad | C22: Hari Raya Aidilfitri Hari Kedua | D22: Putrajaya
A24: 46143 | B24: Jumaat | C24: Hari Pekerja | D24: Putrajaya
A26: 46173 | B26: Ahad | C26: Hari Wesak | D26: Putrajaya
... A46: 46381 | B46: Jumaat | C46: Hari Krismas | D46: Putrajaya
A49: * Subject to change (Tertakluk kepada perubahan), TBC - To be confirmed

Sheet KDI
A1: Indicator No. | B1: Indicator | E1: Frequency of Deduction | F1: Biomedical Equipment Purchase Cost (RM) | H1: Deduction Range Value (RM) | J1: Maximum Demerit Point per Work Order
F2: From | G2: To
A3: B.1 | B3: The Company shall respond to the request within the specified time frame | E3: Per event | F3: 0.00 5,000.00 10,000.00 15,000.00 20,000.00 25,000.00 30,000.00 35,000.00 40,000.00 > 45,000.00 | G3: 4,999.99 9,999.99 14,999.99 19,999.99 24,999.99 29,999.99 34,999.99 39,999.99 44,999.99 | H3: 10.00 20.00 30.00 40.00 50.00 60.00 70.00 80.00 90.00 100.00 | J3: 1
A4: B.2 | B4: The Company shall carry out repairs to restore faulty medical equipment to a specified condition when it fails to function as per manufacturer’s specification within seven (7) working days. | E4: Per day | F4: 0.00 5,000.00 10,000.00 15,000.00 20,000.00 25,000.00 30,000.00 35,000.00 40,000.00 > 45,000.00 | G4: 4,999.99 9,999.99 14,999.99 19,999.99 24,999.99 29,999.99 34,999.99 39,999.99 44,999.99 | H4: 10.00 20.00 30.00 40.00 50.00 60.00 70.00 80.00 90.00 100.00 | J4: Number of working days for the month
A5: B.3 | B5: The Company shall carry out scheduled maintenance as per schedule in accordance to the procedure as specified in Agreement. Scheduled maintenance shall include complete safety and performance tests. | E5: Per event | F5: 0.00 5,000.00 10,000.00 15,000.00 20,000.00 25,000.00 30,000.00 35,000.00 40,000.00 45,000.00 | G5: 4,999.99 9,999.99 14,999.99 19,999.99 24,999.99 29,999.99 34,999.99 39,999.99 44,999.99 49,999.99 | H5: 10.00 20.00 30.00 40.00 50.00 60.00 70.00 80.00 90.00 100.00 | J5: 1
F6: For every RM 5,000 increment of equipment cost, an increase of RM10 will be applied subsequently
A7: B.4 | B7: The Company shall ensure biomedical equipment meets the uptime target as set in the Agreement. | E7: Per event | H7: 1st level of Uptime Target (TRKPI) | I7: 2nd level of Uptime Target (80%) | J7: 2
F8: 0.00 5,000.00 10,000.00 15,000.00 20,000.00 25,000.00 30,000.00 35,000.00 40,000.00 45,000.00 | G8: 4,999.99 9,999.99 14,999.99 19,999.99 24,999.99 29,999.99 34,999.99 39,999.99 44,999.99 49,999.99 | H8: 10.00 20.00 30.00 40.00 50.00 60.00 70.00 80.00 90.00 100.00 | I8: 20.00 40.00 60.00 80.00 100.00 120.00 140.00 160.00 180.00 200.00
F9: For every RM 5,000 increment of equipment cost, an increase of RM10 will be applied subsequently for 1st Uptime Target and an increase of RM20 for 2nd Uptime Target will be applied subsequently
A10: B.5 | B10: The Company shall attend and witness T&C and manage biomedical equipment within the warranty period. | E10: Per event | F10: 0.00 5,000.00 10,000.00 15,000.00 20,000.00 25,000.00 30,000.00 35,000.00 40,000.00 45,000.00 | G10: 4,999.99 9,999.99 14,999.99 19,999.99 24,999.99 29,999.99 34,999.99 39,999.99 44,999.99 49,999.99 | H10: 10.00 20.00 30.00 40.00 50.00 60.00 70.00 80.00 90.00 100.00 | J10: 1
F11: For every RM 5,000 increment of equipment cost, an increase of RM10 will be applied subsequently

Sheet Sheet1
A3: Equipments | B3: Group | C3: Operating Hours | D3: Operating Hours/WK (Days) | E3: Uptime Equipment | F3: Uptime Equipment | G3: Uptime Equipment
E4: < 5YRS | F4: 5-10 YRS | G4: >10 YRS
A5: Therapeutics
A6: Alternating Pressure Mattress | B6: P | C6: 12 | D6: 6 | E6: 0.96 | F6: 0.92 | G6: 0.85
A7: Aneasthesia Units and Vaporizers | B7: C | C7: 24 | D7: 7 | E7: 0.99 | F7: 0.95 | G7: 0.88
A8: Aneasthesia Ventilators | B8: C | C8: 24 | D8: 7 | E8: 0.99 | F8: 0.95 | G8: 0.88
A9: Aspirators | B9: C | C9: 24 | D9: 7 | E9: 0.99 | F9: 0.95 | G9: 0.88
A10: Defibrillators | B10: C | C10: 24 | D10: 7 | E10: 0.99 | F10: 0.95 | G10: 0.88
A11: Dental Equipment | B11: P | C11: 24 | D11: 7 | E11: 0.96 | F11: 0.92 | G11: 0.85
A12: Diathermy Units | B12: C | C12: 24 | D12: 7 | E12: 0.99 | F12: 0.95 | G12: 0.88
A13: Electrosurgical Units | B13: C | C13: 24 | D13: 7 | E13: 0.99 | F13: 0.95 | G13: 0.88
A14: Heamodialysis Units | B14: C | C14: 24 | D14: 7 | E14: 0.99 | F14: 0.95 | G14: 0.88
A15: Humidifiers | B15: C | C15: 24 | D15: 7 | E15: 0.99 | F15: 0.95 | G15: 0.88
A16: Hypo/hyperthermia Units | B16: C | C16: 24 | D16: 7 | E16: 0.99 | F16: 0.95 | G16: 0.88
A17: Incubators | B17: C | C17: 24 | D17: 7 | E17: 0.99 | F17: 0.95 | G17: 0.88
... A59: Vector Cardiographs | B59: P | C59: 12 | D59: 6 | E59: 0.96 | F59: 0.92 | G59: 0.85
A60: Analysers
A61: · Amino Acid | B61: P | C61: 12 | D61: 6 | E61: 0.96 | F61: 0.92 | G61: 0.85
A62: · Bilirubinometers | B62: P | C62: 12 | D62: 6 | E62: 0.96 | F62: 0.92 | G62: 0.85
A63: · Blood Gas | B63: P | C63: 12 | D63: 6 | E63: 0.96 | F63: 0.92 | G63: 0.85
A64: · Calcium | B64: P | C64: 12 | D64: 6 | E64: 0.96 | F64: 0.92 | G64: 0.85
A65: · Clinical Chemistry | B65: P | C65: 12 | D65: 6 | E65: 0.96 | F65: 0.92 | G65: 0.85
A66: · Coagulation | B66: P | C66: 12 | D66: 6 | E66: 0.96 | F66: 0.92 | G66: 0.85
A67: · Counter, Gamma | B67: P | C67: 12 | D67: 6 | E67: 0.96 | F67: 0.92 | G67: 0.85
A68: · Electrolyte | B68: P | C68: 12 | D68: 6 | E68: 0.96 | F68: 0.92 | G68: 0.85
A69: · Immunoassay | B69: P | C69: 12 | D69: 6 | E69: 0.96 | F69: 0.92 | G69: 0.85
A70: · Glucose | B70: P | C70: 12 | D70: 6 | E70: 0.96 | F70: 0.92 | G70: 0.85
A71: · Hematology | B71: P | C71: 12 | D71: 6 | E71: 0.96 | F71: 0.92 | G71: 0.85
A72: · Platelet Aggregation | B72: P | C72: 12 | D72: 6 | E72: 0.96 | F72: 0.92 | G72: 0.85
... A84: Spectrophotometers | B84: P | C84: 12 | D84: 6 | E84: 0.96 | F84: 0.92 | G84: 0.85

Sheet Sheet2
A4: No | B4: Asset No | C4: Asset Description | D4: Asset Purchase Price (RM) | E4: Work Order No. | G4: User Location | H4: Work Order/ Complaint Details | I4: Response Category (Emergency/ Normal) | J4: Total Response Time (minutes) | K4: Work Request Date | L4: Work Completion Date | M4: Deduction Ringgit Equivalent (RM) | N4: Indicator B.1 | Q4: Indicator B.2 | W4: Contract
F5: wo | N5: Validate Status (Y/N) | O5: Deduction Value (RM) | P5: Remarks/ Exemption | Q5: Validate Status (Y/N) | R5: Total Repair Time (day) | S5: Last date of 7 working days (dd/mm/yy) | T5: Demerit Point | U5: Deduction Value (RM) | V5: Remarks/ Exemption | X5: Total Repair Time (day) | Y5: Hours | Z5: Total Hours | AA5: Total Hours / Year | AB5: Balance Uptime | AC5: Uptime Percentage | AD5: Uptime TRKPI | AE5: Uptime Deduction Yes / No
A6: 23 | B6: IKN400966 | C6: LINEAR ACCELERATOR | D6: 12049370 | E6: 1811 | G6: RT159 | H6: Lazer Double | I6: Normal | J6: 0.010416667 | K6: 43781 | L6: 43795 | M6: =IF(D6>44999.99,100,ROUNDUP((D6/4999.99)*10,-1)) -> 100 | N6: N | O6: =IF(N6="Y",M6,0) -> 0 | P6: Response On_Time | Q6: N | R6: =L6-K6+1 -> 15 | S6: =WORKDAY(K6,6,tarikhcuti) -> 43789 | T6: =IF(L6>S6,L6-S6,0) -> 6 | U6: =M6*T6 -> 600 | W6: Strands | X6: =R6 -> 15 | Y6: 24 | Z6: =X6*Y6 -> 360 | AA6: 8072 | AB6: =AA6-Z6 -> 7712 | AC6: =AB6/8072 -> 0.95540139 | AD6: 0.92 | AE6: No
A7: 1 | B7: IKN400292 | C7: Infusion Pumps, General-Purpose | D7: 10825 | E7: 1655 | G7: WAD 8A | H7: Infucient Pump-Mesin Problem | I7: Normal | J7: 0.025694444 | K7: 43774 | L7: 43799 | M7: =IF(D7>44999.99,100,ROUNDUP((D7/4999.99)*10,-1)) -> 30 | N7: N | O7: =IF(N7="Y",M7,0) -> 0 | P7: Response On_Time | Q7: Y | R7: =L7-K7+1 -> 26 | S7: =WORKDAY(K7,6,tarikhcuti) -> 43782 | T7: =IF(L7>S7,L7-S7,0) -> 17 | U7: =M7*T7 -> 510 | W7: Strands | X7: =R7 -> 26 | Y7: 24 | Z7: =X7*Y7 -> 624 | AA7: 8072 | AB7: =AA7-Z7 -> 7448 | AC7: =AB7/8072 -> 0.92269574 | AD7: 0.95 | AE7: Yes
A8: =A7+1 -> 2 | B8: IKN400978 | C8: Scanning Systems, Computed Tomography | D8: 3557530 | E8: 1172 | G8: RT | H8: sendingg image from vsim to mosaiq | I8: Normal | J8: 0.020833333 | K8: 43770 | L8: 43782 | M8: =IF(D8>44999.99,100,ROUNDUP((D8/4999.99)*10,-1)) -> 100 | N8: N | O8: =IF(N8="Y",M8,0) -> 0 | P8: Response On_Time | Q8: N | R8: =L8-K8+1 -> 13 | S8: 43763 | T8: =R8 -> 13 | U8: =M8*T8 -> 1300 | W8: Strands | X8: =R8 -> 13 | Y8: 24 | Z8: =X8*Y8 -> 312 | AA8: 8072 | AB8: =AA8-Z8 -> 7760 | AC8: =AB8/8072 -> 0.96134787 | AD8: 0.95 | AE8: No
A9: =A8+1 -> 3 | B9: IKN400973 | C9: Scanning Systems, Computed Tomography | D9: 3557530 | E9: 1173 | G9: RT | H9: sendingg image from vsim to mosaiq | I9: Normal | J9: 0.013888889 | K9: 43770 | L9: 43782 | M9: =IF(D9>44999.99,100,ROUNDUP((D9/4999.99)*10,-1)) -> 100 | N9: N | O9: =IF(N9="Y",M9,0) -> 0 | P9: Response On_Time | Q9: N | R9: =L9-K9+1 -> 13 | S9: 43763 | T9: =R9 -> 13 | U9: =M9*T9 -> 1300 | W9: Strands | X9: =R9 -> 13 | Y9: 24 | Z9: =X9*Y9 -> 312 | AA9: 8072 | AB9: =AA9-Z9 -> 7760 | AC9: =AB9/8072 -> 0.96134787 | AD9: 0.95 | AE9: No
A10: =A9+1 -> 4 | B10: IKN400151 | C10: Mattress Systems, Alternating-Pressure | D10: 28630 | E10: 1449 | G10: WAD 7A | H10: Motor ripple mattress rosak | I10: Normal | J10: 0.027777778 | K10: 43770 | L10: 43775 | M10: =IF(D10>44999.99,100,ROUNDUP((D10/4999.99)*10,-1)) -> 60 | N10: N | O10: =IF(N10="Y",M10,0) -> 0 | P10: Response On_Time | Q10: N | R10: =L10-K10+1 -> 6 | S10: 43774 | T10: =R10 -> 6 | U10: =M10*T10 -> 360 | W10: Strands | X10: =R10 -> 6 | Y10: 24 | Z10: =X10*Y10 -> 144 | AA10: 8072 | AB10: =AA10-Z10 -> 7928 | AC10: =AB10/8072 -> 0.98216056 | AD10: 0.92 | AE10: No
A11: =A10+1 -> 5 | B11: IKN400967 | C11: Linear Accelerators | D11: 12049370 | E11: 1471 | G11: RT | H11: Table verticle movement problem | I11: Normal | J11: 0.065972222 | K11: 43770 | L11: 43773 | M11: =IF(D11>44999.99,100,ROUNDUP((D11/4999.99)*10,-1)) -> 100 | N11: N | O11: =IF(N11="Y",M11,0) -> 0 | P11: Response On_Time | Q11: N | R11: =L11-K11+1 -> 4 | S11: 43775 | T11: =R11 -> 4 | U11: =M11*T11 -> 400 | W11: Strands | X11: =R11 -> 4 | Y11: 24 | Z11: =X11*Y11 -> 96 | AA11: 8072 | AB11: =AA11-Z11 -> 7976 | AC11: =AB11/8072 -> 0.98810704 | AD11: 0.92 | AE11: No
