Workbook
Name _05_04_2009: #REF!
Name _05_04_2009: #REF!
Name _05_04_2009: #REF!
Name _05_04_2009: #REF!
Name _05_04_2009: #REF!
Name a: '[1]Term Outstanding Payment'!#REF!
Name a: '[1]Term Outstanding Payment'!#REF!
Name a: '[1]Term Outstanding Payment'!#REF!
Name a: '[1]Term Outstanding Payment'!#REF!
Name a: '[1]Term Outstanding Payment'!#REF!
Name AA: #REF!
Name AA: #REF!
Name AA: #REF!
Name AA: #REF!
Name AA: #REF!
Name aaa: #REF!
Name aaa: #REF!
Name aaa: #REF!
Name aaa: #REF!
Name aaa: #REF!
Name aaaaa: #REF!
Name aaaaa: #REF!
Name aaaaa: #REF!
Name aaaaa: #REF!
Name aaaaa: #REF!
Name aaaaaaaaaa: #REF!
Name aaaaaaaaaa: #REF!
Name aaaaaaaaaa: #REF!
Name aaaaaaaaaa: #REF!
Name AAAAAAAAAAAAA: #REF!
Name AAAAAAAAAAAAA: #REF!
Name AAAAAAAAAAAAA: #REF!
Name AAAAAAAAAAAAA: #REF!
Name AAAAAAAAAAAAAAAAAA: #REF!
Name AAAAAAAAAAAAAAAAAA: #REF!
Name AAAAAAAAAAAAAAAAAA: #REF!
Name AAAAAAAAAAAAAAAAAA: #REF!
Name AAAAAAAAAAAAAAAAAAAAA: #REF!
Name AAAAAAAAAAAAAAAAAAAAA: #REF!
Name AAAAAAAAAAAAAAAAAAAAA: #REF!
Name AAAAAAAAAAAAAAAAAAAAA: #REF!
Name AAAAAAAAAAAAAAAAAAAAAAAAAAA: #REF!
Name AAAAAAAAAAAAAAAAAAAAAAAAAAA: #REF!
Name AAAAAAAAAAAAAAAAAAAAAAAAAAA: #REF!
Name AAAAAAAAAAAAAAAAAAAAAAAAAAA: #REF!
Name AAAAAAAAAAAAAAAAAAAAAAAAAAAA: #REF!
Name AAAAAAAAAAAAAAAAAAAAAAAAAAAA: #REF!
Name AAAAAAAAAAAAAAAAAAAAAAAAAAAA: #REF!
Name AAAAAAAAAAAAAAAAAAAAAAAAAAAA: #REF!
Name AAAAAAAAAAAAAAAAAAAAAAAAAAAAAA: #REF!
Name AAAAAAAAAAAAAAAAAAAAAAAAAAAAAA: #REF!
Name AAAAAAAAAAAAAAAAAAAAAAAAAAAAAA: #REF!
Name AAAAAAAAAAAAAAAAAAAAAAAAAAAAAA: #REF!
Name AAAAAAAAAAAAAAAAAAAAAAAAAAAAAAA: #REF!
Name AAAAAAAAAAAAAAAAAAAAAAAAAAAAAAA: #REF!
Name AAAAAAAAAAAAAAAAAAAAAAAAAAAAAAA: #REF!
Name AAAAAAAAAAAAAAAAAAAAAAAAAAAAAAA: #REF!
Name AAAAAAAAAAAAAAAAAAAAAAAAAAAAAAAAA: #REF!
Name AAAAAAAAAAAAAAAAAAAAAAAAAAAAAAAAA: #REF!
Name AAAAAAAAAAAAAAAAAAAAAAAAAAAAAAAAA: #REF!

Sheet KDI
A1: Indicator No. | B1: Indicator | E1: Frequency of Deduction | F1: Biomedical Equipment Purchase Cost (RM) | H1: Deduction Range Value (RM) | J1: Maximum Demerit Point per Work Order
F2: From | G2: To
A3: B.1 | B3: The Company shall respond to the request within the specified time frame | E3: Per event | F3: 0.00 5,000.00 10,000.00 15,000.00 20,000.00 25,000.00 30,000.00 35,000.00 40,000.00 > 45,000.00 | G3: 4,999.99 9,999.99 14,999.99 19,999.99 24,999.99 29,999.99 34,999.99 39,999.99 44,999.99 | H3: 10.00 20.00 30.00 40.00 50.00 60.00 70.00 80.00 90.00 100.00 | J3: 1
A4: B.2 | B4: The Company shall carry out repairs to restore faulty medical equipment to a specified condition when it fails to function as per manufacturer’s specification within seven (7) working days. | E4: Per day | F4: 0.00 5,000.00 10,000.00 15,000.00 20,000.00 25,000.00 30,000.00 35,000.00 40,000.00 > 45,000.00 | G4: 4,999.99 9,999.99 14,999.99 19,999.99 24,999.99 29,999.99 34,999.99 39,999.99 44,999.99 | H4: 10.00 20.00 30.00 40.00 50.00 60.00 70.00 80.00 90.00 100.00 | J4: Number of working days for the month
A5: B.3 | B5: The Company shall carry out scheduled maintenance as per schedule in accordance to the procedure as specified in Agreement. Scheduled maintenance shall include complete safety and performance tests. | E5: Per event | F5: 0.00 5,000.00 10,000.00 15,000.00 20,000.00 25,000.00 30,000.00 35,000.00 40,000.00 45,000.00 | G5: 4,999.99 9,999.99 14,999.99 19,999.99 24,999.99 29,999.99 34,999.99 39,999.99 44,999.99 49,999.99 | H5: 10.00 20.00 30.00 40.00 50.00 60.00 70.00 80.00 90.00 100.00 | J5: 1
F6: For every RM 5,000 increment of equipment cost, an increase of RM10 will be applied subsequently
A7: B.4 | B7: The Company shall ensure biomedical equipment meets the uptime target as set in the Agreement. | E7: Per event | H7: 1st level of Uptime Target (TRKPI) | I7: 2nd level of Uptime Target (80%) | J7: 2
F8: 0.00 5,000.00 10,000.00 15,000.00 20,000.00 25,000.00 30,000.00 35,000.00 40,000.00 45,000.00 | G8: 4,999.99 9,999.99 14,999.99 19,999.99 24,999.99 29,999.99 34,999.99 39,999.99 44,999.99 49,999.99 | H8: 10.00 20.00 30.00 40.00 50.00 60.00 70.00 80.00 90.00 100.00 | I8: 20.00 40.00 60.00 80.00 100.00 120.00 140.00 160.00 180.00 200.00
F9: For every RM 5,000 increment of equipment cost, an increase of RM10 will be applied subsequently for 1st Uptime Target and an increase of RM20 for 2nd Uptime Target will be applied subsequently
A10: B.5 | B10: The Company shall attend and witness T&C and manage biomedical equipment within the warranty period. | E10: Per event | F10: 0.00 5,000.00 10,000.00 15,000.00 20,000.00 25,000.00 30,000.00 35,000.00 40,000.00 45,000.00 | G10: 4,999.99 9,999.99 14,999.99 19,999.99 24,999.99 29,999.99 34,999.99 39,999.99 44,999.99 49,999.99 | H10: 10.00 20.00 30.00 40.00 50.00 60.00 70.00 80.00 90.00 100.00 | J10: 1
F11: For every RM 5,000 increment of equipment cost, an increase of RM10 will be applied subsequently

Sheet Public Holiday
A1: ­
A2: Tarikh | B2: Hari | C2: Cuti | D2: Negeri Berkenaan
A4: 46023 | B4: Khamis | C4: Tahun Baru | D4: Putrajaya
A6: 46070 | B6: Selasa | C6: Tahun Baru Cina | D6: Putrajaya
A8: 46071 | B8: Rabu | C8: Tahun Baru Cina Hari Kedua | D8: Putrajaya
A10: 46055 | B10: Isnin | C10: Hari Wilayah Persekutuan | D10: Putrajaya
A12: 46055 | B12: Isnin | C12: Hari Thaipusam | D12: Putrajaya
A14: 46088 | B14: Sabtu | C14: Hari Nuzul Al-Quran | D14: Putrajaya
A16: 46101 | B16: Sabtu | C16: Hari Raya Aidilfitri | D16: Putrajaya
A18: 46102 | B18: Sabtu | C18: Hari Raya Aidilfitri | D18: Putrajaya
A20: 46103 | B20: Ahad | C20: Hari Raya Aidilfitri Hari Kedua | D20: Putrajaya
A22: 46104 | B22: Ahad | C22: Hari Raya Aidilfitri Hari Kedua | D22: Putrajaya
A24: 46143 | B24: Jumaat | C24: Hari Pekerja | D24: Putrajaya
A26: 46173 | B26: Ahad | C26: Hari Wesak | D26: Putrajaya
... A46: 46381 | B46: Jumaat | C46: Hari Krismas | D46: Putrajaya
A49: * Subject to change (Tertakluk kepada perubahan), TBC - To be confirmed

Sheet BEMSdar
A1: MINISTRY OF HEALTH
A2: Deduction Mapping Report Biomedical Engineering Maintenance Services (BEMS)
D5: HOSPITAL NAME : | E5: Institut Kanser Negara | I5: STATE: | J5: W.P. Putrajaya
D7: MONTH/YEAR : | E7: 46082 | I7: COMPANY: | J7: Ambang Wira Sdn Bhd
A9: MONTHLY SERVICE FEE (RM) : | E9: 1363910.9
A11: BEMS MONTHLY FEE (RM) @ 97.5% : | E11: =97.5%*E9 -> 1329813.2
A13: FMS MONTHLY FEE (RM) @ 2.5% : | E13: =2.5%*E9 -> 34097.773
A17: No | B17: Key Deduction Indicators | I17: Frequency | L17: Deduction Value (RM) | N17: Deduction % | O17: Performance Level (%)
A19: B.1 | B19: All service requests shall be responded by the Company’s trained technical personal within the timeframe as stipulated in the Agreement. | I19: Per event | L19: 0 | N19: 0 | O19: =100-N19 -> 100
A20: B.2 | B20: All unscheduled maintenance works including relevant maintenance calibration, safety tests and functional checks shall be completed within seven (7) working days. | I20: Per day | L20: ='B1&B2 UNSCHEDULED'!U103 -> 500 | N20: =L20/$E$11% -> 0.037599267 | O20: =100-N20 -> 99.962401
A21: B.3 | B21: Scheduled maintenance shall be carried out as per schedule and according to the procedure as specified in the Agreement. Scheduled maintenance shall include complete safety and performance tests. | I21: Per event | L21: ='B3-SCHEDULED'!L264 -> 440 | N21: =L21/$E$11% -> 0.033087355 | O21: =100-N21 -> 99.966913
A22: B.4 | B22: All biomedical equipment shall be functioning and maintained to ensure uptime target as specified in the TRKPI are met. | I22: Per event | L22: 0 | N22: =L22/$E$11% -> 0 | O22: =100-N22 -> 100
A23: B.5 | B23: T&C and Warranty Management of newly introduced biomedical shall be managed and performed according to the Agreement and related acts, standards and regulations. | I23: Per event | L23: ='B5-T&C'!O21 -> 0 | N23: =L23/$E$11% -> 0 | O23: =100-N23 -> 100
A24: Total | L24: =SUM(L19:M23) -> 940 | N24: =SUM(N19:N23) -> 0.070686622 | O24: =100-N24 -> 99.929313
C27: Prepared by: | I27: Verified by:
C31: Siti Norsaliana Binti Abu Khalid | I31: Mohd Shahrulnizam bin Tarmizi
C32: Head of BEMS | I32: Facility Manager
C33: Ambang Wira Sdn Bhd- Institut Kanser Negara | I33: Ambang Wira Sdn Bhd- Institut Kanser Negara
C34: Date: | I34: Date:

Sheet B1&B2 UNSCHEDULED
A2: MINISTRY OF HEALTH
A3: Deduction Mapping Report Biomedical Engineering Maintenance Services (BEMS)
A4: INDICATOR B.1 RESPONSE TIME & B.2 REPAIR TIME
A6: HOSPITAL NAME: | C6: INSTITUT KANSER NEGARA | I6: FIRST DATE OF THE MONTH : | M6: 46082 | Q6: (For Calculation)
A8: STATE: | C8: WILAYAH PERSEKUTUAN PUTRAJAYA | I8: LAST DATE OF THE MONTH : | M8: 46112 | Q8: (For Calculation)
A10: COMPANY: | C10: AMBANG WIRA SDN BHD | I10: BEMS MONTHLY FEE (RM) @ 97.5% : | M10: =BEMSdar!E11 -> 1329813.2
A12: MONTH/YEAR: | C12: 46082 | I12: FMS MONTHLY FEE (RM) @ 2.5% : | M12: =BEMSdar!E13 -> 34097.773
A14: Notes:
A15: 1) Deduction Ringgit Equivalent is based on Appendix 11 of the Agreement, Section B3 Key Deduction Indicators for BEMS
A16: 2) Deduction Value for Indicator B.1 is Deduction Ringgit Equivalent (per event)
A17: 3) Total Repair Time includes weekend & public holiday
A18: 4) Demerit Point for Indicator B.2 is calculated based on completion date against request date, less by 7 working days
A19: 5) Deduction Value for Indicator B.2 is Demerit Point multiply by Deduction Ringgit Equivalent
A21: No | B21: Asset No | C21: Asset Description | D21: Asset Purchase Price (RM) | E21: Work Order No. | F21: User Location | G21: Work Order/ Complaint Details | H21: Response Category (Emergency/ Normal) | I21: Total Response Time (minutes) | J21: Work Request Date | K21: Response Time (Minutes) | L21: Work Completion Date | M21: Deduction Ringgit Equivalent (RM) | N21: Indicator B.1 | Q21: Indicator B.2
N22: Validate Status (Y/N) | O22: Deduction Value (RM) | P22: Remarks/ Exemption | Q22: Validate Status (Y/N) | R22: Total Repair Time (day) | S22: Last date of 7 working days (dd/mm/yy) | T22: Demerit Point | U22: Deduction Value (RM) | V22: Remarks/ Exemption
A23: Current Month (Work Order Completed)
A24: 1 | B24: IKN400762 | C24: =VLOOKUP(B24,[14]AssetDetails_UEM!$A$3:$AH$1849,6,FALSE) -> Analyzers, Laboratory, Immunoassay, Chemiluminescent | D24: =VLOOKUP(B24,[14]AssetDetails_UEM!$A$3:$AK$1849,22,FALSE) -> 1443450 | E24: IKNWIBE26003941 | F24: 04LA133 | G24: MACHINE ARCHITECT'WASTE TANK'-PATHOLOGY ARAS 4 | H24: Normal | I24: 0 days, 0 hrs, 42 mins | J24: 01-Mar-2026 08:18:00 | K24: 01-Mar-2026 09:00:00 | L24: 01-Mar-2026 10:30:00 | M24: =IF(D24>44999.99,100,ROUNDUP((D24/4999.99)*10,-1)) -> 100 | N24: N | O24: ='[15]B1& B2 UNSCHEDULED'!$O$24 -> 0 | Q24: N | R24: =IF(L24="",AKHIR-J24,L24-J24+1) -> 1.0916667 | S24: =WORKDAY(J24,6,AKHIR) -> 46090 | T24: 0 | U24: =IF(Q24="N",0,M24*T24) -> 0 | V24: CLEAN UP THE TUBING , DO DAILY MAINTENANCE ,CHECKED ,TESTED OKAY AND FIT TO USE
A25: 2 | B25: IKN400353 | C25: =VLOOKUP(B25,[14]AssetDetails_UEM!$A$3:$AH$1849,6,FALSE) -> Monitors, Physiologic, Vital Signs | D25: =VLOOKUP(B25,[14]AssetDetails_UEM!$A$3:$AK$1849,22,FALSE) -> 18765 | E25: IKNWIBE26003944 | F25: 07WF133 | G25: CUFF BP SET TERKOYAK 7B | H25: Normal | I25: 0 days, 0 hrs, 21 mins | J25: 01-Mar-2026 11:39:00 | K25: 01-Mar-2026 12:00:00 | L25: 01-Mar-2026 18:00:00 | M25: =IF(D25>44999.99,100,ROUNDUP((D25/4999.99)*10,-1)) -> 40 | N25: N | O25: ='[15]B1& B2 UNSCHEDULED'!$O$24 -> 0 | Q25: N | R25: =IF(L25="",AKHIR-J25,L25-J25+1) -> 1.2645833 | S25: =WORKDAY(J25,6,AKHIR) -> 46090 | T25: 0 | U25: =IF(Q25="N",0,M25*T25) -> 0 | V25: REPLACE NEW CONNECTOR HOSE,REPLACE THE CUFF.TESTED OKAY ,INFLATE WELL
A26: 3 | B26: NA | C26: RIPPLE MATTRESS | D26: NA | E26: IKNWIBE26003945 | F26: 09WJ237 | G26: SPRING LOCK ANGIN RIPPLE MATTRESS ROSAK(NO SIRI:NB355553)-9A | H26: Normal | I26: 0 days, 0 hrs, 33 mins | J26: 01-Mar-2026 16:27:00 | K26: 01-Mar-2026 17:00:00 | L26: 02-Mar-2026 21:30:00 | M26: 0 | N26: N | O26: ='[15]B1& B2 UNSCHEDULED'!$O$24 -> 0 | Q26: N | R26: =IF(L26="",AKHIR-J26,L26-J26+1) -> 2.2104167 | S26: =WORKDAY(J26,6,AKHIR) -> 46090 | T26: 0 | U26: =IF(Q26="N",0,M26*T26) -> 0 | V26: FOUND IN LOCKING PIN MISSING.REPLACED NEW LOCKING PIN.TESTED OKAY AND FIT TO USE
A27: 4 | B27: IKN400762 | C27: =VLOOKUP(B27,[14]AssetDetails_UEM!$A$3:$AH$1849,6,FALSE) -> Analyzers, Laboratory, Immunoassay, Chemiluminescent | D27: =VLOOKUP(B27,[14]AssetDetails_UEM!$A$3:$AK$1849,22,FALSE) -> 1443450 | E27: IKNWIBE26004000 | F27: 04LA133 | G27: MESIN ARCHITECT INTERNAL WASTE TANK FULL - PATTHOLOGI ARAS 4 | H27: Normal | I27: 0 days, 0 hrs, 11 mins | J27: 02-Mar-2026 09:29:00 | K27: 02-Mar-2026 09:40:00 | L27: 02-Mar-2026 23:00:00 | M27: =IF(D27>44999.99,100,ROUNDUP((D27/4999.99)*10,-1)) -> 100 | N27: N | O27: ='[15]B1& B2 UNSCHEDULED'!$O$24 -> 0 | Q27: N | R27: =IF(L27="",AKHIR-J27,L27-J27+1) -> 1.5631944 | S27: =WORKDAY(J27,6,AKHIR) -> 46091 | T27: 0 | U27: =IF(Q27="N",0,M27*T27) -> 0 | V27: CLEAN LOW CONTRATION WASTE TANK,TUBING
A28: 5 | B28: IKN400787 | C28: =VLOOKUP(B28,[14]AssetDetails_UEM!$A$3:$AH$1849,6,FALSE) -> Radiographic Units, Mobile | D28: =VLOOKUP(B28,[14]AssetDetails_UEM!$A$3:$AK$1849,22,FALSE) -> 1149550 | E28: IKNWIBE26004021 | F28: 03ID106 | G28: MESIN TIDAK BOLEH HANTAR GAMBAR MELALUI WIFI - RADIOLOGI ARAS 3 | H28: Normal | I28: 0 days, 0 hrs, 12 mins | J28: 02-Mar-2026 15:28:00 | K28: 02-Mar-2026 15:40:00 | L28: 02-Mar-2026 16:00:00 | M28: =IF(D28>44999.99,100,ROUNDUP((D28/4999.99)*10,-1)) -> 100 | N28: N | O28: ='[15]B1& B2 UNSCHEDULED'!$O$24 -> 0 | Q28: N | R28: =IF(L28="",AKHIR-J28,L28-J28+1) -> 1.0222222 | S28: =WORKDAY(J28,6,AKHIR) -> 46091 | T28: 0 | U28: =IF(Q28="N",0,M28*T28) -> 0 | V28: RECONECT WIFI AND TESTED OKAY.
A29: 6 | B29: IKN400049 | C29: =VLOOKUP(B29,[14]AssetDetails_UEM!$A$3:$AH$1849,6,FALSE) -> Physiologic Monitoring Systems, Acute Care | D29: =VLOOKUP(B29,[14]AssetDetails_UEM!$A$3:$AK$1849,22,FALSE) -> 119690 | E29: IKNWIBE26004154 | F29: 05IC131 | G29: MONITOR BLANK - ICU ARAS 5 | H29: Normal | I29: 0 days, 0 hrs, 13 mins | J29: 03-Mar-2026 17:57:00 | K29: 03-Mar-2026 18:10:00 | L29: 03-Mar-2026 21:40:00 | M29: =IF(D29>44999.99,100,ROUNDUP((D29/4999.99)*10,-1)) -> 100 | N29: N | O29: ='[15]B1& B2 UNSCHEDULED'!$O$24 -> 0 | Q29: N | R29: =IF(L29="",AKHIR-J29,L29-J29+1) -> 1.1548611 | S29: =WORKDAY(J29,6,AKHIR) -> 46092 | T29: 0 | U29: =IF(Q29="N",0,M29*T29) -> 0 | V29: FOUND SWITH FOR MODERN NOT TURN ON.TURN ON AND TESTED FUNCTIONING OKAY
A30: 7 | B30: IKN402166 | C30: =VLOOKUP(B30,[14]AssetDetails_UEM!$A$3:$AH$1849,6,FALSE) -> Mattress Systems, Alternating-Pressure | D30: =VLOOKUP(B30,[14]AssetDetails_UEM!$A$3:$AK$1849,22,FALSE) -> 4000 | E30: IKNWIBE26004156 | F30: 05WB149 | G30: RIPPLE MATTRESS BERBUNYI - WAD 5A | H30: Normal | I30: 0 days, 0 hrs, 10 mins | J30: 03-Mar-2026 18:35:00 | K30: 46084.781 | L30: 05-Mar-2026 10:00:00 | M30: =IF(D30>44999.99,100,ROUNDUP((D30/4999.99)*10,-1)) -> 10 | N30: N | O30: ='[15]B1& B2 UNSCHEDULED'!$O$24 -> 0 | Q30: N | R30: =IF(L30="",AKHIR-J30,L30-J30+1) -> 2.6423611 | S30: =WORKDAY(J30,6,AKHIR) -> 46092 | T30: 0 | U30: =IF(Q30="N",0,M30*T30) -> 0 | V30: REPLACE NEW CELL.CHECKED AND TESTED OKAY.FUNCTIONING .NO MORE ALARM
A31: 8 | B31: IKN400386 | C31: =VLOOKUP(B31,[14]AssetDetails_UEM!$A$3:$AH$1849,6,FALSE) -> Physiologic Monitoring Systems, Acute Care | D31: =VLOOKUP(B31,[14]AssetDetails_UEM!$A$3:$AK$1849,22,FALSE) -> 44510 | E31: IKNWIBE26004223 | F31: 07WE113 | G31: BP CUFF TIDAK BOLEH GUNA - WAD 7A | H31: Normal | I31: 0 days, 1 hrs, 5 mins | J31: 04-Mar-2026 09:40:00 | K31: 04-Mar-2026 10:45:00 | L31: 04-Mar-2026 11:15:00 | M31: =IF(D31>44999.99,100,ROUNDUP((D31/4999.99)*10,-1)) -> 90 | N31: N | O31: ='[15]B1& B2 UNSCHEDULED'!$O$24 -> 0 | Q31: N | R31: =IF(L31="",AKHIR-J31,L31-J31+1) -> 1.0659722 | S31: =WORKDAY(J31,6,AKHIR) -> 46093 | T31: 0 | U31: =IF(Q31="N",0,M31*T31) -> 0 | V31: RESEAT MODULE AND NIBP CABLE.TESTED ,CUFF CAN INFLATE
A32: 9 | B32: IKN400387 | C32: =VLOOKUP(B32,[14]AssetDetails_UEM!$A$3:$AH$1849,6,FALSE) -> Sphygmomanometers, Electronic, Automatic | D32: =VLOOKUP(B32,[14]AssetDetails_UEM!$A$3:$AK$1849,22,FALSE) -> 4510 | E32: IKNWIBE26004224 | F32: 07WE143 | G32: BP CUFF BATERI TIDAK BERFUNGSI- 7A | H32: Normal | I32: 0 days, 0 hrs, 18 mins | J32: 04-Mar-2026 09:42:00 | K32: 04-Mar-2026 10:00:00 | L32: 10-Mar-2026 15:00:00 | M32: =IF(D32>44999.99,100,ROUNDUP((D32/4999.99)*10,-1)) -> 10 | N32: N | O32: ='[15]B1& B2 UNSCHEDULED'!$O$24 -> 0 | Q32: N | R32: 5 | S32: =WORKDAY(J32,6,AKHIR) -> 46093 | T32: 0 | U32: =IF(Q32="N",0,M32*T32) -> 0 | V32: UNDER MONITORING. V2,REPLACE NEW BATTERY AND NEED FURTHER MONITORING WHETHER THE BATTERY CAN SUSTAIN WITHOUT CHARGE OR NOT. V3, MACHINE FUNCTIONING AND BATTERY CAN SUSTAIN LONGER.FEEDBACK FROM USER CHECKED AND TESTED
A33: 10 | B33: IKN401027 | C33: =VLOOKUP(B33,[14]AssetDetails_UEM!$A$3:$AH$1849,6,FALSE) -> Tables, Operating | D33: =VLOOKUP(B33,[14]AssetDetails_UEM!$A$3:$AK$1849,22,FALSE) -> 239350 | E33: IKNWIBE26004225 | F33: 05OT120 | G33: TABLE OPERATING CANNOT FUCTION AND CANNOT USE- GOT ARAS 5 | H33: Normal | I33: 0 days, 0 hrs, 9 mins | J33: 04-Mar-2026 09:51:00 | K33: 46085.417 | L33: 05-Mar-2026 10:00:00 | M33: =IF(D33>44999.99,100,ROUNDUP((D33/4999.99)*10,-1)) -> 100 | N33: N | O33: ='[15]B1& B2 UNSCHEDULED'!$O$24 -> 0 | Q33: N | R33: =IF(L33="",AKHIR-J33,L33-J33+1) -> 2.00625 | S33: =WORKDAY(J33,6,AKHIR) -> 46093 | T33: 0 | U33: =IF(Q33="N",0,M33*T33) -> 0 | V33: REPLACED NEW POWER SUPPLY CABLE, UNIT TEST AND FUNCTIONING IN GOOD CONDITION
A34: 11 | B34: IKN400454 | C34: =VLOOKUP(B34,[14]AssetDetails_UEM!$A$3:$AH$1849,6,FALSE) -> Mattress Systems, Alternating-Pressure | D34: =VLOOKUP(B34,[14]AssetDetails_UEM!$A$3:$AK$1849,22,FALSE) -> 28630 | E34: IKNWIBE26004226 | F34: 06WC113 | G34: HOSE RIPPLE MATTRESS LOOSE - WAD 6A | H34: Normal | I34: 0 days, 0 hrs, 26 mins | J34: 04-Mar-2026 10:34:00 | K34: 04-Mar-2026 11:00:00 | L34: 04-Mar-2026 12:00:00 | M34: =IF(D34>44999.99,100,ROUNDUP((D34/4999.99)*10,-1)) -> 60 | N34: N | O34: ='[15]B1& B2 UNSCHEDULED'!$O$24 -> 0 | Q34: N | R34: =IF(L34="",AKHIR-J34,L34-J34+1) -> 1.0597222 | S34: =WORKDAY(J34,6,AKHIR) -> 46093 | T34: 0 | U34: =IF(Q34="N",0,M34*T34) -> 0 | V34: CHANGE NEW CLIP HOSE,MAKE SURE IT TIGHT ,TEST HOSE OK.UNIT FIT TO USE
A35: 12 | B35: IKN400762 | C35: =VLOOKUP(B35,[14]AssetDetails_UEM!$A$3:$AH$1849,6,FALSE) -> Analyzers, Laboratory, Immunoassay, Chemiluminescent | D35: =VLOOKUP(B35,[14]AssetDetails_UEM!$A$3:$AK$1849,22,FALSE) -> 1443450 | E35: IKNWIBE26004236 | F35: 04LA133 | G35: PIPETEER MOVEMEMENT LLESTRIK AT MIDDLE REAGENT STEP NUMBER - PATOLOGI ARAS | H35: Normal | I35: 0 days, 0 hrs, 6 mins | J35: 04-Mar-2026 12:54:00 | K35: 46085.542 | L35: 46093.542 | M35: =IF(D35>44999.99,100,ROUNDUP((D35/4999.99)*10,-1)) -> 100 | N35: N | O35: ='[15]B1& B2 UNSCHEDULED'!$O$24 -> 0 | Q35: N | R35: 7 | S35: =WORKDAY(J35,6,AKHIR) -> 46093 | T35: 0 | U35: =IF(Q35="N",0,M35*T35) -> 0 | V35: REAGENT PROBE ERROR. REALLIGMENT REAGENT PROBE, RUN CAL, QC AND OK
A36: 13 | B36: IKN400757 | C36: =VLOOKUP(B36,[14]AssetDetails_UEM!$A$3:$AH$1849,6,FALSE) -> Analyzers, Laboratory, Hematology, Cell Counting, Automated | D36: =VLOOKUP(B36,[14]AssetDetails_UEM!$A$3:$AK$1849,22,FALSE) -> 565350 | E36: IKNWIBE26004317 | F36: 04LA131 | G36: USER TRAINING HEMATOLOGY ANALYZER - IKN400757 | H36: User Training | I36: 0 days, 0 hrs, 09 mins | J36: 05-Mar-2026 09:51:00 | K36: 46086.417 | L36: 05-Mar-2026 11:00:00 | M36: =IF(D36>44999.99,100,ROUNDUP((D36/4999.99)*10,-1)) -> 100 | N36: N | O36: ='[15]B1& B2 UNSCHEDULED'!$O$24 -> 0 | Q36: N | R36: =IF(L36="",AKHIR-J36,L36-J36+1) -> 1.0479167 | S36: =WORKDAY(J36,6,AKHIR) -> 46094 | T36: 0 | U36: =IF(Q36="N",0,M36*T36) -> 0 | V36: USER TRAINING DONE
A37: 14 | B37: IKN402179 | C37: =VLOOKUP(B37,[14]AssetDetails_UEM!$A$3:$AH$1849,6,FALSE) -> Scanning Systems, Computed Tomography/ Positron Emission Tomography | D37: =VLOOKUP(B37,[14]AssetDetails_UEM!$A$3:$AK$1849,22,FALSE) -> 3410390 | E37: IKNWIBE26004321 | F37: 03NM161 | G37: REQ- CHECK XELERIS | H37: Normal | I37: 0 days, 0 hrs, 10 mins | J37: 05-Mar-2026 08:30:00 | K37: 05-Mar-2026 08:40:00 | L37: 05-Mar-2026 09:00:00 | M37: =IF(D37>44999.99,100,ROUNDUP((D37/4999.99)*10,-1)) -> 100 | N37: N | O37: ='[15]B1& B2 UNSCHEDULED'!$O$24 -> 0 | Q37: N | R37: =IF(L37="",AKHIR-J37,L37-J37+1) -> 1.0208333 | S37: =WORKDAY(J37,6,AKHIR) -> 46094 | T37: 0 | U37: =IF(Q37="N",0,M37*T37) -> 0 | V37: VENDOR RUN LFW RESTRORE THE BACKUP CONFIGURATION. RE-CONFIGURE THE DICOM PARAMETER. QUERY AND RETRIEVED PASSED
A38: 15 | B38: IKN400799 | C38: =VLOOKUP(B38,[14]AssetDetails_UEM!$A$3:$AH$1849,6,FALSE) -> Radiographic Systems, Digital | D38: =VLOOKUP(B38,[14]AssetDetails_UEM!$A$3:$AK$1849,22,FALSE) -> 1958605 | E38: IKNWIBE26004404 | F38: 03ID186 | G38: HANDLE GRID MACHINE XRAY TERCABUT - BILIK XRAY ARAS 3 | H38: Normal | I38: 0 days, 0 hrs, 15 mins | J38: 46087.375 | K38: 06-Mar-2026 09:15:00 | L38: 06-Mar-2026 10:00:00 | M38: =IF(D38>44999.99,100,ROUNDUP((D38/4999.99)*10,-1)) -> 100 | N38: N | O38: ='[15]B1& B2 UNSCHEDULED'!$O$24 -> 0 | Q38: N | R38: =IF(L38="",AKHIR-J38,L38-J38+1) -> 1.0416667 | S38: =WORKDAY(J38,6,AKHIR) -> 46097 | T38: 0 | U38: =IF(Q38="N",0,M38*T38) -> 0 | V38: REPLACED BATTERIES FOR REMOTED CONTROL , TESTED FUNCTIONING OKAY
A39: 16 | B39: IKN400967 | C39: =VLOOKUP(B39,[14]AssetDetails_UEM!$A$3:$AH$1849,6,FALSE) -> Linear Accelerators | D39: =VLOOKUP(B39,[14]AssetDetails_UEM!$A$3:$AK$1849,22,FALSE) -> 12049370 | E39: IKNWIBE26004417 | F39: 01RT164 | G39: PC DAN MONITOR IMAGE REVIEW DI LINAC 2 TERPADAM - RADIOTERAPI ARAS 1 (KKN/IKN/H/13/5032) | H39: Normal | I39: 0 days, 0 hrs, 6 mins | J39: 06-Mar-2026 11:09:00 | K39: 06-Mar-2026 11:15:00 | L39: 06-Mar-2026 13:00:00 | M39: =IF(D39>44999.99,100,ROUNDUP((D39/4999.99)*10,-1)) -> 100 | N39: N | O39: ='[15]B1& B2 UNSCHEDULED'!$O$24 -> 0 | Q39: N | R39: =IF(L39="",AKHIR-J39,L39-J39+1) -> 1.0770833 | S39: =WORKDAY(J39,6,AKHIR) -> 46097 | T39: 0 | U39: =IF(Q39="N",0,M39*T39) -> 0 | V39: RESET ALL CABLE AND CONECTORS. TESTED OKAY , AND UNIT LEFT IN FULLY FUNCTIONALITY.
A40: 17 | B40: IKN400956 | C40: =VLOOKUP(B40,[14]AssetDetails_UEM!$A$3:$AH$1849,6,FALSE) -> Linear Accelerators | D40: =VLOOKUP(B40,[14]AssetDetails_UEM!$A$3:$AK$1849,22,FALSE) -> 21961900 | E40: IKNWIBE26004420 | F40: 01RT172 | G40: POWER TRIP - ERROR FLOW PUMP KFIL - RADIOTERAPI | H40: Normal | I40: 0 days, 0 hrs, 28 mins | J40: 06-Mar-2026 12:02:00 | K40: 06-Mar-2026 12:30:00 | L40: 11-Mar-2026 15:00:00 | M40: =IF(D40>44999.99,100,ROUNDUP((D40/4999.99)*10,-1)) -> 100 | N40: N | O40: ='[15]B1& B2 UNSCHEDULED'!$O$24 -> 0 | Q40: N | R40: 4 | S40: =WORKDAY(J40,6,AKHIR) -> 46097 | T40: 0 | U40: =IF(Q40="N",0,M40*T40) -> 0 | V40: RUN BACKUP CHILLER FOR TEMPORARY. REPLACED WITH NEW WATER PUMP AND TEST OK. UNIT LEFT IN FULLY FUNCTIONING.
A41: 18 | B41: IKN402157 | C41: =VLOOKUP(B41,[14]AssetDetails_UEM!$A$3:$AH$1849,6,FALSE) -> Infusion Pumps, General-Purpose | D41: =VLOOKUP(B41,[14]AssetDetails_UEM!$A$3:$AK$1849,22,FALSE) -> 3500 | E41: IKNWIBE26004424 | F41: 08WH107 | G41: MESIN INFUSION KELUAR "ERR 205" - 8B | H41: Normal | I41: 0 days, 0 hrs, 17 mins | J41: 06-Mar-2026 16:23:00 | K41: 46087.694 | L41: 09-Mar-2026 19:15:00 | M41: =IF(D41>44999.99,100,ROUNDUP((D41/4999.99)*10,-1)) -> 10 | N41: N | O41: ='[15]B1& B2 UNSCHEDULED'!$O$24 -> 0 | Q41: N | R41: 2 | S41: =WORKDAY(J41,6,AKHIR) -> 46097 | T41: 0 | U41: =IF(Q41="N",0,M41*T41) -> 0 | V41: TROUBLESHOOT BY CHECKING / BATTERY IN RANGE , CONDUCTED FUNCTIONAL TEST AND INFUSION SIMULATION TEST FOR 2 HOURS. NO ERROR AT ALL. UNIT READY FOR USE.
A42: 19 | B42: NA | C42: Linear Accelerators | D42: 0 | E42: IKNWIBE26004425 | F42: 01RT183 | G42: MESIN LINAC 5 KELUAR BGM - RADIOTERAPI (KKM/IKN/H/25/152) | H42: Normal | I42: 0 days, 0 hrs, 20 mins | J42: 06-Mar-2026 17:00:00 | K42: 06-Mar-2026 17:20:00 | L42: 08-Mar-2026 16:30:00 | M42: =IF(D42>44999.99,100,ROUNDUP((D42/4999.99)*10,-1)) -> 0 | N42: N | O42: ='[15]B1& B2 UNSCHEDULED'!$O$24 -> 0 | Q42: N | R42: 2 | S42: =WORKDAY(J42,6,AKHIR) -> 46097 | T42: 0 | U42: =IF(Q42="N",0,M42*T42) -> 0 | V42: M-REPLACED ION CHAMBER SECONDARY RESOLVER BY VENDOR AND UNIT WERE BACK TO NORMAL CONDITION.UNIT LEFT IN FULL FUNCTIONALITY (ASSET NEW, DW)
A43: 20 | B43: IKN400690 | C43: =VLOOKUP(B43,[14]AssetDetails_UEM!$A$3:$AH$1849,6,FALSE) -> Pumps, Enteral Feeding | D43: =VLOOKUP(B43,[14]AssetDetails_UEM!$A$3:$AK$1849,22,FALSE) -> 6615 | E43: IKNWIBE26004436 | F43: 05IC113 | G43: KANGAROO PUMP TIDAK BERFUNGSI - ICU | H43: Normal | I43: 0 days, 0 hrs, 16 mins | J43: 07-Mar-2026 13:14:00 | K43: 07-Mar-2026 13:30:00 | L43: 13-Mar-2026 14:30:00 | M43: =IF(D43>44999.99,100,ROUNDUP((D43/4999.99)*10,-1)) -> 20 | N43: N | O43: ='[15]B1& B2 UNSCHEDULED'!$O$24 -> 0 | Q43: N | R43: 5 | S43: =WORKDAY(J43,6,AKHIR) -> 46097 | T43: 0 | U43: =IF(Q43="N",0,M43*T43) -> 0 | V43: REPLACE NEW CHARGER FOR FEEDING PUMP.UNIT TEST AND FUNCTIONING IN GOOD CONDITION
A44: 21 | B44: IKN400082 | C44: =VLOOKUP(B44,[14]AssetDetails_UEM!$A$3:$AH$1849,6,FALSE) -> Pumps, Enteral Feeding | D44: =VLOOKUP(B44,[14]AssetDetails_UEM!$A$3:$AK$1849,22,FALSE) -> 6615 | E44: IKNWIBE26004437 | F44: 05IC114 | G44: PENUTUP BIRU KANGAROO PUMP TIADA - ICU ARAS 5 | H44: Normal | I44: 0 days, 0 hrs, 15 mins | J44: 07-Mar-2026 13:15:00 | K44: 07-Mar-2026 13:30:00 | L44: 11-Mar-2026 16:00:00 | M44: =IF(D44>44999.99,100,ROUNDUP((D44/4999.99)*10,-1)) -> 20 | N44: N | O44: ='[15]B1& B2 UNSCHEDULED'!$O$24 -> 0 | Q44: N | R44: 3 | S44: =WORKDAY(J44,6,AKHIR) -> 46097 | T44: 0 | U44: =IF(Q44="N",0,M44*T44) -> 0 | V44: FOUND SIDE COVER AT DEPARTMENT , ATTACHED BACK SIDE COVER TO MAIN UNIT
A45: 22 | B45: IKN400967 | C45: =VLOOKUP(B45,[14]AssetDetails_UEM!$A$3:$AH$1849,6,FALSE) -> Linear Accelerators | D45: =VLOOKUP(B45,[14]AssetDetails_UEM!$A$3:$AK$1849,22,FALSE) -> 12049370 | E45: IKNWIBE26004514 | F45: 01RT165 | G45: MLC STUCK (LINAC 2) - RADIOTERAPI ARAS 1 | H45: Normal | I45: 0 days, 0 hrs, 15 mins | J45: 09-Mar-2026 08:30:00 | K45: 09-Mar-2026 08:45:00 | L45: 09-Mar-2026 12:00:00 | M45: =IF(D45>44999.99,100,ROUNDUP((D45/4999.99)*10,-1)) -> 100 | N45: N | O45: ='[15]B1& B2 UNSCHEDULED'!$O$24 -> 0 | Q45: N | R45: =IF(L45="",AKHIR-J45,L45-J45+1) -> 1.1458333 | S45: =WORKDAY(J45,6,AKHIR) -> 46098 | T45: 0 | U45: =IF(Q45="N",0,M45*T45) -> 0 | V45: REPLACED WITH NEW LEAF MOTOR AND TESTED OK. UNIT LEFT IN FULL FUNCTIONALITY
A46: 23 | B46: IKN400967 | C46: =VLOOKUP(B46,[14]AssetDetails_UEM!$A$3:$AH$1849,6,FALSE) -> Linear Accelerators | D46: =VLOOKUP(B46,[14]AssetDetails_UEM!$A$3:$AK$1849,22,FALSE) -> 12049370 | E46: IKNWIBE26004627 | F46: 01RT165 | G46: MACHINE LINAC 2 ERROR FAULT (5) | H46: Normal | I46: 0 days, 0 hrs, 18 mins | J46: 10-Mar-2026 07:42:00 | K46: 10-Mar-2026 08:00:00 | L46: 10-Mar-2026 11:00:00 | M46: =IF(D46>44999.99,100,ROUNDUP((D46/4999.99)*10,-1)) -> 100 | N46: N | O46: ='[15]B1& B2 UNSCHEDULED'!$O$24 -> 0 | Q46: N | R46: =IF(L46="",AKHIR-J46,L46-J46+1) -> 1.1375 | S46: =WORKDAY(J46,6,AKHIR) -> 46099 | T46: 0 | U46: =IF(Q46="N",0,M46*T46) -> 0 | V46: REBOOT AND RESTART XV GENERATOR. SYSTEM BACK TO NORMAL CONDITION AND UNIT LEFT IN FULL FUNCTIONALITY
A47: 24 | B47: IKN400293 | C47: =VLOOKUP(B47,[14]AssetDetails_UEM!$A$3:$AH$1849,6,FALSE) -> Oximeters, Pulse | D47: =VLOOKUP(B47,[14]AssetDetails_UEM!$A$3:$AK$1849,22,FALSE) -> 5410 | E47: IKNWIBE26004633 | F47: 08WH121 | G47: MACHINE SPO2 BATTERY FAULT- 8B | H47: Normal | I47: 0 days, 0 hrs, 37 mins | J47: 10-Mar-2026 09:23:00 | K47: 46091.417 | L47: 10-Mar-2026 11:00:00 | M47: =IF(D47>44999.99,100,ROUNDUP((D47/4999.99)*10,-1)) -> 20 | N47: N | O47: ='[15]B1& B2 UNSCHEDULED'!$O$24 -> 0 | Q47: N | R47: =IF(L47="",AKHIR-J47,L47-J47+1) -> 1.0673611 | S47: =WORKDAY(J47,6,AKHIR) -> 46099 | T47: 0 | U47: =IF(Q47="N",0,M47*T47) -> 0 | V47: REPLACE NEW BATTERY , TEST OK.
...

Sheet B3-SCHEDULED
A3: MINISTRY OF HEALTH
A4: Deduction Mapping Report Biomedical Engineering Maintenance Services (BEMS)
A5: INDICATOR B.3 SCHEDULED MAINTENANCE
A7: HOSPITAL NAME : | C7: INSTITUT KANSER NEGARA | H7: MONTH/YEAR : | J7: 46082
B9: STATE : | C9: WILAYAH PERSEKUTUAN PUTRAJAYA | G9: BEMS MONTHLY FEE (RM) @ 97.5% : | J9: =BEMSdar!E11 -> 1329813.2
B11: COMPANY : | C11: AMBANG WIRA SDN BHD | G11: FMS MONTHLY FEE (RM) @ 2.5% : | J11: =BEMSdar!E13 -> 34097.773
A13: Notes:
A14: 1) Deduction Ringgit Equivalent is based on Appendix 11 of the Agreement, Section B3 Key Deduction Indicators for BEMS
A15: 2) Deduction Value for Indicator B.3 is Deduction Ringgit Equivalent (per event)
A16: 3) Rescheduled Date is the final rescheduled date if there are multiple rescheduling
A17: 4) Display only asset affected by deduction
A19: No | B19: Asset No | C19: Asset Description | D19: Asset Purchase Price (RM) | E19: Work Order No. | F19: User Location | G19: Scheduled Start Date | H19: Maintenance Date | I19: Rescheduled Date | J19: Validate Status (Y/N) | K19: Deduction Ringgit Equivalent (RM) | L19: Indicator B.3
L20: Deduction Value (RM) | M20: Remarks/ Exemption
A21: Current Month (Closed)
A22: 1 | B22: IKN400173 | C22: Ventilators, Transport | D22: =VLOOKUP(B22,[14]AssetDetails_UEM!$A$3:$X$1848,22,FALSE) -> 60150 | E22: IKNWOBE26003369 | F22: 05IC106 | G22: 46083 | H22: 02-Mar-2026 08:30:00 | I22: NA | J22: N | K22: =ROUNDUP((D22/4999.99)*10,-1) -> 130 | L22: =IF(J22="N",0,K22) -> 0 | M22: P- QE:16, MAINTENANCE DONE ACCORDING TO HEPPM CHECKLIST ATTACHED
A23: 2 | B23: IKN400210 | C23: Electrocardiographs, Multichannel, Interpretative | D23: =VLOOKUP(B23,[14]AssetDetails_UEM!$A$3:$X$1848,22,FALSE) -> 25260 | E23: IKNWOBE26003370 | F23: 09WJ130 | G23: 02-Mar-2026 00:00:00 | H23: 02-Mar-2026 10:30:00 | I23: NA | J23: N | K23: =ROUNDUP((D23/4999.99)*10,-1) -> 60 | L23: =IF(J23="N",0,K23) -> 0 | M23: M,QE:16-PPMDONE AS CHECKLIST ATTACHED
A24: 3 | B24: IKN400223 | C24: Electrocardiographs, Multichannel, Interpretative | D24: =VLOOKUP(B24,[14]AssetDetails_UEM!$A$3:$X$1848,22,FALSE) -> 25260 | E24: IKNWOBE26003371 | F24: 09WJ222 | G24: 02-Mar-2026 00:00:00 | H24: 02-Mar-2026 11:50:00 | I24: NA | J24: N | K24: =ROUNDUP((D24/4999.99)*10,-1) -> 60 | L24: =IF(J24="N",0,K24) -> 0 | M24: M,QE:16-PPM DONE AS PERCHECKLIST ATTACHED
A25: 4 | B25: IKN400732 | C25: pH Meters | D25: =VLOOKUP(B25,[14]AssetDetails_UEM!$A$3:$X$1848,22,FALSE) -> 8000 | E25: IKNWOBE26003372 | F25: 04LA127 | G25: 02-Mar-2026 00:00:00 | H25: 02-Mar-2026 15:00:00 | I25: NA | J25: N | K25: =ROUNDUP((D25/4999.99)*10,-1) -> 20 | L25: =IF(J25="N",0,K25) -> 0 | M25: M,QE:16-PPM DONE AS PER HEPPM CHECKLIST ATTACHED
A26: 5 | B26: IKN401017 | C26: Anesthesia Units | D26: =VLOOKUP(B26,[14]AssetDetails_UEM!$A$3:$X$1848,22,FALSE) -> 144345 | E26: IKNWOBE26003373 | F26: 05OT120 | G26: 02-Mar-2026 00:00:00 | H26: 02-Mar-2026 14:00:00 | I26: NA | J26: N | K26: =ROUNDUP((D26/4999.99)*10,-1) -> 290 | L26: =IF(J26="N",0,K26) -> 0 | M26: P - QE:16, MAINTENANCE DONE AD PER HEPPM CHECKLIST ATTACHED
A27: 6 | B27: IKN400349 | C27: Sphygmomanometers, Electronic, Automatic | D27: =VLOOKUP(B27,[14]AssetDetails_UEM!$A$3:$X$1848,22,FALSE) -> 4510 | E27: IKNWOBE26003374 | F27: 07WF143 | G27: 03-Mar-2026 00:00:00 | H27: 03-Mar-2026 14:00:00 | I27: NA | J27: N | K27: =ROUNDUP((D27/4999.99)*10,-1) -> 10 | L27: =IF(J27="N",0,K27) -> 0 | M27: L, QE:16-PPM HAS BEEN COMPLETE AS PER HEPPM CHECKLIST
A28: 7 | B28: IKN400350 | C28: Sphygmomanometers, Electronic, Automatic | D28: =VLOOKUP(B28,[14]AssetDetails_UEM!$A$3:$X$1848,22,FALSE) -> 4510 | E28: IKNWOBE26003375 | F28: 07WF143 | G28: 03-Mar-2026 00:00:00 | H28: 03-Mar-2026 13:00:00 | I28: NA | J28: N | K28: =ROUNDUP((D28/4999.99)*10,-1) -> 10 | L28: =IF(J28="N",0,K28) -> 0 | M28: L, QE:16-PPM HAS BEEN COMPLETE AS PER HEPPM CHECKLIST
A29: 8 | B29: IKN400813 | C29: Physiologic Monitoring Systems, Acute Care | D29: =VLOOKUP(B29,[14]AssetDetails_UEM!$A$3:$X$1848,22,FALSE) -> 44510 | E29: IKNWOBE26003376 | F29: 01RT238 | G29: 03-Mar-2026 00:00:00 | H29: 03-Mar-2026 08:00:00 | I29: NA | J29: N | K29: =ROUNDUP((D29/4999.99)*10,-1) -> 90 | L29: =IF(J29="N",0,K29) -> 0 | M29: MAINTENANCE DONE ACCORDING TO HEPPM CHECKLIST ATTACHED
A30: 9 | B30: IKN400814 | C30: Physiologic Monitoring Systems, Acute Care | D30: =VLOOKUP(B30,[14]AssetDetails_UEM!$A$3:$X$1848,22,FALSE) -> 44510 | E30: IKNWOBE26003377 | F30: 01RT238 | G30: 03-Mar-2026 00:00:00 | H30: 03-Mar-2026 09:00:00 | I30: NA | J30: N | K30: =ROUNDUP((D30/4999.99)*10,-1) -> 90 | L30: =IF(J30="N",0,K30) -> 0 | M30: P - QE:16, MAINTENANCE DONE ACCORDING TO HEPPM CHECKLIST ATTACHED
A31: 10 | B31: IKN400815 | C31: Physiologic Monitoring Systems, Acute Care | D31: =VLOOKUP(B31,[14]AssetDetails_UEM!$A$3:$X$1848,22,FALSE) -> 44510 | E31: IKNWOBE26003378 | F31: 01RT238 | G31: 03-Mar-2026 00:00:00 | H31: 03-Mar-2026 10:00:00 | I31: NA | J31: N | K31: =ROUNDUP((D31/4999.99)*10,-1) -> 90 | L31: =IF(J31="N",0,K31) -> 0 | M31: P-QE:16, MAINTENANCE DONE ACCORDING TO HEPPM CHECKLLIST ATTACHED
A32: 11 | B32: IKN400849 | C32: Physiologic Monitoring Systems, Acute Care | D32: =VLOOKUP(B32,[14]AssetDetails_UEM!$A$3:$X$1848,22,FALSE) -> 119690 | E32: IKNWOBE26003379 | F32: 01RT278 | G32: 03-Mar-2026 00:00:00 | H32: 03-Mar-2026 12:00:00 | I32: NA | J32: N | K32: =ROUNDUP((D32/4999.99)*10,-1) -> 240 | L32: =IF(J32="N",0,K32) -> 0 | M32: P - QE:16, MAINTENANCE DONE AS PER HEPPM CHECKLIST ATTACHED
A33: 12 | B33: IKN400968 | C33: Warming Units, Patient, Forced-Air | D33: =VLOOKUP(B33,[14]AssetDetails_UEM!$A$3:$X$1848,22,FALSE) -> 15515 | E33: IKNWOBE26003380 | F33: 01RT238 | G33: 03-Mar-2026 00:00:00 | H33: 03-Mar-2026 13:00:00 | I33: NA | J33: N | K33: =ROUNDUP((D33/4999.99)*10,-1) -> 40 | L33: =IF(J33="N",0,K33) -> 0 | M33: P - QE:16, MAINTENANCE DONE AS PER HEPPM CHECKLIST ATTACHED
A34: 13 | B34: IKN400977 | C34: Warming Units, Patient, Forced-Air | D34: =VLOOKUP(B34,[14]AssetDetails_UEM!$A$3:$X$1848,22,FALSE) -> 15515 | E34: IKNWOBE26003381 | F34: 01RT238 | G34: 03-Mar-2026 00:00:00 | H34: 03-Mar-2026 14:00:00 | I34: NA | J34: N | K34: =ROUNDUP((D34/4999.99)*10,-1) -> 40 | L34: =IF(J34="N",0,K34) -> 0 | M34: P - QE:16, MAINTENANCE DONE ACCORDING TO HEPPM CHECKLIST ATTACHED
... A37: 16 | B37: IKN400387 | C37: Sphygmomanometers, Electronic, Automatic | D37: =VLOOKUP(B37,[14]AssetDetails_UEM!$A$3:$X$1848,22,FALSE) -> 4510 | E37: IKNWOBE26003384 | F37: 07WE143 | G37: 04-Mar-2026 00:00:00 | H37: 04-Mar-2026 11:50:00 | I37: NA | J37: N | K37: =ROUNDUP((D37/4999.99)*10,-1) -> 10 | L37: =IF(J37="N",0,K37) -> 0 | M37: L, QE:16-PPM HAS BEEN COMPLETE AS PER HEPPM CHECKLIST
A38: 17 | B38: IKN400389 | C38: Sphygmomanometers, Electronic, Automatic | D38: =VLOOKUP(B38,[14]AssetDetails_UEM!$A$3:$X$1848,22,FALSE) -> 4510 | E38: IKNWOBE26003385 | F38: 07WE143 | G38: 46085 | H38: 09-Mar-2026 09:00:00 | I38: 46092 | J38: N | K38: =ROUNDUP((D38/4999.99)*10,-1) -> 10 | L38: =IF(J38="N",0,K38) -> 0 | M38: P - (ASSET IN USE) PPM HAS BEEN COMPLETED AS PER HEPPM CHECKLIST
A39: 18 | B39: IKN400636 | C39: Infusion Pumps, Syringe | D39: =VLOOKUP(B39,[14]AssetDetails_UEM!$A$3:$X$1848,22,FALSE) -> 10225 | E39: IKNWOBE26003386 | F39: 04DO121 | G39: 04-Mar-2026 00:00:00 | H39: 04-Mar-2026 11:00:00 | I39: NA | J39: N | K39: =ROUNDUP((D39/4999.99)*10,-1) -> 30 | L39: =IF(J39="N",0,K39) -> 0 | M39: M,QE:16- PPM DONE AS PER HEPPM CHECKLIST ATTACHED
A40: 19 | B40: IKN400637 | C40: Infusion Pumps, Syringe | D40: =VLOOKUP(B40,[14]AssetDetails_UEM!$A$3:$X$1848,22,FALSE) -> 10225 | E40: IKNWOBE26003387 | F40: 04DO121 | G40: 04-Mar-2026 00:00:00 | H40: 04-Mar-2026 15:00:00 | I40: NA | J40: N | K40: =ROUNDUP((D40/4999.99)*10,-1) -> 30 | L40: =IF(J40="N",0,K40) -> 0 | M40: M,QE:16-PPM DONE AS PER HEPPM CHECKLIST ATTACHED
A41: 20 | B41: IKN400638 | C41: Infusion Pumps, Syringe | D41: =VLOOKUP(B41,[14]AssetDetails_UEM!$A$3:$X$1848,22,FALSE) -> 10225 | E41: IKNWOBE26003388 | F41: 04DO121 | G41: 04-Mar-2026 00:00:00 | H41: 04-Mar-2026 12:00:00 | I41: NA | J41: N | K41: =ROUNDUP((D41/4999.99)*10,-1) -> 30 | L41: =IF(J41="N",0,K41) -> 0 | M41: M,QE:16-PPM DONE AS PER HEPPM CHECKLIST ATTACHED
A42: 21 | B42: IKN400639 | C42: Infusion Pumps, Syringe | D42: =VLOOKUP(B42,[14]AssetDetails_UEM!$A$3:$X$1848,22,FALSE) -> 10225 | E42: IKNWOBE26003389 | F42: 04DO121 | G42: 04-Mar-2026 00:00:00 | H42: 04-Mar-2026 10:00:00 | I42: NA | J42: N | K42: =ROUNDUP((D42/4999.99)*10,-1) -> 30 | L42: =IF(J42="N",0,K42) -> 0 | M42: M,QE:16-PPM DONE AS PER HEPPM CHECKLIST ATTACHED
A43: 22 | B43: IKN400641 | C43: Infusion Pumps, Syringe | D43: =VLOOKUP(B43,[14]AssetDetails_UEM!$A$3:$X$1848,22,FALSE) -> 10225 | E43: IKNWOBE26003390 | F43: 04DO121 | G43: 04-Mar-2026 00:00:00 | H43: 04-Mar-2026 14:00:00 | I43: NA | J43: N | K43: =ROUNDUP((D43/4999.99)*10,-1) -> 30 | L43: =IF(J43="N",0,K43) -> 0 | M43: M,QE:16-PPM DONE AS PER HEPPM CHECKLIST ATTACHED
A44: 23 | B44: IKN400816 | C44: Physiologic Monitoring Systems, Acute Care | D44: =VLOOKUP(B44,[14]AssetDetails_UEM!$A$3:$X$1848,22,FALSE) -> 44510 | E44: IKNWOBE26003391 | F44: 01RT238 | G44: 04-Mar-2026 00:00:00 | H44: 04-Mar-2026 11:00:00 | I44: NA | J44: N | K44: =ROUNDUP((D44/4999.99)*10,-1) -> 90 | L44: =IF(J44="N",0,K44) -> 0 | M44: P - QE:16, MAINTENANCE DONE AS PER HEPPM CHECKLIST ATTACHED
A45: 24 | B45: IKN400204 | C45: Aspirators | D45: =VLOOKUP(B45,[14]AssetDetails_UEM!$A$3:$X$1848,22,FALSE) -> 10705 | E45: IKNWOBE26003392 | F45: 09WJ126 | G45: 05-Mar-2026 00:00:00 | H45: 05-Mar-2026 15:15:00 | I45: NA | J45: N | K45: =ROUNDUP((D45/4999.99)*10,-1) -> 30 | L45: =IF(J45="N",0,K45) -> 0 | M45: M,QE:16-PPM DONE AS PERCHECKLIST
A46: 25 | B46: IKN400334 | C46: Infusion Pumps, General-Purpose | D46: =VLOOKUP(B46,[14]AssetDetails_UEM!$A$3:$X$1848,22,FALSE) -> 10825 | E46: IKNWOBE26003393 | F46: 07WF121 | G46: 46086 | H46: 10-Mar-2026 11:00:00 | I46: 46093 | J46: N | K46: =ROUNDUP((D46/4999.99)*10,-1) -> 30 | L46: =IF(J46="N",0,K46) -> 0 | M46: P - (ASSET IN USE) PPM HAS BEEN COMPLETED AS PER HEPPM CHECKLIST
A47: 26 | B47: IKN400364 | C47: Infusion Pumps, Syringe | D47: =VLOOKUP(B47,[14]AssetDetails_UEM!$A$3:$X$1848,22,FALSE) -> 10225 | E47: IKNWOBE26003394 | F47: 07WE113 | G47: 46086 | H47: 09-Mar-2026 14:00:00 | I47: 46093 | J47: N | K47: =ROUNDUP((D47/4999.99)*10,-1) -> 30 | L47: =IF(J47="N",0,K47) -> 0 | M47: P - (ASSET IN USE) PPM HAS BEEN COMPLETED AS PER HEPPM CHECKLIST
A48: 27 | B48: IKN400450 | C48: Mattress Systems, Alternating-Pressure | D48: =VLOOKUP(B48,[14]AssetDetails_UEM!$A$3:$X$1848,22,FALSE) -> 28630 | E48: IKNWOBE26003395 | F48: 06WC113 | G48: 05-Mar-2026 00:00:00 | H48: 05-Mar-2026 14:00:00 | I48: NA | J48: N | K48: =ROUNDUP((D48/4999.99)*10,-1) -> 60 | L48: =IF(J48="N",0,K48) -> 0 | M48: M,QE:16-PPM DONE AS PERCHECKLIST
A49: 28 | B49: IKN400451 | C49: Mattress Systems, Alternating-Pressure | D49: =VLOOKUP(B49,[14]AssetDetails_UEM!$A$3:$X$1848,22,FALSE) -> 28630 | E49: IKNWOBE26003396 | F49: 06WC113 | G49: 05-Mar-2026 00:00:00 | H49: 05-Mar-2026 12:00:00 | I49: NA | J49: N | K49: =ROUNDUP((D49/4999.99)*10,-1) -> 60 | L49: =IF(J49="N",0,K49) -> 0 | M49: M,QE:16-PPM DONE AS PERCHECKLIST
...

Sheet B4-UPTIME
A1: MINISTRY OF HEALTH
A2: Deduction Mapping Report Biomedical Engineering Maintenance Services (BEMS)
A3: INDICATOR B.4 UPTIME GUARANTEE
B5: HOSPITAL NAME : | C5: INSTITUT KANSER NEGARA | N5: MONTH/YEAR : | U5: 46082
B7: STATE : | C7: WILAYAH PERSEKUTUAN PUTRAJAYA | N7: BEMS MONTHLY FEE (RM)@ 97.5% : | U7: =[13]BEMSdar!E11 -> 1437864.8
B9: COMPANY : | C9: AMBANG WIRA SDN BHD | N9: FMS MONTHLY FEE (RM) @ 2.5% : | U9: =[13]BEMSdar!E13 -> 36868.327
A11: Notes:
A12: 1) Deduction Ringgit Equivalent is based on Appendix 11 of the Agreement, Section B3 Key Deduction Indicators for BEMS
A13: 2) Deduction Value for 1st cut off is Deduction Ringgit Equivalent (per event)
A14: 3) Deduction Value for 2nd cut off is Deduction Ringgit Equivalent (per event) multiply by 2
A15: 4) Display only asset affected by deduction
A17: No. | B17: Asset No | C17: Type Code | D17: Type Description | E17: Asset Purchase cost (RM) | F17: Asset Age | G17: TRKPI % | H17: Uptime % | T17: Deduction Ringgit Equivalent (RM) | U17: Previous Deduction (Month) | W17: Deduction for the month (Y/N) | Y17: Deduction Value (RM) | AA17: Total Deduction (RM) | AB17: Remarks
H18: Jan | I18: Feb | J18: Mar | K18: Apr | L18: May | M18: Jun | N18: Jul | O18: Aug | P18: Sep | Q18: Oct | R18: Nov | S18: Dec | U18: 1st | V18: 2nd | W18: 1st | X18: 2nd | Y18: 1st | Z18: 2nd
A19: 1 | B19: IKN400440 | C19: 16-173 | D19: Sphygmomanometers, Electronic, Automatic | E19: 4510 | F19: 13 | G19: 88 | H19: 99.82733 | I19: 99.78 | J19: - | T19: =ROUNDUP((E19/4999.99)*10,-1) -> 10 | U19: N | V19: N | W19: N | X19: N | Y19: =IF(W19="Y",T19,0) -> 0 | Z19: =IF(X19="Y",T19*2,0) -> 0 | AA19: =Y19+Z19 -> 0
A20: 2 | B20: IKN400645 | C20: 13-215 | D20: Infusion Pumps, General-Purpose | E20: 10825 | F20: 13 | G20: 88 | H20: 99.961971 | I20: 99.93 | J20: - | T20: =ROUNDUP((E20/4999.99)*10,-1) -> 30 | U20: N | V20: N | W20: N | X20: N | Y20: =IF(W20="Y",T20,0) -> 0 | Z20: =IF(X20="Y",T20*2,0) -> 0 | AA20: =Y20+Z20 -> 0
A21: 3 | B21: IKN401714 | C21: 13-215 | D21: Infusion Pumps, General-Purpose | E21: 5800 | F21: 8 | G21: 95 | H21: 99.962034 | I21: 99.93 | J21: - | T21: =ROUNDUP((E21/4999.99)*10,-1) -> 20 | U21: Y | V21: Y | W21: N | X21: N | Y21: =IF(W21="Y",T21,0) -> 0 | Z21: =IF(X21="Y",T21*2,0) -> 0 | AA21: =Y21+Z21 -> 0
A22: 4 | B22: IKN400446 | C22: 13-215 | D22: Infusion Pumps, General-Purpose | E22: 10825 | F22: 13 | G22: 88 | H22: 99.65 | I22: 99.68 | J22: 98.553172 | T22: =ROUNDUP((E22/4999.99)*10,-1) -> 30 | U22: N | V22: N | W22: N | X22: N | Y22: =IF(W22="Y",T22,0) -> 0 | Z22: =IF(X22="Y",T22*2,0) -> 0 | AA22: =Y22+Z22 -> 0
A23: 5 | B23: IKN400366 | C23: 13-215 | D23: Infusion Pumps, General-Purpose | E23: 10825 | F23: 13 | G23: 88 | H23: 99.65 | I23: 99.68 | J23: 99.330998 | T23: =ROUNDUP((E23/4999.99)*10,-1) -> 30 | U23: N | V23: N | W23: N | X23: N | Y23: =IF(W23="Y",T23,0) -> 0 | Z23: =IF(X23="Y",T23*2,0) -> 0 | AA23: =Y23+Z23 -> 0
A24: 6 | B24: IKN402165 | C24: 13-215 | D24: Infusion Pumps, General-Purpose | E24: 10825 | F24: 13 | G24: 88 | H24: 99.65 | I24: 99.45 | J24: - | T24: =ROUNDUP((E24/4999.99)*10,-1) -> 30 | U24: N | V24: N | W24: N | X24: N | Y24: =IF(W24="Y",T24,0) -> 0 | Z24: =IF(X24="Y",T24*2,0) -> 0 | AA24: =Y24+Z24 -> 0
A25: 7 | B25: IKN400565 | C25: 12-649 | D25: Physiologic Monitoring Systems, Stress Exercise | E25: 138350 | F25: 13 | G25: 88 | H25: 99.65 | I25: 99.56 | J25: - | T25: =ROUNDUP((E25/4999.99)*10,-1) -> 280 | U25: N | V25: N | W25: N | X25: N | Y25: =IF(W25="Y",T25,0) -> 0 | Z25: =IF(X25="Y",T25*2,0) -> 0 | AA25: =Y25+Z25 -> 0
A26: 8 | B26: IKN400439 | C26: 16-173 | D26: Sphygmomanometers, Electronic, Automatic | E26: 4510 | F26: 13 | G26: 88 | H26: 99.65 | I26: 99.53 | J26: - | T26: =ROUNDUP((E26/4999.99)*10,-1) -> 10 | U26: N | V26: N | W26: N | X26: N | Y26: =IF(W26="Y",T26,0) -> 0 | Z26: =IF(X26="Y",T26*2,0) -> 0 | AA26: =Y26+Z26 -> 0
A27: 9 | B27: IKN401076 | C27: 12-306 | D27: Lavage Units, Surgical | E27: 5000 | F27: 13 | G27: 85 | H27: 99.65 | I27: 99.35 | J27: - | T27: =ROUNDUP((E27/4999.99)*10,-1) -> 20 | U27: N | V27: N | W27: N | X27: N | Y27: =IF(W27="Y",T27,0) -> 0 | Z27: =IF(X27="Y",T27*2,0) -> 0 | AA27: =Y27+Z27 -> 0
A28: 10 | B28: IKN402147 | C28: 15-605 | D28: Testers (Ion Chamber Set) | E28: 142000 | F28: 4 | G28: 96 | H28: 99.65 | I28: 99.39 | J28: - | T28: =ROUNDUP((E28/4999.99)*10,-1) -> 290 | U28: N | V28: N | W28: N | X28: N | Y28: =IF(W28="Y",T28,0) -> 0 | Z28: =IF(X28="Y",T28*2,0) -> 0 | AA28: =Y28+Z28 -> 0
A29: 11 | B29: IKN401071 | C29: 18-034 | D29: Video Image Processors, Endoscopic | E29: 80000 | F29: 13 | G29: 88 | H29: 99.65 | I29: 99.35 | J29: - | T29: =ROUNDUP((E29/4999.99)*10,-1) -> 170 | U29: Y | V29: Y | W29: N | X29: N | Y29: =IF(W29="Y",T29,0) -> 0 | Z29: =IF(X29="Y",T29*2,0) -> 0 | AA29: =Y29+Z29 -> 0
A30: 12 | B30: IKN402081 | C30: 13-215 | D30: Infusion Pumps, General-Purpose | E30: 3500 | F30: 5 | G30: 95 | H30: 99.65 | I30: 99.68 | J30: 99.330998 | T30: =ROUNDUP((E30/4999.99)*10,-1) -> 10 | U30: N | V30: N | W30: N | X30: N | Y30: =IF(W30="Y",T30,0) -> 0 | Z30: =IF(X30="Y",T30*2,0) -> 0 | AA30: =Y30+Z30 -> 0
A31: 13 | B31: IKN401353 | C31: 11-758 | D31: Radiographic/Fluoroscopic Units, Mobile | E31: 399000 | F31: 10 | G31: 88 | H31: 99.65 | I31: - | J31: - | T31: =ROUNDUP((E31/4999.99)*10,-1) -> 800 | U31: N | V31: N | W31: N | X31: N | Y31: =IF(W31="Y",T31,0) -> 0 | Z31: =IF(X31="Y",T31*2,0) -> 0 | AA31: =Y31+Z31 -> 0
A32: 14 | B32: IKN400422 | C32: 13-215 | D32: Infusion Pumps, General-Purpose | E32: 10825 | F32: 13 | G32: 88 | H32: 99.65 | I32: 99.68 | J32: 99.330998 | T32: =ROUNDUP((E32/4999.99)*10,-1) -> 30 | U32: Y | V32: N | W32: N | X32: N | Y32: =IF(W32="Y",T32,0) -> 0 | Z32: =IF(X32="Y",T32*2,0) -> 0 | AA32: =Y32+Z32 -> 0
A33: 15 | B33: IKN400482 | C33: 13-215 | D33: Infusion Pumps, General-Purpose | E33: 10825 | F33: 13 | G33: 88 | H33: 99.65 | I33: 99.61 | J33: - | T33: =ROUNDUP((E33/4999.99)*10,-1) -> 30 | U33: N | V33: N | W33: N | X33: N | Y33: =IF(W33="Y",T33,0) -> 0 | Z33: =IF(X33="Y",T33*2,0) -> 0 | AA33: =Y33+Z33 -> 0
A34: 16 | B34: IKN400782 | C34: 17-679 | D34: Laser Imagers | E34: 83100 | F34: 13 | G34: 85 | H34: 99.65 | I34: 99.51 | J34: - | T34: =ROUNDUP((E34/4999.99)*10,-1) -> 170 | U34: N | V34: N | W34: N | X34: N | Y34: =IF(W34="Y",T34,0) -> 0 | Z34: =IF(X34="Y",T34*2,0) -> 0 | AA34: =Y34+Z34 -> 0
A35: 17 | B35: IKN400653 | C35: 16-173 | D35: Sphygmomanometers, Electronic, Automatic | E35: 4510 | F35: 12 | G35: 88 | H35: - | I35: 99.8 | J35: 99.385529 | T35: =ROUNDUP((E35/4999.99)*10,-1) -> 10 | U35: N | V35: N | W35: N | X35: N | Y35: =IF(W35="Y",T35,0) -> 0 | Z35: =IF(X35="Y",T35*2,0) -> 0 | AA35: =Y35+Z35 -> 0
A36: 18 | B36: IKN400171 | C36: 17-429 | D36: Ventilators, Intensive Care | E36: 151560 | F36: 12 | G36: 88 | H36: - | I36: 99.78 | J36: 99.425417 | T36: =ROUNDUP((E36/4999.99)*10,-1) -> 310 | U36: N | V36: N | W36: N | X36: N | Y36: =IF(W36="Y",T36,0) -> 0 | Z36: =IF(X36="Y",T36*2,0) -> 0 | AA36: =Y36+Z36 -> 0
A37: 19 | B37: IKN400168 | C37: 17-429 | D37: Ventilators, Intensive Care | E37: 151560 | F37: 12 | G37: 88 | H37: - | I37: 99.9 | J37: 99.550176 | T37: =ROUNDUP((E37/4999.99)*10,-1) -> 310 | U37: Y | V37: Y | W37: N | X37: N | Y37: =IF(W37="Y",T37,0) -> 0 | Z37: =IF(X37="Y",T37*2,0) -> 0 | AA37: =Y37+Z37 -> 0
A38: 20 | B38: IKN402184 | C38: 12-647 | D38: Physiologic Monitoring Systems, Acute Care | E38: 100000 | F38: 2 | G38: 99 | H38: - | I38: - | J38: 99.677138 | T38: =ROUNDUP((E38/4999.99)*10,-1) -> 210 | U38: N | V38: N | W38: N | X38: N | Y38: =IF(W38="Y",T38,0) -> 0 | Z38: =IF(X38="Y",T38*2,0) -> 0 | AA38: =Y38+Z38 -> 0
A39: 21 | B39: IKN400787 | C39: 13-272 | D39: Radiographic Units, Mobile | E39: 1149550 | F39: 13 | G39: 88 | H39: - | I39: - | J39: 99.824328 | T39: =ROUNDUP((E39/4999.99)*10,-1) -> 2300 | U39: N | V39: N | W39: N | X39: N | Y39: =IF(W39="Y",T39,0) -> 0 | Z39: =IF(X39="Y",T39*2,0) -> 0 | AA39: =Y39+Z39 -> 0
A40: 22 | B40: IKN400937 | C40: 16-173 | D40: Sphygmomanometers, Electronic, Automatic | E40: 336 | F40: 13 | G40: 88 | H40: - | I40: - | J40: 99.916396 | T40: =ROUNDUP((E40/4999.99)*10,-1) -> 10 | U40: Y | V40: N | W40: N | X40: N | Y40: =IF(W40="Y",T40,0) -> 0 | Z40: =IF(X40="Y",T40*2,0) -> 0 | AA40: =Y40+Z40 -> 0
A41: 23 | B41: IKN401007 | C41: 15-999 | D41: Washers, Flexible Endoscope | E41: 126300 | F41: 13 | G41: 85 | H41: - | I41: - | J41: 99.925846 | T41: =ROUNDUP((E41/4999.99)*10,-1) -> 260 | U41: N | V41: N | W41: N | X41: N | Y41: =IF(W41="Y",T41,0) -> 0 | Z41: =IF(X41="Y",T41*2,0) -> 0 | AA41: =Y41+Z41 -> 0
A42: 24 | B42: IKN400293 | C42: 17-148 | D42: Oximeters, Pulse | E42: 5410 | F42: 13 | G42: 88 | H42: - | I42: - | J42: 99.935425 | T42: =ROUNDUP((E42/4999.99)*10,-1) -> 20 | U42: Y | V42: N | W42: N | X42: N
A43: 25 | B43: IKN400029 | C43: 12-647 | D43: Physiologic Monitoring Systems, Acute Care | E43: 105850 | F43: 13 | G43: 88 | H43: - | I43: - | J43: 99.946764 | T43: =ROUNDUP((E43/4999.99)*10,-1) -> 220 | U43: N | V43: N | W43: N | X43: N | Y43: =IF(W43="Y",T43,0) -> 0 | Z43: =IF(X43="Y",T43*2,0) -> 0 | AA43: =Y43+Z43 -> 0
A44: 26 | B44: IKN400722 | C44: 15-104 | D44: Analyzers, Laboratory, Hematology, Platelet Aggregation | E44: 42100 | F44: 13 | G44: 85 | H44: - | I44: - | J44: 99.981897 | T44: =ROUNDUP((E44/4999.99)*10,-1) -> 90 | U44: N | V44: N | W44: N | X44: N | Y44: =IF(W44="Y",T44,0) -> 0 | Z44: =IF(X44="Y",T44*2,0) -> 0 | AA44: =Y44+Z44 -> 0
A45: TOTAL DEDUCTION FOR IND. B.4: | AA45: =SUM(AA19:AA34) -> 0
...

Sheet B5-T&C
A1: MINISTRY OF HEALTH
A2: Deduction Mapping Report Biomedical Engineering Maintenance Services (BEMS)
A3: INDICATOR B.5 TESTING & COMMISSIONING AND WARRANTY MANAGEMENT
B5: HOSPITAL NAME : | C5: INSTITUT KANSER NEGARA | I5: MONTH/YEAR : | K5: 46082
B7: STATE : | C7: WILAYAH PERSEKUTUAN PUTRAJAYA | I7: BEMS MONTHLY FEE (RM) @ 97.5% : | K7: =BEMSdar!E11 -> 1329813.2
B9: COMPANY : | C9: AMBANG WIRA SDN BHD | I9: FMS MONTHLY FEE (RM) @ 2.5% : | K9: =BEMSdar!E13 -> 34097.773
A11: Notes:
A12: 1) Deduction Ringgit Equivalent is based on Appendix 11 of the Agreement, Section B3 Key Deduction Indicators for BEMS
A13: 2) Deduction Value is Deduction Ringgit Equivalent (per event)
A14: 3) Display only asset affected by deduction
A15: 4) *May not be applicable for unregistered asset
A16: 5) **Only applicable for under warranty management deduction
A18: No | B18: Work Order/ NCR | C18: Work Order/ NCR Date | D18: Work Order/ NCR Reference No. | E18: Work Order/ NCR Description | F18: User Location | G18: T&C Date | H18: Completion Date | I18: Asset Number* | J18: Asset Description | K18: Warranty Expiry Date** | L18: Asset Purchase Price (RM) | M18: Deduction Ringgit Equivalent (RM) | N18: Validate Status (Y/N) | O18: Deduction Value (RM) | P18: Remarks
A19: Work Order Close
A20: 1 | B20: Testing and Commissioning (T&C) | C20: 46087.417 | D20: IKNWIBE26004418 | E20: TNC - T&C LIGHT SOURCE | F20: 05OT129 | G20: 46083 | H20: 46083 | I20: IKN402265 | J20: LIGHT SOURCE, FIBEROPTIC | K20: 46447 | L20: 35000 | M20: - | N20: N | O20: - | P20: 1 YEAR WARRANTY UMMI SURGICAL SDN BHD
A21: TOTAL DEDUCTION FOR IND. B.5: | O21: =SUM(O20:O20) -> 0 | P21: -

Sheet Sheet1
A3: Equipments | B3: Group | C3: Operating Hours | D3: Operating Hours/WK (Days) | E3: Uptime Equipment | F3: Uptime Equipment | G3: Uptime Equipment
E4: < 5YRS | F4: 5-10 YRS | G4: >10 YRS
A5: Therapeutics
A6: Alternating Pressure Mattress | B6: P | C6: 12 | D6: 6 | E6: 0.96 | F6: 0.92 | G6: 0.85
A7: Aneasthesia Units and Vaporizers | B7: C | C7: 24 | D7: 7 | E7: 0.99 | F7: 0.95 | G7: 0.88
A8: Aneasthesia Ventilators | B8: C | C8: 24 | D8: 7 | E8: 0.99 | F8: 0.95 | G8: 0.88
A9: Aspirators | B9: C | C9: 24 | D9: 7 | E9: 0.99 | F9: 0.95 | G9: 0.88
A10: Defibrillators | B10: C | C10: 24 | D10: 7 | E10: 0.99 | F10: 0.95 | G10: 0.88
A11: Dental Equipment | B11: P | C11: 24 | D11: 7 | E11: 0.96 | F11: 0.92 | G11: 0.85
A12: Diathermy Units | B12: C | C12: 24 | D12: 7 | E12: 0.99 | F12: 0.95 | G12: 0.88
A13: Electrosurgical Units | B13: C | C13: 24 | D13: 7 | E13: 0.99 | F13: 0.95 | G13: 0.88
A14: Heamodialysis Units | B14: C | C14: 24 | D14: 7 | E14: 0.99 | F14: 0.95 | G14: 0.88
A15: Humidifiers | B15: C | C15: 24 | D15: 7 | E15: 0.99 | F15: 0.95 | G15: 0.88
A16: Hypo/hyperthermia Units | B16: C | C16: 24 | D16: 7 | E16: 0.99 | F16: 0.95 | G16: 0.88
A17: Incubators | B17: C | C17: 24 | D17: 7 | E17: 0.99 | F17: 0.95 | G17: 0.88
... A59: Vector Cardiographs | B59: P | C59: 12 | D59: 6 | E59: 0.96 | F59: 0.92 | G59: 0.85
A60: Analysers
A61: · Amino Acid | B61: P | C61: 12 | D61: 6 | E61: 0.96 | F61: 0.92 | G61: 0.85
A62: · Bilirubinometers | B62: P | C62: 12 | D62: 6 | E62: 0.96 | F62: 0.92 | G62: 0.85
A63: · Blood Gas | B63: P | C63: 12 | D63: 6 | E63: 0.96 | F63: 0.92 | G63: 0.85
A64: · Calcium | B64: P | C64: 12 | D64: 6 | E64: 0.96 | F64: 0.92 | G64: 0.85
A65: · Clinical Chemistry | B65: P | C65: 12 | D65: 6 | E65: 0.96 | F65: 0.92 | G65: 0.85
A66: · Coagulation | B66: P | C66: 12 | D66: 6 | E66: 0.96 | F66: 0.92 | G66: 0.85
A67: · Counter, Gamma | B67: P | C67: 12 | D67: 6 | E67: 0.96 | F67: 0.92 | G67: 0.85
A68: · Electrolyte | B68: P | C68: 12 | D68: 6 | E68: 0.96 | F68: 0.92 | G68: 0.85
A69: · Immunoassay | B69: P | C69: 12 | D69: 6 | E69: 0.96 | F69: 0.92 | G69: 0.85
A70: · Glucose | B70: P | C70: 12 | D70: 6 | E70: 0.96 | F70: 0.92 | G70: 0.85
A71: · Hematology | B71: P | C71: 12 | D71: 6 | E71: 0.96 | F71: 0.92 | G71: 0.85
A72: · Platelet Aggregation | B72: P | C72: 12 | D72: 6 | E72: 0.96 | F72: 0.92 | G72: 0.85
... A84: Spectrophotometers | B84: P | C84: 12 | D84: 6 | E84: 0.96 | F84: 0.92 | G84: 0.85

Sheet Sheet2
A4: No | B4: Asset No | C4: Asset Description | D4: Asset Purchase Price (RM) | E4: Work Order No. | G4: User Location | H4: Work Order/ Complaint Details | I4: Response Category (Emergency/ Normal) | J4: Total Response Time (minutes) | K4: Work Request Date | L4: Work Completion Date | M4: Deduction Ringgit Equivalent (RM) | N4: Indicator B.1 | Q4: Indicator B.2 | W4: Contract
F5: wo | N5: Validate Status (Y/N) | O5: Deduction Value (RM) | P5: Remarks/ Exemption | Q5: Validate Status (Y/N) | R5: Total Repair Time (day) | S5: Last date of 7 working days (dd/mm/yy) | T5: Demerit Point | U5: Deduction Value (RM) | V5: Remarks/ Exemption | X5: Total Repair Time (day) | Y5: Hours | Z5: Total Hours | AA5: Total Hours / Year | AB5: Balance Uptime | AC5: Uptime Percentage | AD5: Uptime TRKPI | AE5: Uptime Deduction Yes / No
A6: 23 | B6: IKN400966 | C6: LINEAR ACCELERATOR | D6: 12049370 | E6: 1811 | G6: RT159 | H6: Lazer Double | I6: Normal | J6: 0.010416667 | K6: 43781 | L6: 43795 | M6: =IF(D6>44999.99,100,ROUNDUP((D6/4999.99)*10,-1)) -> 100 | N6: N | O6: =IF(N6="Y",M6,0) -> 0 | P6: Response On_Time | Q6: N | R6: =L6-K6+1 -> 15 | S6: =WORKDAY(K6,6,tarikhcuti) -> 43789 | T6: =IF(L6>S6,L6-S6,0) -> 6 | U6: =M6*T6 -> 600 | W6: Strands | X6: =R6 -> 15 | Y6: 24 | Z6: =X6*Y6 -> 360 | AA6: 8072 | AB6: =AA6-Z6 -> 7712 | AC6: =AB6/8072 -> 0.95540139 | AD6: 0.92 | AE6: No
A7: 1 | B7: IKN400292 | C7: Infusion Pumps, General-Purpose | D7: 10825 | E7: 1655 | G7: WAD 8A | H7: Infucient Pump-Mesin Problem | I7: Normal | J7: 0.025694444 | K7: 43774 | L7: 43799 | M7: =IF(D7>44999.99,100,ROUNDUP((D7/4999.99)*10,-1)) -> 30 | N7: N | O7: =IF(N7="Y",M7,0) -> 0 | P7: Response On_Time | Q7: Y | R7: =L7-K7+1 -> 26 | S7: =WORKDAY(K7,6,tarikhcuti) -> 43782 | T7: =IF(L7>S7,L7-S7,0) -> 17 | U7: =M7*T7 -> 510 | W7: Strands | X7: =R7 -> 26 | Y7: 24 | Z7: =X7*Y7 -> 624 | AA7: 8072 | AB7: =AA7-Z7 -> 7448 | AC7: =AB7/8072 -> 0.92269574 | AD7: 0.95 | AE7: Yes
A8: =A7+1 -> 2 | B8: IKN400978 | C8: Scanning Systems, Computed Tomography | D8: 3557530 | E8: 1172 | G8: RT | H8: sendingg image from vsim to mosaiq | I8: Normal | J8: 0.020833333 | K8: 43770 | L8: 43782 | M8: =IF(D8>44999.99,100,ROUNDUP((D8/4999.99)*10,-1)) -> 100 | N8: N | O8: =IF(N8="Y",M8,0) -> 0 | P8: Response On_Time | Q8: N | R8: =L8-K8+1 -> 13 | S8: 43763 | T8: =R8 -> 13 | U8: =M8*T8 -> 1300 | W8: Strands | X8: =R8 -> 13 | Y8: 24 | Z8: =X8*Y8 -> 312 | AA8: 8072 | AB8: =AA8-Z8 -> 7760 | AC8: =AB8/8072 -> 0.96134787 | AD8: 0.95 | AE8: No
A9: =A8+1 -> 3 | B9: IKN400973 | C9: Scanning Systems, Computed Tomography | D9: 3557530 | E9: 1173 | G9: RT | H9: sendingg image from vsim to mosaiq | I9: Normal | J9: 0.013888889 | K9: 43770 | L9: 43782 | M9: =IF(D9>44999.99,100,ROUNDUP((D9/4999.99)*10,-1)) -> 100 | N9: N | O9: =IF(N9="Y",M9,0) -> 0 | P9: Response On_Time | Q9: N | R9: =L9-K9+1 -> 13 | S9: 43763 | T9: =R9 -> 13 | U9: =M9*T9 -> 1300 | W9: Strands | X9: =R9 -> 13 | Y9: 24 | Z9: =X9*Y9 -> 312 | AA9: 8072 | AB9: =AA9-Z9 -> 7760 | AC9: =AB9/8072 -> 0.96134787 | AD9: 0.95 | AE9: No
A10: =A9+1 -> 4 | B10: IKN400151 | C10: Mattress Systems, Alternating-Pressure | D10: 28630 | E10: 1449 | G10: WAD 7A | H10: Motor ripple mattress rosak | I10: Normal | J10: 0.027777778 | K10: 43770 | L10: 43775 | M10: =IF(D10>44999.99,100,ROUNDUP((D10/4999.99)*10,-1)) -> 60 | N10: N | O10: =IF(N10="Y",M10,0) -> 0 | P10: Response On_Time | Q10: N | R10: =L10-K10+1 -> 6 | S10: 43774 | T10: =R10 -> 6 | U10: =M10*T10 -> 360 | W10: Strands | X10: =R10 -> 6 | Y10: 24 | Z10: =X10*Y10 -> 144 | AA10: 8072 | AB10: =AA10-Z10 -> 7928 | AC10: =AB10/8072 -> 0.98216056 | AD10: 0.92 | AE10: No
A11: =A10+1 -> 5 | B11: IKN400967 | C11: Linear Accelerators | D11: 12049370 | E11: 1471 | G11: RT | H11: Table verticle movement problem | I11: Normal | J11: 0.065972222 | K11: 43770 | L11: 43773 | M11: =IF(D11>44999.99,100,ROUNDUP((D11/4999.99)*10,-1)) -> 100 | N11: N | O11: =IF(N11="Y",M11,0) -> 0 | P11: Response On_Time | Q11: N | R11: =L11-K11+1 -> 4 | S11: 43775 | T11: =R11 -> 4 | U11: =M11*T11 -> 400 | W11: Strands | X11: =R11 -> 4 | Y11: 24 | Z11: =X11*Y11 -> 96 | AA11: 8072 | AB11: =AA11-Z11 -> 7976 | AC11: =AB11/8072 -> 0.98810704 | AD11: 0.92 | AE11: No
A12: =A11+1 -> 6 | B12: NB 355296 | C12: Mattress Systems, Alternating-Pressure | D12: 28630 | E12: 1476 | G12: WAD 7B | H12: Ripple Mattress tidak boleh pump | I12: Normal | J12: 0.023611111 | K12: 43770 | L12: 43775 | M12: =IF(D12>44999.99,100,ROUNDUP((D12/4999.99)*10,-1)) -> 60 | N12: N | O12: =IF(N12="Y",M12,0) -> 0 | P12: Response On_Time | Q12: N | R12: =L12-K12+1 -> 6 | S12: 43775 | T12: =R12 -> 6 | U12: =M12*T12 -> 360 | W12: #N/A | X12: =R12 -> 6 | Y12: 24 | Z12: =X12*Y12 -> 144 | AA12: 8072 | AB12: =AA12-Z12 -> 7928 | AC12: =AB12/8072 -> 0.98216056 | AD12: 0.92 | AE12: No
A13: =A12+1 -> 7 | B13: IKN400350 | C13: Sphygmomanometers, Electronic, Automatic | D13: 4510 | E13: 1496 | G13: WAD 7B | H13: BP Set warna putih rosak. | I13: Normal | J13: 0.010416667 | K13: 43770 | L13: 43775 | M13: =IF(D13>44999.99,100,ROUNDUP((D13/4999.99)*10,-1)) -> 10 | N13: N | O13: =IF(N13="Y",M13,0) -> 0 | P13: Response On_Time | Q13: N | R13: =L13-K13+1 -> 6 | S13: 43775 | T13: =R13 -> 6 | U13: =M13*T13 -> 60 | W13: Strands | X13: =R13 -> 6 | Y13: 24 | Z13: =X13*Y13 -> 144 | AA13: 8072 | AB13: =AA13-Z13 -> 7928 | AC13: =AB13/8072 -> 0.98216056 | AD13: 0.92 | AE13: No
A14: =A13+1 -> 8 | B14: IKN400775 | C14: Scanning Systems, Ultrasonic, General-Purpose | D14: 1044560 | E14: 1535 | G14: ID | H14: Ultrasound tidak keluar gambar | I14: Normal | J14: 0.017361111 | K14: 43770 | L14: 43773 | M14: =IF(D14>44999.99,100,ROUNDUP((D14/4999.99)*10,-1)) -> 100 | N14: N | O14: =IF(N14="Y",M14,0) -> 0 | P14: Response On_Time | Q14: N | R14: =L14-K14+1 -> 4 | S14: 43776 | T14: =R14 -> 4 | U14: =M14*T14 -> 400 | W14: Strands | X14: =R14 -> 4 | Y14: 24 | Z14: =X14*Y14 -> 96 | AA14: 8072 | AB14: =AA14-Z14 -> 7976 | AC14: =AB14/8072 -> 0.98810704 | AD14: 0.95 | AE14: No
A15: =A14+1 -> 9 | B15: IKN400567 | C15: Cameras, Gamma | D15: 3191750 | E15: 1550 | G15: NM | H15: MEGP detector one collision | I15: Normal | J15: 0.0034722222 | K15: 43770 | L15: 43773 | M15: =IF(D15>44999.99,100,ROUNDUP((D15/4999.99)*10,-1)) -> 100 | N15: N | O15: =IF(N15="Y",M15,0) -> 0 | P15: Response On_Time | Q15: N | R15: =L15-K15+1 -> 4 | S15: 43777 | T15: =R15 -> 4 | U15: =M15*T15 -> 400 | W15: Strands | X15: =R15 -> 4 | Y15: 24 | Z15: =X15*Y15 -> 96 | AA15: 8072 | AB15: =AA15-Z15 -> 7976 | AC15: =AB15/8072 -> 0.98810704 | AD15: 0.92 | AE15: No
A16: =A15+1 -> 10 | B16: IKN400786 | C16: Radiographic/Fluoroscopic Systems, Angiographic/Intervention | D16: 3191750 | E16: 1565 | G16: ID | H16: Request for user training at Radiology Department (Angio) on 23/10/2019. | I16: Normal | J16: 0 | K16: 43770 | L16: 43773 | M16: =IF(D16>44999.99,100,ROUNDUP((D16/4999.99)*10,-1)) -> 100 | N16: N | O16: =IF(N16="Y",M16,0) -> 0 | P16: Response On_Time | Q16: N | R16: =L16-K16+1 -> 4 | S16: 43777 | T16: =R16 -> 4 | U16: =M16*T16 -> 400 | W16: Strands | X16: =R16 -> 4 | Y16: 24 | Z16: =X16*Y16 -> 96 | AA16: 8072 | AB16: =AA16-Z16 -> 7976 | AC16: =AB16/8072 -> 0.98810704 | AD16: 0.92 | AE16: No
U17: =SUM(U6:U16) -> 6090
