Workbook
Name _05_04_2009: #REF!
Name _05_04_2009: #REF!
Name _05_04_2009: #REF!
Name _05_04_2009: #REF!
Name _05_04_2009: #REF!
Name a: '[1]Term Outstanding Payment'!#REF!
Name a: '[1]Term Outstanding Payment'!#REF!
Name a: '[1]Term Outstanding Payment'!#REF!
Name a: '[1]Term Outstanding Payment'!#REF!
Name a: '[1]Term Outstanding Payment'!#REF!
Name AA: #REF!
Name AA: #REF!
Name AA: #REF!
Name AA: #REF!
Name AA: #REF!
Name aaa: #REF!
Name aaa: #REF!
Name aaa: #REF!
Name aaa: #REF!
Name aaa: #REF!
Name aaaaa: #REF!
Name aaaaa: #REF!
Name aaaaa: #REF!
Name aaaaa: #REF!
Name aaaaa: #REF!
Name aaaaaaaaaa: #REF!
Name aaaaaaaaaa: #REF!
Name aaaaaaaaaa: #REF!
Name aaaaaaaaaa: #REF!
Name AAAAAAAAAAAAA: #REF!
Name AAAAAAAAAAAAA: #REF!
Name AAAAAAAAAAAAA: #REF!
Name AAAAAAAAAAAAA: #REF!
Name AAAAAAAAAAAAAAAAAA: #REF!
Name AAAAAAAAAAAAAAAAAA: #REF!
Name AAAAAAAAAAAAAAAAAA: #REF!
Name AAAAAAAAAAAAAAAAAA: #REF!
Name AAAAAAAAAAAAAAAAAAAAA: #REF!
Name AAAAAAAAAAAAAAAAAAAAA: #REF!
Name AAAAAAAAAAAAAAAAAAAAA: #REF!
Name AAAAAAAAAAAAAAAAAAAAA: #REF!
Name AAAAAAAAAAAAAAAAAAAAAAAAAAA: #REF!
Name AAAAAAAAAAAAAAAAAAAAAAAAAAA: #REF!
Name AAAAAAAAAAAAAAAAAAAAAAAAAAA: #REF!
Name AAAAAAAAAAAAAAAAAAAAAAAAAAA: #REF!
Name AAAAAAAAAAAAAAAAAAAAAAAAAAAA: #REF!
Name AAAAAAAAAAAAAAAAAAAAAAAAAAAA: #REF!
Name AAAAAAAAAAAAAAAAAAAAAAAAAAAA: #REF!
Name AAAAAAAAAAAAAAAAAAAAAAAAAAAA: #REF!
Name AAAAAAAAAAAAAAAAAAAAAAAAAAAAAA: #REF!
Name AAAAAAAAAAAAAAAAAAAAAAAAAAAAAA: #REF!
Name AAAAAAAAAAAAAAAAAAAAAAAAAAAAAA: #REF!
Name AAAAAAAAAAAAAAAAAAAAAAAAAAAAAA: #REF!
Name AAAAAAAAAAAAAAAAAAAAAAAAAAAAAAA: #REF!
Name AAAAAAAAAAAAAAAAAAAAAAAAAAAAAAA: #REF!
Name AAAAAAAAAAAAAAAAAAAAAAAAAAAAAAA: #REF!
Name AAAAAAAAAAAAAAAAAAAAAAAAAAAAAAA: #REF!
Name AAAAAAAAAAAAAAAAAAAAAAAAAAAAAAAAA: #REF!
Name AAAAAAAAAAAAAAAAAAAAAAAAAAAAAAAAA: #REF!
Name AAAAAAAAAAAAAAAAAAAAAAAAAAAAAAAAA: #REF!

Sheet KDI
A1: Indicator No. | B1: Indicator | E1: Frequency of Deduction | F1: Biomedical Equipment Purchase Cost (RM) | H1: Deduction Range Value (RM) | J1: Maximum Demerit Point per Work Order
F2: From | G2: To
A3: B.1 | B3: The Company shall respond to the request within the specified time frame | E3: Per event | F3: 0.00 5,000.00 10,000.00 15,000.00 20,000.00 25,000.00 30,000.00 35,000.00 40,000.00 > 45,000.00 | G3: 4,999.99 9,999.99 14,999.99 19,999.99 24,999.99 29,999.99 34,999.99 39,999.99 44,999.99 | H3: 10.00 20.00 30.00 40.00 50.00 60.00 70.00 80.00 90.00 100.00 | J3: 1
A4: B.2 | B4: The Company shall carry out repairs to restore faulty medical equipment to a specified condition when it fails to function as per manufacturer’s specification within seven (7) working days. | E4: Per day | F4: 0.00 5,000.00 10,000.00 15,000.00 20,000.00 25,000.00 30,000.00 35,000.00 40,000.00 > 45,000.00 | G4: 4,999.99 9,999.99 14,999.99 19,999.99 24,999.99 29,999.99 34,999.99 39,999.99 44,999.99 | H4: 10.00 20.00 30.00 40.00 50.00 60.00 70.00 80.00 90.00 100.00 | J4: Number of working days for the month
A5: B.3 | B5: The Company shall carry out scheduled maintenance as per schedule in accordance to the procedure as specified in Agreement. Scheduled maintenance shall include complete safety and performance tests. | E5: Per event | F5: 0.00 5,000.00 10,000.00 15,000.00 20,000.00 25,000.00 30,000.00 35,000.00 40,000.00 45,000.00 | G5: 4,999.99 9,999.99 14,999.99 19,999.99 24,999.99 29,999.99 34,999.99 39,999.99 44,999.99 49,999.99 | H5: 10.00 20.00 30.00 40.00 50.00 60.00 70.00 80.00 90.00 100.00 | J5: 1
F6: For every RM 5,000 increment of equipment cost, an increase of RM10 will be applied subsequently
A7: B.4 | B7: The Company shall ensure biomedical equipment meets the uptime target as set in the Agreement. | E7: Per event | H7: 1st level of Uptime Target (TRKPI) | I7: 2nd level of Uptime Target (80%) | J7: 2
F8: 0.00 5,000.00 10,000.00 15,000.00 20,000.00 25,000.00 30,000.00 35,000.00 40,000.00 45,000.00 | G8: 4,999.99 9,999.99 14,999.99 19,999.99 24,999.99 29,999.99 34,999.99 39,999.99 44,999.99 49,999.99 | H8: 10.00 20.00 30.00 40.00 50.00 60.00 70.00 80.00 90.00 100.00 | I8: 20.00 40.00 60.00 80.00 100.00 120.00 140.00 160.00 180.00 200.00
F9: For every RM 5,000 increment of equipment cost, an increase of RM10 will be applied subsequently for 1st Uptime Target and an increase of RM20 for 2nd Uptime Target will be applied subsequently
A10: B.5 | B10: The Company shall attend and witness T&C and manage biomedical equipment within the warranty period. | E10: Per event | F10: 0.00 5,000.00 10,000.00 15,000.00 20,000.00 25,000.00 30,000.00 35,000.00 40,000.00 45,000.00 | G10: 4,999.99 9,999.99 14,999.99 19,999.99 24,999.99 29,999.99 34,999.99 39,999.99 44,999.99 49,999.99 | H10: 10.00 20.00 30.00 40.00 50.00 60.00 70.00 80.00 90.00 100.00 | J10: 1
F11: For every RM 5,000 increment of equipment cost, an increase of RM10 will be applied subsequently

Sheet Public Holiday
A1: ­
A2: Tarikh | B2: Hari | C2: Cuti | D2: Negeri Berkenaan
A4: 45658 | B4: Rabu | C4: Tahun Baru | D4: Putrajaya
A6: 45686 | B6: Rabu | C6: Tahun Baru Cina | D6: Putrajaya
A8: 45687 | B8: Khamis | C8: Tahun Baru Cina Hari Kedua | D8: Putrajaya
A10: 45689 | B10: Sabtu | C10: Hari Wilayah Persekutuan | D10: Putrajaya
A12: 45699 | B12: Selasa | C12: Hari Thaipusam | D12: Putrajaya
A14: 45734 | B14: Selasa | C14: Hari Nuzul Al-Quran | D14: Putrajaya
A16: 45748 | B16: Selasa | C16: Hari Raya Aidilfitri | D16: Putrajaya
A18: 45749 | B18: Rabu | C18: Hari Raya Aidilfitri Hari Kedua | D18: Putrajaya
A20: 45778 | B20: Khamis | C20: Hari Pekerja | D20: Putrajaya
A22: 45789 | B22: Isnin | C22: Hari Wesak | D22: Putrajaya
A24: 45810 | B24: Isnin | C24: Hari Keputeraan YDP Agong | D24: Putrajaya
A26: 45815 | B26: Sabtu | C26: Hari Raya Haji | D26: Putrajaya
... A42: 46016 | B42: Khamis | C42: Hari Krismas | D42: Putrajaya
A45: * Subject to change (Tertakluk kepada perubahan), TBC - To be confirmed

Sheet BEMSdar
A1: MINISTRY OF HEALTH
A2: Deduction Mapping Report Biomedical Engineering Maintenance Services (BEMS)
D5: HOSPITAL NAME : | E5: Institut Kanser Negara | I5: STATE: | J5: W.P. Putrajaya
D7: MONTH/YEAR : | E7: 46023 | I7: COMPANY: | J7: Ambang Wira Sdn Bhd
A9: MONTHLY SERVICE FEE (RM) : | E9: 1474733.1
A11: BEMS MONTHLY FEE (RM) @ 97.5% : | E11: =97.5%*E9 -> 1437864.8
A13: FMS MONTHLY FEE (RM) @ 2.5% : | E13: =2.5%*E9 -> 36868.327
A17: No | B17: Key Deduction Indicators | I17: Frequency | L17: Deduction Value (RM) | N17: Deduction % | O17: Performance Level (%)
A19: B.1 | B19: All service requests shall be responded by the Company’s trained technical personal within the timeframe as stipulated in the Agreement. | I19: Per event | L19: ='B1&B2 UNSCHEDULED'!O122 -> 40 | N19: 0 | O19: =100-N19 -> 100
A20: B.2 | B20: All unscheduled maintenance works including relevant maintenance calibration, safety tests and functional checks shall be completed within seven (7) working days. | I20: Per day | L20: ='B1&B2 UNSCHEDULED'!U122 -> 2850 | N20: =L20/$E$11% -> 0.19821057 | O20: =100-N20 -> 99.801789
A21: B.3 | B21: Scheduled maintenance shall be carried out as per schedule and according to the procedure as specified in the Agreement. Scheduled maintenance shall include complete safety and performance tests. | I21: Per event | L21: ='B3-SCHEDULED'!L131 -> 800 | N21: =L21/$E$11% -> 0.055638055 | O21: =100-N21 -> 99.944362
A22: B.4 | B22: All biomedical equipment shall be functioning and maintained to ensure uptime target as specified in the TRKPI are met. | I22: Per event | L22: ='B4-UPTIME '!AA35 -> 0 | N22: =L22/$E$11% -> 0 | O22: =100-N22 -> 100
A23: B.5 | B23: T&C and Warranty Management of newly introduced biomedical shall be managed and performed according to the Agreement and related acts, standards and regulations. | I23: Per event | L23: ='B5-T&C'!O21 -> 0 | N23: =L23/$E$11% -> 0 | O23: =100-N23 -> 100
A24: Total | L24: =SUM(L19:M23) -> 3690 | N24: =SUM(N19:N23) -> 0.25384863 | O24: =100-N24 -> 99.746151
C27: Prepared by: | I27: Verified by:
C31: Siti Norsaliana Binti Abu Khalid | I31: Mohd Shahrulnizam bin Tarmizi
C32: Head of BEMS | I32: Facility Manager
C33: Ambang Wira Sdn Bhd- Institut Kanser Negara | I33: Ambang Wira Sdn Bhd- Institut Kanser Negara
C34: Date: | I34: Date:

Sheet B1&B2 UNSCHEDULED
A2: MINISTRY OF HEALTH
A3: Deduction Mapping Report Biomedical Engineering Maintenance Services (BEMS)
A4: INDICATOR B.1 RESPONSE TIME & B.2 REPAIR TIME
A6: HOSPITAL NAME: | C6: INSTITUT KANSER NEGARA | I6: FIRST DATE OF THE MONTH : | M6: 46023 | Q6: (For Calculation)
A8: STATE: | C8: WILAYAH PERSEKUTUAN PUTRAJAYA | I8: LAST DATE OF THE MONTH : | M8: 46053 | Q8: (For Calculation)
A10: COMPANY: | C10: AMBANG WIRA SDN BHD | I10: BEMS MONTHLY FEE (RM) @ 97.5% : | M10: =BEMSdar!E11 -> 1437864.8
A12: MONTH/YEAR: | C12: 46023 | I12: FMS MONTHLY FEE (RM) @ 2.5% : | M12: =BEMSdar!E13 -> 36868.327
A14: Notes:
A15: 1) Deduction Ringgit Equivalent is based on Appendix 11 of the Agreement, Section B3 Key Deduction Indicators for BEMS
A16: 2) Deduction Value for Indicator B.1 is Deduction Ringgit Equivalent (per event)
A17: 3) Total Repair Time includes weekend & public holiday
A18: 4) Demerit Point for Indicator B.2 is calculated based on completion date against request date, less by 7 working days
A19: 5) Deduction Value for Indicator B.2 is Demerit Point multiply by Deduction Ringgit Equivalent
A21: No | B21: Asset No | C21: Asset Description | D21: Asset Purchase Price (RM) | E21: Work Order No. | F21: User Location | G21: Work Order/ Complaint Details | H21: Response Category (Emergency/ Normal) | I21: Total Response Time (minutes) | J21: Work Request Date | K21: Response Time (Minutes) | L21: Work Completion Date | M21: Deduction Ringgit Equivalent (RM) | N21: Indicator B.1 | Q21: Indicator B.2
N22: Validate Status (Y/N) | O22: Deduction Value (RM) | P22: Remarks/ Exemption | Q22: Validate Status (Y/N) | R22: Total Repair Time (day) | S22: Last date of 7 working days (dd/mm/yy) | T22: Demerit Point | U22: Deduction Value (RM) | V22: Remarks/ Exemption
A23: Current Month (Work Order Completed)
A24: 1 | B24: IKN400404 | C24: =VLOOKUP(B24,[13]AssetDetails_UEM!$A$3:$AH$1849,6,FALSE) -> Sphygmomanometers, Electronic, Automatic | D24: =VLOOKUP(B24,[13]AssetDetails_UEM!$A$3:$AK$1849,22,FALSE) -> 4510 | E24: IKNWIBE26000053 | F24: 06WD146 | G24: BP ALARM , CALL FOR SERVICE | H24: Normal | I24: 0 days, 0 hrs, 13 mins | J24: 02-Jan-2026 08:17:00 | K24: 02-Jan-2026 08:30:00 | L24: 08-Jan-2026 11:10:00 | M24: =IF(D24>44999.99,100,ROUNDUP((D24/4999.99)*10,-1)) -> 10 | N24: N | O24: ='[14]B1& B2 UNSCHEDULED'!$O$24 -> 0 | Q24: N | R24: =IF(L24="",AKHIR-J24,L24-J24+1) -> 7.1201389 | S24: =WORKDAY(J24,6,AKHIR) -> 46034 | T24: 0 | U24: =IF(Q24="N",0,M24*T24) -> 0 | V24: P - qe:12,DO PERFORMANCE TEST PASSED , UNIT READY TO USE
A25: 2 | B25: IKN400741 | C25: =VLOOKUP(B25,[13]AssetDetails_UEM!$A$3:$AH$1849,6,FALSE) -> Analyzers, Laboratory, Microbiology, Blood Culture, Automate | D25: =VLOOKUP(B25,[13]AssetDetails_UEM!$A$3:$AK$1849,22,FALSE) -> 342820 | E25: IKNWIBE26000058 | F25: 04LA126 | G25: THERMOMETER OUT OF BATTERY | H25: Normal | I25: 0 days, 0 hrs, 7 mins | J25: 02-Jan-2026 10:33:00 | K25: 02-Jan-2026 10:40:00 | L25: 02-Jan-2026 16:00:00 | M25: =IF(D25>44999.99,100,ROUNDUP((D25/4999.99)*10,-1)) -> 100 | N25: N | O25: ='[14]B1& B2 UNSCHEDULED'!$O$24 -> 0 | Q25: N | R25: =IF(L25="",AKHIR-J25,L25-J25+1) -> 1.2270833 | S25: =WORKDAY(J25,6,AKHIR) -> 46034 | T25: 0 | U25: =IF(Q25="N",0,M25*T25) -> 0 | V25: M-REPLACE NEW BATTERY ,TESTING OKAY AND FUNCTIONING
A26: 3 | B26: IKN400403 | C26: =VLOOKUP(B26,[13]AssetDetails_UEM!$A$3:$AH$1849,6,FALSE) -> Sphygmomanometers, Electronic, Automatic | D26: =VLOOKUP(B26,[13]AssetDetails_UEM!$A$3:$AK$1849,22,FALSE) -> 4510 | E26: IKNWIBE26000069 | F26: 06WD146 | G26: CUFF KOYAK | H26: Normal | I26: 0 days, 0 hrs, 0 mins | J26: 02-Jan-2026 11:30:00 | K26: 02-Jan-2026 11:30:00 | L26: 02-Jan-2026 12:00:00 | M26: =IF(D26>44999.99,100,ROUNDUP((D26/4999.99)*10,-1)) -> 10 | N26: N | O26: ='[14]B1& B2 UNSCHEDULED'!$O$24 -> 0 | Q26: N | R26: =IF(L26="",AKHIR-J26,L26-J26+1) -> 1.0208333 | S26: =WORKDAY(J26,6,AKHIR) -> 46034 | T26: 0 | U26: =IF(Q26="N",0,M26*T26) -> 0 | V26: P-REQUEST FOR LARGE CUFF. TESTING OKAY AND FUNCTIONING
A27: 4 | B27: IKN400262 | C27: =VLOOKUP(B27,[13]AssetDetails_UEM!$A$3:$AH$1849,6,FALSE) -> Oximeters, Pulse | D27: =VLOOKUP(B27,[13]AssetDetails_UEM!$A$3:$AK$1849,22,FALSE) -> 5410 | E27: IKNWIBE26000094 | F27: 08WG113 | G27: MACHINE SPO2 NOT FUNCTIONING / OUT OF BATTERY | H27: Normal | I27: 0 days, 0 hrs, 45 mins | J27: 04-Jan-2026 11:15:00 | K27: 04-Jan-2026 12:00:00 | L27: 04-Jan-2026 13:00:00 | M27: =IF(D27>44999.99,100,ROUNDUP((D27/4999.99)*10,-1)) -> 20 | N27: N | O27: ='[14]B1& B2 UNSCHEDULED'!$O$24 -> 0 | Q27: N | R27: =IF(L27="",AKHIR-J27,L27-J27+1) -> 1.0729167 | S27: =WORKDAY(J27,7,AKHIR) -> 46035 | T27: 0 | U27: =IF(Q27="N",0,M27*T27) -> 0 | V27: M-REPLACE NEW BATTERY .TESTED OKAY AND CAN FUNCTIONING
A28: 5 | B28: IKN400774 | C28: =VLOOKUP(B28,[13]AssetDetails_UEM!$A$3:$AH$1849,6,FALSE) -> Scanning Systems, Computed Tomography | D28: =VLOOKUP(B28,[13]AssetDetails_UEM!$A$3:$AK$1849,22,FALSE) -> 4605710 | E28: IKNWIBE26000163 | F28: 03ID156 | G28: IMAGE UNABLE TO BE SEND TO PACS, SENDING INFO TO RADIMETRIC FAILED | H28: Normal | I28: 0 days, 0 hrs, 15 mins | J28: 05-Jan-2026 11:33:00 | K28: 46027.49 | L28: 05-Jan-2026 12:00:00 | M28: =IF(D28>44999.99,100,ROUNDUP((D28/4999.99)*10,-1)) -> 100 | N28: N | O28: ='[14]B1& B2 UNSCHEDULED'!$O$24 -> 0 | Q28: N | R28: =IF(L28="",AKHIR-J28,L28-J28+1) -> 1.01875 | S28: =WORKDAY(J28,6,AKHIR) -> 46035 | T28: 0 | U28: =IF(Q28="N",0,M28*T28) -> 0 | V28: L- VENDOR COME AND SETTLE REDIMETRIC ISSUE, TESTED OKAY
A29: 6 | B29: IKN400681 | C29: =VLOOKUP(B29,[13]AssetDetails_UEM!$A$3:$AH$1849,6,FALSE) -> Sphygmomanometers, Electronic, Automatic | D29: =VLOOKUP(B29,[13]AssetDetails_UEM!$A$3:$AK$1849,22,FALSE) -> 336 | E29: IKNWIBE26000172 | F29: 04TC127 | G29: CHARGER CABLE FAULTY | H29: Normal | I29: 0 days, 0 hrs, 49 mins | J29: 05-Jan-2026 15:36:00 | K29: 05-Jan-2026 16:25:00 | L29: 12-Jan-2026 16:30:00 | M29: =IF(D29>44999.99,100,ROUNDUP((D29/4999.99)*10,-1)) -> 10 | N29: N | O29: ='[14]B1& B2 UNSCHEDULED'!$O$24 -> 0 | Q29: N | R29: =IF(L29="",AKHIR-J29,L29-J29+1) -> 8.0375 | S29: =WORKDAY(J29,6,AKHIR) -> 46035 | T29: 0 | U29: =IF(Q29="N",0,M29*T29) -> 0 | V29: AN- REPLACE NEW CABLE, UNIT TEST FUNCTIONING IN GOOD CONDITION
A30: 7 | B30: IKN400758 | C30: =VLOOKUP(B30,[13]AssetDetails_UEM!$A$3:$AH$1849,6,FALSE) -> Analyzers, Laboratory, Urine, Automated | D30: =VLOOKUP(B30,[13]AssetDetails_UEM!$A$3:$AK$1849,22,FALSE) -> 36080 | E30: IKNWIBE26000232 | F30: 04LA132 | G30: ALARM LIGHT BLINKING, NOT PROPER SHUTDOWN | H30: Normal | I30: 0 days, 1 hrs, 1 mins | J30: 06-Jan-2026 08:59:00 | K30: 06-Jan-2026 10:00:00 | L30: 06-Jan-2026 10:30:00 | M30: =IF(D30>44999.99,100,ROUNDUP((D30/4999.99)*10,-1)) -> 80 | N30: N | O30: ='[14]B1& B2 UNSCHEDULED'!$O$24 -> 0 | Q30: N | R30: =IF(L30="",AKHIR-J30,L30-J30+1) -> 1.0631944 | S30: =WORKDAY(J30,6,AKHIR) -> 46036 | T30: 0 | U30: =IF(Q30="N",0,M30*T30) -> 0 | V30: AN- RESTART SOFTWARE UNIT (TAUFIQ BEMS)
A31: 8 | B31: IKN400756 | C31: =VLOOKUP(B31,[13]AssetDetails_UEM!$A$3:$AH$1849,6,FALSE) -> Analyzers, Laboratory, Hematology, Coagulation, Automated | D31: =VLOOKUP(B31,[13]AssetDetails_UEM!$A$3:$AK$1849,22,FALSE) -> 105860 | E31: IKNWIBE26000233 | F31: 04LA132 | G31: SAMPLE TUBING MOVING UP WHEN SAMPLE SYRINGE MOVING UPWARD, SAMPLE CAP DEFECT | H31: Normal | I31: 0 days, 0 hrs, 33 mins | J31: 06-Jan-2026 09:27:00 | K31: 06-Jan-2026 10:00:00 | L31: 06-Jan-2026 16:00:00 | M31: =IF(D31>44999.99,100,ROUNDUP((D31/4999.99)*10,-1)) -> 100 | N31: N | O31: ='[14]B1& B2 UNSCHEDULED'!$O$24 -> 0 | Q31: N | R31: =IF(L31="",AKHIR-J31,L31-J31+1) -> 1.2729167 | S31: =WORKDAY(J31,6,AKHIR) -> 46036 | T31: 0 | U31: =IF(Q31="N",0,M31*T31) -> 0 | V31: AN- REPLACE ANOTHER CAP (TAUFIK BEMS)
A32: 9 | B32: IKN401519 | C32: =VLOOKUP(B32,[13]AssetDetails_UEM!$A$3:$AH$1849,6,FALSE) -> Analyzers, Physiologic, Body Composition | D32: =VLOOKUP(B32,[13]AssetDetails_UEM!$A$3:$AK$1849,22,FALSE) -> 9500 | E32: IKNWIBE26000331 | F32: 03DU103 | G32: PERFORM YEARLY CALIBRATION | H32: Normal | I32: 0 days, 0 hrs, 10 mins | J32: 07-Jan-2026 10:00:00 | K32: 46029.424 | L32: 07-Jan-2026 11:40:00 | M32: =IF(D32>44999.99,100,ROUNDUP((D32/4999.99)*10,-1)) -> 20 | N32: N | O32: ='[14]B1& B2 UNSCHEDULED'!$O$24 -> 0 | Q32: N | R32: =IF(L32="",AKHIR-J32,L32-J32+1) -> 1.0694444 | S32: =WORKDAY(J32,6,AKHIR) -> 46037 | T32: 0 | U32: =IF(Q32="N",0,M32*T32) -> 0 | V32: L, QE:16-CALIBRATION DONE BY SIRIM , REFER TO CALIBRATION SERTIFICATION AS ATTACHED
A33: 10 | B33: IKN400877 | C33: =VLOOKUP(B33,[13]AssetDetails_UEM!$A$3:$AH$1849,6,FALSE) -> Concentrators, Oxygen | D33: =VLOOKUP(B33,[13]AssetDetails_UEM!$A$3:$AK$1849,22,FALSE) -> 5000 | E33: IKNWIBE26000332 | F33: 04PC109 | G33: REQ- PERFORMANCE CHECK | H33: Normal | I33: 0 days, 0 hrs, 30 mins | J33: 07-Jan-2026 11:00:00 | K33: 07-Jan-2026 11:30:00 | L33: 07-Jan-2026 12:00:00 | M33: =IF(D33>44999.99,100,ROUNDUP((D33/4999.99)*10,-1)) -> 20 | N33: N | O33: ='[14]B1& B2 UNSCHEDULED'!$O$24 -> 0 | Q33: N | R33: =IF(L33="",AKHIR-J33,L33-J33+1) -> 1.0416667 | S33: =WORKDAY(J33,6,AKHIR) -> 46037 | T33: 0 | U33: =IF(Q33="N",0,M33*T33) -> 0 | V33: AN- PERFORMANCE CHECKING DONE AS PER HEPPM CHECKLIST ATTACHED
A34: 11 | B34: IKN402009 | C34: =VLOOKUP(B34,[13]AssetDetails_UEM!$A$3:$AH$1849,6,FALSE) -> Concentrators, Oxygen | D34: =VLOOKUP(B34,[13]AssetDetails_UEM!$A$3:$AK$1849,22,FALSE) -> 3400 | E34: IKNWIBE26000333 | F34: 04PC109 | G34: REQ- PERFORMANCE CHECK | H34: Normal | I34: 0 days, 0 hrs, 30 mins | J34: 07-Jan-2026 11:00:00 | K34: 07-Jan-2026 11:30:00 | L34: 07-Jan-2026 12:00:00 | M34: =IF(D34>44999.99,100,ROUNDUP((D34/4999.99)*10,-1)) -> 10 | N34: N | O34: ='[14]B1& B2 UNSCHEDULED'!$O$24 -> 0 | Q34: N | R34: =IF(L34="",AKHIR-J34,L34-J34+1) -> 1.0416667 | S34: =WORKDAY(J34,6,AKHIR) -> 46037 | T34: 0 | U34: =IF(Q34="N",0,M34*T34) -> 0 | V34: AN- PERFORMANCE CHECKING DONE AS PER HEPPM CHECKLIST ATTACHED (ST BEMS TAUFIK)
A35: 12 | B35: IKN400950 | C35: =VLOOKUP(B35,[13]AssetDetails_UEM!$A$3:$AH$1849,6,FALSE) -> Monitors, Physiologic, Vital Signs | D35: =VLOOKUP(B35,[13]AssetDetails_UEM!$A$3:$AK$1849,22,FALSE) -> 18765 | E35: IKNWIBE26000407 | F35: 03MC107 | G35: BATTERY DEPLATED | H35: Normal | I35: 0 days, 3 hrs, 30 mins | J35: 08-Jan-2026 14:00:00 | K35: 08-Jan-2026 17:30:00 | L35: 08-Jan-2026 19:00:00 | M35: =IF(D35>44999.99,100,ROUNDUP((D35/4999.99)*10,-1)) -> 40 | N35: Y | O35: =M35 -> 40 | Q35: N | R35: =IF(L35="",AKHIR-J35,L35-J35+1) -> 1.2083333 | S35: =WORKDAY(J35,6,AKHIR) -> 46038 | T35: 0 | U35: =IF(Q35="N",0,M35*T35) -> 0 | V35: M-REPLACE NEW BATTERY ,TESTED OKAY AND FUNCTIONING
A36: 13 | B36: IKN400289 | C36: =VLOOKUP(B36,[13]AssetDetails_UEM!$A$3:$AH$1849,6,FALSE) -> Infusion Pumps, General-Purpose | D36: =VLOOKUP(B36,[13]AssetDetails_UEM!$A$3:$AK$1849,22,FALSE) -> 10825 | E36: IKNWIBE26000411 | F36: 08WH121 | G36: CHARGER ADPTER BROKEN | H36: Normal | I36: 0 days, 0 hrs, 23 mins | J36: 08-Jan-2026 16:02:00 | K36: 08-Jan-2026 16:25:00 | L36: 15-Jan-2026 16:00:00 | M36: =IF(D36>44999.99,100,ROUNDUP((D36/4999.99)*10,-1)) -> 30 | N36: N | O36: ='[14]B1& B2 UNSCHEDULED'!$O$24 -> 0 | Q36: N | R36: =IF(L36="",AKHIR-J36,L36-J36+1) -> 7.9986111 | S36: =WORKDAY(J36,6,AKHIR) -> 46038 | T36: 0 | U36: =IF(Q36="N",0,M36*T36) -> 0 | V36: M-REPLACE NEW CHARGER ADPATER.TESTED MACHINE PASSED. (8/1/2026-16:25 UNTILL 15/1/2026-16:00)
A37: 14 | B37: IKN401010 | C37: =VLOOKUP(B37,[13]AssetDetails_UEM!$A$3:$AH$1849,6,FALSE) -> Gastroscopes, Flexible, Video | D37: =VLOOKUP(B37,[13]AssetDetails_UEM!$A$3:$AK$1849,22,FALSE) -> 118230 | E37: IKNWIBE26000477 | F37: IKN401010 | G37: WIPER NOT FUNCTIONING- MDC ARAS 3 | H37: Normal | I37: 0 days, 0 hrs, 10 mins | J37: 09-Jan-2026 10:00:00 | K37: 46031.424 | L37: 46035.625 | M37: =IF(D37>44999.99,100,ROUNDUP((D37/4999.99)*10,-1)) -> 100 | N37: N | O37: ='[14]B1& B2 UNSCHEDULED'!$O$24 -> 0 | Q37: N | R37: =IF(L37="",AKHIR-J37,L37-J37+1) -> 5.2083333 | S37: =WORKDAY(J37,6,AKHIR) -> 46041 | T37: 13 | U37: =IF(Q37="N",0,M37*T37) -> 0 | V37: PARTS CANNOT BE REPAIR. UNDER BER (OBSOLATE PARTS).
A38: 15 | B38: IKN400967 | C38: =VLOOKUP(B38,[13]AssetDetails_UEM!$A$3:$AH$1849,6,FALSE) -> Linear Accelerators | D38: =VLOOKUP(B38,[13]AssetDetails_UEM!$A$3:$AK$1849,22,FALSE) -> 12049370 | E38: IKNWIBE26000586 | F38: 01RT165 | G38: VACUUM TARGET VALUE BELOW 5.5 | H38: Normal | I38: 0 days, 0 hrs, 20 mins | J38: 12-Jan-2026 08:10:00 | K38: 12-Jan-2026 08:30:00 | L38: 13-Jan-2026 09:15:00 | M38: =IF(D38>44999.99,100,ROUNDUP((D38/4999.99)*10,-1)) -> 100 | N38: N | O38: ='[14]B1& B2 UNSCHEDULED'!$O$24 -> 0 | Q38: N | R38: =IF(L38="",AKHIR-J38,L38-J38+1) -> 2.0451389 | S38: =WORKDAY(J38,6,AKHIR) -> 46042 | T38: 0 | U38: =IF(Q38="N",0,M38*T38) -> 0 | V38: P - RESET VACUUM CIRCUIT BREAKER 3 TIMES. THE VALUE INCREASE UNTIL 6.2. TESTED OKAY
A39: 16 | B39: IKN400850 | C39: =VLOOKUP(B39,[13]AssetDetails_UEM!$A$3:$AH$1849,6,FALSE) -> Brachytherapy Applicators, Afterloading | D39: =VLOOKUP(B39,[13]AssetDetails_UEM!$A$3:$AK$1849,22,FALSE) -> 3420120 | E39: IKNWIBE26000587 | F39: 01RT243 | G39: HDR CANNOT CONNECT TO CAMERA | H39: Normal | I39: 0 days, 0 hrs, 20 mins | J39: 12-Jan-2026 08:20:00 | K39: 12-Jan-2026 08:40:00 | L39: 12-Jan-2026 09:00:00 | M39: =IF(D39>44999.99,100,ROUNDUP((D39/4999.99)*10,-1)) -> 100 | N39: N | O39: ='[14]B1& B2 UNSCHEDULED'!$O$24 -> 0 | Q39: N | R39: =IF(L39="",AKHIR-J39,L39-J39+1) -> 1.0277778 | S39: =WORKDAY(J39,6,AKHIR) -> 46042 | T39: 0 | U39: =IF(Q39="N",0,M39*T39) -> 0 | V39: P QE:12 - RESET CABLE TO CAMERA, CHECK I.P ADDRESS. UNIT TEST AND FUNCTIONING. ADVICE BY VENDOR THRU CALL
A40: 17 | B40: IKN400493 | C40: =VLOOKUP(B40,[13]AssetDetails_UEM!$A$3:$AH$1849,6,FALSE) -> Defibrillators, External, Manual | D40: =VLOOKUP(B40,[13]AssetDetails_UEM!$A$3:$AK$1849,22,FALSE) -> 45000 | E40: IKNWIBE26000597 | F40: 05WB133 | G40: N/A | H40: Normal | I40: 0 days, 0 hrs, 12 mins | J40: 12-Jan-2026 10:28:00 | K40: 12-Jan-2026 10:40:00 | L40: 12-Jan-2026 11:20:00 | M40: =IF(D40>44999.99,100,ROUNDUP((D40/4999.99)*10,-1)) -> 100 | N40: N | O40: ='[14]B1& B2 UNSCHEDULED'!$O$24 -> 0 | Q40: N | R40: =IF(L40="",AKHIR-J40,L40-J40+1) -> 1.0361111 | S40: =WORKDAY(J40,6,AKHIR) -> 46042 | T40: 0 | U40: =IF(Q40="N",0,M40*T40) -> 0 | V40: L, QE:16-REPLACE NEW ECG 3 LEAD
A41: 18 | B41: IKN400494 | C41: =VLOOKUP(B41,[13]AssetDetails_UEM!$A$3:$AH$1849,6,FALSE) -> Sphygmomanometers, Electronic, Automatic | D41: =VLOOKUP(B41,[13]AssetDetails_UEM!$A$3:$AK$1849,22,FALSE) -> 4510 | E41: IKNWIBE26000756 | F41: 05WB143 | G41: CUFF CONNECTOR BROKEN | H41: Normal | I41: 0 days, 0 hrs, 0 mins | J41: 14-Jan-2026 07:50:00 | K41: 14-Jan-2026 07:50:00 | L41: 14-Jan-2026 09:00:00 | M41: =IF(D41>44999.99,100,ROUNDUP((D41/4999.99)*10,-1)) -> 10 | N41: N | O41: ='[14]B1& B2 UNSCHEDULED'!$O$24 -> 0 | Q41: N | R41: =IF(L41="",AKHIR-J41,L41-J41+1) -> 1.0486111 | S41: =WORKDAY(J41,6,AKHIR) -> 46044 | T41: 0 | U41: =IF(Q41="N",0,M41*T41) -> 0 | V41: L, QE:16-REPLACE NEW CUFF CONNECTOR , UNIT TEST AND FUCTIONING IN GOOD CONDITION
A42: 19 | B42: IKN400967 | C42: =VLOOKUP(B42,[13]AssetDetails_UEM!$A$3:$AH$1849,6,FALSE) -> Linear Accelerators | D42: =VLOOKUP(B42,[13]AssetDetails_UEM!$A$3:$AK$1849,22,FALSE) -> 12049370 | E42: IKNWIBE26000757 | F42: 01RT165 | G42: VACUUM PRESSURE WERE BELOW THE RANGE TARGETED | H42: Normal | I42: 0 days, 0 hrs, 18 mins | J42: 14-Jan-2026 08:47:00 | K42: 14-Jan-2026 09:05:00 | L42: 19-Jan-2026 08:20:00 | M42: =IF(D42>44999.99,100,ROUNDUP((D42/4999.99)*10,-1)) -> 100 | N42: N | O42: ='[14]B1& B2 UNSCHEDULED'!$O$24 -> 0 | Q42: N | R42: =IF(L42="",AKHIR-J42,L42-J42+1) -> 5.98125 | S42: =WORKDAY(J42,6,AKHIR) -> 46044 | T42: 0 | U42: =IF(Q42="N",0,M42*T42) -> 0 | V42: P - PLANNED WITH VENDOR / SUPPLIER FOR PARTS REPLACEMENT
A43: 20 | B43: IKN400308 | C43: =VLOOKUP(B43,[13]AssetDetails_UEM!$A$3:$AH$1849,6,FALSE) -> Defibrillators, External, Manual | D43: =VLOOKUP(B43,[13]AssetDetails_UEM!$A$3:$AK$1849,22,FALSE) -> 45000 | E43: IKNWIBE26000760 | F43: 08WH133 | G43: MACHINE NOT DETECT PATIENT LEAD | H43: Normal | I43: 0 days, 0 hrs, 23 mins | J43: 14-Jan-2026 09:07:00 | K43: 14-Jan-2026 09:30:00 | L43: 14-Jan-2026 11:30:00 | M43: =IF(D43>44999.99,100,ROUNDUP((D43/4999.99)*10,-1)) -> 100 | N43: N | O43: ='[14]B1& B2 UNSCHEDULED'!$O$24 -> 0 | Q43: N | R43: =IF(L43="",AKHIR-J43,L43-J43+1) -> 1.0993056 | S43: =WORKDAY(J43,6,AKHIR) -> 46044 | T43: 0 | U43: =IF(Q43="N",0,M43*T43) -> 0 | V43: L, QE:16-SETTING AND RECALIBRATE UNIT WITH TESTER, TEST PASSED UNIT OBSERVED
A44: 21 | B44: IKN400965 | C44: =VLOOKUP(B44,[13]AssetDetails_UEM!$A$3:$AH$1849,6,FALSE) -> Linear Accelerators | D44: =VLOOKUP(B44,[13]AssetDetails_UEM!$A$3:$AK$1849,22,FALSE) -> 19351760 | E44: IKNWIBE26000763 | F44: 01RT177 | G44: DOSE VALUE LESS THAN EXPECTED CAUSED ERROr BY INCREASE THE DOSE VALVE | H44: Normal | I44: 0 days, 0 hrs, 6 mins | J44: 14-Jan-2026 10:24:00 | K44: 14-Jan-2026 10:30:00 | L44: 15-Jan-2026 08:30:00 | M44: =IF(D44>44999.99,100,ROUNDUP((D44/4999.99)*10,-1)) -> 100 | N44: N | O44: ='[14]B1& B2 UNSCHEDULED'!$O$24 -> 0 | Q44: N | R44: =IF(L44="",AKHIR-J44,L44-J44+1) -> 1.9208333 | S44: =WORKDAY(J44,6,AKHIR) -> 46044 | T44: 0 | U44: =IF(Q44="N",0,M44*T44) -> 0 | V44: M-AFTER TUNING AND MAKE CALIBRATION BY THE MVCT OKAY AND NORMAL.CAN BE AS USUAL
A45: 22 | B45: IKN401034 | C45: =VLOOKUP(B45,[13]AssetDetails_UEM!$A$3:$AH$1849,6,FALSE) -> Physiologic Monitoring Systems, Acute Care | D45: =VLOOKUP(B45,[13]AssetDetails_UEM!$A$3:$AK$1849,22,FALSE) -> 119690 | E45: IKNWIBE26000765 | F45: 05OT123 | G45: CUFF NEED TO REPLACED | H45: Normal | I45: 0 days, 0 hrs, 0 mins | J45: 14-Jan-2026 10:30:00 | K45: 14-Jan-2026 10:30:00 | L45: 14-Jan-2026 11:00:00 | M45: =IF(D45>44999.99,100,ROUNDUP((D45/4999.99)*10,-1)) -> 100 | N45: N | O45: ='[14]B1& B2 UNSCHEDULED'!$O$24 -> 0 | Q45: N | R45: =IF(L45="",AKHIR-J45,L45-J45+1) -> 1.0208333 | S45: =WORKDAY(J45,6,AKHIR) -> 46044 | T45: 0 | U45: =IF(Q45="N",0,M45*T45) -> 0 | V45: L, QE:16-REPLACE NEW CUFF, UNIT TESTE AND FUCTIONING IN GOOD CONDITION
A46: 23 | B46: IKN400404 | C46: =VLOOKUP(B46,[13]AssetDetails_UEM!$A$3:$AH$1849,6,FALSE) -> Sphygmomanometers, Electronic, Automatic | D46: =VLOOKUP(B46,[13]AssetDetails_UEM!$A$3:$AK$1849,22,FALSE) -> 4510 | E46: IKNWIBE26000766 | F46: 06WD146 | G46: CUFF BP LEAKING | H46: Normal | I46: 0 days, 0 hrs, 8 mins | J46: 14-Jan-2026 11:22:00 | K46: 14-Jan-2026 11:30:00 | L46: 14-Jan-2026 13:50:00 | M46: =IF(D46>44999.99,100,ROUNDUP((D46/4999.99)*10,-1)) -> 10 | N46: N | O46: ='[14]B1& B2 UNSCHEDULED'!$O$24 -> 0 | Q46: N | R46: =IF(L46="",AKHIR-J46,L46-J46+1) -> 1.1027778 | S46: =WORKDAY(J46,6,AKHIR) -> 46044 | T46: 0 | U46: =IF(Q46="N",0,M46*T46) -> 0 | V46: L- REPAIR TUBING DO PERFORMANCE TEST PASSED UNIT READY TO USE
A47: 24 | B47: IKN402231 | C47: Physiologic Monitoring Systems, Acute Care | D47: 10200 | E47: IKNWIBE26000788 | F47: 01AE111 | G47: USER REQUEST | H47: Normal | I47: 0 days, 0 hrs, 0 mins | J47: 14-Jan-2026 15:00:00 | K47: 14-Jan-2026 15:00:00 | L47: 14-Jan-2026 17:00:00 | M47: =IF(D47>44999.99,100,ROUNDUP((D47/4999.99)*10,-1)) -> 30 | N47: N | O47: ='[14]B1& B2 UNSCHEDULED'!$O$24 -> 0 | Q47: N | R47: =IF(L47="",AKHIR-J47,L47-J47+1) -> 1.0833333 | S47: =WORKDAY(J47,6,AKHIR) -> 46044 | T47: 0 | U47: =IF(Q47="N",0,M47*T47) -> 0 | V47: L, QE:16-INSTALL THE BASE OF THE PATIENT MONITOR IN THE AMBULANCE, THE PATIENT MONITOR AS TRANSPORT (USE IN THE EMERGENCY AND IN AMBULANCE)
...

Sheet B3-SCHEDULED
A3: MINISTRY OF HEALTH
A4: Deduction Mapping Report Biomedical Engineering Maintenance Services (BEMS)
A5: INDICATOR B.3 SCHEDULED MAINTENANCE
A7: HOSPITAL NAME : | C7: INSTITUT KANSER NEGARA | H7: MONTH/YEAR : | J7: 46023
B9: STATE : | C9: WILAYAH PERSEKUTUAN PUTRAJAYA | G9: BEMS MONTHLY FEE (RM) @ 97.5% : | J9: =[15]BEMSdar!E11 -> 1437864.8
B11: COMPANY : | C11: AMBANG WIRA SDN BHD | G11: FMS MONTHLY FEE (RM) @ 2.5% : | J11: =[15]BEMSdar!E13 -> 36868.327
A13: Notes:
A14: 1) Deduction Ringgit Equivalent is based on Appendix 11 of the Agreement, Section B3 Key Deduction Indicators for BEMS
A15: 2) Deduction Value for Indicator B.3 is Deduction Ringgit Equivalent (per event)
A16: 3) Rescheduled Date is the final rescheduled date if there are multiple rescheduling
A17: 4) Display only asset affected by deduction
A19: No | B19: Asset No | C19: Asset Description | D19: Asset Purchase Price (RM) | E19: Work Order No. | F19: User Location | G19: Scheduled Start Date | H19: Maintenance Date | I19: Rescheduled Date | J19: Validate Status (Y/N) | K19: Deduction Ringgit Equivalent (RM) | L19: Indicator B.3
L20: Deduction Value (RM) | M20: Remarks/ Exemption
A21: Current Month (Closed) | M21: =PROPER(#REF!) -> #REF!
A22: 1 | B22: IKN400803 | C22: Ventilators, Transport | D22: =VLOOKUP(B22,[13]AssetDetails_UEM!$A$3:$X$1848,22,FALSE) -> 60150 | E22: IKNWOBE26000241 | F22: 01RT233 | G22: 13-Jan-2026 00:00:00 | H22: 13-Jan-2026 10:00:00 | I22: NA | J22: N | K22: =ROUNDUP((D22/4999.99)*10,-1) -> 130 | L22: =IF(J22="N",0,K22) -> 0 | M22: L, QE:16-MAINTAINANCE DONE AS PER HEPPM CHECKLIST ATTACHED
A23: 2 | B23: IKN400804 | C23: Intubation Scopes, Flexible Fiberoptic | D23: =VLOOKUP(B23,[13]AssetDetails_UEM!$A$3:$X$1848,22,FALSE) -> 38360 | E23: IKNWOBE26000242 | F23: 05OT169 | G23: 13-Jan-2026 00:00:00 | H23: 13-Jan-2026 12:20:00 | I23: NA | J23: N | K23: =ROUNDUP((D23/4999.99)*10,-1) -> 80 | L23: =IF(J23="N",0,K23) -> 0 | M23: L, QE:16-MAINTAINANCE DONE AS PER HEPPM CHECKLIST ATTACHED
A24: 3 | B24: IKN400805 | C24: Intubation Scopes, Flexible Fiberoptic | D24: =VLOOKUP(B24,[13]AssetDetails_UEM!$A$3:$X$1848,22,FALSE) -> 38575 | E24: IKNWOBE26000243 | F24: 05OT169 | G24: 13-Jan-2026 00:00:00 | H24: 13-Jan-2026 14:10:00 | I24: NA | J24: N | K24: =ROUNDUP((D24/4999.99)*10,-1) -> 80 | L24: =IF(J24="N",0,K24) -> 0 | M24: L, QE:16-MAINTAINANCE DONE AS PER HEPPM CHECKLIST ATTACHED
A25: 4 | B25: IKN401013 | C25: Television Systems, Endoscope | D25: =VLOOKUP(B25,[13]AssetDetails_UEM!$A$3:$X$1848,22,FALSE) -> 10000 | E25: IKNWOBE26000244 | F25: 05OT167 | G25: 13-Jan-2026 00:00:00 | H25: 13-Jan-2026 14:00:00 | I25: NA | J25: N | K25: =ROUNDUP((D25/4999.99)*10,-1) -> 30 | L25: =IF(J25="N",0,K25) -> 0 | M25: L, QE:16-MAINTAINANCE DONE AS PER ROUTINE INSPECTION CHECKLIST ATTACHED
A26: 5 | B26: IKN401014 | C26: Light Sources, Fiberoptic | D26: =VLOOKUP(B26,[13]AssetDetails_UEM!$A$3:$X$1848,22,FALSE) -> 50000 | E26: IKNWOBE26000245 | F26: 05OT167 | G26: 13-Jan-2026 00:00:00 | H26: 13-Jan-2026 14:30:00 | I26: NA | J26: N | K26: =ROUNDUP((D26/4999.99)*10,-1) -> 110 | L26: =IF(J26="N",0,K26) -> 0 | M26: L, QE:16-MAINTAINANCE DONE AS PER HEPPM CHECKLIST ATTACHED
A27: 6 | B27: IKN400541 | C27: Defibrillators, External, Manual | D27: =VLOOKUP(B27,[13]AssetDetails_UEM!$A$3:$X$1848,22,FALSE) -> 45000 | E27: IKNWOBE26000246 | F27: 03WA121 | G27: 13-Jan-2026 00:00:00 | H27: 13-Jan-2026 14:15:00 | I27: NA | J27: N | K27: =ROUNDUP((D27/4999.99)*10,-1) -> 100 | L27: =IF(J27="N",0,K27) -> 0 | M27: L, QE:16-PPM COMPLETE AS PER CHECKLIST UNIT TESTED OKEY
A28: 7 | B28: IKN400841 | C28: Anesthesia Units | D28: =VLOOKUP(B28,[13]AssetDetails_UEM!$A$3:$X$1848,22,FALSE) -> 144345 | E28: IKNWOBE26000247 | F28: 01RT278 | G28: 13-Jan-2026 00:00:00 | H28: 13-Jan-2026 08:00:00 | I28: NA | J28: N | K28: =ROUNDUP((D28/4999.99)*10,-1) -> 290 | L28: =IF(J28="N",0,K28) -> 0 | M28: L, QE:16-MAINTAINANCE DONE AS PER HEPPM CHECKLIST ATTACHED
A29: 8 | B29: IKN400959 | C29: Anesthesia Units | D29: =VLOOKUP(B29,[13]AssetDetails_UEM!$A$3:$X$1848,22,FALSE) -> 144345 | E29: IKNWOBE26000248 | F29: 01RT212 | G29: 13-Jan-2026 00:00:00 | H29: 13-Jan-2026 10:00:00 | I29: NA | J29: N | K29: =ROUNDUP((D29/4999.99)*10,-1) -> 290 | L29: =IF(J29="N",0,K29) -> 0 | M29: L, QE:16-MAINTAINANCE DONE AS PER HEPPM CHECKLIST ATTACHED
A30: 9 | B30: IKN400587 | C30: Defibrillator/Pacemakers, External | D30: =VLOOKUP(B30,[13]AssetDetails_UEM!$A$3:$X$1848,22,FALSE) -> 45000 | E30: IKNWOBE26000251 | F30: 03NM164 | G30: 15-Jan-2026 00:00:00 | H30: 15-Jan-2026 12:00:00 | I30: NA | J30: N | K30: =ROUNDUP((D30/4999.99)*10,-1) -> 100 | L30: =IF(J30="N",0,K30) -> 0 | M30: L, QE:16-PPM COMPLETE AS PER CHECKLIST, UNIT FUCTIONING OKEY
A31: 10 | B31: IKN400777 | C31: Anesthesia Units | D31: =VLOOKUP(B31,[13]AssetDetails_UEM!$A$3:$X$1848,22,FALSE) -> 144345 | E31: IKNWOBE26000252 | F31: 03ID167 | G31: 15-Jan-2026 00:00:00 | H31: 15-Jan-2026 17:30:00 | I31: NA | J31: N | K31: =ROUNDUP((D31/4999.99)*10,-1) -> 290 | L31: =IF(J31="N",0,K31) -> 0 | M31: L, QE:16-MAINTAINANCE DONE AS PER HEPPM CHECKLIST ATTACHED
A32: 11 | B32: IKN401011 | C32: Nasopharyngoscopes | D32: =VLOOKUP(B32,[13]AssetDetails_UEM!$A$3:$X$1848,22,FALSE) -> 59362 | E32: IKNWOBE26000253 | F32: 05OT167 | G32: 15-Jan-2026 00:00:00 | H32: 15-Jan-2026 09:00:00 | I32: NA | J32: N | K32: =ROUNDUP((D32/4999.99)*10,-1) -> 120 | L32: =IF(J32="N",0,K32) -> 0 | M32: L, QE:16-MAINTAINANCE DONE AS PER HEPPM CHECKLIST ATTACHED
A33: 12 | B33: IKN400004 | C33: Electrocardiographs, Multichannel, Interpretative | D33: =VLOOKUP(B33,[13]AssetDetails_UEM!$A$3:$X$1848,22,FALSE) -> 25260 | E33: IKNWOBE26000256 | F33: 01AE110 | G33: 16-Jan-2026 00:00:00 | H33: 46038.688 | I33: NA | J33: N | K33: =ROUNDUP((D33/4999.99)*10,-1) -> 60 | L33: =IF(J33="N",0,K33) -> 0 | M33: MAINTENANCE DONE ACCORDING TO HEPPM CHECKLIST ATTACHED.
A34: 13 | B34: IKN400493 | C34: Defibrillators, External, Manual | D34: =VLOOKUP(B34,[13]AssetDetails_UEM!$A$3:$X$1848,22,FALSE) -> 45000 | E34: IKNWOBE26000257 | F34: 05WB133 | G34: 16-Jan-2026 00:00:00 | H34: 16-Jan-2026 14:30:00 | I34: NA | J34: N | K34: =ROUNDUP((D34/4999.99)*10,-1) -> 100 | L34: =IF(J34="N",0,K34) -> 0 | M34: L, QE:16-MAINTAINANCE DONE AS PER HEPPM CHECKLIST ATTACHED
A35: 14 | B35: IKN400828 | C35: Anesthesia Units | D35: =VLOOKUP(B35,[13]AssetDetails_UEM!$A$3:$X$1848,22,FALSE) -> 144345 | E35: IKNWOBE26000258 | F35: 01RT275 | G35: 16-Jan-2026 00:00:00 | H35: 16-Jan-2026 14:00:00 | I35: NA | J35: N | K35: =ROUNDUP((D35/4999.99)*10,-1) -> 290 | L35: =IF(J35="N",0,K35) -> 0 | M35: L, QE:16-MAINTAINANCE DONE AS PER HEPPM CHECKLIST ATTACHED
A36: 15 | B36: IKN400835 | C36: Electrosurgical Units, Monopolar/Bipolar | D36: =VLOOKUP(B36,[13]AssetDetails_UEM!$A$3:$X$1848,22,FALSE) -> 97190 | E36: IKNWOBE26000259 | F36: 01RT275 | G36: 16-Jan-2026 00:00:00 | H36: 16-Jan-2026 10:00:00 | I36: NA | J36: N | K36: =ROUNDUP((D36/4999.99)*10,-1) -> 200 | L36: =IF(J36="N",0,K36) -> 0 | M36: L, QE:16-MAINTAINANCE DONE AS PER HEPPM CHECKLIST ATTACHED
A37: 16 | B37: IKN402050 | C37: Electrocardiographs, Multichannel, Non-Interpretative | D37: =VLOOKUP(B37,[13]AssetDetails_UEM!$A$3:$X$1848,22,FALSE) -> 12900 | E37: IKNWOBE26000260 | F37: 01AE106 | G37: 16-Jan-2026 00:00:00 | H37: 16-Jan-2026 15:00:00 | I37: NA | J37: N | K37: =ROUNDUP((D37/4999.99)*10,-1) -> 30 | L37: =IF(J37="N",0,K37) -> 0 | M37: L, QE:16-MAINTAINANCE DONE AS PER CHECKLIST ATTACHED
A38: 17 | B38: IKN400798 | C38: Radiographic Systems, Digital | D38: =VLOOKUP(B38,[13]AssetDetails_UEM!$A$3:$X$1848,22,FALSE) -> 1958605 | E38: IKNWOBE26000899 | F38: 03ID181 | G38: 46045 | H38: 27-Jan-2026 10:00:00 | I38: 46052 | J38: N | K38: =ROUNDUP((D38/4999.99)*10,-1) -> 3920 | L38: =IF(J38="N",0,K38) -> 0 | M38: M,QE:16-PPM COMPLETED BY VENDOR.UNIT FUNCTIONING OKAY
A39: 18 | B39: IKN400799 | C39: Radiographic Systems, Digital | D39: =VLOOKUP(B39,[13]AssetDetails_UEM!$A$3:$X$1848,22,FALSE) -> 1958605 | E39: IKNWOBE26000900 | F39: 03ID186 | G39: 46046 | H39: 26-Jan-2026 10:00:00 | I39: 46052 | J39: N | K39: =ROUNDUP((D39/4999.99)*10,-1) -> 3920 | L39: =IF(J39="N",0,K39) -> 0 | M39: M,QE:16-PPM COMPLETED BY VENDOR .UNIT FUNCTIONING OKAY
A40: 19 | B40: IKN401005 | C40: Oxygen Monitors | D40: =VLOOKUP(B40,[13]AssetDetails_UEM!$A$3:$X$1848,22,FALSE) -> 3079 | E40: IKNWOBE26000868 | F40: 05OT165 | G40: 19-Jan-2026 00:00:00 | H40: 19-Jan-2026 09:00:00 | I40: NA | J40: N | K40: =ROUNDUP((D40/4999.99)*10,-1) -> 10 | L40: =IF(J40="N",0,K40) -> 0 | M40: P, QE16: MAINTENANCE DONE AS PER HEPPM CHECKLIST ATTACHED
A41: 20 | B41: IKN400001 | C41: Defibrillators, External, Manual | D41: =VLOOKUP(B41,[13]AssetDetails_UEM!$A$3:$X$1848,22,FALSE) -> 45000 | E41: IKNWOBE26000870 | F41: 01AE112 | G41: 20-Jan-2026 00:00:00 | H41: 46042.542 | I41: NA | J41: N | K41: =ROUNDUP((D41/4999.99)*10,-1) -> 100 | L41: =IF(J41="N",0,K41) -> 0 | M41: MAINTENANCE DONE ACCORDING TO HEPPM CHECKLIST ATTACHED.
A42: 21 | B42: IKN400562 | C42: Defibrillators, External, Manual | D42: =VLOOKUP(B42,[13]AssetDetails_UEM!$A$3:$X$1848,22,FALSE) -> 45000 | E42: IKNWOBE26000871 | F42: 03NM155 | G42: 20-Jan-2026 00:00:00 | H42: 20-Jan-2026 14:00:00 | I42: NA | J42: N | K42: =ROUNDUP((D42/4999.99)*10,-1) -> 100 | L42: =IF(J42="N",0,K42) -> 0 | M42: L, QE:16-PPM COMPLETE AS PER CHECKLIST, UNIT TESTED OKEY
A43: 22 | B43: IKN400723 | C43: Microscopes, Light, Laboratory, Fluorescence | D43: =VLOOKUP(B43,[13]AssetDetails_UEM!$A$3:$X$1848,22,FALSE) -> 169530 | E43: IKNWOBE26000872 | F43: 04LA114 | G43: 20-Jan-2026 00:00:00 | H43: 20-Jan-2026 15:00:00 | I43: NA | J43: N | K43: =ROUNDUP((D43/4999.99)*10,-1) -> 340 | L43: =IF(J43="N",0,K43) -> 0 | M43: L, QE:16-MAINTAINANCE DONE AS PER HEPPM CHECKLIST ATTACHED
A44: 23 | B44: IKN402183 | C44: Physiologic Monitoring Systems, Acute Care | D44: =VLOOKUP(B44,[13]AssetDetails_UEM!$A$3:$X$1848,22,FALSE) -> RM100,00.00 | E44: IKNWOBE26000874 | F44: 03NM158 | G44: 20-Jan-2026 00:00:00 | H44: 20-Feb-2026 15:00:00 | I44: NA | J44: N | K44: =ROUNDUP((D44/4999.99)*10,-1) -> #VALUE! | L44: =IF(J44="N",0,K44) -> 0 | M44: L, QE:16-PPM COMPLETE AS PER CHECKLIST. UNIT FUCTIONING OKEY
A45: 24 | B45: IKN402184 | C45: Physiologic Monitoring Systems, Acute Care | D45: =VLOOKUP(B45,[13]AssetDetails_UEM!$A$3:$X$1848,22,FALSE) -> RM100,00.00 | E45: IKNWOBE26000875 | F45: 03NM161 | G45: 20-Jan-2026 00:00:00 | H45: 20-Jan-2026 16:00:00 | I45: NA | J45: N | K45: =ROUNDUP((D45/4999.99)*10,-1) -> #VALUE! | L45: =IF(J45="N",0,K45) -> 0 | M45: L, QE:16-PPM COMPLETE AS PER CHECKLIST. UNIT FUCTIONING OKEY
A46: 25 | B46: IKN400023 | C46: Warming Units, Blood/Solution | D46: =VLOOKUP(B46,[13]AssetDetails_UEM!$A$3:$X$1848,22,FALSE) -> 4990 | E46: IKNWOBE26000877 | F46: 01AE110 | G46: 21-Jan-2026 00:00:00 | H46: 21-Jan-2026 15:00:00 | I46: NA | J46: N | K46: =ROUNDUP((D46/4999.99)*10,-1) -> 10 | L46: =IF(J46="N",0,K46) -> 0 | M46: L, QE:16-MAINTAINANCE DONE AS PERCHECKLIST ATTACHED
A47: 26 | B47: IKN400024 | C47: Warming Units, Blood/Solution | D47: =VLOOKUP(B47,[13]AssetDetails_UEM!$A$3:$X$1848,22,FALSE) -> 4990 | E47: IKNWOBE26000878 | F47: 01AE110 | G47: 21-Jan-2026 00:00:00 | H47: 21-Jan-2026 16:00:00 | I47: NA | J47: N | K47: =ROUNDUP((D47/4999.99)*10,-1) -> 10 | L47: =IF(J47="N",0,K47) -> 0 | M47: N-QE:16 MAINTENANCE DONE AS PER CHECKLIST ATTACHED
...

Sheet B4-UPTIME 
A1: MINISTRY OF HEALTH
A2: Deduction Mapping Report Biomedical Engineering Maintenance Services (BEMS)
A3: INDICATOR B.4 UPTIME GUARANTEE
B5: HOSPITAL NAME : | C5: INSTITUT KANSER NEGARA | N5: MONTH/YEAR : | U5: 46023
B7: STATE : | C7: WILAYAH PERSEKUTUAN PUTRAJAYA | N7: BEMS MONTHLY FEE (RM)@ 97.5% : | U7: =BEMSdar!E11 -> 1437864.8
B9: COMPANY : | C9: AMBANG WIRA SDN BHD | N9: FMS MONTHLY FEE (RM) @ 2.5% : | U9: =BEMSdar!E13 -> 36868.327
A11: Notes:
A12: 1) Deduction Ringgit Equivalent is based on Appendix 11 of the Agreement, Section B3 Key Deduction Indicators for BEMS
A13: 2) Deduction Value for 1st cut off is Deduction Ringgit Equivalent (per event)
A14: 3) Deduction Value for 2nd cut off is Deduction Ringgit Equivalent (per event) multiply by 2
A15: 4) Display only asset affected by deduction
A17: No. | B17: Asset No | C17: Type Code | D17: Type Description | E17: Asset Purchase cost (RM) | F17: Asset Age | G17: TRKPI % | H17: Uptime % | T17: Deduction Ringgit Equivalent (RM) | U17: Previous Deduction (Month) | W17: Deduction for the month (Y/N) | Y17: Deduction Value (RM) | AA17: Total Deduction (RM) | AB17: Remarks
H18: Jan | I18: Feb | J18: Mar | K18: Apr | L18: May | M18: Jun | N18: Jul | O18: Aug | P18: Sep | Q18: Oct | R18: Nov | S18: Dec | U18: 1st | V18: 2nd | W18: 1st | X18: 2nd | Y18: 1st | Z18: 2nd
A19: 1 | B19: IKN400440 | C19: 16-173 | D19: Sphygmomanometers, Electronic, Automatic | E19: 4510 | F19: 13 | G19: 0.88 | H19: 99.82733 | T19: =ROUNDUP((E19/4999.99)*10,-1) -> 10 | U19: N | V19: N | W19: N | X19: N | Y19: =IF(W19="Y",T19,0) -> 0 | Z19: =IF(X19="Y",T19*2,0) -> 0 | AA19: =Y19+Z19 -> 0
A20: 2 | B20: IKN400645 | C20: 13-215 | D20: Infusion Pumps, General-Purpose | E20: 10825 | F20: 13 | G20: 0.88 | H20: 99.961971 | T20: =ROUNDUP((E20/4999.99)*10,-1) -> 30 | U20: N | V20: N | W20: N | X20: N | Y20: =IF(W20="Y",T20,0) -> 0 | Z20: =IF(X20="Y",T20*2,0) -> 0 | AA20: =Y20+Z20 -> 0
A21: 3 | B21: IKN401714 | C21: 13-215 | D21: Infusion Pumps, General-Purpose | E21: 5800 | F21: 8 | G21: 0.95 | H21: 99.962034 | T21: =ROUNDUP((E21/4999.99)*10,-1) -> 20 | U21: Y | V21: Y | W21: N | X21: N | Y21: =IF(W21="Y",T21,0) -> 0 | Z21: =IF(X21="Y",T21*2,0) -> 0 | AA21: =Y21+Z21 -> 0
A22: 4 | B22: IKN400446 | C22: 13-215 | D22: Infusion Pumps, General-Purpose | E22: 10825 | F22: 13 | G22: 0.88 | H22: 99.059561 | T22: =ROUNDUP((E22/4999.99)*10,-1) -> 30 | U22: N | V22: N | W22: N | X22: N | Y22: =IF(W22="Y",T22,0) -> 0 | Z22: =IF(X22="Y",T22*2,0) -> 0 | AA22: =Y22+Z22 -> 0
A23: 5 | B23: IKN400366 | C23: 13-215 | D23: Infusion Pumps, General-Purpose | E23: 10825 | F23: 13 | G23: 0.88 | H23: 99.082187 | T23: =ROUNDUP((E23/4999.99)*10,-1) -> 30 | U23: N | V23: N | W23: N | X23: N | Y23: =IF(W23="Y",T23,0) -> 0 | Z23: =IF(X23="Y",T23*2,0) -> 0 | AA23: =Y23+Z23 -> 0
A24: 6 | B24: IKN402165 | C24: 13-215 | D24: Infusion Pumps, General-Purpose | E24: 10825 | F24: 13 | G24: 0.88 | H24: 99.139282 | T24: =ROUNDUP((E24/4999.99)*10,-1) -> 30 | U24: N | V24: N | W24: N | X24: N | Y24: =IF(W24="Y",T24,0) -> 0 | Z24: =IF(X24="Y",T24*2,0) -> 0 | AA24: =Y24+Z24 -> 0
A25: 7 | B25: IKN400565 | C25: 12-649 | D25: Physiologic Monitoring Systems, Stress Exercise | E25: 138350 | F25: 13 | G25: 0.88 | H25: 99.17824 | T25: =ROUNDUP((E25/4999.99)*10,-1) -> 280 | U25: N | V25: N | W25: N | X25: N | Y25: =IF(W25="Y",T25,0) -> 0 | Z25: =IF(X25="Y",T25*2,0) -> 0 | AA25: =Y25+Z25 -> 0
A26: 8 | B26: IKN400439 | C26: 16-173 | D26: Sphygmomanometers, Electronic, Automatic | E26: 4510 | F26: 13 | G26: 0.88 | H26: 99.188573 | T26: =ROUNDUP((E26/4999.99)*10,-1) -> 10 | U26: N | V26: N | W26: N | X26: N | Y26: =IF(W26="Y",T26,0) -> 0 | Z26: =IF(X26="Y",T26*2,0) -> 0 | AA26: =Y26+Z26 -> 0
A27: 9 | B27: IKN401076 | C27: 12-306 | D27: Lavage Units, Surgical | E27: 5000 | F27: 13 | G27: 0.85 | H27: 99.248469 | T27: =ROUNDUP((E27/4999.99)*10,-1) -> 20 | U27: N | V27: N | W27: N | X27: N | Y27: =IF(W27="Y",T27,0) -> 0 | Z27: =IF(X27="Y",T27*2,0) -> 0 | AA27: =Y27+Z27 -> 0
A28: 10 | B28: IKN402147 | C28: 15-605 | D28: Testers (Ion Chamber Set) | E28: 142000 | F28: 4 | G28: 0.96 | H28: 97.751902 | T28: =ROUNDUP((E28/4999.99)*10,-1) -> 290 | U28: N | V28: N | W28: N | X28: N | Y28: =IF(W28="Y",T28,0) -> 0 | Z28: =IF(X28="Y",T28*2,0) -> 0 | AA28: =Y28+Z28 -> 0
A29: 11 | B29: IKN401071 | C29: 18-034 | D29: Video Image Processors, Endoscopic | E29: 80000 | F29: 13 | G29: 0.88 | H29: 99.473871 | T29: =ROUNDUP((E29/4999.99)*10,-1) -> 170 | U29: Y | V29: Y | W29: N | X29: N | Y29: =IF(W29="Y",T29,0) -> 0 | Z29: =IF(X29="Y",T29*2,0) -> 0 | AA29: =Y29+Z29 -> 0
A30: 12 | B30: IKN402081 | C30: 13-215 | D30: Infusion Pumps, General-Purpose | E30: 3500 | F30: 5 | G30: 0.95 | H30: 99.49708 | T30: =ROUNDUP((E30/4999.99)*10,-1) -> 10 | U30: N | V30: N | W30: N | X30: N | Y30: =IF(W30="Y",T30,0) -> 0 | Z30: =IF(X30="Y",T30*2,0) -> 0 | AA30: =Y30+Z30 -> 0
... A34: 16 | B34: IKN400782 | C34: 17-679 | D34: Laser Imagers | E34: 83100 | F34: 13 | G34: 0.85 | H34: 99.640291 | T34: =ROUNDUP((E34/4999.99)*10,-1) -> 170 | U34: N | V34: N | W34: N | X34: N | Y34: =IF(W34="Y",T34,0) -> 0 | Z34: =IF(X34="Y",T34*2,0) -> 0 | AA34: =Y34+Z34 -> 0
A35: TOTAL DEDUCTION FOR IND. B.4: | AA35: =SUM(AA19:AA34) -> 0
