Workbook
Name _05_04_2009: #REF!
Name _05_04_2009: #REF!
Name _05_04_2009: #REF!
Name _05_04_2009: #REF!
Name _05_04_2009: #REF!
Name a: '[1]Term Outstanding Payment'!#REF!
Name a: '[1]Term Outstanding Payment'!#REF!
Name a: '[1]Term Outstanding Payment'!#REF!
Name a: '[1]Term Outstanding Payment'!#REF!
Name a: '[1]Term Outstanding Payment'!#REF!
Name AA: #REF!
Name AA: #REF!
Name AA: #REF!
Name AA: #REF!
Name AA: #REF!
Name aaa: #REF!
Name aaa: #REF!
Name aaa: #REF!
Name aaa: #REF!
Name aaa: #REF!
Name aaaaa: #REF!
Name aaaaa: #REF!
Name aaaaa: #REF!
Name aaaaa: #REF!
Name aaaaa: #REF!
Name aaaaaaaaaa: #REF!
Name aaaaaaaaaa: #REF!
Name aaaaaaaaaa: #REF!
Name aaaaaaaaaa: #REF!
Name AAAAAAAAAAAAA: #REF!
Name AAAAAAAAAAAAA: #REF!
Name AAAAAAAAAAAAA: #REF!
Name AAAAAAAAAAAAA: #REF!
Name AAAAAAAAAAAAAAAAAA: #REF!
Name AAAAAAAAAAAAAAAAAA: #REF!
Name AAAAAAAAAAAAAAAAAA: #REF!
Name AAAAAAAAAAAAAAAAAA: #REF!
Name AAAAAAAAAAAAAAAAAAAAA: #REF!
Name AAAAAAAAAAAAAAAAAAAAA: #REF!
Name AAAAAAAAAAAAAAAAAAAAA: #REF!
Name AAAAAAAAAAAAAAAAAAAAA: #REF!
Name AAAAAAAAAAAAAAAAAAAAAAAAAAA: #REF!
Name AAAAAAAAAAAAAAAAAAAAAAAAAAA: #REF!
Name AAAAAAAAAAAAAAAAAAAAAAAAAAA: #REF!
Name AAAAAAAAAAAAAAAAAAAAAAAAAAA: #REF!
Name AAAAAAAAAAAAAAAAAAAAAAAAAAAA: #REF!
Name AAAAAAAAAAAAAAAAAAAAAAAAAAAA: #REF!
Name AAAAAAAAAAAAAAAAAAAAAAAAAAAA: #REF!
Name AAAAAAAAAAAAAAAAAAAAAAAAAAAA: #REF!
Name AAAAAAAAAAAAAAAAAAAAAAAAAAAAAA: #REF!
Name AAAAAAAAAAAAAAAAAAAAAAAAAAAAAA: #REF!
Name AAAAAAAAAAAAAAAAAAAAAAAAAAAAAA: #REF!
Name AAAAAAAAAAAAAAAAAAAAAAAAAAAAAA: #REF!
Name AAAAAAAAAAAAAAAAAAAAAAAAAAAAAAA: #REF!
Name AAAAAAAAAAAAAAAAAAAAAAAAAAAAAAA: #REF!
Name AAAAAAAAAAAAAAAAAAAAAAAAAAAAAAA: #REF!
Name AAAAAAAAAAAAAAAAAAAAAAAAAAAAAAA: #REF!
Name AAAAAAAAAAAAAAAAAAAAAAAAAAAAAAAAA: #REF!
Name AAAAAAAAAAAAAAAAAAAAAAAAAAAAAAAAA: #REF!
Name AAAAAAAAAAAAAAAAAAAAAAAAAAAAAAAAA: #REF!

Sheet BEMSdar
A1: MINISTRY OF HEALTH
A2: Deduction Mapping Report Biomedical Engineering Maintenance Services (BEMS)
D5: HOSPITAL NAME : | E5: Institut Kanser Negara | I5: STATE: | J5: W.P. Putrajaya
D7: MONTH/YEAR : | E7: 46113 | I7: COMPANY: | J7: Ambang Wira Sdn Bhd
A9: MONTHLY SERVICE FEE (RM) : | E9: 1363910.9
A11: BEMS MONTHLY FEE (RM) @ 97.5% : | E11: =97.5%*E9 -> 1329813.2
A13: FMS MONTHLY FEE (RM) @ 2.5% : | E13: =2.5%*E9 -> 34097.773
A17: No | B17: Key Deduction Indicators | I17: Frequency | L17: Deduction Value (RM) | N17: Deduction % | O17: Performance Level (%)
A19: B.1 | B19: All service requests shall be responded by the Company’s trained technical personal within the timeframe as stipulated in the Agreement. | I19: Per event | L19: 0 | N19: 0 | O19: =100-N19 -> 100
A20: B.2 | B20: All unscheduled maintenance works including relevant maintenance calibration, safety tests and functional checks shall be completed within seven (7) working days. | I20: Per day | L20: ='B1&B2 UNSCHEDULED'!U122 -> 1600 | N20: =L20/$E$11% -> 0.12031765 | O20: =100-N20 -> 99.879682
A21: B.3 | B21: Scheduled maintenance shall be carried out as per schedule and according to the procedure as specified in the Agreement. Scheduled maintenance shall include complete safety and performance tests. | I21: Per event | L21: ='B3-SCHEDULED'!L313 -> 0 | N21: =L21/$E$11% -> 0 | O21: =100-N21 -> 100
A22: B.4 | B22: All biomedical equipment shall be functioning and maintained to ensure uptime target as specified in the TRKPI are met. | I22: Per event | L22: 0 | N22: =L22/$E$11% -> 0 | O22: =100-N22 -> 100
A23: B.5 | B23: T&C and Warranty Management of newly introduced biomedical shall be managed and performed according to the Agreement and related acts, standards and regulations. | I23: Per event | L23: ='B5-T&C'!O24 -> 0 | N23: =L23/$E$11% -> 0 | O23: =100-N23 -> 100
A24: Total | L24: =SUM(L19:M23) -> 1600 | N24: =SUM(N19:N23) -> 0.12031765 | O24: =100-N24 -> 99.879682
C27: Prepared by: | I27: Verified by:
C31: Siti Norsaliana Binti Abu Khalid | I31: Mohd Shahrulnizam bin Tarmizi
C32: Head of BEMS | I32: Facility Manager
C33: Ambang Wira Sdn Bhd- Institut Kanser Negara | I33: Ambang Wira Sdn Bhd- Institut Kanser Negara
C34: Date: | I34: Date:

Sheet B1&B2 UNSCHEDULED
A2: MINISTRY OF HEALTH
A3: Deduction Mapping Report Biomedical Engineering Maintenance Services (BEMS)
A4: INDICATOR B.1 RESPONSE TIME & B.2 REPAIR TIME
A6: HOSPITAL NAME: | C6: INSTITUT KANSER NEGARA | I6: FIRST DATE OF THE MONTH : | M6: 46113 | Q6: (For Calculation)
A8: STATE: | C8: WILAYAH PERSEKUTUAN PUTRAJAYA | I8: LAST DATE OF THE MONTH : | M8: 46142 | Q8: (For Calculation)
A10: COMPANY: | C10: AMBANG WIRA SDN BHD | I10: BEMS MONTHLY FEE (RM) @ 97.5% : | M10: =BEMSdar!E11 -> 1329813.2
A12: MONTH/YEAR: | C12: 46082 | I12: FMS MONTHLY FEE (RM) @ 2.5% : | M12: =BEMSdar!E13 -> 34097.773
A14: Notes:
A15: 1) Deduction Ringgit Equivalent is based on Appendix 11 of the Agreement, Section B3 Key Deduction Indicators for BEMS
A16: 2) Deduction Value for Indicator B.1 is Deduction Ringgit Equivalent (per event)
A17: 3) Total Repair Time includes weekend & public holiday
A18: 4) Demerit Point for Indicator B.2 is calculated based on completion date against request date, less by 7 working days
A19: 5) Deduction Value for Indicator B.2 is Demerit Point multiply by Deduction Ringgit Equivalent
A21: No | B21: Asset No | C21: Asset Description | D21: Asset Purchase Price (RM) | E21: Work Order No. | F21: User Location | G21: Work Order/ Complaint Details | H21: Response Category (Emergency/ Normal) | I21: Total Response Time (minutes) | J21: Work Request Date | K21: Response Time (Minutes) | L21: Work Completion Date | M21: Deduction Ringgit Equivalent (RM) | N21: Indicator B.1 | Q21: Indicator B.2
N22: Validate Status (Y/N) | O22: Deduction Value (RM) | P22: Remarks/ Exemption | Q22: Validate Status (Y/N) | R22: Total Repair Time (day) | S22: Last date of 7 working days (dd/mm/yy) | T22: Demerit Point | U22: Deduction Value (RM) | V22: Remarks/ Exemption
A23: Current Month (Work Order Completed)
A24: 1 | B24: IKN400756 | C24: =VLOOKUP(B24,[13]AssetDetails_UEM!$A$3:$AH$1849,6,FALSE) -> Analyzers, Laboratory, Hematology, Coagulation, Automated | D24: =VLOOKUP(B24,[13]AssetDetails_UEM!$A$3:$AK$1849,22,FALSE) -> 105860 | E24: IKNWIBE26006151 | F24: 04LA132 | G24: CUVETTE STUCK AT MOTOR | H24: Normal | I24: 0 days, 0 hrs, 23 mins | J24: 01-Apr-2026 14:07:00 | K24: 01-Apr-2026 14:30:00 | L24: 01-Apr-2026 16:30:00 | M24: =IF(D24>44999.99,100,ROUNDUP((D24/4999.99)*10,-1)) -> 100 | N24: N | O24: ='[14]B1& B2 UNSCHEDULED'!$O$24 -> 0 | Q24: N | R24: =IF(L24="",AKHIR-J24,L24-J24+1) -> 1.0993056 | S24: =WORKDAY(J24,6,AKHIR) -> 46121 | T24: 0 | U24: =IF(Q24="N",0,M24*T24) -> 0 | V24: P - QE:12, REMOVE CUVETTE FROM MOTR. RESTART THE UNIT
A25: 2 | B25: IKN400756 | C25: =VLOOKUP(B25,[13]AssetDetails_UEM!$A$3:$AH$1849,6,FALSE) -> Analyzers, Laboratory, Hematology, Coagulation, Automated | D25: =VLOOKUP(B25,[13]AssetDetails_UEM!$A$3:$AK$1849,22,FALSE) -> 105860 | E25: IKNWIBE26006247 | F25: 04LA132 | G25: WRONG POSITIONING CUVETTE | H25: Normal | I25: 0 days, 0 hrs, 10 mins | J25: 02-Apr-2026 10:24:00 | K25: 46114.44 | L25: 02-Apr-2026 15:30:00 | M25: =IF(D25>44999.99,100,ROUNDUP((D25/4999.99)*10,-1)) -> 100 | N25: N | O25: ='[14]B1& B2 UNSCHEDULED'!$O$24 -> 0 | Q25: N | R25: =IF(L25="",AKHIR-J25,L25-J25+1) -> 1.2125 | S25: =WORKDAY(J25,6,AKHIR) -> 46122 | T25: 0 | U25: =IF(Q25="N",0,M25*T25) -> 0 | V25: AK- ADJUST CUVETTE POSITION INFORM USER TO ADJUST CUVETTE POSITIONING
A26: 3 | B26: IKN400286 | C26: =VLOOKUP(B26,[13]AssetDetails_UEM!$A$3:$AH$1849,6,FALSE) -> Infusion Pumps, Syringe | D26: =VLOOKUP(B26,[13]AssetDetails_UEM!$A$3:$AK$1849,22,FALSE) -> 10225 | E26: IKNWIBE26006251 | F26: 08WH121 | G26: USER TRAINING FOR INFUSION PUMPS, SYRINGE | H26: User Training | I26: 0 days, 0 hrs, 10 mins | J26: 02-Apr-2026 14:30:00 | K26: 46114.611 | L26: 46114.653 | M26: =IF(D26>44999.99,100,ROUNDUP((D26/4999.99)*10,-1)) -> 30 | N26: N | O26: ='[14]B1& B2 UNSCHEDULED'!$O$24 -> 0 | Q26: N | R26: =IF(L26="",AKHIR-J26,L26-J26+1) -> 1.0486111 | S26: =WORKDAY(J26,6,AKHIR) -> 46122 | T26: 0 | U26: =IF(Q26="N",0,M26*T26) -> 0 | V26: DONE DO THE USER TRAINING FOR INFUSION PUMPS, SYRINGE
A27: 4 | B27: IKN400349 | C27: =VLOOKUP(B27,[13]AssetDetails_UEM!$A$3:$AH$1849,6,FALSE) -> Sphygmomanometers, Electronic, Automatic | D27: =VLOOKUP(B27,[13]AssetDetails_UEM!$A$3:$AK$1849,22,FALSE) -> 4510 | E27: IKNWIBE26006256 | F27: 07WF143 | G27: CUFF LEAKING.UNABLE TO PUMP | H27: Normal | I27: 0 days, 0 hrs, 56 mins | J27: 02-Apr-2026 16:34:00 | K27: 02-Apr-2026 17:30:00 | L27: 02-Apr-2026 18:10:00 | M27: =IF(D27>44999.99,100,ROUNDUP((D27/4999.99)*10,-1)) -> 10 | N27: N | O27: ='[14]B1& B2 UNSCHEDULED'!$O$24 -> 0 | Q27: N | R27: =IF(L27="",AKHIR-J27,L27-J27+1) -> 1.0666667 | S27: =WORKDAY(J27,6,AKHIR) -> 46122 | T27: 0 | U27: =IF(Q27="N",0,M27*T27) -> 0 | V27: M-REPLACE CUFF. TESTED OKAY AND FUNCTIONING
A28: 5 | B28: IKN402179 | C28: =VLOOKUP(B28,[13]AssetDetails_UEM!$A$3:$AH$1849,6,FALSE) -> Scanning Systems, Computed Tomography/ Positron Emission Tomography | D28: =VLOOKUP(B28,[13]AssetDetails_UEM!$A$3:$AK$1849,22,FALSE) -> 3410390 | E28: IKNWIBE26006261 | F28: 03NM161 | G28: PREDICTIVE MAINTENANCE SPECT CT | H28: Corrective Maintenance (CM) | I28: 0 days, 0 hrs, 10 mins | J28: 02-Apr-2026 14:00:00 | K28: 46114.59 | L28: 02-Apr-2026 20:00:00 | M28: =IF(D28>44999.99,100,ROUNDUP((D28/4999.99)*10,-1)) -> 100 | N28: N | O28: ='[14]B1& B2 UNSCHEDULED'!$O$24 -> 0 | Q28: N | R28: =IF(L28="",AKHIR-J28,L28-J28+1) -> 1.25 | S28: =WORKDAY(J28,6,AKHIR) -> 46122 | T28: 0 | U28: =IF(Q28="N",0,M28*T28) -> 0 | V28: L, QE:15-PLANNED PREDECTIVE MAINTENANCE AND INSTALLED PATIENT TABLE ELEVATION LOCKING MECHANISM BY VENDOR, TESTED OKAY
A29: 6 | B29: IKN400586 | C29: =VLOOKUP(B29,[13]AssetDetails_UEM!$A$3:$AH$1849,6,FALSE) -> Oximeters, Pulse | D29: =VLOOKUP(B29,[13]AssetDetails_UEM!$A$3:$AK$1849,22,FALSE) -> 11120 | E29: IKNWIBE26006262 | F29: 03NM108 | G29: UNIT UNDER BREAKDOWN | H29: Corrective Maintenance (CM) | I29: 0 days, 1 hrs, 40 mins | J29: 02-Apr-2026 13:00:00 | K29: 46114.611 | L29: 09-Apr-2026 15:00:00 | M29: =IF(D29>44999.99,100,ROUNDUP((D29/4999.99)*10,-1)) -> 30 | N29: N | O29: ='[14]B1& B2 UNSCHEDULED'!$O$24 -> 0 | Q29: N | R29: 6 | S29: =WORKDAY(J29,6,AKHIR) -> 46122 | T29: 0 | U29: =IF(Q29="N",0,M29*T29) -> 0 | V29: L, QE:12-REPLACED BATTERY AMD SPO2 PROBE TESTED OKAY
A30: 7 | B30: IKN400413 | C30: =VLOOKUP(B30,[13]AssetDetails_UEM!$A$3:$AH$1849,6,FALSE) -> Sphygmomanometers, Electronic, Automatic | D30: =VLOOKUP(B30,[13]AssetDetails_UEM!$A$3:$AK$1849,22,FALSE) -> 7770 | E30: IKNWIBE26006349 | F30: 06WD124 | G30: BP SET CANNOT READING | H30: Normal | I30: 0 days, 0 hrs, 28 mins | J30: 03-Apr-2026 11:47:00 | K30: 03-Apr-2026 12:15:00 | L30: 03-Apr-2026 18:50:00 | M30: =IF(D30>44999.99,100,ROUNDUP((D30/4999.99)*10,-1)) -> 20 | N30: N | O30: ='[14]B1& B2 UNSCHEDULED'!$O$24 -> 0 | Q30: N | R30: 5 | S30: =WORKDAY(J30,6,AKHIR) -> 46125 | T30: 0 | U30: =IF(Q30="N",0,M30*T30) -> 0 | V30: L, QE:12- UNIT KEEP PUMPING READING BP NOT APPEAR ERROR 803, UNIT FOUND LACK OF AIR , CHECK TUBING MAKE SURE NO COGGED, TEST UNIT AIR, BP READING APPEAR, UNIT FIT TO USE
A31: 8 | B31: IKN402180 | C31: =VLOOKUP(B31,[13]AssetDetails_UEM!$A$3:$AH$1849,6,FALSE) -> Scanning Systems, Computed Tomography/ Positron Emission Tomography | D31: =VLOOKUP(B31,[13]AssetDetails_UEM!$A$3:$AK$1849,22,FALSE) -> 3413750 | E31: IKNWIBE26006360 | F31: 03NM158 | G31: PREDICTIVE MAINTENANCE SPECT CT | H31: Corrective Maintenance (CM) | I31: 0 days, 0 hrs, 10 mins | J31: 03-Apr-2026 14:00:00 | K31: 46115.59 | L31: 03-Apr-2026 20:00:00 | M31: =IF(D31>44999.99,100,ROUNDUP((D31/4999.99)*10,-1)) -> 100 | N31: N | O31: ='[14]B1& B2 UNSCHEDULED'!$O$24 -> 0 | Q31: N | R31: =IF(L31="",AKHIR-J31,L31-J31+1) -> 1.25 | S31: =WORKDAY(J31,6,AKHIR) -> 46125 | T31: 0 | U31: =IF(Q31="N",0,M31*T31) -> 0 | V31: L, QE:15-PLANNED PREDECTIVE MAINTENANCE AND INSTALLED PATIENT TABLE ELEVATION LOCKING MECHANISM BY VENDOR, TESTED OKAY
A32: 9 | B32: IKN402237 | C32: Tester | D32: 40001 | E32: IKNWIBE26006556 | F32: 01AE111 | G32: USER TRAINING FOR SIMULATOR MULTIPARAMETER | H32: User Training | I32: 0 days, 0 hrs, 10 mins | J32: 07-Apr-2026 08:30:00 | K32: 46119.361 | L32: 46119.396 | M32: =IF(D32>44999.99,100,ROUNDUP((D32/4999.99)*10,-1)) -> 90 | N32: N | O32: ='[14]B1& B2 UNSCHEDULED'!$O$24 -> 0 | Q32: N | R32: =IF(L32="",AKHIR-J32,L32-J32+1) -> 1.0416667 | S32: =WORKDAY(J32,6,AKHIR) -> 46127 | T32: 0 | U32: =IF(Q32="N",0,M32*T32) -> 0 | V32: DONE DO THE USER TRAINING FOR SIMULATOR MULTIPARAMETER
A33: 10 | B33: IKN400016 | C33: =VLOOKUP(B33,[13]AssetDetails_UEM!$A$3:$AH$1849,6,FALSE) -> Infusion Pumps, General-Purpose | D33: =VLOOKUP(B33,[13]AssetDetails_UEM!$A$3:$AK$1849,22,FALSE) -> 10825 | E33: IKNWIBE26006559 | F33: 01AE119 | G33: USER TRAINING FOR INFUSION PUMPS, SYRINGE | H33: User Training | I33: 0 days, 0 hrs, 05 mins | J33: 07-Apr-2026 09:30:00 | K33: 46119.399 | L33: 46119.438 | M33: =IF(D33>44999.99,100,ROUNDUP((D33/4999.99)*10,-1)) -> 30 | N33: N | O33: ='[14]B1& B2 UNSCHEDULED'!$O$24 -> 0 | Q33: N | R33: 7 | S33: =WORKDAY(J33,6,AKHIR) -> 46127 | T33: 0 | U33: =IF(Q33="N",0,M33*T33) -> 0 | V33: DONE DO THE USER TRAINING FOR INFUSION PUMPS, SYRINGE
A34: 11 | B34: IKN400741 | C34: =VLOOKUP(B34,[13]AssetDetails_UEM!$A$3:$AH$1849,6,FALSE) -> Analyzers, Laboratory, Microbiology, Blood Culture, Automate | D34: =VLOOKUP(B34,[13]AssetDetails_UEM!$A$3:$AK$1849,22,FALSE) -> 342820 | E34: IKNWIBE26006562 | F34: 04LA126 | G34: LOW THERMOMETER BATTERY | H34: Normal | I34: 0 days, 0 hrs, 13 mins | J34: 07-Apr-2026 09:17:00 | K34: 07-Apr-2026 09:30:00 | L34: 07-Apr-2026 10:30:00 | M34: =IF(D34>44999.99,100,ROUNDUP((D34/4999.99)*10,-1)) -> 100 | N34: N | O34: ='[14]B1& B2 UNSCHEDULED'!$O$24 -> 0 | Q34: N | R34: =IF(L34="",AKHIR-J34,L34-J34+1) -> 1.0506944 | S34: =WORKDAY(J34,6,AKHIR) -> 46127 | T34: 0 | U34: =IF(Q34="N",0,M34*T34) -> 0 | V34: M-REPLACE LR41H ALKALINE BUTTON CELL BATTERY
A35: 12 | B35: IKN400224 | C35: =VLOOKUP(B35,[13]AssetDetails_UEM!$A$3:$AH$1849,6,FALSE) -> Infusion Pumps, Syringe | D35: =VLOOKUP(B35,[13]AssetDetails_UEM!$A$3:$AK$1849,22,FALSE) -> 10225 | E35: IKNWIBE26006570 | F35: 09WJ201 | G35: USER TRAINING FOR INFUSION PUMPS, SYRINGE | H35: User Training | I35: 0 days, 0 hrs, 06 mins | J35: 07-Apr-2026 14:30:00 | K35: 46119.608 | L35: 46119.65 | M35: =IF(D35>44999.99,100,ROUNDUP((D35/4999.99)*10,-1)) -> 30 | N35: N | O35: ='[14]B1& B2 UNSCHEDULED'!$O$24 -> 0 | Q35: N | R35: =IF(L35="",AKHIR-J35,L35-J35+1) -> 1.0458333 | S35: =WORKDAY(J35,6,AKHIR) -> 46127 | T35: 0 | U35: =IF(Q35="N",0,M35*T35) -> 0 | V35: DONE DO THE USER TRAINING FOR INFUSION PUMPS, SYRINGE
A36: 13 | B36: IKN400298 | C36: =VLOOKUP(B36,[13]AssetDetails_UEM!$A$3:$AH$1849,6,FALSE) -> Mattress Systems, Alternating-Pressure | D36: =VLOOKUP(B36,[13]AssetDetails_UEM!$A$3:$AK$1849,22,FALSE) -> 28630 | E36: IKNWIBE26006629 | F36: 08WH121 | G36: RIPPLE MATTRESS CONNECTOR ROSAK - WAD 8B | H36: Normal | I36: 0 days, 0 hrs, 55 mins | J36: 08-Apr-2026 07:05:00 | K36: 08-Apr-2026 08:00:00 | L36: 08-Apr-2026 09:30:00 | M36: =IF(D36>44999.99,100,ROUNDUP((D36/4999.99)*10,-1)) -> 60 | N36: N | O36: ='[14]B1& B2 UNSCHEDULED'!$O$24 -> 0 | Q36: N | R36: =IF(L36="",AKHIR-J36,L36-J36+1) -> 1.1006944 | S36: =WORKDAY(J36,6,AKHIR) -> 46128 | T36: 0 | U36: =IF(Q36="N",0,M36*T36) -> 0 | V36: L- REPLACE NEW COVER HOSE TEST ON MATTRESS , MAKE SURE NO LEAKING , UNIT OKAY READY FOR USE
A37: 14 | B37: IKN400277 | C37: =VLOOKUP(B37,[13]AssetDetails_UEM!$A$3:$AH$1849,6,FALSE) -> Electrocardiographs, Multichannel, Interpretative | D37: =VLOOKUP(B37,[13]AssetDetails_UEM!$A$3:$AK$1849,22,FALSE) -> 25260 | E37: IKNWIBE26006637 | F37: 08WH107 | G37: MESIN ECG BACAAN GRAF TIDAK KELUAR - 8B ARAS 8 | H37: Normal | I37: 0 days, 0 hrs, 52 mins | J37: 08-Apr-2026 10:08:00 | K37: 08-Apr-2026 11:00:00 | L37: 09-Apr-2026 18:50:00 | M37: =IF(D37>44999.99,100,ROUNDUP((D37/4999.99)*10,-1)) -> 60 | N37: N | O37: ='[14]B1& B2 UNSCHEDULED'!$O$24 -> 0 | Q37: N | R37: =IF(L37="",AKHIR-J37,L37-J37+1) -> 2.3625 | S37: =WORKDAY(J37,6,AKHIR) -> 46128 | T37: 0 | U37: =IF(Q37="N",0,M37*T37) -> 0 | V37: L, QE:12-CHANGE UNIT 2 HOUR DO PERFORMANCE TEST UNTIL CLEAN ECG , IT FULLY DETECT AND SHOW FULL GRAPH , UNIT READY FOR USE
A38: 15 | B38: IKN400300 | C38: =VLOOKUP(B38,[13]AssetDetails_UEM!$A$3:$AH$1849,6,FALSE) -> Mattress Systems, Alternating-Pressure | D38: =VLOOKUP(B38,[13]AssetDetails_UEM!$A$3:$AK$1849,22,FALSE) -> 28630 | E38: IKNWIBE26006648 | F38: 08WH121 | G38: TUBING ROSAK | H38: Normal | I38: 0 days, 0 hrs, 47 mins | J38: 08-Apr-2026 16:53:00 | K38: 46120.736 | L38: 08-Apr-2026 18:40:00 | M38: =IF(D38>44999.99,100,ROUNDUP((D38/4999.99)*10,-1)) -> 60 | N38: N | O38: ='[14]B1& B2 UNSCHEDULED'!$O$24 -> 0 | Q38: N | R38: =IF(L38="",AKHIR-J38,L38-J38+1) -> 1.0743056 | S38: =WORKDAY(J38,6,AKHIR) -> 46128 | T38: 0 | U38: =IF(Q38="N",0,M38*T38) -> 0 | V38: L, QE:12-REPLACE NEW COVER HOSE, TEST ON MATTRESS, MAKE SURE NO LELAKING , UNIT OKAY READY FOR USE
A39: 16 | B39: IKN400956 | C39: =VLOOKUP(B39,[13]AssetDetails_UEM!$A$3:$AH$1849,6,FALSE) -> Linear Accelerators | D39: =VLOOKUP(B39,[13]AssetDetails_UEM!$A$3:$AK$1849,22,FALSE) -> 21961900 | E39: IKNWIBE26006701 | F39: 01RT172 | G39: MLC ERROR INTERMITTEN | H39: Normal | I39: 0 days, 0 hrs, 35 mins | J39: 09-Apr-2026 08:15:00 | K39: 46121.368 | L39: 46121.438 | M39: =IF(D39>44999.99,100,ROUNDUP((D39/4999.99)*10,-1)) -> 100 | N39: N | O39: ='[14]B1& B2 UNSCHEDULED'!$O$24 -> 0 | Q39: N | R39: =IF(L39="",AKHIR-J39,L39-J39+1) -> 1.09375 | S39: =WORKDAY(J39,6,AKHIR) -> 46129 | T39: 0 | U39: =IF(Q39="N",0,M39*T39) -> 0 | V39: BE SIDE LEAF STUCK, REPLACE HALF HD MOTOR FOR SIDE B LEAF
A40: 17 | B40: IKN400442 | C40: =VLOOKUP(B40,[13]AssetDetails_UEM!$A$3:$AH$1849,6,FALSE) -> Infusion Pumps, Syringe | D40: =VLOOKUP(B40,[13]AssetDetails_UEM!$A$3:$AK$1849,22,FALSE) -> 10225 | E40: IKNWIBE26006714 | F40: 06WC113 | G40: USER TRAINING FOR INFUSION PUMPS, SYRINGE | H40: User Training | I40: 0 days, 0 hrs, 06 mins | J40: 09-Apr-2026 14:30:00 | K40: 46121.608 | L40: 46121.65 | M40: =IF(D40>44999.99,100,ROUNDUP((D40/4999.99)*10,-1)) -> 30 | N40: N | O40: ='[14]B1& B2 UNSCHEDULED'!$O$24 -> 0 | Q40: N | R40: =IF(L40="",AKHIR-J40,L40-J40+1) -> 1.0458333 | S40: =WORKDAY(J40,6,AKHIR) -> 46129 | T40: 0 | U40: =IF(Q40="N",0,M40*T40) -> 0 | V40: DONE DO THE USER TRAINING FOR INFUSION PUMPS, SYRINGE
A41: 18 | B41: IKN400605 | C41: =VLOOKUP(B41,[13]AssetDetails_UEM!$A$3:$AH$1849,6,FALSE) -> Infusion Pumps, General-Purpose | D41: =VLOOKUP(B41,[13]AssetDetails_UEM!$A$3:$AK$1849,22,FALSE) -> 10825 | E41: IKNWIBE26006717 | F41: 04DO111 | G41: CHARGER FAULTY | H41: Normal | I41: 0 days, 0 hrs, 31 mins | J41: 09-Apr-2026 15:29:00 | K41: 09-Apr-2026 16:00:00 | L41: 09-Apr-2026 16:30:00 | M41: =IF(D41>44999.99,100,ROUNDUP((D41/4999.99)*10,-1)) -> 30 | N41: N | O41: ='[14]B1& B2 UNSCHEDULED'!$O$24 -> 0 | Q41: N | R41: =IF(L41="",AKHIR-J41,L41-J41+1) -> 1.0423611 | S41: =WORKDAY(J41,6,AKHIR) -> 46129 | T41: 0 | U41: =IF(Q41="N",0,M41*T41) -> 0 | V41: M-REPLACE ANOTHER CHARGER
A42: 19 | B42: IKN400300 | C42: =VLOOKUP(B42,[13]AssetDetails_UEM!$A$3:$AH$1849,6,FALSE) -> Mattress Systems, Alternating-Pressure | D42: =VLOOKUP(B42,[13]AssetDetails_UEM!$A$3:$AK$1849,22,FALSE) -> 28630 | E42: IKNWIBE26006804 | F42: 08WH121 | G42: CONNECTOR RIPPLE MATTRESS ROSAK | H42: Normal | I42: 0 days, 0 hrs, 31 mins | J42: 10-Apr-2026 18:59:00 | K42: 10-Apr-2026 19:30:00 | L42: 13-Apr-2026 15:00:00 | M42: =IF(D42>44999.99,100,ROUNDUP((D42/4999.99)*10,-1)) -> 60 | N42: N | O42: ='[14]B1& B2 UNSCHEDULED'!$O$24 -> 0 | Q42: N | R42: =IF(L42="",AKHIR-J42,L42-J42+1) -> 3.8340278 | S42: =WORKDAY(J42,6,AKHIR) -> 46132 | T42: 0 | U42: =IF(Q42="N",0,M42*T42) -> 0 | V42: L, QE:12-REPLACE NOW COVER HOSE, TEST ON MATTRESS MAKE SURE NO LEAKING ,UNIT FUNCTIONING OKAY READY FOR USE
A43: 20 | B43: IKN400300 | C43: =VLOOKUP(B43,[13]AssetDetails_UEM!$A$3:$AH$1849,6,FALSE) -> Mattress Systems, Alternating-Pressure | D43: =VLOOKUP(B43,[13]AssetDetails_UEM!$A$3:$AK$1849,22,FALSE) -> 28630 | E43: IKNWIBE26006824 | F43: 08WH121 | G43: BUTTON TRANSPORT RIPPLE MATTRESS TERCABUT | H43: Normal | I43: 0 days, 0 hrs, 9 mins | J43: 12-Apr-2026 00:51:00 | K43: 12-Apr-2026 01:00:00 | L43: 13-Apr-2026 17:00:00 | M43: =IF(D43>44999.99,100,ROUNDUP((D43/4999.99)*10,-1)) -> 60 | N43: N | O43: ='[14]B1& B2 UNSCHEDULED'!$O$24 -> 0 | Q43: N | R43: =IF(L43="",AKHIR-J43,L43-J43+1) -> 2.6729167 | S43: =WORKDAY(J43,6,AKHIR) -> 46132 | T43: 0 | U43: =IF(Q43="N",0,M43*T43) -> 0 | V43: L, QE:12-BUTTON TRANSPORT RIPPLE MATTRESS INSTALL BUTTON, MAKE SURE FIT TO USE, TEST UNIT OKAY
A44: 21 | B44: IKN400967 | C44: =VLOOKUP(B44,[13]AssetDetails_UEM!$A$3:$AH$1849,6,FALSE) -> Linear Accelerators | D44: =VLOOKUP(B44,[13]AssetDetails_UEM!$A$3:$AK$1849,22,FALSE) -> 12049370 | E44: IKNWIBE26006881 | F44: 01RT165 | G44: LINAC VACUUM TARGET DROP | H44: Normal | I44: 0 days, 0 hrs, 08 mins | J44: 13-Apr-2026 08:22:00 | K44: 46125.354 | L44: 46125.396 | M44: =IF(D44>44999.99,100,ROUNDUP((D44/4999.99)*10,-1)) -> 100 | N44: N | O44: ='[14]B1& B2 UNSCHEDULED'!$O$24 -> 0 | Q44: N | R44: =IF(L44="",AKHIR-J44,L44-J44+1) -> 1.0472222 | S44: =WORKDAY(J44,6,AKHIR) -> 46133 | T44: 0 | U44: =IF(Q44="N",0,M44*T44) -> 0 | V44: RESET VACUUM BREAKER AND LET HOLD FOR 10 MINUTES. UNIT RETURN TO NORMAL CONDITION AND TESTED PASS.
A45: 22 | B45: IKN400762 | C45: =VLOOKUP(B45,[13]AssetDetails_UEM!$A$3:$AH$1849,6,FALSE) -> Analyzers, Laboratory, Immunoassay, Chemiluminescent | D45: =VLOOKUP(B45,[13]AssetDetails_UEM!$A$3:$AK$1849,22,FALSE) -> 1443450 | E45: IKNWIBE26006887 | F45: 04LA133 | G45: MOTOR RUSTY MAKE NOUSY SOUND | H45: Normal | I45: 0 days, 0 hrs, 7 mins | J45: 13-Apr-2026 09:03:00 | K45: 13-Apr-2026 09:10:00 | L45: 13-Apr-2026 09:30:00 | M45: =IF(D45>44999.99,100,ROUNDUP((D45/4999.99)*10,-1)) -> 100 | N45: N | O45: ='[14]B1& B2 UNSCHEDULED'!$O$24 -> 0 | Q45: N | R45: =IF(L45="",AKHIR-J45,L45-J45+1) -> 1.01875 | S45: =WORKDAY(J45,6,AKHIR) -> 46133 | T45: 0 | U45: =IF(Q45="N",0,M45*T45) -> 0 | V45: M-CLEAN MOTOR WITH LUBRICATE , CLEAN IT
A46: 23 | B46: IKN400304 | C46: =VLOOKUP(B46,[13]AssetDetails_UEM!$A$3:$AH$1849,6,FALSE) -> Incubators, Laboratory, Thermocycling | D46: =VLOOKUP(B46,[13]AssetDetails_UEM!$A$3:$AK$1849,22,FALSE) -> 16240 | E46: IKNWIBE26006909 | F46: 04LA126 | G46: PASANG DATA LOGGER | H46: Normal | I46: 0 days, 1 hrs, 2 mins | J46: 13-Apr-2026 12:58:00 | K46: 13-Apr-2026 14:00:00 | L46: 13-Apr-2026 14:30:00 | M46: =IF(D46>44999.99,100,ROUNDUP((D46/4999.99)*10,-1)) -> 40 | N46: N | O46: ='[14]B1& B2 UNSCHEDULED'!$O$24 -> 0 | Q46: N | R46: =IF(L46="",AKHIR-J46,L46-J46+1) -> 1.0638889 | S46: =WORKDAY(J46,6,AKHIR) -> 46133 | T46: 0 | U46: =IF(Q46="N",0,M46*T46) -> 0 | V46: L, QE:12-INSTALL DATA LOGGER
A47: 24 | B47: IKN400741 | C47: =VLOOKUP(B47,[13]AssetDetails_UEM!$A$3:$AH$1849,6,FALSE) -> Analyzers, Laboratory, Microbiology, Blood Culture, Automate | D47: =VLOOKUP(B47,[13]AssetDetails_UEM!$A$3:$AK$1849,22,FALSE) -> 342820 | E47: IKNWIBE26006910 | F47: 04LA126 | G47: PASANG DATA LOGGER | H47: Normal | I47: 0 days, 0 hrs, 23 mins | J47: 13-Apr-2026 13:07:00 | K47: 13-Apr-2026 13:30:00 | L47: 13-Apr-2026 14:00:00 | M47: =IF(D47>44999.99,100,ROUNDUP((D47/4999.99)*10,-1)) -> 100 | N47: N | O47: ='[14]B1& B2 UNSCHEDULED'!$O$24 -> 0 | Q47: N | R47: =IF(L47="",AKHIR-J47,L47-J47+1) -> 1.0368056 | S47: =WORKDAY(J47,6,AKHIR) -> 46133 | T47: 0 | U47: =IF(Q47="N",0,M47*T47) -> 0 | V47: L, QE:12-INSTALL DATA LOGGER
...

Sheet B3-SCHEDULED
A3: MINISTRY OF HEALTH
A4: Deduction Mapping Report Biomedical Engineering Maintenance Services (BEMS)
A5: INDICATOR B.3 SCHEDULED MAINTENANCE
A7: HOSPITAL NAME : | C7: INSTITUT KANSER NEGARA | H7: MONTH/YEAR : | J7: 46113
B9: STATE : | C9: WILAYAH PERSEKUTUAN PUTRAJAYA | G9: BEMS MONTHLY FEE (RM) @ 97.5% : | J9: =BEMSdar!E11 -> 1329813.2
B11: COMPANY : | C11: AMBANG WIRA SDN BHD | G11: FMS MONTHLY FEE (RM) @ 2.5% : | J11: =BEMSdar!E13 -> 34097.773
A13: Notes:
A14: 1) Deduction Ringgit Equivalent is based on Appendix 11 of the Agreement, Section B3 Key Deduction Indicators for BEMS
A15: 2) Deduction Value for Indicator B.3 is Deduction Ringgit Equivalent (per event)
A16: 3) Rescheduled Date is the final rescheduled date if there are multiple rescheduling
A17: 4) Display only asset affected by deduction
A19: No | B19: Asset No | C19: Asset Description | D19: Asset Purchase Price (RM) | E19: Work Order No. | F19: User Location | G19: Scheduled Start Date | H19: Maintenance Date | I19: Rescheduled Date | J19: Validate Status (Y/N) | K19: Deduction Ringgit Equivalent (RM) | L19: Indicator B.3
L20: Deduction Value (RM) | M20: Remarks/ Exemption
A21: Current Month (Closed)
A22: 1 | B22: IKN400174 | C22: Warming Units, Blood/Solution | D22: =VLOOKUP(B22,[13]AssetDetails_UEM!$A$3:$X$1848,22,FALSE) -> 4950 | E22: IKNWOBE26005092 | F22: 03ID156 | G22: 01-Apr-2026 00:00:00 | H22: 01-Apr-2026 15:30:00 | I22: NA | J22: N | K22: =ROUNDUP((D22/4999.99)*10,-1) -> 10 | L22: =IF(J22="N",0,K22) -> 0 | M22: L, QE:16-PPM COMPLETE AS PER CHECKLIST , UNIT TESTED OKAY
A23: 2 | B23: IKN400333 | C23: Infusion Pumps, General-Purpose | D23: =VLOOKUP(B23,[13]AssetDetails_UEM!$A$3:$X$1848,22,FALSE) -> 10825 | E23: IKNWOBE26005093 | F23: 07WF121 | G23: 46113 | H23: 46125.625 | I23: 46134 | J23: N | K23: =ROUNDUP((D23/4999.99)*10,-1) -> 30 | L23: =IF(J23="N",0,K23) -> 0 | M23: Rescheduled Unit in used Done on 13 Apr 2026
A24: 3 | B24: IKN400561 | C24: Centrifuges, Tabletop | D24: =VLOOKUP(B24,[13]AssetDetails_UEM!$A$3:$X$1848,22,FALSE) -> 24060 | E24: IKNWOBE26005094 | F24: 03NM154 | G24: 01-Apr-2026 00:00:00 | H24: 01-Apr-2026 14:00:00 | I24: NA | J24: N | K24: =ROUNDUP((D24/4999.99)*10,-1) -> 50 | L24: =IF(J24="N",0,K24) -> 0 | M24: L, QE:16-PPM COMPLETE AS PER CHECKLIST , UNIT TESTED OKAY
A25: 4 | B25: IKN400715 | C25: Centrifuges, Tabletop, Low-Speed, Nonrefrigerated, Blood Ban | D25: =VLOOKUP(B25,[13]AssetDetails_UEM!$A$3:$X$1848,22,FALSE) -> 5170 | E25: IKNWOBE26005095 | F25: 04LA140 | G25: 01-Apr-2026 00:00:00 | H25: 01-Apr-2026 15:00:00 | I25: NA | J25: N | K25: =ROUNDUP((D25/4999.99)*10,-1) -> 20 | L25: =IF(J25="N",0,K25) -> 0 | M25: M,QE:16-PPM DONE AS PER HEPPM CHECKLIST ATTACHED
A26: 5 | B26: IKN401016 | C26: Recorders, Tape, Video | D26: =VLOOKUP(B26,[13]AssetDetails_UEM!$A$3:$X$1848,22,FALSE) -> 20000 | E26: IKNWOBE26005096 | F26: 05OT167 | G26: 01-Apr-2026 00:00:00 | H26: 01-Apr-2026 09:00:00 | I26: NA | J26: N | K26: =ROUNDUP((D26/4999.99)*10,-1) -> 50 | L26: =IF(J26="N",0,K26) -> 0 | M26: L, QE:16-ROUTINE INSPECTION DONE AS PER CHECKLIST ATTACHED UNIT FUNCTIONING IN GOOD CONDITION
A27: 6 | B27: IKN401061 | C27: Stimulators, Electrical, Peripheral Nerve, Analgesic, Transc | D27: =VLOOKUP(B27,[13]AssetDetails_UEM!$A$3:$X$1848,22,FALSE) -> 6570 | E27: IKNWOBE26005097 | F27: 05OT123 | G27: 01-Apr-2026 00:00:00 | H27: 01-Apr-2026 09:30:00 | I27: NA | J27: N | K27: =ROUNDUP((D27/4999.99)*10,-1) -> 20 | L27: =IF(J27="N",0,K27) -> 0 | M27: L, QE:16-MAINTAINANCE DONE AS PER HEPPM CHECKLIST ATTACHED UNIT FUNCTIONING IN GOOD CONDITION
A28: 7 | B28: IKN401068 | C28: Aspirators | D28: =VLOOKUP(B28,[13]AssetDetails_UEM!$A$3:$X$1848,22,FALSE) -> 10705 | E28: IKNWOBE26005098 | F28: 05OT169 | G28: 01-Apr-2026 00:00:00 | H28: 01-Apr-2026 11:30:00 | I28: NA | J28: N | K28: =ROUNDUP((D28/4999.99)*10,-1) -> 30 | L28: =IF(J28="N",0,K28) -> 0 | M28: L, QE:16-MAINTAINANCE DONE AS PER HEPPM CHECKLIST ATTACHED UNIT FUNCTIONING IN GOOD CONDITION
A29: 8 | B29: IKN401097 | C29: Lights, Surgical | D29: =VLOOKUP(B29,[13]AssetDetails_UEM!$A$3:$X$1848,22,FALSE) -> 10585 | E29: IKNWOBE26005099 | F29: 05IC114 | G29: 01-Apr-2026 00:00:00 | H29: 01-Apr-2026 08:00:00 | I29: NA | J29: N | K29: =ROUNDUP((D29/4999.99)*10,-1) -> 30 | L29: =IF(J29="N",0,K29) -> 0 | M29: L, QE:16-MAINTAINANCE DONE AS PER HEPPM CHECKLIST ATTACHED UNIT FUNCTIONING IN GOOD CONDITION
A30: 9 | B30: IKN400449 | C30: Infusion Pumps, General-Purpose | D30: =VLOOKUP(B30,[13]AssetDetails_UEM!$A$3:$X$1848,22,FALSE) -> 10825 | E30: IKNWOBE26005100 | F30: 06WC113 | G30: 02-Apr-2026 00:00:00 | H30: 02-Apr-2026 14:00:00 | I30: NA | J30: N | K30: =ROUNDUP((D30/4999.99)*10,-1) -> 30 | L30: =IF(J30="N",0,K30) -> 0 | M30: L, QE:16-PPM DONE AS PERCHEKLIST
A31: 10 | B31: IKN400586 | C31: Oximeters, Pulse | D31: =VLOOKUP(B31,[13]AssetDetails_UEM!$A$3:$X$1848,22,FALSE) -> 11120 | E31: IKNWOBE26005101 | F31: 03NM108 | G31: 09-Apr-2026 00:00:00 | H31: 09-Apr-2026 14:00:00 | I31: NA | J31: N | K31: =ROUNDUP((D31/4999.99)*10,-1) -> 30 | L31: =IF(J31="N",0,K31) -> 0 | M31: L, QE:16-PPM COMPLETE AS PER CHECKLIST , UNIT TESTED OKAY
A32: 11 | B32: IKN400609 | C32: Balances, Electronic, Analytical | D32: =VLOOKUP(B32,[13]AssetDetails_UEM!$A$3:$X$1848,22,FALSE) -> 4000 | E32: IKNWOBE26005102 | F32: 04DO114 | G32: 02-Apr-2026 00:00:00 | H32: 02-Apr-2026 10:00:00 | I32: NA | J32: N | K32: =ROUNDUP((D32/4999.99)*10,-1) -> 10 | L32: =IF(J32="N",0,K32) -> 0 | M32: M,QE:16-PPM DONE AS PER VENDOR CHECKLIST ATTACHED
A33: 12 | B33: IKN400678 | C33: Aspirators | D33: =VLOOKUP(B33,[13]AssetDetails_UEM!$A$3:$X$1848,22,FALSE) -> 5052 | E33: IKNWOBE26005103 | F33: 04TC119 | G33: 02-Apr-2026 00:00:00 | H33: 02-Apr-2026 11:00:00 | I33: NA | J33: N | K33: =ROUNDUP((D33/4999.99)*10,-1) -> 20 | L33: =IF(J33="N",0,K33) -> 0 | M33: L, QE:16-PPM DONE AS PER HEPPM CHECKLIST ATTACHED
A34: 13 | B34: IKN400704 | C34: Centrifuges, Tabletop | D34: =VLOOKUP(B34,[13]AssetDetails_UEM!$A$3:$X$1848,22,FALSE) -> 24060 | E34: IKNWOBE26005104 | F34: 04LA137 | G34: 02-Apr-2026 00:00:00 | H34: 02-Apr-2026 18:30:00 | I34: NA | J34: N | K34: =ROUNDUP((D34/4999.99)*10,-1) -> 50 | L34: =IF(J34="N",0,K34) -> 0 | M34: M,QE:16-PPM DONE AS PER HEPPM CHECKLIST ATTACHED
A35: 14 | B35: IKN400708 | C35: Centrifuges, Tabletop | D35: =VLOOKUP(B35,[13]AssetDetails_UEM!$A$3:$X$1848,22,FALSE) -> 24060 | E35: IKNWOBE26005105 | F35: 04LA130 | G35: 02-Apr-2026 00:00:00 | H35: 02-Apr-2026 16:30:00 | I35: NA | J35: N | K35: =ROUNDUP((D35/4999.99)*10,-1) -> 50 | L35: =IF(J35="N",0,K35) -> 0 | M35: M,QE:16-PPM DONE AS PER HEPPM CHECKLIST ATTACHED
... A47: 26 | B47: IKN401510 | C47: Balances, Electronic | D47: =VLOOKUP(B47,[13]AssetDetails_UEM!$A$3:$X$1848,22,FALSE) -> 660 | E47: IKNWOBE26005117 | F47: 01KT106 | G47: 02-Apr-2026 00:00:00 | H47: 02-Apr-2026 10:30:00 | I47: NA | J47: N | K47: =ROUNDUP((D47/4999.99)*10,-1) -> 10 | L47: =IF(J47="N",0,K47) -> 0 | M47: AN- QE:16. PPM HAS BEEN COMPLETED AS PER HEPPM CHECKLIST
A48: 27 | B48: IKN401518 | C48: Scales, Patient, Floor | D48: =VLOOKUP(B48,[13]AssetDetails_UEM!$A$3:$X$1848,22,FALSE) -> 3515 | E48: IKNWOBE26005118 | F48: 03DU103 | G48: 02-Apr-2026 00:00:00 | H48: 46114.646 | I48: NA | J48: N | K48: =ROUNDUP((D48/4999.99)*10,-1) -> 10 | L48: =IF(J48="N",0,K48) -> 0 | M48: AN- QE:16. PPM HAS BEEN COMPLETED AS PER HEPPM CHECKLIST
A49: 28 | B49: IKN401544 | C49: Scales, Clinical, Laboratory | D49: =VLOOKUP(B49,[13]AssetDetails_UEM!$A$3:$X$1848,22,FALSE) -> 3500 | E49: IKNWOBE26005119 | F49: 05PF146 | G49: 02-Apr-2026 00:00:00 | H49: 02-Apr-2026 14:30:00 | I49: NA | J49: N | K49: =ROUNDUP((D49/4999.99)*10,-1) -> 10 | L49: =IF(J49="N",0,K49) -> 0 | M49: AN- QE:16. PPM HAS BEEN COMPLETED AS PER HEPPM CHECKLIST
A50: 29 | B50: IKN401545 | C50: Balances, Electronic | D50: =VLOOKUP(B50,[13]AssetDetails_UEM!$A$3:$X$1848,22,FALSE) -> 5490 | E50: IKNWOBE26005120 | F50: 05PF112 | G50: 02-Apr-2026 00:00:00 | H50: 02-Apr-2026 12:30:00 | I50: NA | J50: N | K50: =ROUNDUP((D50/4999.99)*10,-1) -> 20 | L50: =IF(J50="N",0,K50) -> 0 | M50: AN- QE:16. PPM HAS BEEN COMPLETED AS PER HEPPM CHECKLIST
A51: 30 | B51: IKN401581 | C51: Balances, Electronic | D51: =VLOOKUP(B51,[13]AssetDetails_UEM!$A$3:$X$1848,22,FALSE) -> 3380 | E51: IKNWOBE26005121 | F51: 01KT101 | G51: 02-Apr-2026 00:00:00 | H51: 02-Apr-2026 11:30:00 | I51: NA | J51: N | K51: =ROUNDUP((D51/4999.99)*10,-1) -> 10 | L51: =IF(J51="N",0,K51) -> 0 | M51: AN- QE:16. PPM HAS BEEN COMPLETED AS PER HEPPM CHECKLIST
A52: 31 | B52: IKN401656 | C52: Balances, Electronic | D52: =VLOOKUP(B52,[13]AssetDetails_UEM!$A$3:$X$1848,22,FALSE) -> 1500 | E52: IKNWOBE26005122 | F52: 05OT120 | G52: 02-Apr-2026 00:00:00 | H52: 02-Apr-2026 10:00:00 | I52: NA | J52: N | K52: =ROUNDUP((D52/4999.99)*10,-1) -> 10 | L52: =IF(J52="N",0,K52) -> 0 | M52: L, QE:16-MAINTAINANCE DONE AS CALIBRATION CERTIFICATE ATTACHED UNIT FUNCTIONING IN GOOD CONDITION
A53: 32 | B53: IKN401691 | C53: Scales, Patient, Floor | D53: =VLOOKUP(B53,[13]AssetDetails_UEM!$A$3:$X$1848,22,FALSE) -> 3300 | E53: IKNWOBE26005123 | F53: 04HP128 | G53: 02-Apr-2026 00:00:00 | H53: 46114.688 | I53: NA | J53: N | K53: =ROUNDUP((D53/4999.99)*10,-1) -> 10 | L53: =IF(J53="N",0,K53) -> 0 | M53: PPM DONE AS A PERCHECKLIST
A54: 33 | B54: IKN401734 | C54: Balances, Electronic, Analytical | D54: =VLOOKUP(B54,[13]AssetDetails_UEM!$A$3:$X$1848,22,FALSE) -> 6617 | E54: IKNWOBE26005124 | F54: 03NM153 | G54: 02-Apr-2026 00:00:00 | H54: 02-Apr-2026 15:40:00 | I54: NA | J54: N | K54: =ROUNDUP((D54/4999.99)*10,-1) -> 20 | L54: =IF(J54="N",0,K54) -> 0 | M54: L, QE:16-CALIBRATION COMPLETE BY VENDOR , UNIT TESTED OKAY
A55: 34 | B55: IKN401999 | C55: Balances, Electronic | D55: =VLOOKUP(B55,[13]AssetDetails_UEM!$A$3:$X$1848,22,FALSE) -> 3850 | E55: IKNWOBE26005125 | F55: 05PF110 | G55: 02-Apr-2026 00:00:00 | H55: 02-Apr-2026 13:30:00 | I55: NA | J55: N | K55: =ROUNDUP((D55/4999.99)*10,-1) -> 10 | L55: =IF(J55="N",0,K55) -> 0 | M55: AN- QE:16. PPM HAS BEEN COMPLETED AS PER HEPPM CHECKLIST
A56: 35 | B56: IKN402055 | C56: Fluorometers | D56: =VLOOKUP(B56,[13]AssetDetails_UEM!$A$3:$X$1848,22,FALSE) -> 16800 | E56: IKNWOBE26005126 | F56: 04LA120 | G56: 02-Apr-2026 00:00:00 | H56: 02-Apr-2026 15:00:00 | I56: NA | J56: N | K56: =ROUNDUP((D56/4999.99)*10,-1) -> 40 | L56: =IF(J56="N",0,K56) -> 0 | M56: L, QE:16-PPM DONE AS PER HEPPM CHECKLIST
A57: 36 | B57: IKN401109 | C57: Lights, Surgical | D57: =VLOOKUP(B57,[13]AssetDetails_UEM!$A$3:$X$1848,22,FALSE) -> 10585 | E57: IKNWOBE26005127 | F57: 09WJ130 | G57: 02-Apr-2026 00:00:00 | H57: 02-Apr-2026 11:00:00 | I57: NA | J57: N | K57: =ROUNDUP((D57/4999.99)*10,-1) -> 30 | L57: =IF(J57="N",0,K57) -> 0 | M57: L, QE:16-PPM DONE AS PERCHEKLIST
A58: 37 | B58: IKN400774 | C58: Scanning Systems, Computed Tomography | D58: =VLOOKUP(B58,[13]AssetDetails_UEM!$A$3:$X$1848,22,FALSE) -> 4605710 | E58: IKNWOBE26005128 | F58: 03ID156 | G58: 03-Apr-2026 00:00:00 | H58: 03-Apr-2026 08:00:00 | I58: NA | J58: N | K58: =ROUNDUP((D58/4999.99)*10,-1) -> 9220 | L58: =IF(J58="N",0,K58) -> 0 | M58: L, QE:16-PPM NOT DONE, UNIT UNDER BER
...

Sheet B4-UPTIME
A1: MINISTRY OF HEALTH
A2: Deduction Mapping Report Biomedical Engineering Maintenance Services (BEMS)
A3: INDICATOR B.4 UPTIME GUARANTEE
B5: HOSPITAL NAME : | C5: INSTITUT KANSER NEGARA | N5: MONTH/YEAR : | U5: 46113
B7: STATE : | C7: WILAYAH PERSEKUTUAN PUTRAJAYA | N7: BEMS MONTHLY FEE (RM)@ 97.5% : | U7: =[15]BEMSdar!E11 -> 1437864.8
B9: COMPANY : | C9: AMBANG WIRA SDN BHD | N9: FMS MONTHLY FEE (RM) @ 2.5% : | U9: =[15]BEMSdar!E13 -> 36868.327
A11: Notes:
A12: 1) Deduction Ringgit Equivalent is based on Appendix 11 of the Agreement, Section B3 Key Deduction Indicators for BEMS
A13: 2) Deduction Value for 1st cut off is Deduction Ringgit Equivalent (per event)
A14: 3) Deduction Value for 2nd cut off is Deduction Ringgit Equivalent (per event) multiply by 2
A15: 4) Display only asset affected by deduction
A17: No. | B17: Asset No | C17: Type Code | D17: Type Description | E17: Asset Purchase cost (RM) | F17: Asset Age | G17: TRKPI % | H17: Uptime % | T17: Deduction Ringgit Equivalent (RM) | U17: Previous Deduction (Month) | W17: Deduction for the month (Y/N) | Y17: Deduction Value (RM) | AA17: Total Deduction (RM) | AB17: Remarks
H18: Jan | I18: Feb | J18: Mar | K18: Apr | L18: May | M18: Jun | N18: Jul | O18: Aug | P18: Sep | Q18: Oct | R18: Nov | S18: Dec | U18: 1st | V18: 2nd | W18: 1st | X18: 2nd | Y18: 1st | Z18: 2nd
A19: 1 | B19: IKN400440 | C19: 16-173 | D19: Sphygmomanometers, Electronic, Automatic | E19: 4510 | F19: 13 | G19: 88 | H19: 99.82733 | I19: 99.78 | J19: - | K19: - | T19: =ROUNDUP((E19/4999.99)*10,-1) -> 10 | U19: N | V19: N | W19: N | X19: N | Y19: =IF(W19="Y",T19,0) -> 0 | Z19: =IF(X19="Y",T19*2,0) -> 0 | AA19: =Y19+Z19 -> 0
A20: 2 | B20: IKN400645 | C20: 13-215 | D20: Infusion Pumps, General-Purpose | E20: 10825 | F20: 13 | G20: 88 | H20: 99.961971 | I20: 99.93 | J20: - | K20: - | T20: =ROUNDUP((E20/4999.99)*10,-1) -> 30 | U20: N | V20: N | W20: N | X20: N | Y20: =IF(W20="Y",T20,0) -> 0 | Z20: =IF(X20="Y",T20*2,0) -> 0 | AA20: =Y20+Z20 -> 0
A21: 3 | B21: IKN401714 | C21: 13-215 | D21: Infusion Pumps, General-Purpose | E21: 5800 | F21: 8 | G21: 95 | H21: 99.962034 | I21: 99.93 | J21: - | K21: - | T21: =ROUNDUP((E21/4999.99)*10,-1) -> 20 | U21: Y | V21: Y | W21: N | X21: N | Y21: =IF(W21="Y",T21,0) -> 0 | Z21: =IF(X21="Y",T21*2,0) -> 0 | AA21: =Y21+Z21 -> 0
A22: 4 | B22: IKN400446 | C22: 13-215 | D22: Infusion Pumps, General-Purpose | E22: 10825 | F22: 13 | G22: 88 | H22: 99.65 | I22: 99.68 | J22: 98.553172 | K22: - | T22: =ROUNDUP((E22/4999.99)*10,-1) -> 30 | U22: N | V22: N | W22: N | X22: N | Y22: =IF(W22="Y",T22,0) -> 0 | Z22: =IF(X22="Y",T22*2,0) -> 0 | AA22: =Y22+Z22 -> 0
A23: 5 | B23: IKN400366 | C23: 13-215 | D23: Infusion Pumps, General-Purpose | E23: 10825 | F23: 13 | G23: 88 | H23: 99.65 | I23: 99.68 | J23: 99.330998 | K23: 99.04 | T23: =ROUNDUP((E23/4999.99)*10,-1) -> 30 | U23: N | V23: N | W23: N | X23: N | Y23: =IF(W23="Y",T23,0) -> 0 | Z23: =IF(X23="Y",T23*2,0) -> 0 | AA23: =Y23+Z23 -> 0
A24: 6 | B24: IKN402165 | C24: 13-215 | D24: Infusion Pumps, General-Purpose | E24: 10825 | F24: 13 | G24: 88 | H24: 99.65 | I24: 99.45 | J24: - | K24: - | T24: =ROUNDUP((E24/4999.99)*10,-1) -> 30 | U24: N | V24: N | W24: N | X24: N | Y24: =IF(W24="Y",T24,0) -> 0 | Z24: =IF(X24="Y",T24*2,0) -> 0 | AA24: =Y24+Z24 -> 0
A25: 7 | B25: IKN400565 | C25: 12-649 | D25: Physiologic Monitoring Systems, Stress Exercise | E25: 138350 | F25: 13 | G25: 88 | H25: 99.65 | I25: 99.56 | J25: - | K25: - | T25: =ROUNDUP((E25/4999.99)*10,-1) -> 280 | U25: N | V25: N | W25: N | X25: N | Y25: =IF(W25="Y",T25,0) -> 0 | Z25: =IF(X25="Y",T25*2,0) -> 0 | AA25: =Y25+Z25 -> 0
A26: 8 | B26: IKN400439 | C26: 16-173 | D26: Sphygmomanometers, Electronic, Automatic | E26: 4510 | F26: 13 | G26: 88 | H26: 99.65 | I26: 99.53 | J26: - | K26: - | T26: =ROUNDUP((E26/4999.99)*10,-1) -> 10 | U26: N | V26: N | W26: N | X26: N | Y26: =IF(W26="Y",T26,0) -> 0 | Z26: =IF(X26="Y",T26*2,0) -> 0 | AA26: =Y26+Z26 -> 0
A27: 9 | B27: IKN401076 | C27: 12-306 | D27: Lavage Units, Surgical | E27: 5000 | F27: 13 | G27: 85 | H27: 99.65 | I27: 99.35 | J27: - | K27: - | T27: =ROUNDUP((E27/4999.99)*10,-1) -> 20 | U27: N | V27: N | W27: N | X27: N | Y27: =IF(W27="Y",T27,0) -> 0 | Z27: =IF(X27="Y",T27*2,0) -> 0 | AA27: =Y27+Z27 -> 0
A28: 10 | B28: IKN402147 | C28: 15-605 | D28: Testers (Ion Chamber Set) | E28: 142000 | F28: 4 | G28: 96 | H28: 99.65 | I28: 99.39 | J28: - | K28: - | T28: =ROUNDUP((E28/4999.99)*10,-1) -> 290 | U28: N | V28: N | W28: N | X28: N | Y28: =IF(W28="Y",T28,0) -> 0 | Z28: =IF(X28="Y",T28*2,0) -> 0 | AA28: =Y28+Z28 -> 0
A29: 11 | B29: IKN401071 | C29: 18-034 | D29: Video Image Processors, Endoscopic | E29: 80000 | F29: 13 | G29: 88 | H29: 99.65 | I29: 99.35 | J29: - | K29: - | T29: =ROUNDUP((E29/4999.99)*10,-1) -> 170 | U29: Y | V29: Y | W29: N | X29: N | Y29: =IF(W29="Y",T29,0) -> 0 | Z29: =IF(X29="Y",T29*2,0) -> 0 | AA29: =Y29+Z29 -> 0
A30: 12 | B30: IKN402081 | C30: 13-215 | D30: Infusion Pumps, General-Purpose | E30: 3500 | F30: 5 | G30: 95 | H30: 99.65 | I30: 99.68 | J30: 99.330998 | K30: 98.99 | T30: =ROUNDUP((E30/4999.99)*10,-1) -> 10 | U30: N | V30: N | W30: N | X30: N | Y30: =IF(W30="Y",T30,0) -> 0 | Z30: =IF(X30="Y",T30*2,0) -> 0 | AA30: =Y30+Z30 -> 0
A31: 13 | B31: IKN401353 | C31: 11-758 | D31: Radiographic/Fluoroscopic Units, Mobile | E31: 399000 | F31: 10 | G31: 88 | H31: 99.65 | I31: - | J31: - | K31: - | T31: =ROUNDUP((E31/4999.99)*10,-1) -> 800 | U31: N | V31: N | W31: N | X31: N | Y31: =IF(W31="Y",T31,0) -> 0 | Z31: =IF(X31="Y",T31*2,0) -> 0 | AA31: =Y31+Z31 -> 0
A32: 14 | B32: IKN400422 | C32: 13-215 | D32: Infusion Pumps, General-Purpose | E32: 10825 | F32: 13 | G32: 88 | H32: 99.65 | I32: 99.68 | J32: 99.330998 | K32: 98.87 | T32: =ROUNDUP((E32/4999.99)*10,-1) -> 30 | U32: Y | V32: N | W32: N | X32: N | Y32: =IF(W32="Y",T32,0) -> 0 | Z32: =IF(X32="Y",T32*2,0) -> 0 | AA32: =Y32+Z32 -> 0 | AB32: RW
A33: 15 | B33: IKN400482 | C33: 13-215 | D33: Infusion Pumps, General-Purpose | E33: 10825 | F33: 13 | G33: 88 | H33: 99.65 | I33: 99.61 | J33: - | K33: - | T33: =ROUNDUP((E33/4999.99)*10,-1) -> 30 | U33: N | V33: N | W33: N | X33: N | Y33: =IF(W33="Y",T33,0) -> 0 | Z33: =IF(X33="Y",T33*2,0) -> 0 | AA33: =Y33+Z33 -> 0
A34: 16 | B34: IKN400782 | C34: 17-679 | D34: Laser Imagers | E34: 83100 | F34: 13 | G34: 85 | H34: 99.65 | I34: 99.51 | J34: - | K34: - | T34: =ROUNDUP((E34/4999.99)*10,-1) -> 170 | U34: N | V34: N | W34: N | X34: N | Y34: =IF(W34="Y",T34,0) -> 0 | Z34: =IF(X34="Y",T34*2,0) -> 0 | AA34: =Y34+Z34 -> 0
A35: 17 | B35: IKN400653 | C35: 16-173 | D35: Sphygmomanometers, Electronic, Automatic | E35: 4510 | F35: 12 | G35: 88 | H35: - | I35: 99.8 | J35: 99.385529 | K35: 99.37 | T35: =ROUNDUP((E35/4999.99)*10,-1) -> 10 | U35: N | V35: N | W35: N | X35: N | Y35: =IF(W35="Y",T35,0) -> 0 | Z35: =IF(X35="Y",T35*2,0) -> 0 | AA35: =Y35+Z35 -> 0
A36: 18 | B36: IKN400171 | C36: 17-429 | D36: Ventilators, Intensive Care | E36: 151560 | F36: 12 | G36: 88 | H36: - | I36: 99.78 | J36: 99.425417 | K36: 99.08 | T36: =ROUNDUP((E36/4999.99)*10,-1) -> 310 | U36: N | V36: N | W36: N | X36: N | Y36: =IF(W36="Y",T36,0) -> 0 | Z36: =IF(X36="Y",T36*2,0) -> 0 | AA36: =Y36+Z36 -> 0
A37: 19 | B37: IKN400168 | C37: 17-429 | D37: Ventilators, Intensive Care | E37: 151560 | F37: 12 | G37: 88 | H37: - | I37: 99.9 | J37: 99.550176 | K37: 99.21 | T37: =ROUNDUP((E37/4999.99)*10,-1) -> 310 | U37: Y | V37: Y | W37: N | X37: N | Y37: =IF(W37="Y",T37,0) -> 0 | Z37: =IF(X37="Y",T37*2,0) -> 0 | AA37: =Y37+Z37 -> 0
A38: 20 | B38: IKN402184 | C38: 12-647 | D38: Physiologic Monitoring Systems, Acute Care | E38: 100000 | F38: 2 | G38: 99 | H38: - | I38: - | J38: 99.677138 | K38: 99.5 | T38: =ROUNDUP((E38/4999.99)*10,-1) -> 210 | U38: N | V38: N | W38: N | X38: N | Y38: =IF(W38="Y",T38,0) -> 0 | Z38: =IF(X38="Y",T38*2,0) -> 0 | AA38: =Y38+Z38 -> 0
A39: 21 | B39: IKN400787 | C39: 13-272 | D39: Radiographic Units, Mobile | E39: 1149550 | F39: 13 | G39: 88 | H39: - | I39: - | J39: 99.824328 | K39: 99.48 | T39: =ROUNDUP((E39/4999.99)*10,-1) -> 2300 | U39: N | V39: N | W39: N | X39: N | Y39: =IF(W39="Y",T39,0) -> 0 | Z39: =IF(X39="Y",T39*2,0) -> 0 | AA39: =Y39+Z39 -> 0
A40: 22 | B40: IKN400937 | C40: 16-173 | D40: Sphygmomanometers, Electronic, Automatic | E40: 336 | F40: 13 | G40: 88 | H40: - | I40: - | J40: 99.916396 | K40: 99.58 | T40: =ROUNDUP((E40/4999.99)*10,-1) -> 10 | U40: Y | V40: N | W40: N | X40: N | Y40: =IF(W40="Y",T40,0) -> 0 | Z40: =IF(X40="Y",T40*2,0) -> 0 | AA40: =Y40+Z40 -> 0
A41: 23 | B41: IKN401007 | C41: 15-999 | D41: Washers, Flexible Endoscope | E41: 126300 | F41: 13 | G41: 85 | H41: - | I41: - | J41: 99.925846 | K41: 99.59 | T41: =ROUNDUP((E41/4999.99)*10,-1) -> 260 | U41: N | V41: N | W41: N | X41: N | Y41: =IF(W41="Y",T41,0) -> 0 | Z41: =IF(X41="Y",T41*2,0) -> 0 | AA41: =Y41+Z41 -> 0
A42: 24 | B42: IKN400293 | C42: 17-148 | D42: Oximeters, Pulse | E42: 5410 | F42: 13 | G42: 88 | H42: - | I42: - | J42: 99.935425 | K42: 99.93 | T42: =ROUNDUP((E42/4999.99)*10,-1) -> 20 | U42: Y | V42: N | W42: N | X42: N
A43: 25 | B43: IKN400029 | C43: 12-647 | D43: Physiologic Monitoring Systems, Acute Care | E43: 105850 | F43: 13 | G43: 88 | H43: - | I43: - | J43: 99.946764 | K43: 99.95 | T43: =ROUNDUP((E43/4999.99)*10,-1) -> 220 | U43: N | V43: N | W43: N | X43: N | Y43: =IF(W43="Y",T43,0) -> 0 | Z43: =IF(X43="Y",T43*2,0) -> 0 | AA43: =Y43+Z43 -> 0
A44: 26 | B44: IKN400722 | C44: 15-104 | D44: Analyzers, Laboratory, Hematology, Platelet Aggregation | E44: 42100 | F44: 13 | G44: 85 | H44: - | I44: - | J44: 99.981897 | K44: 99.91 | T44: =ROUNDUP((E44/4999.99)*10,-1) -> 90 | U44: N | V44: N | W44: N | X44: N | Y44: =IF(W44="Y",T44,0) -> 0 | Z44: =IF(X44="Y",T44*2,0) -> 0 | AA44: =Y44+Z44 -> 0
A45: 27 | B45: IKN400200 | C45: 18-147 | D45: Mattress Systems, Alternating-Pressure | E45: 28630 | F45: 13 | G45: 85 | H45: - | I45: - | J45: - | K45: 99.664774 | T45: =ROUNDUP((E45/4999.99)*10,-1) -> 60 | U45: N | V45: N | W45: N | X45: N | Y45: =IF(W45="Y",T45,0) -> 0 | Z45: =IF(X45="Y",T45*2,0) -> 0 | AA45: =Y45+Z45 -> 0
...

Sheet B5-T&C
A1: MINISTRY OF HEALTH
A2: Deduction Mapping Report Biomedical Engineering Maintenance Services (BEMS)
A3: INDICATOR B.5 TESTING & COMMISSIONING AND WARRANTY MANAGEMENT
B5: HOSPITAL NAME : | C5: INSTITUT KANSER NEGARA | I5: MONTH/YEAR : | K5: 46113
B7: STATE : | C7: WILAYAH PERSEKUTUAN PUTRAJAYA | I7: BEMS MONTHLY FEE (RM) @ 97.5% : | K7: =BEMSdar!E11 -> 1329813.2
B9: COMPANY : | C9: AMBANG WIRA SDN BHD | I9: FMS MONTHLY FEE (RM) @ 2.5% : | K9: =BEMSdar!E13 -> 34097.773
A11: Notes:
A12: 1) Deduction Ringgit Equivalent is based on Appendix 11 of the Agreement, Section B3 Key Deduction Indicators for BEMS
A13: 2) Deduction Value is Deduction Ringgit Equivalent (per event)
A14: 3) Display only asset affected by deduction
A15: 4) *May not be applicable for unregistered asset
A16: 5) **Only applicable for under warranty management deduction
A18: No | B18: Work Order/ NCR | C18: Work Order/ NCR Date | D18: Work Order/ NCR Reference No. | E18: Work Order/ NCR Description | F18: User Location | G18: T&C Date | H18: Completion Date | I18: Asset Number* | J18: Asset Description | K18: Warranty Expiry Date** | L18: Asset Purchase Price (RM) | M18: Deduction Ringgit Equivalent (RM) | N18: Validate Status (Y/N) | O18: Deduction Value (RM) | P18: Remarks
A19: Work Order Close
A20: 1 | B20: Testing and Commissioning (T&C) | C20: 46113.631 | D20: IKNWIBE26006155 | E20: T&C - UNIT PATIENT MONITOR DI ACCU | F20: 01AE111 | G20: 46113.633 | H20: 46113.708 | I20: IKN402265 | J20: Patient Monitoring System | K20: 2 YEARS | L20: 12400 | M20: - | N20: N | O20: - | P20: RESPIMEDIC SDN BHD
A21: 2 | B21: Testing and Commissioning (T&C) | C21: 46119 | D21: IKNWIBE26006578 | E21: TNC- T&C Electrocardiograph (IKN402266) -ARAS 1 | F21: 01RT109 | G21: 46114.633 | H21: 46114.708 | I21: IKN402266 | J21: Electrocardiograph | K21: 1 YEAR | L21: 12000 | M21: - | N21: N | O21: - | P21: SUPPLIER ALAM MEDIK SDN BHD
A22: 3 | B22: Testing and Commissioning (T&C) | C22: 46119 | D22: IKNWIBE26006579 | E22: TNC -: T&C ELECTROCARDIOGRAPH (IKN402267 -ARAS 5) | F22: 05CX143 | G22: 07-Apr-2026 14:30:00 | H22: 07-Apr-2026 16:30:00 | I22: IKN402267 | J22: ELECTROCARDIOGRAPH | K22: 1 YEAR | L22: 12000 | M22: - | N22: N | O22: - | P22: SUPPLIER ALAM MEDIK SDN BHD
A23: 4 | B23: Testing and Commissioning (T&C) | C23: 46126 | D23: IKNWIBE26007001 | E23: T&C - Patient Monitoring System | F23: 06WC113 | G23: 14-Apr-2026 10:10:00 | H23: 14-Apr-2026 12:38:00 | J23: Patient Monitoring System | K23: 2 YEARS | L23: 9000 | M23: - | N23: N | O23: - | P23: SUPPLIER ALAM MEDIK SDN BHD
A24: TOTAL DEDUCTION FOR IND. B.5: | O24: =SUM(O20:O20) -> 0 | P24: -

Sheet KDI
A1: Indicator No. | B1: Indicator | E1: Frequency of Deduction | F1: Biomedical Equipment Purchase Cost (RM) | H1: Deduction Range Value (RM) | J1: Maximum Demerit Point per Work Order
F2: From | G2: To
A3: B.1 | B3: The Company shall respond to the request within the specified time frame | E3: Per event | F3: 0.00 5,000.00 10,000.00 15,000.00 20,000.00 25,000.00 30,000.00 35,000.00 40,000.00 > 45,000.00 | G3: 4,999.99 9,999.99 14,999.99 19,999.99 24,999.99 29,999.99 34,999.99 39,999.99 44,999.99 | H3: 10.00 20.00 30.00 40.00 50.00 60.00 70.00 80.00 90.00 100.00 | J3: 1
A4: B.2 | B4: The Company shall carry out repairs to restore faulty medical equipment to a specified condition when it fails to function as per manufacturer’s specification within seven (7) working days. | E4: Per day | F4: 0.00 5,000.00 10,000.00 15,000.00 20,000.00 25,000.00 30,000.00 35,000.00 40,000.00 > 45,000.00 | G4: 4,999.99 9,999.99 14,999.99 19,999.99 24,999.99 29,999.99 34,999.99 39,999.99 44,999.99 | H4: 10.00 20.00 30.00 40.00 50.00 60.00 70.00 80.00 90.00 100.00 | J4: Number of working days for the month
A5: B.3 | B5: The Company shall carry out scheduled maintenance as per schedule in accordance to the procedure as specified in Agreement. Scheduled maintenance shall include complete safety and performance tests. | E5: Per event | F5: 0.00 5,000.00 10,000.00 15,000.00 20,000.00 25,000.00 30,000.00 35,000.00 40,000.00 45,000.00 | G5: 4,999.99 9,999.99 14,999.99 19,999.99 24,999.99 29,999.99 34,999.99 39,999.99 44,999.99 49,999.99 | H5: 10.00 20.00 30.00 40.00 50.00 60.00 70.00 80.00 90.00 100.00 | J5: 1
F6: For every RM 5,000 increment of equipment cost, an increase of RM10 will be applied subsequently
A7: B.4 | B7: The Company shall ensure biomedical equipment meets the uptime target as set in the Agreement. | E7: Per event | H7: 1st level of Uptime Target (TRKPI) | I7: 2nd level of Uptime Target (80%) | J7: 2
F8: 0.00 5,000.00 10,000.00 15,000.00 20,000.00 25,000.00 30,000.00 35,000.00 40,000.00 45,000.00 | G8: 4,999.99 9,999.99 14,999.99 19,999.99 24,999.99 29,999.99 34,999.99 39,999.99 44,999.99 49,999.99 | H8: 10.00 20.00 30.00 40.00 50.00 60.00 70.00 80.00 90.00 100.00 | I8: 20.00 40.00 60.00 80.00 100.00 120.00 140.00 160.00 180.00 200.00
F9: For every RM 5,000 increment of equipment cost, an increase of RM10 will be applied subsequently for 1st Uptime Target and an increase of RM20 for 2nd Uptime Target will be applied subsequently
A10: B.5 | B10: The Company shall attend and witness T&C and manage biomedical equipment within the warranty period. | E10: Per event | F10: 0.00 5,000.00 10,000.00 15,000.00 20,000.00 25,000.00 30,000.00 35,000.00 40,000.00 45,000.00 | G10: 4,999.99 9,999.99 14,999.99 19,999.99 24,999.99 29,999.99 34,999.99 39,999.99 44,999.99 49,999.99 | H10: 10.00 20.00 30.00 40.00 50.00 60.00 70.00 80.00 90.00 100.00 | J10: 1
F11: For every RM 5,000 increment of equipment cost, an increase of RM10 will be applied subsequently

Sheet Public Holiday
A1: ­
A2: Tarikh | B2: Hari | C2: Cuti | D2: Negeri Berkenaan
A4: 46023 | B4: Khamis | C4: Tahun Baru | D4: Putrajaya
A6: 46070 | B6: Selasa | C6: Tahun Baru Cina | D6: Putrajaya
A8: 46071 | B8: Rabu | C8: Tahun Baru Cina Hari Kedua | D8: Putrajaya
A10: 46055 | B10: Isnin | C10: Hari Wilayah Persekutuan | D10: Putrajaya
A12: 46055 | B12: Isnin | C12: Hari Thaipusam | D12: Putrajaya
A14: 46088 | B14: Sabtu | C14: Hari Nuzul Al-Quran | D14: Putrajaya
A16: 46101 | B16: Sabtu | C16: Hari Raya Aidilfitri | D16: Putrajaya
A18: 46102 | B18: Sabtu | C18: Hari Raya Aidilfitri | D18: Putrajaya
A20: 46103 | B20: Ahad | C20: Hari Raya Aidilfitri Hari Kedua | D20: Putrajaya
A22: 46104 | B22: Ahad | C22: Hari Raya Aidilfitri Hari Kedua | D22: Putrajaya
A24: 46143 | B24: Jumaat | C24: Hari Pekerja | D24: Putrajaya
A26: 46173 | B26: Ahad | C26: Hari Wesak | D26: Putrajaya
... A46: 46381 | B46: Jumaat | C46: Hari Krismas | D46: Putrajaya
A49: * Subject to change (Tertakluk kepada perubahan), TBC - To be confirmed

Sheet Sheet1
A3: Equipments | B3: Group | C3: Operating Hours | D3: Operating Hours/WK (Days) | E3: Uptime Equipment | F3: Uptime Equipment | G3: Uptime Equipment
E4: < 5YRS | F4: 5-10 YRS | G4: >10 YRS
A5: Therapeutics
A6: Alternating Pressure Mattress | B6: P | C6: 12 | D6: 6 | E6: 0.96 | F6: 0.92 | G6: 0.85
A7: Aneasthesia Units and Vaporizers | B7: C | C7: 24 | D7: 7 | E7: 0.99 | F7: 0.95 | G7: 0.88
A8: Aneasthesia Ventilators | B8: C | C8: 24 | D8: 7 | E8: 0.99 | F8: 0.95 | G8: 0.88
A9: Aspirators | B9: C | C9: 24 | D9: 7 | E9: 0.99 | F9: 0.95 | G9: 0.88
A10: Defibrillators | B10: C | C10: 24 | D10: 7 | E10: 0.99 | F10: 0.95 | G10: 0.88
A11: Dental Equipment | B11: P | C11: 24 | D11: 7 | E11: 0.96 | F11: 0.92 | G11: 0.85
A12: Diathermy Units | B12: C | C12: 24 | D12: 7 | E12: 0.99 | F12: 0.95 | G12: 0.88
A13: Electrosurgical Units | B13: C | C13: 24 | D13: 7 | E13: 0.99 | F13: 0.95 | G13: 0.88
A14: Heamodialysis Units | B14: C | C14: 24 | D14: 7 | E14: 0.99 | F14: 0.95 | G14: 0.88
A15: Humidifiers | B15: C | C15: 24 | D15: 7 | E15: 0.99 | F15: 0.95 | G15: 0.88
A16: Hypo/hyperthermia Units | B16: C | C16: 24 | D16: 7 | E16: 0.99 | F16: 0.95 | G16: 0.88
A17: Incubators | B17: C | C17: 24 | D17: 7 | E17: 0.99 | F17: 0.95 | G17: 0.88
... A59: Vector Cardiographs | B59: P | C59: 12 | D59: 6 | E59: 0.96 | F59: 0.92 | G59: 0.85
A60: Analysers
A61: · Amino Acid | B61: P | C61: 12 | D61: 6 | E61: 0.96 | F61: 0.92 | G61: 0.85
A62: · Bilirubinometers | B62: P | C62: 12 | D62: 6 | E62: 0.96 | F62: 0.92 | G62: 0.85
A63: · Blood Gas | B63: P | C63: 12 | D63: 6 | E63: 0.96 | F63: 0.92 | G63: 0.85
A64: · Calcium | B64: P | C64: 12 | D64: 6 | E64: 0.96 | F64: 0.92 | G64: 0.85
A65: · Clinical Chemistry | B65: P | C65: 12 | D65: 6 | E65: 0.96 | F65: 0.92 | G65: 0.85
A66: · Coagulation | B66: P | C66: 12 | D66: 6 | E66: 0.96 | F66: 0.92 | G66: 0.85
A67: · Counter, Gamma | B67: P | C67: 12 | D67: 6 | E67: 0.96 | F67: 0.92 | G67: 0.85
A68: · Electrolyte | B68: P | C68: 12 | D68: 6 | E68: 0.96 | F68: 0.92 | G68: 0.85
A69: · Immunoassay | B69: P | C69: 12 | D69: 6 | E69: 0.96 | F69: 0.92 | G69: 0.85
A70: · Glucose | B70: P | C70: 12 | D70: 6 | E70: 0.96 | F70: 0.92 | G70: 0.85
A71: · Hematology | B71: P | C71: 12 | D71: 6 | E71: 0.96 | F71: 0.92 | G71: 0.85
A72: · Platelet Aggregation | B72: P | C72: 12 | D72: 6 | E72: 0.96 | F72: 0.92 | G72: 0.85
... A84: Spectrophotometers | B84: P | C84: 12 | D84: 6 | E84: 0.96 | F84: 0.92 | G84: 0.85

Sheet Sheet2
A4: No | B4: Asset No | C4: Asset Description | D4: Asset Purchase Price (RM) | E4: Work Order No. | G4: User Location | H4: Work Order/ Complaint Details | I4: Response Category (Emergency/ Normal) | J4: Total Response Time (minutes) | K4: Work Request Date | L4: Work Completion Date | M4: Deduction Ringgit Equivalent (RM) | N4: Indicator B.1 | Q4: Indicator B.2 | W4: Contract
F5: wo | N5: Validate Status (Y/N) | O5: Deduction Value (RM) | P5: Remarks/ Exemption | Q5: Validate Status (Y/N) | R5: Total Repair Time (day) | S5: Last date of 7 working days (dd/mm/yy) | T5: Demerit Point | U5: Deduction Value (RM) | V5: Remarks/ Exemption | X5: Total Repair Time (day) | Y5: Hours | Z5: Total Hours | AA5: Total Hours / Year | AB5: Balance Uptime | AC5: Uptime Percentage | AD5: Uptime TRKPI | AE5: Uptime Deduction Yes / No
A6: 23 | B6: IKN400966 | C6: LINEAR ACCELERATOR | D6: 12049370 | E6: 1811 | G6: RT159 | H6: Lazer Double | I6: Normal | J6: 0.010416667 | K6: 43781 | L6: 43795 | M6: =IF(D6>44999.99,100,ROUNDUP((D6/4999.99)*10,-1)) -> 100 | N6: N | O6: =IF(N6="Y",M6,0) -> 0 | P6: Response On_Time | Q6: N | R6: =L6-K6+1 -> 15 | S6: =WORKDAY(K6,6,tarikhcuti) -> 43789 | T6: =IF(L6>S6,L6-S6,0) -> 6 | U6: =M6*T6 -> 600 | W6: Strands | X6: =R6 -> 15 | Y6: 24 | Z6: =X6*Y6 -> 360 | AA6: 8072 | AB6: =AA6-Z6 -> 7712 | AC6: =AB6/8072 -> 0.95540139 | AD6: 0.92 | AE6: No
A7: 1 | B7: IKN400292 | C7: Infusion Pumps, General-Purpose | D7: 10825 | E7: 1655 | G7: WAD 8A | H7: Infucient Pump-Mesin Problem | I7: Normal | J7: 0.025694444 | K7: 43774 | L7: 43799 | M7: =IF(D7>44999.99,100,ROUNDUP((D7/4999.99)*10,-1)) -> 30 | N7: N | O7: =IF(N7="Y",M7,0) -> 0 | P7: Response On_Time | Q7: Y | R7: =L7-K7+1 -> 26 | S7: =WORKDAY(K7,6,tarikhcuti) -> 43782 | T7: =IF(L7>S7,L7-S7,0) -> 17 | U7: =M7*T7 -> 510 | W7: Strands | X7: =R7 -> 26 | Y7: 24 | Z7: =X7*Y7 -> 624 | AA7: 8072 | AB7: =AA7-Z7 -> 7448 | AC7: =AB7/8072 -> 0.92269574 | AD7: 0.95 | AE7: Yes
A8: =A7+1 -> 2 | B8: IKN400978 | C8: Scanning Systems, Computed Tomography | D8: 3557530 | E8: 1172 | G8: RT | H8: sendingg image from vsim to mosaiq | I8: Normal | J8: 0.020833333 | K8: 43770 | L8: 43782 | M8: =IF(D8>44999.99,100,ROUNDUP((D8/4999.99)*10,-1)) -> 100 | N8: N | O8: =IF(N8="Y",M8,0) -> 0 | P8: Response On_Time | Q8: N | R8: =L8-K8+1 -> 13 | S8: 43763 | T8: =R8 -> 13 | U8: =M8*T8 -> 1300 | W8: Strands | X8: =R8 -> 13 | Y8: 24 | Z8: =X8*Y8 -> 312 | AA8: 8072 | AB8: =AA8-Z8 -> 7760 | AC8: =AB8/8072 -> 0.96134787 | AD8: 0.95 | AE8: No
A9: =A8+1 -> 3 | B9: IKN400973 | C9: Scanning Systems, Computed Tomography | D9: 3557530 | E9: 1173 | G9: RT | H9: sendingg image from vsim to mosaiq | I9: Normal | J9: 0.013888889 | K9: 43770 | L9: 43782 | M9: =IF(D9>44999.99,100,ROUNDUP((D9/4999.99)*10,-1)) -> 100 | N9: N | O9: =IF(N9="Y",M9,0) -> 0 | P9: Response On_Time | Q9: N | R9: =L9-K9+1 -> 13 | S9: 43763 | T9: =R9 -> 13 | U9: =M9*T9 -> 1300 | W9: Strands | X9: =R9 -> 13 | Y9: 24 | Z9: =X9*Y9 -> 312 | AA9: 8072 | AB9: =AA9-Z9 -> 7760 | AC9: =AB9/8072 -> 0.96134787 | AD9: 0.95 | AE9: No
A10: =A9+1 -> 4 | B10: IKN400151 | C10: Mattress Systems, Alternating-Pressure | D10: 28630 | E10: 1449 | G10: WAD 7A | H10: Motor ripple mattress rosak | I10: Normal | J10: 0.027777778 | K10: 43770 | L10: 43775 | M10: =IF(D10>44999.99,100,ROUNDUP((D10/4999.99)*10,-1)) -> 60 | N10: N | O10: =IF(N10="Y",M10,0) -> 0 | P10: Response On_Time | Q10: N | R10: =L10-K10+1 -> 6 | S10: 43774 | T10: =R10 -> 6 | U10: =M10*T10 -> 360 | W10: Strands | X10: =R10 -> 6 | Y10: 24 | Z10: =X10*Y10 -> 144 | AA10: 8072 | AB10: =AA10-Z10 -> 7928 | AC10: =AB10/8072 -> 0.98216056 | AD10: 0.92 | AE10: No
A11: =A10+1 -> 5 | B11: IKN400967 | C11: Linear Accelerators | D11: 12049370 | E11: 1471 | G11: RT | H11: Table verticle movement problem | I11: Normal | J11: 0.065972222 | K11: 43770 | L11: 43773 | M11: =IF(D11>44999.99,100,ROUNDUP((D11/4999.99)*10,-1)) -> 100 | N11: N | O11: =IF(N11="Y",M11,0) -> 0 | P11: Response On_Time | Q11: N | R11: =L11-K11+1 -> 4 | S11: 43775 | T11: =R11 -> 4 | U11: =M11*T11 -> 400 | W11: Strands | X11: =R11 -> 4 | Y11: 24 | Z11: =X11*Y11 -> 96 | AA11: 8072 | AB11: =AA11-Z11 -> 7976 | AC11: =AB11/8072 -> 0.98810704 | AD11: 0.92 | AE11: No
A12: =A11+1 -> 6 | B12: NB 355296 | C12: Mattress Systems, Alternating-Pressure | D12: 28630 | E12: 1476 | G12: WAD 7B | H12: Ripple Mattress tidak boleh pump | I12: Normal | J12: 0.023611111 | K12: 43770 | L12: 43775 | M12: =IF(D12>44999.99,100,ROUNDUP((D12/4999.99)*10,-1)) -> 60 | N12: N | O12: =IF(N12="Y",M12,0) -> 0 | P12: Response On_Time | Q12: N | R12: =L12-K12+1 -> 6 | S12: 43775 | T12: =R12 -> 6 | U12: =M12*T12 -> 360 | W12: #N/A | X12: =R12 -> 6 | Y12: 24 | Z12: =X12*Y12 -> 144 | AA12: 8072 | AB12: =AA12-Z12 -> 7928 | AC12: =AB12/8072 -> 0.98216056 | AD12: 0.92 | AE12: No
A13: =A12+1 -> 7 | B13: IKN400350 | C13: Sphygmomanometers, Electronic, Automatic | D13: 4510 | E13: 1496 | G13: WAD 7B | H13: BP Set warna putih rosak. | I13: Normal | J13: 0.010416667 | K13: 43770 | L13: 43775 | M13: =IF(D13>44999.99,100,ROUNDUP((D13/4999.99)*10,-1)) -> 10 | N13: N | O13: =IF(N13="Y",M13,0) -> 0 | P13: Response On_Time | Q13: N | R13: =L13-K13+1 -> 6 | S13: 43775 | T13: =R13 -> 6 | U13: =M13*T13 -> 60 | W13: Strands | X13: =R13 -> 6 | Y13: 24 | Z13: =X13*Y13 -> 144 | AA13: 8072 | AB13: =AA13-Z13 -> 7928 | AC13: =AB13/8072 -> 0.98216056 | AD13: 0.92 | AE13: No
A14: =A13+1 -> 8 | B14: IKN400775 | C14: Scanning Systems, Ultrasonic, General-Purpose | D14: 1044560 | E14: 1535 | G14: ID | H14: Ultrasound tidak keluar gambar | I14: Normal | J14: 0.017361111 | K14: 43770 | L14: 43773 | M14: =IF(D14>44999.99,100,ROUNDUP((D14/4999.99)*10,-1)) -> 100 | N14: N | O14: =IF(N14="Y",M14,0) -> 0 | P14: Response On_Time | Q14: N | R14: =L14-K14+1 -> 4 | S14: 43776 | T14: =R14 -> 4 | U14: =M14*T14 -> 400 | W14: Strands | X14: =R14 -> 4 | Y14: 24 | Z14: =X14*Y14 -> 96 | AA14: 8072 | AB14: =AA14-Z14 -> 7976 | AC14: =AB14/8072 -> 0.98810704 | AD14: 0.95 | AE14: No
